{"data":{"asks":[["new",3824.35,108039.0],["new",3824.45,1424.0],["new",3824.6,4771.0],["new",3824.95,1000.0],["new",3825.0,5485.0],["new",3825.05,16717.0],["new",3825.15,1658.0],["new",3825.3,8972.0],["new",3825.35,14134.0],["new",3825.4,7110.0],["new",3825.45,32105.0],["new",3825.65,3.0],["new",3825.7,4443.0],["new",3825.8,11655.0],["new",3825.9,38403.0],["new",3826.0,4531.0],["new",3826.1,1658.0],["new",3826.15,4446.0],["new",3826.2,10077.0],["new",3826.6,6972069.0],["new",3843.3,5000.0],["new",3844.4,20000.0],["new",3844.45,5000.0],["new",3845.25,20000.0],["new",3850.9,80000.0],["new",3850.95,80000.0],["new",3863.35,320000.0],["new",3863.85,320000.0],["new",3891.25,50.0],["new",3891.35,50.0],["new",3904.6,50.0],["new",3912.05,50.0],["new",3953.15,50.0],["new",3974.3,50.0],["new",3992.9,50.0],["new",3994.1,50.0],["new",4000.0,1151205.0],["new",4007.75,50.0],["new",4034.0,50.0],["new",4200.0,2110000.0],["new",4650.0,4656.0],["new",5050.0,4634.0],["new",5555.0,10001.0],["new",7180.4,1.0],["new",9999.0,2.0],["new",9999.95,1.0],["new",10000.0,16.0],["new",11000.0,20.0],["new",18285.0,30000.0],["new",20000.0,3400.0],["new",38500.0,40.0],["new",40000.0,1000000.0],["new",50000.0,11.0],["new",51853.0,10.0],["new",90000.0,2000.0]],"bids":[["new",3824.3,2717.0],["new",3824.15,520.0],["new",3824.1,1000.0],["new",3823.9,9700.0],["new",3823.8,17525.0],["new",3823.75,22000.0],["new",3823.65,19994.0],["new",3823.6,16717.0],["new",3823.55,1584.0],["new",3823.4,5355.0],["new",3823.35,27629.0],["new",3823.3,2216.0],["new",3823.25,4454.0],["new",3823.15,360.0],["new",3823.1,17030.0],["new",3823.0,1327.0],["new",3822.9,4447.0],["new",3822.8,2060.0],["new",3822.75,4451.0],["new",3817.25,105000.0],["new",3817.2,105000.0],["new",3806.9,320000.0],["new",3806.85,320000.0],["new",3778.1,50.0],["new",3769.95,50.0],["new",3767.45,50.0],["new",3761.8,50.0],["new",3741.4,50.0],["new",3725.4,50.0],["new",3721.0,50.0],["new",3705.55,50.0],["new",3672.8,50.0],["new",3664.9,50.0],["new",3659.8,50.0],["new",3657.0,50.0],["new",3637.25,50.0],["new",3617.5,50.0],["new",3558.2,50.0],["new",3300.0,1000000.0],["new",3000.0,2500.0],["new",2621.55,1.0],["new",2619.55,3.0],["new",2618.55,26.0],["new",2550.0,250.0],["new",2500.0,150.0],["new",2006.4,23.0],["new",2000.0,5.0],["new",1800.0,1.0],["new",1700.0,231.0],["new",1500.0,13.0],["new",1435.0,50.0],["new",1405.3,1386.0],["new",1400.0,14.0],["new",1300.0,22.0],["new",1242.0,64580.0],["new",1234.0,120.0],["new",1215.1,223.0],["new",1200.0,713.0],["new",1199.9,10000.0],["new",1193.9,20000.0],["new",1102.0,43740.0],["new",1050.0,2.0],["new",1000.0,41050.0],["new",942.0,131220.0],["new",900.0,4600.0],["new",800.0,17400.0],["new",762.0,393660.0],["new",750.8,386.0],["new",701.0,45.0],["new",691.0,49.0],["new",681.0,53.0],["new",671.0,56.0],["new",661.0,59.0],["new",651.0,61.0],["new",641.0,61.0],["new",631.0,62.0],["new",623.45,915.0],["new",621.0,62.0],["new",611.0,60.0],["new",601.0,58.0],["new",600.0,2509.0],["new",591.0,55.0],["new",581.0,52.0],["new",571.0,47.0],["new",561.0,43.0],["new",551.0,37.0],["new",541.0,32.0],["new",531.0,27.0],["new",524.0,87474.0],["new",521.0,22.0],["new",520.0,2.0],["new",511.0,17.0],["new",501.0,13.0],["new",500.0,3121.0],["new",400.0,250039.0],["new",350.0,240.0],["new",345.0,50.0],["new",300.0,251006.0],["new",260.0,500000.0],["new",222.0,20.0],["new",212.0,2.0],["new",203.0,280.0],["new",200.0,64.0],["new",199.0,100.0],["new",195.0,2000.0],["new",192.0,2.0],["new",181.0,120000.0],["new",172.05,30.0],["new",150.0,30.0],["new",143.55,20.0],["new",140.0,100000.0],["new",135.0,200010.0],["new",130.0,300020.0],["new",125.0,400020.0],["new",121.0,12.0],["new",120.0,130.0],["new",115.0,20.0],["new",110.0,30.0],["new",105.0,20.0],["new",101.0,10.0],["new",100.0,1051.0],["new",92.0,34.0],["new",90.0,25.0],["new",60.0,220.0],["new",58.0,1.0],["new",55.0,45.0],["new",50.0,913.0],["new",45.0,10000005.0],["new",40.0,40.0],["new",32.0,5.0],["new",30.0,70.0],["new",29.0,220.0],["new",25.0,20.0],["new",23.0,100.0],["new",22.2,1.0],["new",21.0,10.0],["new",20.0,2230.0],["new",10.0,370.0],["new",9.95,1.0],["new",8.0,2.0],["new",6.0,200.0],["new",5.0,43.0],["new",4.0,1844.0],["new",1.45,1330.0],["new",1.1,7.0],["new",1.0,90.0],["new",0.5,1.0],["new",0.2,2.0]],"change_id":46343789656,"instrument_name":"ETH-PERPETUAL","timestamp":1761154813378,"type":"snapshot"},"instrument":"ETH-PERPETUAL","timestamp":1761154815183}
{"data":{"asks":[["new",107870.0,254560.0],["new",107870.5,12630.0],["new",107871.0,20.0],["new",107871.5,20.0],["new",107872.0,20.0],["new",107872.5,20.0],["new",107873.0,20.0],["new",107873.5,21620.0],["new",107874.0,25000.0],["new",107875.5,6000.0],["new",107876.5,490.0],["new",107877.0,12310.0],["new",107877.5,2100.0],["new",107881.0,8550.0],["new",107881.5,13440.0],["new",107882.0,20240.0],["new",107882.5,22340.0],["new",107886.5,11000.0],["new",107887.5,50000.0],["new",107923.5,5625750.0],["new",107955.0,100.0],["new",107966.5,10.0],["new",107997.0,5000.0],["new",108015.0,10.0],["new",108063.5,10.0],["new",108112.0,10.0],["new",108134.0,7087000.0],["new",108140.5,5000.0],["new",108160.5,20010.0],["new",108209.0,10.0],["new",108257.5,10.0],["new",108306.0,10.0],["new",108354.5,10.0],["new",108391.0,80000.0],["new",108403.5,10.0],["new",108412.5,20000.0],["new",108452.0,10.0],["new",108500.5,10.0],["new",108549.0,10.0],["new",108597.5,10.0],["new",108631.0,80000.0],["new",108643.5,320000.0],["new",108646.0,10.0],["new",108694.0,10.0],["new",108742.5,10.0],["new",108791.0,10.0],["new",108816.0,320000.0],["new",108839.5,10.0],["new",108888.5,10.0],["new",108937.0,10.0],["new",108985.5,10.0],["new",109034.0,10.0],["new",109082.5,10.0],["new",109131.0,10.0],["new",109250.5,50.0],["new",109407.0,50.0],["new",109484.5,50.0],["new",109568.5,50.0],["new",109705.5,50.0],["new",109969.0,50.0],["new",110069.5,50.0],["new",110116.0,50.0],["new",110150.5,50.0],["new",110617.0,300.0],["new",110654.0,50.0],["new",110694.5,50.0],["new",111300.0,300.0],["new",111437.5,50.0],["new",111507.5,50.0],["new",111656.5,50.0],["new",111868.0,50.0],["new",111870.0,50.0],["new",111898.0,50.0],["new",112409.0,50.0],["new",115000.0,110.0],["new",115500.0,10.0],["new",115700.0,2151520.0],["new",116000.0,10.0],["new",116500.0,10.0],["new",117000.0,10.0],["new",117500.0,10.0],["new",118000.0,10.0],["new",118500.0,10.0],["new",119000.0,10.0],["new",119500.0,10.0],["new",120000.0,10.0],["new",120500.0,10.0],["new",120653.0,10.0],["new",121000.0,10.0],["new",121500.0,10.0],["new",122000.0,10.0],["new",122500.0,10.0],["new",123000.0,10.0],["new",123500.0,10.0],["new",123737.5,1200.0],["new",124000.0,10.0],["new",124500.0,10.0],["new",124926.0,2730.0],["new",124974.5,540.0],["new",125000.0,110.0],["new",125500.0,10.0],["new",126000.0,10.0],["new",126500.0,10.0],["new",127000.0,10.0],["new",127351.5,2730.0],["new",127449.5,630.0],["new",127500.0,10.0],["new",128000.0,10.0],["new",128500.0,10.0],["new",129000.0,10.0],["new",129458.5,840.0],["new",129500.0,10.0],["new",129559.5,1500.0],["new",129924.0,630.0],["new",130976.5,10.0],["new",131091.0,111030.0],["new",139042.0,80.0],["new",150000.0,38101030.0]],"bids":[["new",107869.5,171460.0],["new",107864.0,15220.0],["new",107863.5,50000.0],["new",107862.5,1000.0],["new",107860.5,13500.0],["new",107856.0,25990.0],["new",107855.5,21980.0],["new",107855.0,24100.0],["new",107852.5,30.0],["new",107852.0,61590.0],["new",107851.5,8770.0],["new",107850.5,2100.0],["new",107850.0,20.0],["new",107849.5,13880.0],["new",107849.0,16620.0],["new",107848.0,8440.0],["new",107846.5,13870.0],["new",107845.0,33360.0],["new",107839.0,13880.0],["new",107838.0,26940.0],["new",107816.0,6462890.0],["new",107810.0,10.0],["new",107761.5,10.0],["new",107713.0,10.0],["new",107693.0,5000.0],["new",107664.5,10.0],["new",107637.0,20000.0],["new",107636.5,185000.0],["new",107616.0,10.0],["new",107605.5,8008500.0],["new",107568.0,10.0],["new",107519.5,10.0],["new",107471.0,10.0],["new",107422.5,10.0],["new",107401.0,320000.0],["new",107374.0,10.0],["new",107325.5,10.0],["new",107277.0,10.0],["new",107268.5,320000.0],["new",107228.5,10.0],["new",107180.0,10.0],["new",107145.0,50.0],["new",107131.5,10.0],["new",107083.0,10.0],["new",107034.5,10.0],["new",106986.0,10.0],["new",106937.5,10.0],["new",106889.0,10.0],["new",105390.0,50.0],["new",105300.0,300.0],["new",104909.0,50.0],["new",104510.5,50.0],["new",103000.0,10.0],["new",102500.0,10.0],["new",102055.0,1050.0],["new",102000.0,10.0],["new",101500.0,10.0],["new",101156.5,1000.0],["new",101000.0,10.0],["new",100600.0,1390.0],["new",100500.0,10.0],["new",100000.0,10492390.0],["new",99500.0,10.0],["new",99000.0,10.0],["new",98549.0,10.0],["new",98500.0,10.0],["new",98000.0,10.0],["new",97500.0,10.0],["new",97000.0,10.0],["new",96566.0,100.0],["new",96500.0,10.0],["new",96000.0,10.0],["new",95635.0,58730.0],["new",95620.0,20.0],["new",95500.0,10.0],["new",95385.0,58550.0],["new",95000.0,30000380.0],["new",94665.0,58020.0],["new",94511.0,58010.0],["new",94500.0,10.0],["new",94498.0,57950.0],["new",94236.0,57730.0],["new",94000.0,10.0],["new",93500.0,10.0],["new",93000.0,10.0],["new",92500.0,60.0],["new",92000.0,10.0],["new",91500.0,10.0],["new",91000.0,10.0],["new",90976.5,20.0],["new",90500.0,10.0],["new",90403.5,50.0],["new",90000.0,50.0],["new",89500.0,10.0],["new",89000.0,160.0],["new",88500.0,10.0],["new",88000.0,10.0],["new",87500.0,10.0],["new",87000.0,10.0],["new",86500.0,10.0],["new",86000.0,10.0],["new",85500.0,70.0],["new",85332.0,52020.0],["new",85000.0,10.0],["new",84552.0,48090.0],["new",84500.0,10.0],["new",84000.0,10.0],["new",83500.0,10.0],["new",83000.0,10.0],["new",82500.0,10.0],["new",82000.0,10.0],["new",81500.0,10.0],["new",81152.0,250.0],["new",81000.0,10.0],["new",80978.0,10.0],["new",80957.5,500000.0],["new",80940.0,60.0],["new",80746.0,250.0],["new",80500.0,10.0],["new",80496.0,250.0],["new",80183.0,100.0],["new",80168.0,10.0],["new",80000.0,130.0],["new",79691.0,250.0],["new",79500.0,10.0],["new",79426.0,170.0],["new",79366.0,10.0],["new",79041.5,100.0],["new",79017.5,100.0],["new",79000.0,10.0],["new",78668.5,300.0],["new",78500.0,10.0],["new",78000.0,10.0],["new",77911.5,520.0],["new",77500.0,10.0],["new",77132.5,500000.0],["new",77000.0,10.0],["new",76500.0,10.0],["new",76000.0,10.0],["new",75500.0,10.0],["new",75000.0,10.0],["new",74500.0,10.0],["new",74113.0,500000.0],["new",74000.0,60.0],["new",73500.0,10.0],["new",73273.5,10.0],["new",73246.5,10.0],["new",73000.0,10.0],["new",72500.0,10.0],["new",72000.0,10.0],["new",71500.0,10.0],["new",71000.0,10.0],["new",70708.5,10.0],["new",70500.0,10.0],["new",70000.0,100520.0],["new",69500.0,10.0],["new",69000.0,10.0],["new",68500.0,10.0],["new",68000.0,240.0],["new",67500.0,50.0],["new",67000.0,10.0],["new",66823.5,70.0],["new",66805.5,50.0],["new",66794.0,50.0],["new",66755.0,50.0],["new",66500.0,10.0],["new",66000.0,10.0],["new",65500.0,50.0],["new",65000.0,90.0],["new",64500.0,10.0],["new",64483.5,90.0],["new",64000.0,64090.0],["new",63900.0,150.0],["new",63755.5,160.0],["new",63500.0,10.0],["new",63027.5,290.0],["new",63000.0,10.0],["new",62500.0,10.0],["new",62299.5,500.0],["new",62100.0,60000.0],["new",62000.0,10.0],["new",61500.0,10.0],["new",61028.5,500000.0],["new",61000.0,10.0],["new",60686.0,50.0],["new",60500.0,30.0],["new",60000.0,73680.0],["new",59500.0,10.0],["new",59000.0,10.0],["new",58500.0,10.0],["new",58000.0,10.0],["new",57500.0,10.0],["new",57000.0,142510.0],["new",56500.0,10.0],["new",56000.0,140010.0],["new",55500.0,10.0],["new",55000.5,500.0],["new",55000.0,290.0],["new",54500.0,10.0],["new",54224.5,5420.0],["new",54000.0,10.0],["new",53580.5,500000.0],["new",53500.0,10.0],["new",53000.0,10.0],["new",52718.5,10.0],["new",52683.0,10.0],["new",52635.0,10.0],["new",52629.5,10.0],["new",52620.5,10.0],["new",52610.0,10.0],["new",52547.0,10.0],["new",52500.0,10.0],["new",52130.5,10.0],["new",52000.0,20.0],["new",51567.5,20.0],["new",51500.0,10.0],["new",51000.0,740.0],["new",50500.0,10.0],["new",50023.0,10.0],["new",50022.0,10.0],["new",50021.0,10.0],["new",50020.0,10.0],["new",50019.0,10.0],["new",50018.0,10.0],["new",50017.0,10.0],["new",50016.0,10.0],["new",50015.0,10.0],["new",50014.0,10.0],["new",50013.0,10.0],["new",50012.0,10.0],["new",50011.0,10.0],["new",50010.0,20.0],["new",50009.0,20.0],["new",50008.0,20.0],["new",50007.0,20.0],["new",50006.0,20.0],["new",50005.0,20.0],["new",50004.0,20.0],["new",50003.0,20.0],["new",50002.0,20.0],["new",50001.0,20.0],["new",50000.0,13750.0],["new",49500.0,10.0],["new",49133.5,25000.0],["new",49000.0,210.0],["new",48500.0,10.0],["new",48000.0,30.0],["new",47500.0,10.0],["new",47000.0,10.0],["new",46605.0,10.0],["new",46580.0,10.0],["new",46500.0,10.0],["new",46000.0,10.0],["new",45500.0,10.0],["new",45000.5,30.0],["new",45000.0,500.0],["new",44900.0,30.0],["new",44500.0,10.0],["new",44000.0,160.0],["new",43500.0,10.0],["new",43000.0,10.0],["new",42500.0,10.0],["new",42000.0,10.0],["new",41500.0,10.0],["new",41000.0,10.0],["new",40575.0,40.0],["new",40500.0,30.0],["new",40000.0,2250.0],["new",39500.0,10.0],["new",39000.0,10.0],["new",38500.0,10.0],["new",38000.0,600010.0],["new",37500.0,10.0],["new",37000.0,40010.0],["new",36500.0,10.0],["new",36000.0,10.0],["new",35500.0,10.0],["new",35000.0,401870.0],["new",34500.0,10.0],["new",34000.0,10.0],["new",33500.0,10.0],["new",33000.0,30.0],["new",32500.0,10.0],["new",32000.0,30.0],["new",31500.0,10.0],["new",31313.0,10.0],["new",31000.0,1040.0],["new",30500.0,10.0],["new",30049.0,10.0],["new",30048.0,10.0],["new",30047.0,10.0],["new",30046.0,10.0],["new",30045.0,10.0],["new",30044.0,10.0],["new",30043.0,10.0],["new",30042.0,10.0],["new",30041.0,10.0],["new",30040.0,10.0],["new",30039.0,10.0],["new",30038.0,10.0],["new",30037.0,10.0],["new",30036.0,10.0],["new",30035.0,10.0],["new",30034.0,10.0],["new",30033.0,10.0],["new",30032.0,10.0],["new",30031.0,10.0],["new",30030.0,10.0],["new",30029.0,10.0],["new",30028.0,10.0],["new",30027.0,10.0],["new",30026.0,10.0],["new",30025.0,10.0],["new",30024.0,10.0],["new",30023.0,10.0],["new",30022.0,10.0],["new",30021.0,10.0],["new",30020.0,10.0],["new",30019.0,10.0],["new",30018.0,10.0],["new",30017.0,10.0],["new",30016.0,10.0],["new",30015.0,10.0],["new",30014.0,10.0],["new",30013.0,10.0],["new",30012.0,10.0],["new",30011.0,10.0],["new",30010.0,10.0],["new",30009.0,10.0],["new",30008.0,10.0],["new",30007.0,10.0],["new",30006.0,10.0],["new",30005.0,10.0],["new",30004.0,10.0],["new",30003.0,10.0],["new",30002.0,10.0],["new",30001.0,10.0],["new",30000.0,2460.0],["new",29500.0,10.0],["new",29000.0,10.0],["new",28500.0,10.0],["new",28000.0,10.0],["new",27500.0,10.0],["new",27000.0,10.0],["new",26500.0,10.0],["new",26000.0,10.0],["new",25500.0,10.0],["new",25000.0,330.0],["new",24500.0,10.0],["new",24000.0,10.0],["new",23500.0,10.0],["new",23000.0,10.0],["new",22706.0,13850.0],["new",22500.0,108010.0],["new",22392.5,80000.0],["new",22310.5,10.0],["new",22284.5,300.0],["new",22250.0,108000.0],["new",22222.0,82600.0],["new",22209.0,500000.0],["new",22000.0,20.0],["new",21795.0,300.0],["new",21500.0,10.0],["new",21375.0,500000.0],["new",21305.5,300.0],["new",21000.0,20110.0],["new",20949.5,40.0],["new",20816.0,300.0],["new",20500.0,10.0],["new",20326.5,300.0],["new",20200.0,1000.0],["new",20100.0,1000.0],["new",20000.0,2680.0],["new",19940.0,10.0],["new",19582.0,120.0],["new",19500.0,50.0],["new",19400.0,10.0],["new",19373.0,300.0],["new",19347.5,600.0],["new",19288.5,500000.0],["new",19129.0,180.0],["new",19000.0,20.0],["new",18500.0,10.0],["new",18368.5,600.0],["new",18328.0,500000.0],["new",18000.0,90.0],["new",17612.5,500000.0],["new",17503.0,10.0],["new",17500.0,10.0],["new",17389.5,600.0],["new",17135.0,160.0],["new",17000.0,160.0],["new",16926.0,500000.0],["new",16900.0,20.0],["new",16625.0,92610.0],["new",16600.0,100000.0],["new",16575.0,100000.0],["new",16550.0,100000.0],["new",16525.0,100000.0],["new",16515.0,10.0],["new",16500.0,10.0],["new",16410.5,600.0],["new",16328.0,500000.0],["new",16141.5,2890.0],["new",16134.0,1080.0],["new",16088.0,2890.0],["new",16080.5,1080.0],["new",16034.5,2890.0],["new",16026.5,1080.0],["new",16000.0,240.0],["new",15973.0,1080.0],["new",15919.5,1080.0],["new",15866.0,1110.0],["new",15704.5,500000.0],["new",15620.0,1000.0],["new",15500.0,310010.0],["new",15444.0,100.0],["new",15431.5,600.0],["new",15400.0,10050.0],["new",15285.0,270.0],["new",15263.0,110.0],["new",15165.0,10000.0],["new",15162.5,10000.0],["new",15100.0,10.0],["new",15063.0,270.0],["new",15045.0,810.0],["new",15000.0,1100920.0],["new",14899.0,200.0],["new",14888.0,148880.0],["new",14864.5,2430.0],["new",14823.5,270.0],["new",14823.0,810.0],["new",14681.0,4800.0],["new",14565.0,2430.0],["new",14500.0,20.0],["new",14343.0,2430.0],["new",14200.0,14210.0],["new",14090.0,400.0],["new",14000.0,340.0],["new",13964.0,150000.0],["new",13835.0,13840.0],["new",13700.0,100.0],["new",13500.0,10.0],["new",13360.0,100.0],["new",13078.5,98000.0],["new",13000.0,540.0],["new",12839.0,23040.0],["new",12800.0,111360.0],["new",12510.5,150000.0],["new",12500.0,12510.0],["new",12345.0,550.0],["new",12334.0,500.0],["new",12304.5,7290.0],["new",12300.0,125880.0],["new",12232.5,30.0],["new",12200.0,500000.0],["new",12189.5,1220.0],["new",12104.0,2000.0],["new",12000.0,5030.0],["new",11937.5,2000.0],["new",11867.5,2000.0],["new",11797.5,2000.0],["new",11728.0,2000.0],["new",11700.0,4120.0],["new",11659.0,2000.0],["new",11522.0,2000.0],["new",11500.0,10.0],["new",11454.0,2000.0],["new",11450.5,20.0],["new",11420.5,30.0],["new",11360.5,90.0],["new",11240.5,270.0],["new",11230.0,200.0],["new",11200.0,10.0],["new",11187.0,2000.0],["new",11121.0,2000.0],["new",11100.0,10.0],["new",11055.5,2000.0],["new",11000.5,810.0],["new",11000.0,500410.0],["new",10990.5,2000.0],["new",10926.0,2000.0],["new",10861.5,2000.0],["new",10797.5,2000.0],["new",10734.0,2000.0],["new",10682.5,2430.0],["new",10682.0,2430.0],["new",10600.0,10.0],["new",10520.5,2430.0],["new",10500.0,20.0],["new",10399.0,10.0],["new",10200.0,130.0],["new",10179.0,50.0],["new",10172.5,810.0],["new",10164.5,2430.0],["new",10142.0,100000.0],["new",10027.5,90.0],["new",10026.0,810.0],["new",10022.0,26730.0],["new",10009.5,150.0],["new",10001.0,10.0],["new",10000.0,2087280.0],["new",9951.5,2200.0],["new",9876.0,2430.0],["new",9874.0,2430.0],["new",9866.0,100000.0],["new",9811.5,2430.0],["new",9785.5,7290.0],["new",9775.5,2430.0],["new",9743.5,2430.0],["new",9693.5,2430.0],["new",9692.5,2430.0],["new",9687.5,2430.0],["new",9687.0,24300.0],["new",9674.0,3660.0],["new",9657.5,100.0],["new",9650.0,2430.0],["new",9640.5,7290.0],["new",9632.5,1000.0],["new",9607.5,10000.0],["new",9600.0,100.0],["new",9597.0,2430.0],["new",9595.5,2430.0],["new",9582.5,97000.0],["new",9546.0,2430.0],["new",9524.5,7290.0],["new",9500.0,95010.0],["new",9411.0,8560.0],["new",9362.0,43740.0],["new",9326.5,150000.0],["new",9317.5,890.0],["new",9274.0,100000.0],["new",9250.5,7290.0],["new",9250.0,167450.0],["new",9234.0,7290.0],["new",9210.0,736800.0],["new",9155.5,550000.0],["new",9142.5,40.0],["new",9127.0,330.0],["new",9103.5,7290.0],["new",9102.5,160.0],["new",9100.0,273000.0],["new",9053.5,7290.0],["new",9047.5,7290.0],["new",9022.5,640.0],["new",9010.0,7290.0],["new",9000.0,1230.0],["new",8957.0,7290.0],["new",8900.0,100.0],["new",8878.0,2560.0],["new",8862.5,2560.0],["new",8854.0,150000.0],["new",8839.0,600.0],["new",8802.0,2560.0],["new",8800.0,100.0],["new",8785.0,9740.0],["new",8761.5,1040.0],["new",8760.0,100000.0],["new",8735.0,9000.0],["new",8700.0,100.0],["new",8685.0,9000.0],["new",8651.5,1560.0],["new",8638.5,10.0],["new",8635.0,9000.0],["new",8600.0,100.0],["new",8599.0,720.0],["new",8585.0,9000.0],["new",8571.0,1250.0],["new",8546.0,2430.0],["new",8535.0,9000.0],["new",8500.0,89310.0],["new",8485.0,9000.0],["new",8450.0,2110.0],["new",8435.0,9000.0],["new",8400.0,100.0],["new",8393.0,14630.0],["new",8385.0,9000.0],["new",8350.0,2090.0],["new",8338.5,320.0],["new",8335.0,9000.0],["new",8300.0,100.0],["new",8290.0,1600.0],["new",8285.0,9000.0],["new",8241.5,4120.0],["new",8235.0,9000.0],["new",8218.0,8100.0],["new",8200.0,100.0],["new",8185.0,9000.0],["new",8135.0,9000.0],["new",8100.0,100.0],["new",8085.0,9000.0],["new",8066.5,17120.0],["new",8035.0,9000.0],["new",8000.0,1220.0],["new",7987.5,900.0],["new",7985.0,9000.0],["new",7973.0,29260.0],["new",7900.0,100.0],["new",7892.0,700000.0],["new",7890.5,640.0],["new",7876.0,58520.0],["new",7809.0,500000.0],["new",7800.0,10100.0],["new",7777.0,10.0],["new",7700.0,100.0],["new",7672.0,150.0],["new",7659.5,150.0],["new",7600.0,100.0],["new",7555.5,10.0],["new",7523.5,40.0],["new",7500.0,2250.0],["new",7472.0,160.0],["new",7447.0,450.0],["new",7434.5,450.0],["new",7420.5,10.0],["new",7400.0,100.0],["new",7390.0,640.0],["new",7353.0,1280.0],["new",7300.0,100.0],["new",7200.0,1100.0],["new",7190.0,450.0],["new",7170.5,500.0],["new",7160.0,7160.0],["new",7100.0,100100.0],["new",7048.5,10240.0],["new",7005.5,32000.0],["new",7000.0,1110.0],["new",6931.0,5000.0],["new",6900.0,100.0],["new",6800.0,100.0],["new",6735.5,128000.0],["new",6708.0,2560.0],["new",6700.0,100.0],["new",6600.0,100.0],["new",6590.0,8620.0],["new",6589.0,6470.0],["new",6588.0,28390.0],["new",6587.0,24480.0],["new",6551.0,20.0],["new",6550.0,20.0],["new",6512.0,35850.0],["new",6511.0,69260.0],["new",6510.0,221750.0],["new",6509.0,35860.0],["new",6500.0,1600.0],["new",6418.5,10.0],["new",6400.0,100.0],["new",6395.0,64660.0],["new",6394.0,92760.0],["new",6393.0,217970.0],["new",6392.0,66110.0],["new",6390.5,10.0],["new",6300.0,100.0],["new",6295.0,100.0],["new",6286.5,138300.0],["new",6285.5,286720.0],["new",6284.5,211380.0],["new",6283.5,246610.0],["new",6259.5,750.0],["new",6200.0,100.0],["new",6186.5,73690.0],["new",6185.5,340510.0],["new",6184.5,21880.0],["new",6183.5,186350.0],["new",6169.5,450.0],["new",6100.0,100.0],["new",6050.0,40.0],["new",6000.0,2520.0],["new",5999.0,5000.0],["new",5934.0,5120.0],["new",5925.5,512000.0],["new",5900.0,210.0],["new",5800.0,100.0],["new",5700.0,100.0],["new",5600.0,100.0],["new",5500.0,2100.0],["new",5400.0,100.0],["new",5359.5,2250.0],["new",5346.0,7290.0],["new",5309.0,50.0],["new",5300.0,100.0],["new",5200.0,100.0],["new",5118.0,2560.0],["new",5100.0,100.0],["new",5050.5,450.0],["new",5044.5,150.0],["new",5005.0,10240.0],["new",5000.0,9760.0],["new",4999.0,20520.0],["new",4964.0,10.0],["new",4922.0,450.0],["new",4757.5,200.0],["new",4690.0,1000.0],["new",4610.0,10000.0],["new",4600.0,2000.0],["new",4597.0,1600.0],["new",4594.5,450.0],["new",4514.5,1000000.0],["new",4500.0,2810.0],["new",4414.0,46280.0],["new",4003.0,40.0],["new",4001.0,20.0],["new",4000.0,640.0],["new",3921.0,23040.0],["new",3845.0,40.0],["new",3800.0,10050.0],["new",3777.5,6400.0],["new",3774.0,3000.0],["new",3773.0,1000.0],["new",3754.5,1000.0],["new",3708.0,27000.0],["new",3700.0,30.0],["new",3680.0,10.0],["new",3655.0,20.0],["new",3650.0,10.0],["new",3600.0,36000.0],["new",3590.0,10000.0],["new",3567.0,500.0],["new",3500.0,230.0],["new",3400.0,80.0],["new",3230.0,10.0],["new",3228.0,10.0],["new",3200.0,20.0],["new",3001.0,20.0],["new",3000.0,7200.0],["new",2999.0,40.0],["new",2879.0,300.0],["new",2601.0,20.0],["new",2544.0,10.0],["new",2500.0,20.0],["new",2467.0,25600.0],["new",2400.0,1000.0],["new",2309.0,250.0],["new",2300.0,20.0],["new",2222.0,680.0],["new",2211.0,40.0],["new",2005.0,140.0],["new",2000.0,21250.0],["new",1999.0,10.0],["new",1994.5,5000.0],["new",1979.0,60.0],["new",1900.0,30.0],["new",1700.0,300.0],["new",1675.0,200.0],["new",1400.0,40.0],["new",1225.0,100000.0],["new",1205.0,40.0],["new",1160.0,10.0],["new",1100.0,20.0],["new",1099.0,10.0],["new",1002.5,70.0],["new",1001.5,60.0],["new",1000.5,80.0],["new",1000.0,13520.0],["new",900.0,10.0],["new",800.0,10.0],["new",648.0,40.0],["new",600.0,560.0],["new",541.5,10000.0],["new",502.0,1350.0],["new",500.0,2520.0],["new",400.0,150.0],["new",300.0,540.0],["new",288.0,10.0],["new",287.0,10.0],["new",281.0,100.0],["new",234.0,20.0],["new",222.0,300.0],["new",200.0,1220.0],["new",150.0,100.0],["new",123.0,1000.0],["new",120.0,190.0],["new",113.0,10.0],["new",110.0,100.0],["new",101.0,110.0],["new",100.0,123910.0],["new",80.0,10.0],["new",78.0,100.0],["new",70.0,20.0],["new",60.0,660.0],["new",58.0,10.0],["new",50.0,1000.0],["new",40.0,120.0],["new",35.5,20.0],["new",30.0,10400.0],["new",25.0,30.0],["new",20.0,2150.0],["new",16.5,10.0],["new",15.0,20.0],["new",13.0,30.0],["new",12.0,2160.0],["new",11.0,10.0],["new",10.0,4150.0],["new",9.0,20.0],["new",6.5,10.0],["new",6.0,40.0],["new",5.0,250.0],["new",4.0,40.0],["new",3.0,20.0],["new",2.0,10.0],["new",1.0,950.0],["new",0.5,61250.0]],"change_id":67840091761,"instrument_name":"BTC-PERPETUAL","timestamp":1761154813145,"type":"snapshot"},"instrument":"BTC-PERPETUAL","timestamp":1761154815327}
{"data":{"asks":[],"bids":[["change",3824.15,109.0]],"change_id":46343793749,"instrument_name":"ETH-PERPETUAL","prev_change_id":46343789656,"timestamp":1761154814207,"type":"change"},"instrument":"ETH-PERPETUAL","timestamp":1761154815453}
{"data":{"asks":[["delete",3824.35,0.0],["change",3825.8,87982.0]],"bids":[],"change_id":46343794670,"instrument_name":"ETH-PERPETUAL","prev_change_id":46343793749,"timestamp":1761154815077,"type":"change"},"instrument":"ETH-PERPETUAL","timestamp":1761154816379}
{"data":{"asks":[],"bids":[["delete",3824.3,0.0],["new",3821.85,4546.0]],"change_id":46343794671,"instrument_name":"ETH-PERPETUAL","prev_change_id":46343794670,"timestamp":1761154815078,"type":"change"},"instrument":"ETH-PERPETUAL","timestamp":1761154816385}
{"data":{"asks":[["delete",3824.45,0.0],["new",3825.75,17779.0]],"bids":[],"change_id":46343794674,"instrument_name":"ETH-PERPETUAL","prev_change_id":46343794671,"timestamp":1761154815117,"type":"change"},"instrument":"ETH-PERPETUAL","timestamp":1761154816423}
{"data":{"asks":[],"bids":[["delete",3824.15,0.0],["new",3821.9,21601.0]],"change_id":46343794675,"instrument_name":"ETH-PERPETUAL","prev_change_id":46343794674,"timestamp":1761154815119,"type":"change"},"instrument":"ETH-PERPETUAL","timestamp":1761154816429}
{"data":{"asks":[["delete",3824.6,0.0],["change",3825.7,12711.0]],"bids":[],"change_id":46343794907,"instrument_name":"ETH-PERPETUAL","prev_change_id":46343794675,"timestamp":1761154815156,"type":"change"},"instrument":"ETH-PERPETUAL","timestamp":1761154816468}
{"data":{"asks":[],"bids":[["delete",3824.1,0.0],["new",3822.05,4578.0]],"change_id":46343794908,"instrument_name":"ETH-PERPETUAL","prev_change_id":46343794907,"timestamp":1761154815158,"type":"change"},"instrument":"ETH-PERPETUAL","timestamp":1761154816472}
{"data":{"asks":[["delete",3824.95,0.0],["change",3825.65,39014.0]],"bids":[],"change_id":46343794911,"instrument_name":"ETH-PERPETUAL","prev_change_id":46343794908,"timestamp":1761154815196,"type":"change"},"instrument":"ETH-PERPETUAL","timestamp":1761154816511}
{"data":{"asks":[],"bids":[["delete",3823.9,0.0],["new",3822.1,1367.0]],"change_id":46343794914,"instrument_name":"ETH-PERPETUAL","prev_change_id":46343794911,"timestamp":1761154815200,"type":"change"},"instrument":"ETH-PERPETUAL","timestamp":1761154816515}
{"data":{"asks":[["delete",3825.0,0.0],["new",3825.6,36467.0]],"bids":[],"change_id":46343794915,"instrument_name":"ETH-PERPETUAL","prev_change_id":46343794914,"timestamp":1761154815236,"type":"change"},"instrument":"ETH-PERPETUAL","timestamp":1761154816550}
{"data":{"asks":[],"bids":[["delete",3823.8,0.0],["new",3822.15,15388.0]],"change_id":46343794918,"instrument_name":"ETH-PERPETUAL","prev_change_id":46343794915,"timestamp":1761154815240,"type":"change"},"instrument":"ETH-PERPETUAL","timestamp":1761154816554}
{"data":{"asks":[["delete",3825.05,0.0],["change",3825.45,64210.0]],"bids":[],"change_id":46343794921,"instrument_name":"ETH-PERPETUAL","prev_change_id":46343794918,"timestamp":1761154815276,"type":"change"},"instrument":"ETH-PERPETUAL","timestamp":1761154816603}
{"data":{"asks":[],"bids":[["delete",3823.75,0.0],["new",3822.25,4596.0]],"change_id":46343794924,"instrument_name":"ETH-PERPETUAL","prev_change_id":46343794921,"timestamp":1761154815280,"type":"change"},"instrument":"ETH-PERPETUAL","timestamp":1761154816607}
{"data":{"asks":[["delete",3825.15,0.0],["change",3825.4,26670.0]],"bids":[],"change_id":46343794951,"instrument_name":"ETH-PERPETUAL","prev_change_id":46343794924,"timestamp":1761154815315,"type":"change"},"instrument":"ETH-PERPETUAL","timestamp":1761154816634}
{"data":{"asks":[],"bids":[["delete",3823.65,0.0],["new",3822.3,1615.0]],"change_id":46343794955,"instrument_name":"ETH-PERPETUAL","prev_change_id":46343794951,"timestamp":1761154815321,"type":"change"},"instrument":"ETH-PERPETUAL","timestamp":1761154816642}
{"data":{"asks":[["change",3825.3,4447.0]],"bids":[],"change_id":46343794961,"instrument_name":"ETH-PERPETUAL","prev_change_id":46343794955,"timestamp":1761154815356,"type":"change"},"instrument":"ETH-PERPETUAL","timestamp":1761154816687}
{"data":{"asks":[],"bids":[["delete",3823.6,0.0],["new",3822.4,6445.0]],"change_id":46343794964,"instrument_name":"ETH-PERPETUAL","prev_change_id":46343794961,"timestamp":1761154815362,"type":"change"},"instrument":"ETH-PERPETUAL","timestamp":1761154816692}
{"data":{"asks":[["new",3825.2,4425.0],["delete",3825.35,0.0]],"bids":[],"change_id":46343794988,"instrument_name":"ETH-PERPETUAL","prev_change_id":46343794964,"timestamp":1761154815399,"type":"change"},"instrument":"ETH-PERPETUAL","timestamp":1761154816747}
{"data":{"asks":[],"bids":[["delete",3823.55,0.0],["new",3822.6,1445.0]],"change_id":46343795012,"instrument_name":"ETH-PERPETUAL","prev_change_id":46343794988,"timestamp":1761154815403,"type":"change"},"instrument":"ETH-PERPETUAL","timestamp":1761154816754}
{"data":{"asks":[["new",3825.15,11734.0],["change",3825.4,19560.0]],"bids":[],"change_id":46343795368,"instrument_name":"ETH-PERPETUAL","prev_change_id":46343795012,"timestamp":1761154815440,"type":"change"},"instrument":"ETH-PERPETUAL","timestamp":1761154816792}
{"data":{"asks":[],"bids":[["delete",3823.4,0.0],["new",3822.65,16592.0]],"change_id":46343795373,"instrument_name":"ETH-PERPETUAL","prev_change_id":46343795368,"timestamp":1761154815445,"type":"change"},"instrument":"ETH-PERPETUAL","timestamp":1761154816799}
{"data":{"asks":[["new",3825.05,16717.0],["change",3825.45,32105.0]],"bids":[],"change_id":46343795382,"instrument_name":"ETH-PERPETUAL","prev_change_id":46343795373,"timestamp":1761154815480,"type":"change"},"instrument":"ETH-PERPETUAL","timestamp":1761154816835}
{"data":{"asks":[],"bids":[["delete",3823.35,0.0],["change",3822.75,7314.0]],"change_id":46343795387,"instrument_name":"ETH-PERPETUAL","prev_change_id":46343795382,"timestamp":1761154815485,"type":"change"},"instrument":"ETH-PERPETUAL","timestamp":1761154816839}
{"data":{"asks":[["new",3825.0,6193.0],["change",3825.65,39011.0]],"bids":[],"change_id":46343795512,"instrument_name":"ETH-PERPETUAL","prev_change_id":46343795387,"timestamp":1761154815521,"type":"change"},"instrument":"ETH-PERPETUAL","timestamp":1761154816866}
{"data":{"asks":[],"bids":[["delete",3823.3,0.0],["change",3822.8,11072.0]],"change_id":46343795537,"instrument_name":"ETH-PERPETUAL","prev_change_id":46343795512,"timestamp":1761154815525,"type":"change"},"instrument":"ETH-PERPETUAL","timestamp":1761154816869}
{"data":{"asks":[["new",3824.75,1658.0],["change",3825.7,8268.0]],"bids":[],"change_id":46343795540,"instrument_name":"ETH-PERPETUAL","prev_change_id":46343795537,"timestamp":1761154815559,"type":"change"},"instrument":"ETH-PERPETUAL","timestamp":1761154816895}
{"data":{"asks":[],"bids":[["delete",3823.25,0.0],["new",3822.85,12500.0]],"change_id":46343795547,"instrument_name":"ETH-PERPETUAL","prev_change_id":46343795540,"timestamp":1761154815566,"type":"change"},"instrument":"ETH-PERPETUAL","timestamp":1761154816904}
{"data":{"asks":[["new",3824.6,5771.0],["change",3825.8,76327.0]],"bids":[],"change_id":46343795551,"instrument_name":"ETH-PERPETUAL","prev_change_id":46343795547,"timestamp":1761154815598,"type":"change"},"instrument":"ETH-PERPETUAL","timestamp":1761154816939}
{"data":{"asks":[],"bids":[["delete",3823.15,0.0],["change",3822.9,21164.0]],"change_id":46343795562,"instrument_name":"ETH-PERPETUAL","prev_change_id":46343795551,"timestamp":1761154815607,"type":"change"},"instrument":"ETH-PERPETUAL","timestamp":1761154816946}
{"data":{"asks":[["new",3824.55,9700.0],["delete",3825.9,0.0]],"bids":[],"change_id":46343795565,"instrument_name":"ETH-PERPETUAL","prev_change_id":46343795562,"timestamp":1761154815638,"type":"change"},"instrument":"ETH-PERPETUAL","timestamp":1761154816981}
{"data":{"asks":[],"bids":[["delete",3823.1,0.0],["change",3823.0,30703.0]],"change_id":46343795579,"instrument_name":"ETH-PERPETUAL","prev_change_id":46343795565,"timestamp":1761154815646,"type":"change"},"instrument":"ETH-PERPETUAL","timestamp":1761154816988}
{"data":{"asks":[["new",3824.4,4618.0],["delete",3826.0,0.0]],"bids":[],"change_id":46343795622,"instrument_name":"ETH-PERPETUAL","prev_change_id":46343795579,"timestamp":1761154815677,"type":"change"},"instrument":"ETH-PERPETUAL","timestamp":1761154817026}
{"data":{"asks":[],"bids":[["new",3823.1,22000.0],["change",3823.0,29376.0]],"change_id":46343795631,"instrument_name":"ETH-PERPETUAL","prev_change_id":46343795622,"timestamp":1761154815688,"type":"change"},"instrument":"ETH-PERPETUAL","timestamp":1761154817034}
{"data":{"asks":[["new",3824.35,25272.0],["delete",3826.1,0.0]],"bids":[],"change_id":46343795636,"instrument_name":"ETH-PERPETUAL","prev_change_id":46343795631,"timestamp":1761154815719,"type":"change"},"instrument":"ETH-PERPETUAL","timestamp":1761154817180}
{"data":{"asks":[],"bids":[["new",3823.15,360.0],["change",3822.9,16717.0]],"change_id":46343795643,"instrument_name":"ETH-PERPETUAL","prev_change_id":46343795636,"timestamp":1761154815732,"type":"change"},"instrument":"ETH-PERPETUAL","timestamp":1761154817197}
{"data":{"asks":[["new",3824.3,11350.0],["delete",3826.15,0.0]],"bids":[],"change_id":46343795720,"instrument_name":"ETH-PERPETUAL","prev_change_id":46343795643,"timestamp":1761154815766,"type":"change"},"instrument":"ETH-PERPETUAL","timestamp":1761154817266}
{"data":{"asks":[],"bids":[["new",3823.25,1000.0],["change",3822.8,9012.0]],"change_id":46343795727,"instrument_name":"ETH-PERPETUAL","prev_change_id":46343795720,"timestamp":1761154815772,"type":"change"},"instrument":"ETH-PERPETUAL","timestamp":1761154817270}
{"data":{"asks":[["new",3824.25,12670.0],["delete",3826.2,0.0]],"bids":[],"change_id":46343795733,"instrument_name":"ETH-PERPETUAL","prev_change_id":46343795727,"timestamp":1761154815806,"type":"change"},"instrument":"ETH-PERPETUAL","timestamp":1761154817275}
{"data":{"asks":[],"bids":[["new",3823.75,8.0],["change",3822.75,2863.0]],"change_id":46343795742,"instrument_name":"ETH-PERPETUAL","prev_change_id":46343795733,"timestamp":1761154815812,"type":"change"},"instrument":"ETH-PERPETUAL","timestamp":1761154817278}
{"data":{"asks":[["new",3824.2,129298.0]],"bids":[],"change_id":46343795749,"instrument_name":"ETH-PERPETUAL","prev_change_id":46343795742,"timestamp":1761154815845,"type":"change"},"instrument":"ETH-PERPETUAL","timestamp":1761154817286}
{"data":{"asks":[],"bids":[["new",3824.15,42.0]],"change_id":46343795758,"instrument_name":"ETH-PERPETUAL","prev_change_id":46343795749,"timestamp":1761154815853,"type":"change"},"instrument":"ETH-PERPETUAL","timestamp":1761154817299}
{"data":{"asks":[["new",3826.2,6972069.0],["delete",3826.6,0.0]],"bids":[],"change_id":46343795929,"instrument_name":"ETH-PERPETUAL","prev_change_id":46343795758,"timestamp":1761154815931,"type":"change"},"instrument":"ETH-PERPETUAL","timestamp":1761154817330}
{"data":{"asks":[["change",3824.6,7683.0]],"bids":[],"change_id":46343797069,"instrument_name":"ETH-PERPETUAL","prev_change_id":46343795929,"timestamp":1761154816784,"type":"change"},"instrument":"ETH-PERPETUAL","timestamp":1761154818261}
{"data":{"asks":[["delete",107870.0,0.0],["new",107898.5,50000.0]],"bids":[],"change_id":67840096521,"instrument_name":"BTC-PERPETUAL","prev_change_id":67840091761,"timestamp":1761154816785,"type":"change"},"instrument":"BTC-PERPETUAL","timestamp":1761154818267}
{"data":{"asks":[],"bids":[["delete",107869.5,0.0],["new",107837.5,10870.0]],"change_id":67840096522,"instrument_name":"BTC-PERPETUAL","prev_change_id":67840096521,"timestamp":1761154816786,"type":"change"},"instrument":"BTC-PERPETUAL","timestamp":1761154818270}
{"data":{"asks":[["delete",107870.5,0.0],["new",107897.5,95080.0]],"bids":[],"change_id":67840096574,"instrument_name":"BTC-PERPETUAL","prev_change_id":67840096522,"timestamp":1761154816825,"type":"change"},"instrument":"BTC-PERPETUAL","timestamp":1761154818275}
{"data":{"asks":[],"bids":[["delete",107864.0,0.0],["change",107839.0,27760.0]],"change_id":67840096575,"instrument_name":"BTC-PERPETUAL","prev_change_id":67840096574,"timestamp":1761154816827,"type":"change"},"instrument":"BTC-PERPETUAL","timestamp":1761154818287}
{"data":{"asks":[["delete",107871.0,0.0],["new",107894.5,1000.0]],"bids":[],"change_id":67840096576,"instrument_name":"BTC-PERPETUAL","prev_change_id":67840096575,"timestamp":1761154816865,"type":"change"},"instrument":"BTC-PERPETUAL","timestamp":1761154818318}
{"data":{"asks":[],"bids":[["delete",107863.5,0.0],["new",107841.0,50300.0]],"change_id":67840096577,"instrument_name":"BTC-PERPETUAL","prev_change_id":67840096576,"timestamp":1761154816867,"type":"change"},"instrument":"BTC-PERPETUAL","timestamp":1761154818347}
{"data":{"asks":[["delete",107871.5,0.0],["new",107893.5,57710.0]],"bids":[],"change_id":67840096582,"instrument_name":"BTC-PERPETUAL","prev_change_id":67840096577,"timestamp":1761154816905,"type":"change"},"instrument":"BTC-PERPETUAL","timestamp":1761154818406}
{"data":{"asks":[],"bids":[["delete",107862.5,0.0],["new",107841.5,9230.0]],"change_id":67840096585,"instrument_name":"BTC-PERPETUAL","prev_change_id":67840096582,"timestamp":1761154816907,"type":"change"},"instrument":"BTC-PERPETUAL","timestamp":1761154818433}
{"data":{"asks":[["delete",107872.0,0.0],["new",107892.5,33290.0]],"bids":[],"change_id":67840096587,"instrument_name":"BTC-PERPETUAL","prev_change_id":67840096585,"timestamp":1761154816944,"type":"change"},"instrument":"BTC-PERPETUAL","timestamp":1761154818444}
{"data":{"asks":[],"bids":[["delete",107860.5,0.0],["change",107845.0,66720.0]],"change_id":67840096589,"instrument_name":"BTC-PERPETUAL","prev_change_id":67840096587,"timestamp":1761154816949,"type":"change"},"instrument":"BTC-PERPETUAL","timestamp":1761154818449}
{"data":{"asks":[["delete",107872.5,0.0],["new",107889.5,12700.0]],"bids":[],"change_id":67840096591,"instrument_name":"BTC-PERPETUAL","prev_change_id":67840096589,"timestamp":1761154816984,"type":"change"},"instrument":"BTC-PERPETUAL","timestamp":1761154818478}
{"data":{"asks":[],"bids":[["delete",107856.0,0.0],["change",107846.5,27740.0]],"change_id":67840096593,"instrument_name":"BTC-PERPETUAL","prev_change_id":67840096591,"timestamp":1761154816989,"type":"change"},"instrument":"BTC-PERPETUAL","timestamp":1761154818483}
{"data":{"asks":[["delete",107873.0,0.0],["new",107888.5,2100.0]],"bids":[],"change_id":67840096708,"instrument_name":"BTC-PERPETUAL","prev_change_id":67840096593,"timestamp":1761154817024,"type":"change"},"instrument":"BTC-PERPETUAL","timestamp":1761154818487}
{"data":{"asks":[],"bids":[["delete",107855.5,0.0],["new",107847.5,8440.0]],"change_id":67840096712,"instrument_name":"BTC-PERPETUAL","prev_change_id":67840096708,"timestamp":1761154817028,"type":"change"},"instrument":"BTC-PERPETUAL","timestamp":1761154818495}
{"data":{"asks":[["delete",107873.5,0.0],["new",107888.0,11000.0]],"bids":[],"change_id":67840096715,"instrument_name":"BTC-PERPETUAL","prev_change_id":67840096712,"timestamp":1761154817063,"type":"change"},"instrument":"BTC-PERPETUAL","timestamp":1761154818535}
{"data":{"asks":[],"bids":[["delete",107855.0,0.0],["change",107849.0,32500.0]],"change_id":67840096718,"instrument_name":"BTC-PERPETUAL","prev_change_id":67840096715,"timestamp":1761154817068,"type":"change"},"instrument":"BTC-PERPETUAL","timestamp":1761154818540}
{"data":{"asks":[["delete",107874.0,0.0],["change",107887.5,100000.0]],"bids":[],"change_id":67840096721,"instrument_name":"BTC-PERPETUAL","prev_change_id":67840096718,"timestamp":1761154817103,"type":"change"},"instrument":"BTC-PERPETUAL","timestamp":1761154818590}
{"data":{"asks":[],"bids":[["delete",107852.5,0.0],["change",107849.5,15980.0]],"change_id":67840096724,"instrument_name":"BTC-PERPETUAL","prev_change_id":67840096721,"timestamp":1761154817108,"type":"change"},"instrument":"BTC-PERPETUAL","timestamp":1761154818594}
{"data":{"asks":[["delete",107875.5,0.0],["new",107887.0,20740.0]],"bids":[],"change_id":67840096728,"instrument_name":"BTC-PERPETUAL","prev_change_id":67840096724,"timestamp":1761154817143,"type":"change"},"instrument":"BTC-PERPETUAL","timestamp":1761154818616}
{"data":{"asks":[],"bids":[["delete",107852.0,0.0],["change",107850.0,61630.0]],"change_id":67840096731,"instrument_name":"BTC-PERPETUAL","prev_change_id":67840096728,"timestamp":1761154817148,"type":"change"},"instrument":"BTC-PERPETUAL","timestamp":1761154818627}
{"data":{"asks":[["delete",107876.5,0.0],["change",107882.5,44830.0]],"bids":[],"change_id":67840096854,"instrument_name":"BTC-PERPETUAL","prev_change_id":67840096731,"timestamp":1761154817185,"type":"change"},"instrument":"BTC-PERPETUAL","timestamp":1761154818671}
{"data":{"asks":[],"bids":[["delete",107851.5,0.0],["change",107850.5,21120.0]],"change_id":67840097071,"instrument_name":"BTC-PERPETUAL","prev_change_id":67840096854,"timestamp":1761154817193,"type":"change"},"instrument":"BTC-PERPETUAL","timestamp":1761154818682}
{"data":{"asks":[["delete",107877.0,0.0],["new",107880.5,13440.0]],"bids":[],"change_id":67840097096,"instrument_name":"BTC-PERPETUAL","prev_change_id":67840097071,"timestamp":1761154817226,"type":"change"},"instrument":"BTC-PERPETUAL","timestamp":1761154818783}
{"data":{"asks":[],"bids":[["new",107855.0,20.0],["change",107850.5,19020.0]],"change_id":67840097146,"instrument_name":"BTC-PERPETUAL","prev_change_id":67840097096,"timestamp":1761154817236,"type":"change"},"instrument":"BTC-PERPETUAL","timestamp":1761154818826}
{"data":{"asks":[["delete",107877.5,0.0],["new",107880.0,3690.0]],"bids":[],"change_id":67840097232,"instrument_name":"BTC-PERPETUAL","prev_change_id":67840097146,"timestamp":1761154817266,"type":"change"},"instrument":"BTC-PERPETUAL","timestamp":1761154818870}
{"data":{"asks":[],"bids":[["new",107858.5,8650.0],["change",107850.0,61610.0]],"change_id":67840097237,"instrument_name":"BTC-PERPETUAL","prev_change_id":67840097232,"timestamp":1761154817275,"type":"change"},"instrument":"BTC-PERPETUAL","timestamp":1761154818875}
{"data":{"asks":[["new",107877.5,2100.0],["delete",107881.0,0.0]],"bids":[],"change_id":67840097274,"instrument_name":"BTC-PERPETUAL","prev_change_id":67840097237,"timestamp":1761154817306,"type":"change"},"instrument":"BTC-PERPETUAL","timestamp":1761154818878}
{"data":{"asks":[],"bids":[["new",107860.5,2590.0],["change",107849.5,2100.0]],"change_id":67840097279,"instrument_name":"BTC-PERPETUAL","prev_change_id":67840097274,"timestamp":1761154817315,"type":"change"},"instrument":"BTC-PERPETUAL","timestamp":1761154818882}
{"data":{"asks":[["new",107875.5,6000.0],["delete",107881.5,0.0]],"bids":[],"change_id":67840097284,"instrument_name":"BTC-PERPETUAL","prev_change_id":67840097279,"timestamp":1761154817346,"type":"change"},"instrument":"BTC-PERPETUAL","timestamp":1761154818889}
{"data":{"asks":[],"bids":[["new",107861.0,11020.0],["change",107849.0,15880.0]],"change_id":67840097350,"instrument_name":"BTC-PERPETUAL","prev_change_id":67840097284,"timestamp":1761154817355,"type":"change"},"instrument":"BTC-PERPETUAL","timestamp":1761154818894}
{"data":{"asks":[["new",107874.0,20.0],["delete",107882.0,0.0]],"bids":[],"change_id":67840097537,"instrument_name":"BTC-PERPETUAL","prev_change_id":67840097350,"timestamp":1761154817387,"type":"change"},"instrument":"BTC-PERPETUAL","timestamp":1761154818905}
{"data":{"asks":[],"bids":[["new",107861.5,36980.0],["delete",107848.0,0.0]],"change_id":67840097544,"instrument_name":"BTC-PERPETUAL","prev_change_id":67840097537,"timestamp":1761154817409,"type":"change"},"instrument":"BTC-PERPETUAL","timestamp":1761154818914}
{"data":{"asks":[["new",107873.5,25020.0],["change",107882.5,22490.0]],"bids":[],"change_id":67840097549,"instrument_name":"BTC-PERPETUAL","prev_change_id":67840097544,"timestamp":1761154817428,"type":"change"},"instrument":"BTC-PERPETUAL","timestamp":1761154818931}
{"data":{"asks":[],"bids":[["new",107862.0,13330.0],["change",107846.5,13870.0]],"change_id":67840097556,"instrument_name":"BTC-PERPETUAL","prev_change_id":67840097549,"timestamp":1761154817450,"type":"change"},"instrument":"BTC-PERPETUAL","timestamp":1761154818935}
{"data":{"asks":[["new",107873.0,20.0],["delete",107886.5,0.0]],"bids":[],"change_id":67840097661,"instrument_name":"BTC-PERPETUAL","prev_change_id":67840097556,"timestamp":1761154817467,"type":"change"},"instrument":"BTC-PERPETUAL","timestamp":1761154818956}
{"data":{"asks":[],"bids":[["new",107862.5,1000.0],["change",107845.0,33360.0]],"change_id":67840097668,"instrument_name":"BTC-PERPETUAL","prev_change_id":67840097661,"timestamp":1761154817490,"type":"change"},"instrument":"BTC-PERPETUAL","timestamp":1761154818999}
{"data":{"asks":[["new",107872.5,20.0],["change",107887.5,50000.0]],"bids":[],"change_id":67840097673,"instrument_name":"BTC-PERPETUAL","prev_change_id":67840097668,"timestamp":1761154817507,"type":"change"},"instrument":"BTC-PERPETUAL","timestamp":1761154819033}
{"data":{"asks":[],"bids":[["new",107869.0,500.0],["change",107839.0,13880.0]],"change_id":67840097681,"instrument_name":"BTC-PERPETUAL","prev_change_id":67840097673,"timestamp":1761154817530,"type":"change"},"instrument":"BTC-PERPETUAL","timestamp":1761154819101}
{"data":{"asks":[["new",107870.0,138750.0]],"bids":[],"change_id":67840097687,"instrument_name":"BTC-PERPETUAL","prev_change_id":67840097681,"timestamp":1761154817546,"type":"change"},"instrument":"BTC-PERPETUAL","timestamp":1761154819153}
{"data":{"asks":[],"bids":[["new",107869.5,219580.0],["delete",107838.0,0.0]],"change_id":67840097847,"instrument_name":"BTC-PERPETUAL","prev_change_id":67840097687,"timestamp":1761154817570,"type":"change"},"instrument":"BTC-PERPETUAL","timestamp":1761154819194}
{"data":{"asks":[],"bids":[["new",3806.95,320000.0],["delete",3806.85,0.0]],"change_id":46343798160,"instrument_name":"ETH-PERPETUAL","prev_change_id":46343797069,"timestamp":1761154817674,"type":"change"},"instrument":"ETH-PERPETUAL","timestamp":1761154819236}
{"data":{"asks":[],"bids":[["change",3817.2,25000.0],["change",3806.95,400000.0]],"change_id":46343798161,"instrument_name":"ETH-PERPETUAL","prev_change_id":46343798160,"timestamp":1761154817675,"type":"change"},"instrument":"ETH-PERPETUAL","timestamp":1761154819240}
{"data":{"asks":[],"bids":[["new",3817.3,20000.0],["change",3817.2,5000.0]],"change_id":46343798162,"instrument_name":"ETH-PERPETUAL","prev_change_id":46343798161,"timestamp":1761154817676,"type":"change"},"instrument":"ETH-PERPETUAL","timestamp":1761154819243}
{"data":{"asks":[],"bids":[["change",3817.3,25000.0],["delete",3817.2,0.0]],"change_id":46343798163,"instrument_name":"ETH-PERPETUAL","prev_change_id":46343798162,"timestamp":1761154817677,"type":"change"},"instrument":"ETH-PERPETUAL","timestamp":1761154819246}
{"data":{"asks":[],"bids":[["new",107629.0,8008500.0],["delete",107605.5,0.0]],"change_id":67840100293,"instrument_name":"BTC-PERPETUAL","prev_change_id":67840097847,"timestamp":1761154819479,"type":"change"},"instrument":"BTC-PERPETUAL","timestamp":1761154821179}
{"data":{"asks":[],"bids":[["new",107614.0,320000.0],["delete",107401.0,0.0]],"change_id":67840100294,"instrument_name":"BTC-PERPETUAL","prev_change_id":67840100293,"timestamp":1761154819528,"type":"change"},"instrument":"BTC-PERPETUAL","timestamp":1761154821181}
{"data":{"asks":[["delete",108134.0,0.0],["new",108157.5,7087000.0]],"bids":[],"change_id":67840100515,"instrument_name":"BTC-PERPETUAL","prev_change_id":67840100294,"timestamp":1761154819824,"type":"change"},"instrument":"BTC-PERPETUAL","timestamp":1761154821518}
{"data":{"asks":[["change",3824.2,131210.0]],"bids":[],"change_id":46343801059,"instrument_name":"ETH-PERPETUAL","prev_change_id":46343798163,"timestamp":1761154820220,"type":"change"},"instrument":"ETH-PERPETUAL","timestamp":1761154821864}
{"data":{"asks":[["change",3824.2,1912.0],["new",3826.9,1328.0]],"bids":[],"change_id":46343801084,"instrument_name":"ETH-PERPETUAL","prev_change_id":46343801059,"timestamp":1761154820328,"type":"change"},"instrument":"ETH-PERPETUAL","timestamp":1761154821980}
{"data":{"asks":[],"bids":[["delete",3824.15,0.0],["new",3823.4,1926.0]],"change_id":46343801085,"instrument_name":"ETH-PERPETUAL","prev_change_id":46343801084,"timestamp":1761154820329,"type":"change"},"instrument":"ETH-PERPETUAL","timestamp":1761154821986}
{"data":{"asks":[],"bids":[["change",107637.0,340000.0],["delete",107268.5,0.0]],"change_id":67840101173,"instrument_name":"BTC-PERPETUAL","prev_change_id":67840100515,"timestamp":1761154820352,"type":"change"},"instrument":"BTC-PERPETUAL","timestamp":1761154822006}
{"data":{"asks":[["delete",3824.25,0.0],["new",3826.7,6032.0]],"bids":[],"change_id":46343801086,"instrument_name":"ETH-PERPETUAL","prev_change_id":46343801085,"timestamp":1761154820369,"type":"change"},"instrument":"ETH-PERPETUAL","timestamp":1761154822024}
{"data":{"asks":[],"bids":[["delete",3823.75,0.0],["new",3823.55,4439.0]],"change_id":46343801087,"instrument_name":"ETH-PERPETUAL","prev_change_id":46343801086,"timestamp":1761154820370,"type":"change"},"instrument":"ETH-PERPETUAL","timestamp":1761154822035}
{"data":{"asks":[["delete",3824.3,0.0],["new",3826.6,3012.0]],"bids":[],"change_id":46343801252,"instrument_name":"ETH-PERPETUAL","prev_change_id":46343801087,"timestamp":1761154820414,"type":"change"},"instrument":"ETH-PERPETUAL","timestamp":1761154822092}
{"data":{"asks":[],"bids":[["new",3823.6,21311.0],["delete",3823.25,0.0]],"change_id":46343801254,"instrument_name":"ETH-PERPETUAL","prev_change_id":46343801252,"timestamp":1761154820418,"type":"change"},"instrument":"ETH-PERPETUAL","timestamp":1761154822100}
{"data":{"asks":[["delete",3824.35,0.0],["new",3826.55,10076.0]],"bids":[],"change_id":46343801495,"instrument_name":"ETH-PERPETUAL","prev_change_id":46343801254,"timestamp":1761154820454,"type":"change"},"instrument":"ETH-PERPETUAL","timestamp":1761154822154}
{"data":{"asks":[],"bids":[["new",3823.7,8.0],["delete",3823.15,0.0]],"change_id":46343801503,"instrument_name":"ETH-PERPETUAL","prev_change_id":46343801495,"timestamp":1761154820463,"type":"change"},"instrument":"ETH-PERPETUAL","timestamp":1761154822158}
{"data":{"asks":[["delete",3824.4,0.0],["new",3826.4,4445.0]],"bids":[],"change_id":46343801520,"instrument_name":"ETH-PERPETUAL","prev_change_id":46343801503,"timestamp":1761154820493,"type":"change"},"instrument":"ETH-PERPETUAL","timestamp":1761154822162}
{"data":{"asks":[],"bids":[["new",3823.75,1650.0],["delete",3823.1,0.0]],"change_id":46343801522,"instrument_name":"ETH-PERPETUAL","prev_change_id":46343801520,"timestamp":1761154820502,"type":"change"},"instrument":"ETH-PERPETUAL","timestamp":1761154822167}
{"data":{"asks":[["delete",3824.55,0.0],["change",3826.2,7006195.0]],"bids":[],"change_id":46343801667,"instrument_name":"ETH-PERPETUAL","prev_change_id":46343801522,"timestamp":1761154820534,"type":"change"},"instrument":"ETH-PERPETUAL","timestamp":1761154822248}
{"data":{"asks":[],"bids":[["change",107637.0,660000.0],["delete",107614.0,0.0]],"change_id":67840101516,"instrument_name":"BTC-PERPETUAL","prev_change_id":67840101173,"timestamp":1761154820545,"type":"change"},"instrument":"BTC-PERPETUAL","timestamp":1761154822259}
{"data":{"asks":[],"bids":[["new",3823.8,4445.0],["delete",3823.0,0.0]],"change_id":46343801668,"instrument_name":"ETH-PERPETUAL","prev_change_id":46343801667,"timestamp":1761154820543,"type":"change"},"instrument":"ETH-PERPETUAL","timestamp":1761154822290}
{"data":{"asks":[["change",3824.6,1912.0],["new",3826.15,4446.0]],"bids":[],"change_id":46343801673,"instrument_name":"ETH-PERPETUAL","prev_change_id":46343801668,"timestamp":1761154820574,"type":"change"},"instrument":"ETH-PERPETUAL","timestamp":1761154822298}
{"data":{"asks":[],"bids":[["new",3823.85,16717.0],["delete",3822.9,0.0]],"change_id":46343801674,"instrument_name":"ETH-PERPETUAL","prev_change_id":46343801673,"timestamp":1761154820583,"type":"change"},"instrument":"ETH-PERPETUAL","timestamp":1761154822306}
{"data":{"asks":[["delete",3824.75,0.0],["new",3826.1,1658.0]],"bids":[],"change_id":46343801680,"instrument_name":"ETH-PERPETUAL","prev_change_id":46343801674,"timestamp":1761154820614,"type":"change"},"instrument":"ETH-PERPETUAL","timestamp":1761154822310}
{"data":{"asks":[],"bids":[["new",3823.9,4029.0],["delete",3822.85,0.0]],"change_id":46343801681,"instrument_name":"ETH-PERPETUAL","prev_change_id":46343801680,"timestamp":1761154820623,"type":"change"},"instrument":"ETH-PERPETUAL","timestamp":1761154822314}
{"data":{"asks":[["delete",3825.0,0.0],["new",3826.05,15119.0]],"bids":[],"change_id":46343801726,"instrument_name":"ETH-PERPETUAL","prev_change_id":46343801681,"timestamp":1761154820655,"type":"change"},"instrument":"ETH-PERPETUAL","timestamp":1761154822327}
{"data":{"asks":[],"bids":[["new",3824.1,16943.0],["delete",3822.8,0.0]],"change_id":46343801727,"instrument_name":"ETH-PERPETUAL","prev_change_id":46343801726,"timestamp":1761154820661,"type":"change"},"instrument":"ETH-PERPETUAL","timestamp":1761154822334}
{"data":{"asks":[["delete",3825.05,0.0],["new",3826.0,38134.0]],"bids":[],"change_id":46343801735,"instrument_name":"ETH-PERPETUAL","prev_change_id":46343801727,"timestamp":1761154820696,"type":"change"},"instrument":"ETH-PERPETUAL","timestamp":1761154822394}
{"data":{"asks":[],"bids":[["new",3824.15,3469.0],["delete",3822.75,0.0]],"change_id":46343801736,"instrument_name":"ETH-PERPETUAL","prev_change_id":46343801735,"timestamp":1761154820700,"type":"change"},"instrument":"ETH-PERPETUAL","timestamp":1761154822398}
{"data":{"asks":[["delete",3825.15,0.0],["new",3825.85,7105.0]],"bids":[],"change_id":46343801743,"instrument_name":"ETH-PERPETUAL","prev_change_id":46343801736,"timestamp":1761154820737,"type":"change"},"instrument":"ETH-PERPETUAL","timestamp":1761154822418}
{"data":{"asks":[["delete",3824.2,0.0]],"bids":[["new",3824.25,13072.0],["delete",3822.65,0.0]],"change_id":46343801744,"instrument_name":"ETH-PERPETUAL","prev_change_id":46343801743,"timestamp":1761154820739,"type":"change"},"instrument":"ETH-PERPETUAL","timestamp":1761154822422}
{"data":{"asks":[["delete",3825.2,0.0],["change",3825.8,77327.0]],"bids":[],"change_id":46343801825,"instrument_name":"ETH-PERPETUAL","prev_change_id":46343801744,"timestamp":1761154820777,"type":"change"},"instrument":"ETH-PERPETUAL","timestamp":1761154822458}
{"data":{"asks":[],"bids":[["new",3824.3,1650.0],["delete",3822.6,0.0]],"change_id":46343801826,"instrument_name":"ETH-PERPETUAL","prev_change_id":46343801825,"timestamp":1761154820779,"type":"change"},"instrument":"ETH-PERPETUAL","timestamp":1761154822463}
{"data":{"asks":[["delete",3825.3,0.0],["change",3825.75,34496.0]],"bids":[],"change_id":46343801836,"instrument_name":"ETH-PERPETUAL","prev_change_id":46343801826,"timestamp":1761154820820,"type":"change"},"instrument":"ETH-PERPETUAL","timestamp":1761154822511}
{"data":{"asks":[],"bids":[["new",3824.35,5483.0],["delete",3822.4,0.0]],"change_id":46343801838,"instrument_name":"ETH-PERPETUAL","prev_change_id":46343801836,"timestamp":1761154820821,"type":"change"},"instrument":"ETH-PERPETUAL","timestamp":1761154822516}
{"data":{"asks":[["delete",3825.4,0.0],["change",3825.7,13557.0]],"bids":[],"change_id":46343801847,"instrument_name":"ETH-PERPETUAL","prev_change_id":46343801838,"timestamp":1761154820861,"type":"change"},"instrument":"ETH-PERPETUAL","timestamp":1761154822547}
{"data":{"asks":[],"bids":[["new",3824.4,19994.0],["delete",3822.3,0.0]],"change_id":46343801848,"instrument_name":"ETH-PERPETUAL","prev_change_id":46343801847,"timestamp":1761154820862,"type":"change"},"instrument":"ETH-PERPETUAL","timestamp":1761154822553}
{"data":{"asks":[["delete",3825.45,0.0],["new",3825.5,6.0]],"bids":[],"change_id":46343801857,"instrument_name":"ETH-PERPETUAL","prev_change_id":46343801848,"timestamp":1761154820902,"type":"change"},"instrument":"ETH-PERPETUAL","timestamp":1761154822591}
{"data":{"asks":[],"bids":[["new",3824.55,5968.0],["delete",3822.25,0.0]],"change_id":46343801858,"instrument_name":"ETH-PERPETUAL","prev_change_id":46343801857,"timestamp":1761154820903,"type":"change"},"instrument":"ETH-PERPETUAL","timestamp":1761154822595}
{"data":{"asks":[["new",3825.45,11172.0],["delete",3825.6,0.0]],"bids":[],"change_id":46343802015,"instrument_name":"ETH-PERPETUAL","prev_change_id":46343801858,"timestamp":1761154820942,"type":"change"},"instrument":"ETH-PERPETUAL","timestamp":1761154822633}
{"data":{"asks":[["delete",3824.6,0.0]],"bids":[["new",3824.6,7788.0],["delete",3822.15,0.0]],"change_id":46343802016,"instrument_name":"ETH-PERPETUAL","prev_change_id":46343802015,"timestamp":1761154820943,"type":"change"},"instrument":"ETH-PERPETUAL","timestamp":1761154822639}
{"data":{"asks":[["new",3825.4,3285.0],["delete",3825.65,0.0]],"bids":[],"change_id":46343802029,"instrument_name":"ETH-PERPETUAL","prev_change_id":46343802016,"timestamp":1761154820982,"type":"change"},"instrument":"ETH-PERPETUAL","timestamp":1761154822680}
{"data":{"asks":[],"bids":[["new",3824.65,9700.0],["delete",3822.1,0.0]],"change_id":46343802030,"instrument_name":"ETH-PERPETUAL","prev_change_id":46343802029,"timestamp":1761154820983,"type":"change"},"instrument":"ETH-PERPETUAL","timestamp":1761154822686}
{"data":{"asks":[["new",3825.3,50000.0],["change",3825.7,5289.0]],"bids":[],"change_id":46343802097,"instrument_name":"ETH-PERPETUAL","prev_change_id":46343802030,"timestamp":1761154821023,"type":"change"},"instrument":"ETH-PERPETUAL","timestamp":1761154822787}
{"data":{"asks":[],"bids":[["new",3824.75,4009.0],["delete",3822.05,0.0]],"change_id":46343802098,"instrument_name":"ETH-PERPETUAL","prev_change_id":46343802097,"timestamp":1761154821024,"type":"change"},"instrument":"ETH-PERPETUAL","timestamp":1761154822793}
{"data":{"asks":[["new",3825.25,18985.0],["change",3825.75,16717.0]],"bids":[],"change_id":46343802111,"instrument_name":"ETH-PERPETUAL","prev_change_id":46343802098,"timestamp":1761154821066,"type":"change"},"instrument":"ETH-PERPETUAL","timestamp":1761154822802}
{"data":{"asks":[],"bids":[["new",3824.85,1000.0],["delete",3821.9,0.0]],"change_id":46343802112,"instrument_name":"ETH-PERPETUAL","prev_change_id":46343802111,"timestamp":1761154821067,"type":"change"},"instrument":"ETH-PERPETUAL","timestamp":1761154822815}
{"data":{"asks":[["new",3825.0,4010.0],["change",3825.8,1000.0]],"bids":[],"change_id":46343802126,"instrument_name":"ETH-PERPETUAL","prev_change_id":46343802112,"timestamp":1761154821106,"type":"change"},"instrument":"ETH-PERPETUAL","timestamp":1761154822914}
{"data":{"asks":[],"bids":[["new",3824.9,29214.0],["delete",3821.85,0.0]],"change_id":46343802127,"instrument_name":"ETH-PERPETUAL","prev_change_id":46343802126,"timestamp":1761154821107,"type":"change"},"instrument":"ETH-PERPETUAL","timestamp":1761154822922}
{"data":{"asks":[],"bids":[["new",3807.0,320000.0],["delete",3806.9,0.0]],"change_id":46343802415,"instrument_name":"ETH-PERPETUAL","prev_change_id":46343802127,"timestamp":1761154821268,"type":"change"},"instrument":"ETH-PERPETUAL","timestamp":1761154823097}
{"data":{"asks":[["delete",107870.0,0.0],["new",107932.5,2360.0]],"bids":[],"change_id":67840103060,"instrument_name":"BTC-PERPETUAL","prev_change_id":67840101516,"timestamp":1761154822036,"type":"change"},"instrument":"BTC-PERPETUAL","timestamp":1761154823793}
{"data":{"asks":[],"bids":[["delete",107869.5,0.0],["new",107863.5,50010.0]],"change_id":67840103061,"instrument_name":"BTC-PERPETUAL","prev_change_id":67840103060,"timestamp":1761154822037,"type":"change"},"instrument":"BTC-PERPETUAL","timestamp":1761154823801}
{"data":{"asks":[["delete",107872.5,0.0],["new",107932.0,11000.0]],"bids":[],"change_id":67840103062,"instrument_name":"BTC-PERPETUAL","prev_change_id":67840103061,"timestamp":1761154822075,"type":"change"},"instrument":"BTC-PERPETUAL","timestamp":1761154823838}
{"data":{"asks":[],"bids":[["delete",107869.0,0.0],["new",107864.0,13840.0]],"change_id":67840103063,"instrument_name":"BTC-PERPETUAL","prev_change_id":67840103062,"timestamp":1761154822077,"type":"change"},"instrument":"BTC-PERPETUAL","timestamp":1761154823842}
{"data":{"asks":[["delete",107873.0,0.0],["new",107929.5,1000.0]],"bids":[],"change_id":67840103064,"instrument_name":"BTC-PERPETUAL","prev_change_id":67840103063,"timestamp":1761154822115,"type":"change"},"instrument":"BTC-PERPETUAL","timestamp":1761154823879}
{"data":{"asks":[],"bids":[["new",107865.0,25090.0],["delete",107862.5,0.0]],"change_id":67840103065,"instrument_name":"BTC-PERPETUAL","prev_change_id":67840103064,"timestamp":1761154822117,"type":"change"},"instrument":"BTC-PERPETUAL","timestamp":1761154823889}
{"data":{"asks":[["delete",107873.5,0.0],["new",107929.0,6900.0]],"bids":[],"change_id":67840103067,"instrument_name":"BTC-PERPETUAL","prev_change_id":67840103065,"timestamp":1761154822156,"type":"change"},"instrument":"BTC-PERPETUAL","timestamp":1761154823926}
{"data":{"asks":[],"bids":[["new",107871.0,33260.0],["delete",107862.0,0.0]],"change_id":67840103069,"instrument_name":"BTC-PERPETUAL","prev_change_id":67840103067,"timestamp":1761154822158,"type":"change"},"instrument":"BTC-PERPETUAL","timestamp":1761154823930}
{"data":{"asks":[["delete",107874.0,0.0],["new",107928.0,11000.0]],"bids":[],"change_id":67840103072,"instrument_name":"BTC-PERPETUAL","prev_change_id":67840103069,"timestamp":1761154822195,"type":"change"},"instrument":"BTC-PERPETUAL","timestamp":1761154823968}
{"data":{"asks":[],"bids":[["new",107871.5,16120.0],["delete",107861.5,0.0]],"change_id":67840103074,"instrument_name":"BTC-PERPETUAL","prev_change_id":67840103072,"timestamp":1761154822200,"type":"change"},"instrument":"BTC-PERPETUAL","timestamp":1761154823972}
{"data":{"asks":[["delete",107875.5,0.0],["new",107927.5,8200.0]],"bids":[],"change_id":67840103430,"instrument_name":"BTC-PERPETUAL","prev_change_id":67840103074,"timestamp":1761154822235,"type":"change"},"instrument":"BTC-PERPETUAL","timestamp":1761154824007}
{"data":{"asks":[],"bids":[["new",107872.0,5000.0],["delete",107861.0,0.0]],"change_id":67840103527,"instrument_name":"BTC-PERPETUAL","prev_change_id":67840103430,"timestamp":1761154822241,"type":"change"},"instrument":"BTC-PERPETUAL","timestamp":1761154824011}
{"data":{"asks":[["delete",107877.5,0.0],["new",107925.0,8690.0]],"bids":[],"change_id":67840103531,"instrument_name":"BTC-PERPETUAL","prev_change_id":67840103527,"timestamp":1761154822276,"type":"change"},"instrument":"BTC-PERPETUAL","timestamp":1761154824049}
{"data":{"asks":[],"bids":[["new",107873.0,25000.0],["delete",107860.5,0.0]],"change_id":67840103535,"instrument_name":"BTC-PERPETUAL","prev_change_id":67840103531,"timestamp":1761154822281,"type":"change"},"instrument":"BTC-PERPETUAL","timestamp":1761154824053}
{"data":{"asks":[["delete",107880.0,0.0],["new",107924.0,2100.0]],"bids":[],"change_id":67840103569,"instrument_name":"BTC-PERPETUAL","prev_change_id":67840103535,"timestamp":1761154822315,"type":"change"},"instrument":"BTC-PERPETUAL","timestamp":1761154824091}
{"data":{"asks":[],"bids":[["new",107875.0,2100.0],["delete",107858.5,0.0]],"change_id":67840103573,"instrument_name":"BTC-PERPETUAL","prev_change_id":67840103569,"timestamp":1761154822321,"type":"change"},"instrument":"BTC-PERPETUAL","timestamp":1761154824099}
{"data":{"asks":[["delete",107880.5,0.0],["change",107923.5,5626750.0]],"bids":[],"change_id":67840103576,"instrument_name":"BTC-PERPETUAL","prev_change_id":67840103573,"timestamp":1761154822354,"type":"change"},"instrument":"BTC-PERPETUAL","timestamp":1761154824137}
{"data":{"asks":[],"bids":[["new",107876.0,2120.0],["delete",107855.0,0.0]],"change_id":67840103737,"instrument_name":"BTC-PERPETUAL","prev_change_id":67840103576,"timestamp":1761154822363,"type":"change"},"instrument":"BTC-PERPETUAL","timestamp":1761154824143}
{"data":{"asks":[["delete",107882.5,0.0],["new",107923.0,8440.0]],"bids":[],"change_id":67840103843,"instrument_name":"BTC-PERPETUAL","prev_change_id":67840103737,"timestamp":1761154822393,"type":"change"},"instrument":"BTC-PERPETUAL","timestamp":1761154824175}
{"data":{"asks":[],"bids":[["new",107877.5,50300.0],["delete",107850.5,0.0]],"change_id":67840103853,"instrument_name":"BTC-PERPETUAL","prev_change_id":67840103843,"timestamp":1761154822404,"type":"change"},"instrument":"BTC-PERPETUAL","timestamp":1761154824187}
{"data":{"asks":[["delete",107887.0,0.0],["new",107922.5,25000.0]],"bids":[],"change_id":67840103859,"instrument_name":"BTC-PERPETUAL","prev_change_id":67840103853,"timestamp":1761154822442,"type":"change"},"instrument":"BTC-PERPETUAL","timestamp":1761154824227}
{"data":{"asks":[],"bids":[["new",107878.0,20990.0],["delete",107850.0,0.0]],"change_id":67840103863,"instrument_name":"BTC-PERPETUAL","prev_change_id":67840103859,"timestamp":1761154822451,"type":"change"},"instrument":"BTC-PERPETUAL","timestamp":1761154824238}
{"data":{"asks":[["delete",107887.5,0.0],["new",107922.0,13650.0]],"bids":[],"change_id":67840103967,"instrument_name":"BTC-PERPETUAL","prev_change_id":67840103863,"timestamp":1761154822485,"type":"change"},"instrument":"BTC-PERPETUAL","timestamp":1761154824274}
{"data":{"asks":[],"bids":[["new",107880.0,8650.0],["delete",107849.5,0.0]],"change_id":67840103971,"instrument_name":"BTC-PERPETUAL","prev_change_id":67840103967,"timestamp":1761154822493,"type":"change"},"instrument":"BTC-PERPETUAL","timestamp":1761154824278}
{"data":{"asks":[["delete",107888.0,0.0],["new",107919.0,10000.0]],"bids":[],"change_id":67840103985,"instrument_name":"BTC-PERPETUAL","prev_change_id":67840103971,"timestamp":1761154822524,"type":"change"},"instrument":"BTC-PERPETUAL","timestamp":1761154824313}
{"data":{"asks":[],"bids":[["new",107882.5,18970.0],["delete",107849.0,0.0]],"change_id":67840103989,"instrument_name":"BTC-PERPETUAL","prev_change_id":67840103985,"timestamp":1761154822532,"type":"change"},"instrument":"BTC-PERPETUAL","timestamp":1761154824320}
{"data":{"asks":[["delete",107888.5,0.0],["new",107918.5,2990.0]],"bids":[],"change_id":67840104147,"instrument_name":"BTC-PERPETUAL","prev_change_id":67840103989,"timestamp":1761154822563,"type":"change"},"instrument":"BTC-PERPETUAL","timestamp":1761154824356}
{"data":{"asks":[],"bids":[["new",107885.0,50000.0],["delete",107847.5,0.0]],"change_id":67840104151,"instrument_name":"BTC-PERPETUAL","prev_change_id":67840104147,"timestamp":1761154822572,"type":"change"},"instrument":"BTC-PERPETUAL","timestamp":1761154824363}
{"data":{"asks":[["delete",107889.5,0.0],["new",107915.0,6000.0]],"bids":[],"change_id":67840104157,"instrument_name":"BTC-PERPETUAL","prev_change_id":67840104151,"timestamp":1761154822605,"type":"change"},"instrument":"BTC-PERPETUAL","timestamp":1761154824398}
{"data":{"asks":[],"bids":[["new",107887.0,2100.0],["delete",107846.5,0.0]],"change_id":67840104161,"instrument_name":"BTC-PERPETUAL","prev_change_id":67840104157,"timestamp":1761154822612,"type":"change"},"instrument":"BTC-PERPETUAL","timestamp":1761154824406}
{"data":{"asks":[["delete",107892.5,0.0],["new",107914.5,1790.0]],"bids":[],"change_id":67840104181,"instrument_name":"BTC-PERPETUAL","prev_change_id":67840104161,"timestamp":1761154822645,"type":"change"},"instrument":"BTC-PERPETUAL","timestamp":1761154824443}
{"data":{"asks":[],"bids":[["new",107887.5,9230.0],["delete",107845.0,0.0]],"change_id":67840104191,"instrument_name":"BTC-PERPETUAL","prev_change_id":67840104181,"timestamp":1761154822651,"type":"change"},"instrument":"BTC-PERPETUAL","timestamp":1761154824450}
{"data":{"asks":[["delete",107893.5,0.0],["new",107904.5,32000.0]],"bids":[],"change_id":67840104204,"instrument_name":"BTC-PERPETUAL","prev_change_id":67840104191,"timestamp":1761154822684,"type":"change"},"instrument":"BTC-PERPETUAL","timestamp":1761154824486}
{"data":{"asks":[],"bids":[["new",107888.0,17870.0],["delete",107841.5,0.0]],"change_id":67840104210,"instrument_name":"BTC-PERPETUAL","prev_change_id":67840104204,"timestamp":1761154822692,"type":"change"},"instrument":"BTC-PERPETUAL","timestamp":1761154824490}
{"data":{"asks":[["delete",107894.5,0.0],["new",107900.5,1800.0]],"bids":[],"change_id":67840104244,"instrument_name":"BTC-PERPETUAL","prev_change_id":67840104210,"timestamp":1761154822726,"type":"change"},"instrument":"BTC-PERPETUAL","timestamp":1761154824526}
{"data":{"asks":[],"bids":[["new",107892.0,20.0],["delete",107841.0,0.0]],"change_id":67840104251,"instrument_name":"BTC-PERPETUAL","prev_change_id":67840104244,"timestamp":1761154822732,"type":"change"},"instrument":"BTC-PERPETUAL","timestamp":1761154824538}
{"data":{"asks":[["delete",107897.5,0.0],["new",107900.0,20.0]],"bids":[],"change_id":67840104257,"instrument_name":"BTC-PERPETUAL","prev_change_id":67840104251,"timestamp":1761154822771,"type":"change"},"instrument":"BTC-PERPETUAL","timestamp":1761154824580}
{"data":{"asks":[],"bids":[["new",107892.5,94920.0],["delete",107839.0,0.0]],"change_id":67840104265,"instrument_name":"BTC-PERPETUAL","prev_change_id":67840104257,"timestamp":1761154822776,"type":"change"},"instrument":"BTC-PERPETUAL","timestamp":1761154824584}
{"data":{"asks":[["new",107893.5,5600.0],["delete",107898.5,0.0]],"bids":[],"change_id":67840104271,"instrument_name":"BTC-PERPETUAL","prev_change_id":67840104265,"timestamp":1761154822811,"type":"change"},"instrument":"BTC-PERPETUAL","timestamp":1761154824619}
{"data":{"asks":[],"bids":[["new",107893.0,403490.0],["delete",107837.5,0.0]],"change_id":67840104299,"instrument_name":"BTC-PERPETUAL","prev_change_id":67840104271,"timestamp":1761154822818,"type":"change"},"instrument":"BTC-PERPETUAL","timestamp":1761154824624}
{"data":{"asks":[["change",3826.2,34126.0],["new",3827.25,6972069.0]],"bids":[],"change_id":46343804429,"instrument_name":"ETH-PERPETUAL","prev_change_id":46343802415,"timestamp":1761154822849,"type":"change"},"instrument":"ETH-PERPETUAL","timestamp":1761154824659}
{"data":{"asks":[["new",3824.95,733.0]],"bids":[],"change_id":46343805543,"instrument_name":"ETH-PERPETUAL","prev_change_id":46343804429,"timestamp":1761154823674,"type":"change"},"instrument":"ETH-PERPETUAL","timestamp":1761154825592}
{"data":{"asks":[],"bids":[["new",107839.5,6462890.0],["delete",107816.0,0.0]],"change_id":67840107636,"instrument_name":"BTC-PERPETUAL","prev_change_id":67840104299,"timestamp":1761154825367,"type":"change"},"instrument":"BTC-PERPETUAL","timestamp":1761154827357}
{"data":{"asks":[],"bids":[["change",3817.3,105000.0],["change",3806.95,320000.0]],"change_id":46343807670,"instrument_name":"ETH-PERPETUAL","prev_change_id":46343805543,"timestamp":1761154825525,"type":"change"},"instrument":"ETH-PERPETUAL","timestamp":1761154827505}
{"data":{"asks":[["delete",3825.0,0.0],["new",3827.1,1584.0]],"bids":[],"change_id":46343807780,"instrument_name":"ETH-PERPETUAL","prev_change_id":46343807670,"timestamp":1761154825579,"type":"change"},"instrument":"ETH-PERPETUAL","timestamp":1761154827556}
{"data":{"asks":[],"bids":[["delete",3824.9,0.0],["change",3823.6,22636.0]],"change_id":46343807781,"instrument_name":"ETH-PERPETUAL","prev_change_id":46343807780,"timestamp":1761154825580,"type":"change"},"instrument":"ETH-PERPETUAL","timestamp":1761154827563}
{"data":{"asks":[["delete",3825.25,0.0],["new",3826.95,37796.0]],"bids":[],"change_id":46343807782,"instrument_name":"ETH-PERPETUAL","prev_change_id":46343807781,"timestamp":1761154825619,"type":"change"},"instrument":"ETH-PERPETUAL","timestamp":1761154827599}
{"data":{"asks":[],"bids":[["delete",3824.85,0.0],["change",3823.7,16.0]],"change_id":46343807783,"instrument_name":"ETH-PERPETUAL","prev_change_id":46343807782,"timestamp":1761154825621,"type":"change"},"instrument":"ETH-PERPETUAL","timestamp":1761154827605}
{"data":{"asks":[["delete",3825.3,0.0],["change",3826.9,12440.0]],"bids":[],"change_id":46343807825,"instrument_name":"ETH-PERPETUAL","prev_change_id":46343807783,"timestamp":1761154825660,"type":"change"},"instrument":"ETH-PERPETUAL","timestamp":1761154827643}
{"data":{"asks":[],"bids":[["delete",3824.75,0.0],["change",3823.75,3300.0]],"change_id":46343807826,"instrument_name":"ETH-PERPETUAL","prev_change_id":46343807825,"timestamp":1761154825661,"type":"change"},"instrument":"ETH-PERPETUAL","timestamp":1761154827649}
{"data":{"asks":[["delete",3825.4,0.0],["new",3826.85,1211.0]],"bids":[],"change_id":46343807828,"instrument_name":"ETH-PERPETUAL","prev_change_id":46343807826,"timestamp":1761154825702,"type":"change"},"instrument":"ETH-PERPETUAL","timestamp":1761154827688}
{"data":{"asks":[["change",107923.5,1000.0],["new",107947.0,5625750.0]],"bids":[],"change_id":67840107975,"instrument_name":"BTC-PERPETUAL","prev_change_id":67840107636,"timestamp":1761154825703,"type":"change"},"instrument":"BTC-PERPETUAL","timestamp":1761154827694}
{"data":{"asks":[],"bids":[["delete",3824.65,0.0],["change",3823.8,8890.0]],"change_id":46343807830,"instrument_name":"ETH-PERPETUAL","prev_change_id":46343807828,"timestamp":1761154825704,"type":"change"},"instrument":"ETH-PERPETUAL","timestamp":1761154827697}
{"data":{"asks":[["delete",3825.45,0.0],["change",3826.7,22141.0]],"bids":[],"change_id":46343807832,"instrument_name":"ETH-PERPETUAL","prev_change_id":46343807830,"timestamp":1761154825742,"type":"change"},"instrument":"ETH-PERPETUAL","timestamp":1761154827734}
{"data":{"asks":[],"bids":[["delete",3824.6,0.0],["change",3823.85,34791.0]],"change_id":46343807834,"instrument_name":"ETH-PERPETUAL","prev_change_id":46343807832,"timestamp":1761154825745,"type":"change"},"instrument":"ETH-PERPETUAL","timestamp":1761154827737}
{"data":{"asks":[["delete",3825.5,0.0],["change",3826.6,4813.0]],"bids":[],"change_id":46343807910,"instrument_name":"ETH-PERPETUAL","prev_change_id":46343807834,"timestamp":1761154825782,"type":"change"},"instrument":"ETH-PERPETUAL","timestamp":1761154827775}
{"data":{"asks":[],"bids":[["delete",3824.55,0.0],["change",3823.9,5848.0]],"change_id":46343807912,"instrument_name":"ETH-PERPETUAL","prev_change_id":46343807910,"timestamp":1761154825787,"type":"change"},"instrument":"ETH-PERPETUAL","timestamp":1761154827778}
{"data":{"asks":[["delete",3825.7,0.0],["change",3826.55,26793.0]],"bids":[],"change_id":46343807916,"instrument_name":"ETH-PERPETUAL","prev_change_id":46343807912,"timestamp":1761154825824,"type":"change"},"instrument":"ETH-PERPETUAL","timestamp":1761154827832}
{"data":{"asks":[],"bids":[["delete",3824.4,0.0],["new",3824.05,15388.0]],"change_id":46343807918,"instrument_name":"ETH-PERPETUAL","prev_change_id":46343807916,"timestamp":1761154825828,"type":"change"},"instrument":"ETH-PERPETUAL","timestamp":1761154827836}
{"data":{"asks":[["delete",3825.75,0.0],["new",3826.5,19829.0]],"bids":[],"change_id":46343807922,"instrument_name":"ETH-PERPETUAL","prev_change_id":46343807918,"timestamp":1761154825863,"type":"change"},"instrument":"ETH-PERPETUAL","timestamp":1761154827861}
{"data":{"asks":[],"bids":[["delete",3824.35,0.0],["change",3824.1,21386.0]],"change_id":46343807924,"instrument_name":"ETH-PERPETUAL","prev_change_id":46343807922,"timestamp":1761154825868,"type":"change"},"instrument":"ETH-PERPETUAL","timestamp":1761154827866}
{"data":{"asks":[["delete",3825.8,0.0],["new",3826.45,1320.0]],"bids":[],"change_id":46343807928,"instrument_name":"ETH-PERPETUAL","prev_change_id":46343807924,"timestamp":1761154825904,"type":"change"},"instrument":"ETH-PERPETUAL","timestamp":1761154827908}
{"data":{"asks":[],"bids":[["delete",3824.3,0.0],["change",3824.15,15969.0]],"change_id":46343807930,"instrument_name":"ETH-PERPETUAL","prev_change_id":46343807928,"timestamp":1761154825910,"type":"change"},"instrument":"ETH-PERPETUAL","timestamp":1761154827912}
{"data":{"asks":[["delete",3825.85,0.0],["new",3826.3,1650.0]],"bids":[],"change_id":46343808082,"instrument_name":"ETH-PERPETUAL","prev_change_id":46343807930,"timestamp":1761154825946,"type":"change"},"instrument":"ETH-PERPETUAL","timestamp":1761154827948}
{"data":{"asks":[],"bids":[["delete",3824.25,0.0]],"change_id":46343808085,"instrument_name":"ETH-PERPETUAL","prev_change_id":46343808082,"timestamp":1761154825949,"type":"change"},"instrument":"ETH-PERPETUAL","timestamp":1761154827952}
{"data":{"asks":[["delete",3826.0,0.0],["new",3826.25,4449.0]],"bids":[],"change_id":46343808090,"instrument_name":"ETH-PERPETUAL","prev_change_id":46343808085,"timestamp":1761154825987,"type":"change"},"instrument":"ETH-PERPETUAL","timestamp":1761154827994}
{"data":{"asks":[],"bids":[["new",3824.35,15129.0],["change",3824.15,12500.0]],"change_id":46343808093,"instrument_name":"ETH-PERPETUAL","prev_change_id":46343808090,"timestamp":1761154825990,"type":"change"},"instrument":"ETH-PERPETUAL","timestamp":1761154827998}
{"data":{"asks":[["delete",3826.05,0.0],["change",3826.2,34349.0]],"bids":[],"change_id":46343808154,"instrument_name":"ETH-PERPETUAL","prev_change_id":46343808093,"timestamp":1761154826027,"type":"change"},"instrument":"ETH-PERPETUAL","timestamp":1761154828036}
{"data":{"asks":[],"bids":[["new",3824.4,12783.0],["change",3824.1,4443.0]],"change_id":46343808157,"instrument_name":"ETH-PERPETUAL","prev_change_id":46343808154,"timestamp":1761154826030,"type":"change"},"instrument":"ETH-PERPETUAL","timestamp":1761154828040}
{"data":{"asks":[["change",3826.1,4422.0]],"bids":[],"change_id":46343808165,"instrument_name":"ETH-PERPETUAL","prev_change_id":46343808157,"timestamp":1761154826068,"type":"change"},"instrument":"ETH-PERPETUAL","timestamp":1761154828079}
{"data":{"asks":[],"bids":[["new",3824.55,1708.0],["change",3823.9,1819.0]],"change_id":46343808168,"instrument_name":"ETH-PERPETUAL","prev_change_id":46343808165,"timestamp":1761154826071,"type":"change"},"instrument":"ETH-PERPETUAL","timestamp":1761154828083}
{"data":{"asks":[["new",3826.05,4441.0],["delete",3826.15,0.0]],"bids":[],"change_id":46343808175,"instrument_name":"ETH-PERPETUAL","prev_change_id":46343808168,"timestamp":1761154826109,"type":"change"},"instrument":"ETH-PERPETUAL","timestamp":1761154828123}
{"data":{"asks":[],"bids":[["new",3824.6,16717.0],["change",3823.85,18074.0]],"change_id":46343808178,"instrument_name":"ETH-PERPETUAL","prev_change_id":46343808175,"timestamp":1761154826111,"type":"change"},"instrument":"ETH-PERPETUAL","timestamp":1761154828130}
{"data":{"asks":[["new",3826.0,19453.0],["change",3826.2,223.0]],"bids":[],"change_id":46343808295,"instrument_name":"ETH-PERPETUAL","prev_change_id":46343808178,"timestamp":1761154826149,"type":"change"},"instrument":"ETH-PERPETUAL","timestamp":1761154828163}
{"data":{"asks":[],"bids":[["new",3824.65,22000.0],["change",3823.8,4445.0]],"change_id":46343808298,"instrument_name":"ETH-PERPETUAL","prev_change_id":46343808295,"timestamp":1761154826151,"type":"change"},"instrument":"ETH-PERPETUAL","timestamp":1761154828174}
{"data":{"asks":[["new",3825.8,6573.0],["delete",3826.4,0.0]],"bids":[],"change_id":46343808432,"instrument_name":"ETH-PERPETUAL","prev_change_id":46343808298,"timestamp":1761154826191,"type":"change"},"instrument":"ETH-PERPETUAL","timestamp":1761154828217}
{"data":{"asks":[],"bids":[["new",3824.8,10794.0],["change",3823.75,1650.0]],"change_id":46343808435,"instrument_name":"ETH-PERPETUAL","prev_change_id":46343808432,"timestamp":1761154826194,"type":"change"},"instrument":"ETH-PERPETUAL","timestamp":1761154828220}
{"data":{"asks":[["new",3825.75,62000.0],["change",3826.55,16717.0]],"bids":[],"change_id":46343808444,"instrument_name":"ETH-PERPETUAL","prev_change_id":46343808435,"timestamp":1761154826233,"type":"change"},"instrument":"ETH-PERPETUAL","timestamp":1761154828254}
{"data":{"asks":[],"bids":[["new",3824.85,19994.0],["change",3823.7,8.0]],"change_id":46343808447,"instrument_name":"ETH-PERPETUAL","prev_change_id":46343808444,"timestamp":1761154826236,"type":"change"},"instrument":"ETH-PERPETUAL","timestamp":1761154828271}
{"data":{"asks":[["new",3825.7,16466.0],["change",3826.6,1801.0]],"bids":[],"change_id":46343808456,"instrument_name":"ETH-PERPETUAL","prev_change_id":46343808447,"timestamp":1761154826274,"type":"change"},"instrument":"ETH-PERPETUAL","timestamp":1761154826358}
{"data":{"asks":[["delete",3824.95,0.0]],"bids":[["new",3825.05,377.0],["change",3823.6,1325.0]],"change_id":46343808459,"instrument_name":"ETH-PERPETUAL","prev_change_id":46343808456,"timestamp":1761154826276,"type":"change"},"instrument":"ETH-PERPETUAL","timestamp":1761154826363}
{"data":{"asks":[["new",3825.5,6.0],["change",3826.7,16109.0]],"bids":[],"change_id":46343808494,"instrument_name":"ETH-PERPETUAL","prev_change_id":46343808459,"timestamp":1761154826316,"type":"change"},"instrument":"ETH-PERPETUAL","timestamp":1761154826403}
{"data":{"asks":[],"bids":[["new",3825.15,266.0],["delete",3823.55,0.0]],"change_id":46343808497,"instrument_name":"ETH-PERPETUAL","prev_change_id":46343808494,"timestamp":1761154826318,"type":"change"},"instrument":"ETH-PERPETUAL","timestamp":1761154826410}
{"data":{"asks":[["new",3825.4,8958.0],["change",3826.9,11112.0]],"bids":[],"change_id":46343808508,"instrument_name":"ETH-PERPETUAL","prev_change_id":46343808497,"timestamp":1761154826355,"type":"change"},"instrument":"ETH-PERPETUAL","timestamp":1761154826444}
{"data":{"asks":[],"bids":[["new",3825.35,10562.0],["delete",3823.4,0.0]],"change_id":46343808511,"instrument_name":"ETH-PERPETUAL","prev_change_id":46343808508,"timestamp":1761154826359,"type":"change"},"instrument":"ETH-PERPETUAL","timestamp":1761154826449}
{"data":{"asks":[["change",3825.4,9382.0]],"bids":[],"change_id":46343809543,"instrument_name":"ETH-PERPETUAL","prev_change_id":46343808511,"timestamp":1761154827115,"type":"change"},"instrument":"ETH-PERPETUAL","timestamp":1761154827309}
{"data":{"asks":[],"bids":[["new",3807.05,320000.0],["delete",3806.95,0.0]],"change_id":46343809778,"instrument_name":"ETH-PERPETUAL","prev_change_id":46343809543,"timestamp":1761154827175,"type":"change"},"instrument":"ETH-PERPETUAL","timestamp":1761154827315}
{"data":{"asks":[["delete",107893.5,0.0],["new",107921.0,18260.0]],"bids":[],"change_id":67840109769,"instrument_name":"BTC-PERPETUAL","prev_change_id":67840107975,"timestamp":1761154827287,"type":"change"},"instrument":"BTC-PERPETUAL","timestamp":1761154827433}
{"data":{"asks":[],"bids":[["delete",107893.0,0.0],["change",107865.0,55180.0]],"change_id":67840109770,"instrument_name":"BTC-PERPETUAL","prev_change_id":67840109769,"timestamp":1761154827288,"type":"change"},"instrument":"BTC-PERPETUAL","timestamp":1761154827438}
{"data":{"asks":[["delete",107900.0,0.0],["new",107916.0,33150.0]],"bids":[],"change_id":67840109819,"instrument_name":"BTC-PERPETUAL","prev_change_id":67840109770,"timestamp":1761154827326,"type":"change"},"instrument":"BTC-PERPETUAL","timestamp":1761154827477}
{"data":{"asks":[],"bids":[["delete",107892.5,0.0],["new",107865.5,9230.0]],"change_id":67840109821,"instrument_name":"BTC-PERPETUAL","prev_change_id":67840109819,"timestamp":1761154827327,"type":"change"},"instrument":"BTC-PERPETUAL","timestamp":1761154827486}
{"data":{"asks":[["delete",107900.5,0.0],["new",107915.5,17070.0]],"bids":[],"change_id":67840109980,"instrument_name":"BTC-PERPETUAL","prev_change_id":67840109821,"timestamp":1761154827366,"type":"change"},"instrument":"BTC-PERPETUAL","timestamp":1761154827523}
{"data":{"asks":[],"bids":[["delete",107892.0,0.0],["new",107866.5,10.0]],"change_id":67840109981,"instrument_name":"BTC-PERPETUAL","prev_change_id":67840109980,"timestamp":1761154827368,"type":"change"},"instrument":"BTC-PERPETUAL","timestamp":1761154827526}
{"data":{"asks":[["delete",107904.5,0.0],["new",107912.5,2100.0]],"bids":[],"change_id":67840110068,"instrument_name":"BTC-PERPETUAL","prev_change_id":67840109981,"timestamp":1761154827406,"type":"change"},"instrument":"BTC-PERPETUAL","timestamp":1761154827564}
{"data":{"asks":[],"bids":[["delete",107888.0,0.0],["change",107871.0,68520.0]],"change_id":67840110069,"instrument_name":"BTC-PERPETUAL","prev_change_id":67840110068,"timestamp":1761154827408,"type":"change"},"instrument":"BTC-PERPETUAL","timestamp":1761154827567}
{"data":{"asks":[["new",107912.0,20240.0],["delete",107914.5,0.0]],"bids":[],"change_id":67840110072,"instrument_name":"BTC-PERPETUAL","prev_change_id":67840110069,"timestamp":1761154827446,"type":"change"},"instrument":"BTC-PERPETUAL","timestamp":1761154827604}
{"data":{"asks":[],"bids":[["delete",107887.5,0.0],["change",107871.5,28140.0]],"change_id":67840110073,"instrument_name":"BTC-PERPETUAL","prev_change_id":67840110072,"timestamp":1761154827448,"type":"change"},"instrument":"BTC-PERPETUAL","timestamp":1761154827608}
{"data":{"asks":[["new",107909.0,8440.0],["delete",107915.0,0.0]],"bids":[],"change_id":67840110176,"instrument_name":"BTC-PERPETUAL","prev_change_id":67840110073,"timestamp":1761154827486,"type":"change"},"instrument":"BTC-PERPETUAL","timestamp":1761154827646}
{"data":{"asks":[],"bids":[["delete",107887.0,0.0],["change",107873.0,75300.0]],"change_id":67840110177,"instrument_name":"BTC-PERPETUAL","prev_change_id":67840110176,"timestamp":1761154827488,"type":"change"},"instrument":"BTC-PERPETUAL","timestamp":1761154827655}
{"data":{"asks":[["new",107908.5,36000.0],["delete",107918.5,0.0]],"bids":[],"change_id":67840110180,"instrument_name":"BTC-PERPETUAL","prev_change_id":67840110177,"timestamp":1761154827527,"type":"change"},"instrument":"BTC-PERPETUAL","timestamp":1761154827693}
{"data":{"asks":[],"bids":[["delete",107885.0,0.0],["change",107875.0,4200.0]],"change_id":67840110181,"instrument_name":"BTC-PERPETUAL","prev_change_id":67840110180,"timestamp":1761154827532,"type":"change"},"instrument":"BTC-PERPETUAL","timestamp":1761154827697}
{"data":{"asks":[["new",107904.5,8620.0],["delete",107919.0,0.0]],"bids":[],"change_id":67840110338,"instrument_name":"BTC-PERPETUAL","prev_change_id":67840110181,"timestamp":1761154827567,"type":"change"},"instrument":"BTC-PERPETUAL","timestamp":1761154827737}
{"data":{"asks":[],"bids":[["delete",107882.5,0.0],["new",107876.5,14900.0]],"change_id":67840110339,"instrument_name":"BTC-PERPETUAL","prev_change_id":67840110338,"timestamp":1761154827571,"type":"change"},"instrument":"BTC-PERPETUAL","timestamp":1761154827740}
{"data":{"asks":[["new",107904.0,490.0],["delete",107922.0,0.0]],"bids":[],"change_id":67840110344,"instrument_name":"BTC-PERPETUAL","prev_change_id":67840110339,"timestamp":1761154827606,"type":"change"},"instrument":"BTC-PERPETUAL","timestamp":1761154827782}
{"data":{"asks":[],"bids":[["delete",107880.0,0.0],["new",107877.0,61610.0]],"change_id":67840110345,"instrument_name":"BTC-PERPETUAL","prev_change_id":67840110344,"timestamp":1761154827611,"type":"change"},"instrument":"BTC-PERPETUAL","timestamp":1761154827786}
{"data":{"asks":[["new",107900.5,1800.0],["delete",107922.5,0.0]],"bids":[],"change_id":67840110351,"instrument_name":"BTC-PERPETUAL","prev_change_id":67840110345,"timestamp":1761154827647,"type":"change"},"instrument":"BTC-PERPETUAL","timestamp":1761154827817}
{"data":{"asks":[],"bids":[["new",107880.0,8650.0],["delete",107878.0,0.0]],"change_id":67840110352,"instrument_name":"BTC-PERPETUAL","prev_change_id":67840110351,"timestamp":1761154827651,"type":"change"},"instrument":"BTC-PERPETUAL","timestamp":1761154827821}
{"data":{"asks":[["new",107900.0,20.0],["delete",107923.0,0.0]],"bids":[],"change_id":67840110359,"instrument_name":"BTC-PERPETUAL","prev_change_id":67840110352,"timestamp":1761154827686,"type":"change"},"instrument":"BTC-PERPETUAL","timestamp":1761154827859}
{"data":{"asks":[],"bids":[["new",107882.0,500.0],["delete",107877.5,0.0]],"change_id":67840110360,"instrument_name":"BTC-PERPETUAL","prev_change_id":67840110359,"timestamp":1761154827691,"type":"change"},"instrument":"BTC-PERPETUAL","timestamp":1761154827865}
{"data":{"asks":[["new",107898.5,20.0],["delete",107923.5,0.0]],"bids":[],"change_id":67840110367,"instrument_name":"BTC-PERPETUAL","prev_change_id":67840110360,"timestamp":1761154827726,"type":"change"},"instrument":"BTC-PERPETUAL","timestamp":1761154827901}
{"data":{"asks":[],"bids":[["new",107882.5,20770.0],["delete",107876.0,0.0]],"change_id":67840110396,"instrument_name":"BTC-PERPETUAL","prev_change_id":67840110367,"timestamp":1761154827730,"type":"change"},"instrument":"BTC-PERPETUAL","timestamp":1761154827911}
{"data":{"asks":[["new",107898.0,30020.0],["delete",107924.0,0.0]],"bids":[],"change_id":67840110404,"instrument_name":"BTC-PERPETUAL","prev_change_id":67840110396,"timestamp":1761154827766,"type":"change"},"instrument":"BTC-PERPETUAL","timestamp":1761154827944}
{"data":{"asks":[],"bids":[["new",107884.5,20.0],["change",107875.0,2100.0]],"change_id":67840110405,"instrument_name":"BTC-PERPETUAL","prev_change_id":67840110404,"timestamp":1761154827775,"type":"change"},"instrument":"BTC-PERPETUAL","timestamp":1761154827962}
{"data":{"asks":[["new",107897.5,23920.0],["delete",107925.0,0.0]],"bids":[],"change_id":67840110414,"instrument_name":"BTC-PERPETUAL","prev_change_id":67840110405,"timestamp":1761154827812,"type":"change"},"instrument":"BTC-PERPETUAL","timestamp":1761154827994}
{"data":{"asks":[],"bids":[["new",107885.0,36980.0],["change",107873.0,50300.0]],"change_id":67840110415,"instrument_name":"BTC-PERPETUAL","prev_change_id":67840110414,"timestamp":1761154827814,"type":"change"},"instrument":"BTC-PERPETUAL","timestamp":1761154828001}
{"data":{"asks":[["new",107897.0,1810.0],["delete",107927.5,0.0]],"bids":[],"change_id":67840110474,"instrument_name":"BTC-PERPETUAL","prev_change_id":67840110415,"timestamp":1761154827852,"type":"change"},"instrument":"BTC-PERPETUAL","timestamp":1761154828045}
{"data":{"asks":[],"bids":[["new",107888.0,11040.0],["delete",107872.0,0.0]],"change_id":67840110475,"instrument_name":"BTC-PERPETUAL","prev_change_id":67840110474,"timestamp":1761154827854,"type":"change"},"instrument":"BTC-PERPETUAL","timestamp":1761154828050}
{"data":{"asks":[["new",107896.5,10020.0],["delete",107928.0,0.0]],"bids":[],"change_id":67840110485,"instrument_name":"BTC-PERPETUAL","prev_change_id":67840110475,"timestamp":1761154827891,"type":"change"},"instrument":"BTC-PERPETUAL","timestamp":1761154828077}
{"data":{"asks":[],"bids":[["new",107888.5,50990.0],["change",107871.5,12020.0]],"change_id":67840110486,"instrument_name":"BTC-PERPETUAL","prev_change_id":67840110485,"timestamp":1761154827894,"type":"change"},"instrument":"BTC-PERPETUAL","timestamp":1761154828082}
{"data":{"asks":[["new",107896.0,20.0],["delete",107929.0,0.0]],"bids":[],"change_id":67840110497,"instrument_name":"BTC-PERPETUAL","prev_change_id":67840110486,"timestamp":1761154827931,"type":"change"},"instrument":"BTC-PERPETUAL","timestamp":1761154828121}
{"data":{"asks":[],"bids":[["new",107889.0,50000.0],["change",107871.0,35260.0]],"change_id":67840110498,"instrument_name":"BTC-PERPETUAL","prev_change_id":67840110497,"timestamp":1761154827935,"type":"change"},"instrument":"BTC-PERPETUAL","timestamp":1761154828127}
{"data":{"asks":[["new",107895.5,20.0],["delete",107929.5,0.0]],"bids":[],"change_id":67840110509,"instrument_name":"BTC-PERPETUAL","prev_change_id":67840110498,"timestamp":1761154827971,"type":"change"},"instrument":"BTC-PERPETUAL","timestamp":1761154828163}
{"data":{"asks":[],"bids":[["new",107891.5,54900.0],["change",107865.0,30090.0]],"change_id":67840110510,"instrument_name":"BTC-PERPETUAL","prev_change_id":67840110509,"timestamp":1761154827975,"type":"change"},"instrument":"BTC-PERPETUAL","timestamp":1761154828168}
{"data":{"asks":[["new",107895.0,20.0],["delete",107932.0,0.0]],"bids":[],"change_id":67840110635,"instrument_name":"BTC-PERPETUAL","prev_change_id":67840110510,"timestamp":1761154828011,"type":"change"},"instrument":"BTC-PERPETUAL","timestamp":1761154828205}
{"data":{"asks":[],"bids":[["new",107892.0,31310.0],["delete",107864.0,0.0]],"change_id":67840110636,"instrument_name":"BTC-PERPETUAL","prev_change_id":67840110635,"timestamp":1761154828017,"type":"change"},"instrument":"BTC-PERPETUAL","timestamp":1761154828209}
{"data":{"asks":[["new",107893.5,166760.0],["delete",107932.5,0.0]],"bids":[],"change_id":67840110649,"instrument_name":"BTC-PERPETUAL","prev_change_id":67840110636,"timestamp":1761154828052,"type":"change"},"instrument":"BTC-PERPETUAL","timestamp":1761154828248}
{"data":{"asks":[],"bids":[["new",107893.0,240220.0],["delete",107863.5,0.0]],"change_id":67840110650,"instrument_name":"BTC-PERPETUAL","prev_change_id":67840110649,"timestamp":1761154828057,"type":"change"},"instrument":"BTC-PERPETUAL","timestamp":1761154828260}
{"data":{"asks":[["new",3826.8,6972069.0],["delete",3827.25,0.0]],"bids":[],"change_id":46343812734,"instrument_name":"ETH-PERPETUAL","prev_change_id":46343809778,"timestamp":1761154829761,"type":"change"},"instrument":"ETH-PERPETUAL","timestamp":1761154830067}
{"data":{"asks":[["change",3825.4,424.0],["new",3828.0,6126.0]],"bids":[],"change_id":46343813850,"instrument_name":"ETH-PERPETUAL","prev_change_id":46343812734,"timestamp":1761154830580,"type":"change"},"instrument":"ETH-PERPETUAL","timestamp":1761154830928}
{"data":{"asks":[["delete",3825.4,0.0]],"bids":[],"change_id":46343813851,"instrument_name":"ETH-PERPETUAL","prev_change_id":46343813850,"timestamp":1761154830581,"type":"change"},"instrument":"ETH-PERPETUAL","timestamp":1761154830933}
{"data":{"asks":[],"bids":[["delete",3825.35,0.0],["new",3824.25,17760.0]],"change_id":46343813852,"instrument_name":"ETH-PERPETUAL","prev_change_id":46343813851,"timestamp":1761154830581,"type":"change"},"instrument":"ETH-PERPETUAL","timestamp":1761154830944}
{"data":{"asks":[["delete",3825.5,0.0],["new",3827.8,1829.0]],"bids":[],"change_id":46343813872,"instrument_name":"ETH-PERPETUAL","prev_change_id":46343813852,"timestamp":1761154830619,"type":"change"},"instrument":"ETH-PERPETUAL","timestamp":1761154830976}
{"data":{"asks":[],"bids":[["delete",3825.15,0.0],["new",3824.3,6455.0]],"change_id":46343813875,"instrument_name":"ETH-PERPETUAL","prev_change_id":46343813872,"timestamp":1761154830622,"type":"change"},"instrument":"ETH-PERPETUAL","timestamp":1761154830980}
{"data":{"asks":[["delete",3825.7,0.0],["new",3827.75,15388.0]],"bids":[],"change_id":46343813894,"instrument_name":"ETH-PERPETUAL","prev_change_id":46343813875,"timestamp":1761154830658,"type":"change"},"instrument":"ETH-PERPETUAL","timestamp":1761154831016}
{"data":{"asks":[],"bids":[["delete",3825.05,0.0],["change",3824.4,16481.0]],"change_id":46343813931,"instrument_name":"ETH-PERPETUAL","prev_change_id":46343813894,"timestamp":1761154830662,"type":"change"},"instrument":"ETH-PERPETUAL","timestamp":1761154831021}
{"data":{"asks":[["delete",3825.75,0.0],["new",3827.65,4448.0]],"bids":[],"change_id":46343813959,"instrument_name":"ETH-PERPETUAL","prev_change_id":46343813931,"timestamp":1761154830698,"type":"change"},"instrument":"ETH-PERPETUAL","timestamp":1761154831054}
{"data":{"asks":[],"bids":[["delete",3824.85,0.0],["new",3824.5,1664.0]],"change_id":46343813961,"instrument_name":"ETH-PERPETUAL","prev_change_id":46343813959,"timestamp":1761154830700,"type":"change"},"instrument":"ETH-PERPETUAL","timestamp":1761154831063}
{"data":{"asks":[["delete",3825.8,0.0],["new",3827.6,5921.0]],"bids":[],"change_id":46343813979,"instrument_name":"ETH-PERPETUAL","prev_change_id":46343813961,"timestamp":1761154830739,"type":"change"},"instrument":"ETH-PERPETUAL","timestamp":1761154831105}
{"data":{"asks":[],"bids":[["delete",3824.8,0.0],["change",3824.55,3527.0]],"change_id":46343813981,"instrument_name":"ETH-PERPETUAL","prev_change_id":46343813979,"timestamp":1761154830740,"type":"change"},"instrument":"ETH-PERPETUAL","timestamp":1761154831109}
{"data":{"asks":[["delete",3826.0,0.0],["new",3827.55,11661.0]],"bids":[],"change_id":46343814060,"instrument_name":"ETH-PERPETUAL","prev_change_id":46343813981,"timestamp":1761154830780,"type":"change"},"instrument":"ETH-PERPETUAL","timestamp":1761154831143}
{"data":{"asks":[],"bids":[["change",3824.65,250.0]],"change_id":46343814062,"instrument_name":"ETH-PERPETUAL","prev_change_id":46343814060,"timestamp":1761154830782,"type":"change"},"instrument":"ETH-PERPETUAL","timestamp":1761154831147}
{"data":{"asks":[["delete",3826.05,0.0],["new",3827.45,21165.0]],"bids":[],"change_id":46343814064,"instrument_name":"ETH-PERPETUAL","prev_change_id":46343814062,"timestamp":1761154830822,"type":"change"},"instrument":"ETH-PERPETUAL","timestamp":1761154831187}
{"data":{"asks":[],"bids":[["new",3824.8,21111.0],["delete",3824.6,0.0]],"change_id":46343814066,"instrument_name":"ETH-PERPETUAL","prev_change_id":46343814064,"timestamp":1761154830824,"type":"change"},"instrument":"ETH-PERPETUAL","timestamp":1761154831191}
{"data":{"asks":[["delete",3826.1,0.0],["new",3827.4,9213.0]],"bids":[],"change_id":46343814070,"instrument_name":"ETH-PERPETUAL","prev_change_id":46343814066,"timestamp":1761154830861,"type":"change"},"instrument":"ETH-PERPETUAL","timestamp":1761154831227}
{"data":{"asks":[],"bids":[["new",3824.85,24417.0],["change",3824.55,1819.0]],"change_id":46343814072,"instrument_name":"ETH-PERPETUAL","prev_change_id":46343814070,"timestamp":1761154830864,"type":"change"},"instrument":"ETH-PERPETUAL","timestamp":1761154831233}
{"data":{"asks":[["delete",3826.2,0.0]],"bids":[],"change_id":46343814077,"instrument_name":"ETH-PERPETUAL","prev_change_id":46343814072,"timestamp":1761154830900,"type":"change"},"instrument":"ETH-PERPETUAL","timestamp":1761154831272}
{"data":{"asks":[],"bids":[["new",3824.9,1664.0],["change",3824.4,3698.0]],"change_id":46343814079,"instrument_name":"ETH-PERPETUAL","prev_change_id":46343814077,"timestamp":1761154830903,"type":"change"},"instrument":"ETH-PERPETUAL","timestamp":1761154831277}
{"data":{"asks":[["delete",3826.25,0.0],["new",3827.25,4448.0]],"bids":[],"change_id":46343814229,"instrument_name":"ETH-PERPETUAL","prev_change_id":46343814079,"timestamp":1761154830940,"type":"change"},"instrument":"ETH-PERPETUAL","timestamp":1761154831312}
{"data":{"asks":[],"bids":[["new",3825.0,11461.0],["delete",3824.35,0.0]],"change_id":46343814231,"instrument_name":"ETH-PERPETUAL","prev_change_id":46343814229,"timestamp":1761154830944,"type":"change"},"instrument":"ETH-PERPETUAL","timestamp":1761154831317}
{"data":{"asks":[["delete",3826.3,0.0],["new",3827.2,5738.0]],"bids":[],"change_id":46343814241,"instrument_name":"ETH-PERPETUAL","prev_change_id":46343814231,"timestamp":1761154830981,"type":"change"},"instrument":"ETH-PERPETUAL","timestamp":1761154831356}
{"data":{"asks":[],"bids":[["new",3825.1,16717.0],["delete",3824.15,0.0]],"change_id":46343814243,"instrument_name":"ETH-PERPETUAL","prev_change_id":46343814241,"timestamp":1761154830984,"type":"change"},"instrument":"ETH-PERPETUAL","timestamp":1761154831360}
{"data":{"asks":[["delete",3826.45,0.0],["new",3827.15,1000.0]],"bids":[],"change_id":46343814305,"instrument_name":"ETH-PERPETUAL","prev_change_id":46343814243,"timestamp":1761154831020,"type":"change"},"instrument":"ETH-PERPETUAL","timestamp":1761154831404}
{"data":{"asks":[],"bids":[["new",3825.15,9421.0],["delete",3824.1,0.0]],"change_id":46343814307,"instrument_name":"ETH-PERPETUAL","prev_change_id":46343814305,"timestamp":1761154831024,"type":"change"},"instrument":"ETH-PERPETUAL","timestamp":1761154831408}
{"data":{"asks":[["delete",3826.5,0.0],["change",3827.1,3168.0]],"bids":[],"change_id":46343814313,"instrument_name":"ETH-PERPETUAL","prev_change_id":46343814307,"timestamp":1761154831060,"type":"change"},"instrument":"ETH-PERPETUAL","timestamp":1761154831440}
{"data":{"asks":[],"bids":[["new",3825.35,1323.0],["delete",3824.05,0.0]],"change_id":46343814315,"instrument_name":"ETH-PERPETUAL","prev_change_id":46343814313,"timestamp":1761154831065,"type":"change"},"instrument":"ETH-PERPETUAL","timestamp":1761154831447}
{"data":{"asks":[["delete",3826.55,0.0],["new",3827.05,2088.0]],"bids":[],"change_id":46343814323,"instrument_name":"ETH-PERPETUAL","prev_change_id":46343814315,"timestamp":1761154831101,"type":"change"},"instrument":"ETH-PERPETUAL","timestamp":1761154831484}
{"data":{"asks":[],"bids":[["new",3825.4,16717.0],["delete",3823.9,0.0]],"change_id":46343814325,"instrument_name":"ETH-PERPETUAL","prev_change_id":46343814323,"timestamp":1761154831105,"type":"change"},"instrument":"ETH-PERPETUAL","timestamp":1761154831492}
{"data":{"asks":[["delete",3826.6,0.0],["change",3826.95,104513.0]],"bids":[],"change_id":46343814333,"instrument_name":"ETH-PERPETUAL","prev_change_id":46343814325,"timestamp":1761154831142,"type":"change"},"instrument":"ETH-PERPETUAL","timestamp":1761154831524}
{"data":{"asks":[],"bids":[["new",3825.55,16522.0],["delete",3823.85,0.0]],"change_id":46343814445,"instrument_name":"ETH-PERPETUAL","prev_change_id":46343814333,"timestamp":1761154831145,"type":"change"},"instrument":"ETH-PERPETUAL","timestamp":1761154831531}
{"data":{"asks":[["delete",3826.7,0.0],["change",3826.8,7003601.0]],"bids":[],"change_id":46343814574,"instrument_name":"ETH-PERPETUAL","prev_change_id":46343814445,"timestamp":1761154831182,"type":"change"},"instrument":"ETH-PERPETUAL","timestamp":1761154831570}
{"data":{"asks":[],"bids":[["new",3825.6,27537.0],["delete",3823.8,0.0]],"change_id":46343814576,"instrument_name":"ETH-PERPETUAL","prev_change_id":46343814574,"timestamp":1761154831184,"type":"change"},"instrument":"ETH-PERPETUAL","timestamp":1761154831576}
{"data":{"asks":[["new",3826.6,5263.0],["delete",3826.85,0.0]],"bids":[],"change_id":46343814586,"instrument_name":"ETH-PERPETUAL","prev_change_id":46343814576,"timestamp":1761154831223,"type":"change"},"instrument":"ETH-PERPETUAL","timestamp":1761154831616}
{"data":{"asks":[],"bids":[["new",3825.65,5968.0],["delete",3823.75,0.0]],"change_id":46343814588,"instrument_name":"ETH-PERPETUAL","prev_change_id":46343814586,"timestamp":1761154831224,"type":"change"},"instrument":"ETH-PERPETUAL","timestamp":1761154831620}
{"data":{"asks":[["new",3826.55,9700.0],["delete",3826.9,0.0]],"bids":[],"change_id":46343814598,"instrument_name":"ETH-PERPETUAL","prev_change_id":46343814588,"timestamp":1761154831263,"type":"change"},"instrument":"ETH-PERPETUAL","timestamp":1761154831657}
{"data":{"asks":[],"bids":[["new",3825.9,1000.0],["delete",3823.7,0.0]],"change_id":46343814600,"instrument_name":"ETH-PERPETUAL","prev_change_id":46343814598,"timestamp":1761154831264,"type":"change"},"instrument":"ETH-PERPETUAL","timestamp":1761154831661}
{"data":{"asks":[["new",3826.5,2895.0],["change",3826.95,66717.0]],"bids":[],"change_id":46343814611,"instrument_name":"ETH-PERPETUAL","prev_change_id":46343814600,"timestamp":1761154831302,"type":"change"},"instrument":"ETH-PERPETUAL","timestamp":1761154831695}
{"data":{"asks":[],"bids":[["new",3826.1,22000.0],["delete",3823.6,0.0]],"change_id":46343814627,"instrument_name":"ETH-PERPETUAL","prev_change_id":46343814611,"timestamp":1761154831305,"type":"change"},"instrument":"ETH-PERPETUAL","timestamp":1761154831700}
{"data":{"asks":[["new",3826.25,8.0],["change",3827.1,1584.0]],"bids":[],"change_id":46343814649,"instrument_name":"ETH-PERPETUAL","prev_change_id":46343814627,"timestamp":1761154831342,"type":"change"},"instrument":"ETH-PERPETUAL","timestamp":1761154831738}
{"data":{"asks":[],"bids":[["new",3826.15,10487.0]],"change_id":46343814651,"instrument_name":"ETH-PERPETUAL","prev_change_id":46343814649,"timestamp":1761154831346,"type":"change"},"instrument":"ETH-PERPETUAL","timestamp":1761154831748}
{"data":{"asks":[],"bids":[["new",3808.3,320000.0],["delete",3807.0,0.0]],"change_id":46343815613,"instrument_name":"ETH-PERPETUAL","prev_change_id":46343814651,"timestamp":1761154831919,"type":"change"},"instrument":"ETH-PERPETUAL","timestamp":1761154832354}
{"data":{"asks":[["delete",107893.5,0.0],["change",107947.0,5634520.0]],"bids":[],"change_id":67840115885,"instrument_name":"BTC-PERPETUAL","prev_change_id":67840110650,"timestamp":1761154832291,"type":"change"},"instrument":"BTC-PERPETUAL","timestamp":1761154832747}
{"data":{"asks":[],"bids":[["delete",107893.0,0.0],["change",107885.0,41690.0]],"change_id":67840115976,"instrument_name":"BTC-PERPETUAL","prev_change_id":67840115885,"timestamp":1761154832295,"type":"change"},"instrument":"BTC-PERPETUAL","timestamp":1761154832751}
{"data":{"asks":[["delete",107895.0,0.0],["new",107946.5,3620.0]],"bids":[],"change_id":67840116022,"instrument_name":"BTC-PERPETUAL","prev_change_id":67840115976,"timestamp":1761154832332,"type":"change"},"instrument":"BTC-PERPETUAL","timestamp":1761154832786}
{"data":{"asks":[],"bids":[["delete",107892.0,0.0],["new",107886.5,2100.0]],"change_id":67840116024,"instrument_name":"BTC-PERPETUAL","prev_change_id":67840116022,"timestamp":1761154832334,"type":"change"},"instrument":"BTC-PERPETUAL","timestamp":1761154832792}
{"data":{"asks":[["delete",107895.5,0.0],["new",107942.5,33150.0]],"bids":[],"change_id":67840116195,"instrument_name":"BTC-PERPETUAL","prev_change_id":67840116024,"timestamp":1761154832371,"type":"change"},"instrument":"BTC-PERPETUAL","timestamp":1761154832830}
{"data":{"asks":[],"bids":[["delete",107891.5,0.0],["new",107887.0,33150.0]],"change_id":67840116196,"instrument_name":"BTC-PERPETUAL","prev_change_id":67840116195,"timestamp":1761154832374,"type":"change"},"instrument":"BTC-PERPETUAL","timestamp":1761154832833}
{"data":{"asks":[["delete",107896.0,0.0],["new",107941.5,1000.0]],"bids":[],"change_id":67840116285,"instrument_name":"BTC-PERPETUAL","prev_change_id":67840116196,"timestamp":1761154832412,"type":"change"},"instrument":"BTC-PERPETUAL","timestamp":1761154832872}
{"data":{"asks":[],"bids":[["delete",107889.0,0.0],["new",107887.5,11120.0]],"change_id":67840116286,"instrument_name":"BTC-PERPETUAL","prev_change_id":67840116285,"timestamp":1761154832414,"type":"change"},"instrument":"BTC-PERPETUAL","timestamp":1761154832883}
{"data":{"asks":[["delete",107896.5,0.0],["new",107940.5,8990.0]],"bids":[],"change_id":67840116289,"instrument_name":"BTC-PERPETUAL","prev_change_id":67840116286,"timestamp":1761154832452,"type":"change"},"instrument":"BTC-PERPETUAL","timestamp":1761154832917}
{"data":{"asks":[],"bids":[["delete",107888.5,0.0],["change",107888.0,61040.0]],"change_id":67840116291,"instrument_name":"BTC-PERPETUAL","prev_change_id":67840116289,"timestamp":1761154832454,"type":"change"},"instrument":"BTC-PERPETUAL","timestamp":1761154832920}
{"data":{"asks":[["delete",107897.0,0.0],["new",107939.5,16560.0]],"bids":[],"change_id":67840116393,"instrument_name":"BTC-PERPETUAL","prev_change_id":67840116291,"timestamp":1761154832494,"type":"change"},"instrument":"BTC-PERPETUAL","timestamp":1761154832959}
{"data":{"asks":[],"bids":[["new",107889.5,50300.0],["change",107888.0,50000.0]],"change_id":67840116395,"instrument_name":"BTC-PERPETUAL","prev_change_id":67840116393,"timestamp":1761154832498,"type":"change"},"instrument":"BTC-PERPETUAL","timestamp":1761154832963}
{"data":{"asks":[["delete",107897.5,0.0],["new",107939.0,13810.0]],"bids":[],"change_id":67840116399,"instrument_name":"BTC-PERPETUAL","prev_change_id":67840116395,"timestamp":1761154832536,"type":"change"},"instrument":"BTC-PERPETUAL","timestamp":1761154833004}
{"data":{"asks":[],"bids":[["new",107893.0,8600.0],["change",107885.0,4710.0]],"change_id":67840116401,"instrument_name":"BTC-PERPETUAL","prev_change_id":67840116399,"timestamp":1761154832539,"type":"change"},"instrument":"BTC-PERPETUAL","timestamp":1761154833009}
{"data":{"asks":[["delete",107898.0,0.0],["new",107936.0,8770.0]],"bids":[],"change_id":67840116560,"instrument_name":"BTC-PERPETUAL","prev_change_id":67840116401,"timestamp":1761154832576,"type":"change"},"instrument":"BTC-PERPETUAL","timestamp":1761154833047}
{"data":{"asks":[],"bids":[["new",107893.5,33280.0],["delete",107884.5,0.0]],"change_id":67840116562,"instrument_name":"BTC-PERPETUAL","prev_change_id":67840116560,"timestamp":1761154832580,"type":"change"},"instrument":"BTC-PERPETUAL","timestamp":1761154833054}
{"data":{"asks":[["delete",107898.5,0.0],["new",107935.5,31240.0]],"bids":[],"change_id":67840116566,"instrument_name":"BTC-PERPETUAL","prev_change_id":67840116562,"timestamp":1761154832616,"type":"change"},"instrument":"BTC-PERPETUAL","timestamp":1761154833095}
{"data":{"asks":[],"bids":[["new",107894.0,9230.0],["delete",107882.5,0.0]],"change_id":67840116568,"instrument_name":"BTC-PERPETUAL","prev_change_id":67840116566,"timestamp":1761154832619,"type":"change"},"instrument":"BTC-PERPETUAL","timestamp":1761154833098}
{"data":{"asks":[],"bids":[["new",107855.5,6462890.0],["delete",107839.5,0.0]],"change_id":67840116569,"instrument_name":"BTC-PERPETUAL","prev_change_id":67840116568,"timestamp":1761154832630,"type":"change"},"instrument":"BTC-PERPETUAL","timestamp":1761154833102}
{"data":{"asks":[["delete",107900.0,0.0],["new",107932.0,41600.0]],"bids":[],"change_id":67840116575,"instrument_name":"BTC-PERPETUAL","prev_change_id":67840116569,"timestamp":1761154832658,"type":"change"},"instrument":"BTC-PERPETUAL","timestamp":1761154833138}
{"data":{"asks":[],"bids":[["new",107898.0,8620.0],["delete",107882.0,0.0]],"change_id":67840116577,"instrument_name":"BTC-PERPETUAL","prev_change_id":67840116575,"timestamp":1761154832659,"type":"change"},"instrument":"BTC-PERPETUAL","timestamp":1761154833142}
{"data":{"asks":[["delete",107900.5,0.0],["new",107930.5,5000.0]],"bids":[],"change_id":67840116583,"instrument_name":"BTC-PERPETUAL","prev_change_id":67840116577,"timestamp":1761154832698,"type":"change"},"instrument":"BTC-PERPETUAL","timestamp":1761154833177}
{"data":{"asks":[],"bids":[["new",107898.5,172620.0],["delete",107880.0,0.0]],"change_id":67840116585,"instrument_name":"BTC-PERPETUAL","prev_change_id":67840116583,"timestamp":1761154832700,"type":"change"},"instrument":"BTC-PERPETUAL","timestamp":1761154833181}
{"data":{"asks":[["delete",107904.0,0.0],["new",107929.5,2100.0]],"bids":[],"change_id":67840116619,"instrument_name":"BTC-PERPETUAL","prev_change_id":67840116585,"timestamp":1761154832739,"type":"change"},"instrument":"BTC-PERPETUAL","timestamp":1761154833221}
{"data":{"asks":[],"bids":[["new",107899.0,65060.0],["delete",107877.0,0.0]],"change_id":67840116621,"instrument_name":"BTC-PERPETUAL","prev_change_id":67840116619,"timestamp":1761154832741,"type":"change"},"instrument":"BTC-PERPETUAL","timestamp":1761154833231}
{"data":{"asks":[["delete",107904.5,0.0],["new",107929.0,500.0]],"bids":[],"change_id":67840116630,"instrument_name":"BTC-PERPETUAL","prev_change_id":67840116621,"timestamp":1761154832781,"type":"change"},"instrument":"BTC-PERPETUAL","timestamp":1761154833264}
{"data":{"asks":[],"bids":[["new",107900.0,1360.0],["delete",107876.5,0.0]],"change_id":67840116632,"instrument_name":"BTC-PERPETUAL","prev_change_id":67840116630,"timestamp":1761154832783,"type":"change"},"instrument":"BTC-PERPETUAL","timestamp":1761154833271}
{"data":{"asks":[["delete",107908.5,0.0],["new",107928.0,13290.0]],"bids":[],"change_id":67840116660,"instrument_name":"BTC-PERPETUAL","prev_change_id":67840116632,"timestamp":1761154832823,"type":"change"},"instrument":"BTC-PERPETUAL","timestamp":1761154833315}
{"data":{"asks":[],"bids":[["new",107902.0,30.0],["delete",107875.0,0.0]],"change_id":67840116662,"instrument_name":"BTC-PERPETUAL","prev_change_id":67840116660,"timestamp":1761154832824,"type":"change"},"instrument":"BTC-PERPETUAL","timestamp":1761154833319}
{"data":{"asks":[["delete",107909.0,0.0],["new",107925.5,8440.0]],"bids":[],"change_id":67840116700,"instrument_name":"BTC-PERPETUAL","prev_change_id":67840116662,"timestamp":1761154832865,"type":"change"},"instrument":"BTC-PERPETUAL","timestamp":1761154833354}
{"data":{"asks":[],"bids":[["new",107902.5,40000.0],["delete",107873.0,0.0]],"change_id":67840116702,"instrument_name":"BTC-PERPETUAL","prev_change_id":67840116700,"timestamp":1761154832867,"type":"change"},"instrument":"BTC-PERPETUAL","timestamp":1761154833359}
{"data":{"asks":[["delete",107912.0,0.0],["new",107925.0,20.0]],"bids":[],"change_id":67840116713,"instrument_name":"BTC-PERPETUAL","prev_change_id":67840116702,"timestamp":1761154832906,"type":"change"},"instrument":"BTC-PERPETUAL","timestamp":1761154833401}
{"data":{"asks":[],"bids":[["new",107903.0,61590.0],["delete",107871.5,0.0]],"change_id":67840116715,"instrument_name":"BTC-PERPETUAL","prev_change_id":67840116713,"timestamp":1761154832908,"type":"change"},"instrument":"BTC-PERPETUAL","timestamp":1761154833405}
{"data":{"asks":[["delete",107912.5,0.0],["new",107923.0,95200.0]],"bids":[],"change_id":67840116725,"instrument_name":"BTC-PERPETUAL","prev_change_id":67840116715,"timestamp":1761154832947,"type":"change"},"instrument":"BTC-PERPETUAL","timestamp":1761154833448}
{"data":{"asks":[],"bids":[["new",107903.5,30960.0],["delete",107871.0,0.0]],"change_id":67840116727,"instrument_name":"BTC-PERPETUAL","prev_change_id":67840116725,"timestamp":1761154832949,"type":"change"},"instrument":"BTC-PERPETUAL","timestamp":1761154833453}
{"data":{"asks":[["change",107947.0,8770.0],["new",107963.0,5625750.0]],"bids":[],"change_id":67840116729,"instrument_name":"BTC-PERPETUAL","prev_change_id":67840116727,"timestamp":1761154832963,"type":"change"},"instrument":"BTC-PERPETUAL","timestamp":1761154833457}
{"data":{"asks":[["delete",107915.5,0.0],["new",107922.5,33630.0]],"bids":[],"change_id":67840116739,"instrument_name":"BTC-PERPETUAL","prev_change_id":67840116729,"timestamp":1761154832987,"type":"change"},"instrument":"BTC-PERPETUAL","timestamp":1761154833483}
{"data":{"asks":[],"bids":[["new",107908.0,54900.0],["delete",107866.5,0.0]],"change_id":67840116741,"instrument_name":"BTC-PERPETUAL","prev_change_id":67840116739,"timestamp":1761154832989,"type":"change"},"instrument":"BTC-PERPETUAL","timestamp":1761154833487}
{"data":{"asks":[["new",107914.0,6000.0],["delete",107916.0,0.0]],"bids":[],"change_id":67840116867,"instrument_name":"BTC-PERPETUAL","prev_change_id":67840116741,"timestamp":1761154833028,"type":"change"},"instrument":"BTC-PERPETUAL","timestamp":1761154833532}
{"data":{"asks":[],"bids":[["new",107908.5,16400.0],["delete",107865.5,0.0]],"change_id":67840116869,"instrument_name":"BTC-PERPETUAL","prev_change_id":67840116867,"timestamp":1761154833030,"type":"change"},"instrument":"BTC-PERPETUAL","timestamp":1761154833535}
{"data":{"asks":[["new",107909.5,40380.0],["delete",107921.0,0.0]],"bids":[],"change_id":67840116881,"instrument_name":"BTC-PERPETUAL","prev_change_id":67840116869,"timestamp":1761154833070,"type":"change"},"instrument":"BTC-PERPETUAL","timestamp":1761154833573}
{"data":{"asks":[],"bids":[["new",107909.0,413380.0],["delete",107865.0,0.0]],"change_id":67840116883,"instrument_name":"BTC-PERPETUAL","prev_change_id":67840116881,"timestamp":1761154833072,"type":"change"},"instrument":"BTC-PERPETUAL","timestamp":1761154833577}
{"data":{"asks":[],"bids":[["new",3826.2,715.0]],"change_id":46343817110,"instrument_name":"ETH-PERPETUAL","prev_change_id":46343815613,"timestamp":1761154833161,"type":"change"},"instrument":"ETH-PERPETUAL","timestamp":1761154833672}
{"data":{"asks":[],"bids":[["new",107645.0,8008500.0],["delete",107629.0,0.0]],"change_id":67840117724,"instrument_name":"BTC-PERPETUAL","prev_change_id":67840116883,"timestamp":1761154833442,"type":"change"},"instrument":"BTC-PERPETUAL","timestamp":1761154833965}
{"data":{"asks":[["delete",108157.5,0.0],["new",108173.5,7087000.0]],"bids":[],"change_id":67840118063,"instrument_name":"BTC-PERPETUAL","prev_change_id":67840117724,"timestamp":1761154833766,"type":"change"},"instrument":"BTC-PERPETUAL","timestamp":1761154834311}
{"data":{"asks":[],"bids":[["new",107717.0,20000.0],["change",107636.5,165000.0]],"change_id":67840118236,"instrument_name":"BTC-PERPETUAL","prev_change_id":67840118063,"timestamp":1761154834017,"type":"change"},"instrument":"BTC-PERPETUAL","timestamp":1761154834576}
{"data":{"asks":[],"bids":[["new",107677.0,80000.0],["change",107636.5,85000.0]],"change_id":67840118949,"instrument_name":"BTC-PERPETUAL","prev_change_id":67840118236,"timestamp":1761154834477,"type":"change"},"instrument":"BTC-PERPETUAL","timestamp":1761154835064}
{"data":{"asks":[],"bids":[["new",107727.5,5000.0],["change",107636.5,80000.0]],"change_id":67840119281,"instrument_name":"BTC-PERPETUAL","prev_change_id":67840118949,"timestamp":1761154834882,"type":"change"},"instrument":"BTC-PERPETUAL","timestamp":1761154835491}
{"data":{"asks":[],"bids":[["new",107645.5,320000.0],["change",107637.0,340000.0]],"change_id":67840119395,"instrument_name":"BTC-PERPETUAL","prev_change_id":67840119281,"timestamp":1761154835136,"type":"change"},"instrument":"BTC-PERPETUAL","timestamp":1761154835761}
{"data":{"asks":[["delete",3826.25,0.0],["change",3827.8,4681.0]],"bids":[],"change_id":46343820265,"instrument_name":"ETH-PERPETUAL","prev_change_id":46343817110,"timestamp":1761154835829,"type":"change"},"instrument":"ETH-PERPETUAL","timestamp":1761154836501}
{"data":{"asks":[],"bids":[["delete",3826.15,0.0],["new",3824.15,4431.0]],"change_id":46343820266,"instrument_name":"ETH-PERPETUAL","prev_change_id":46343820265,"timestamp":1761154835830,"type":"change"},"instrument":"ETH-PERPETUAL","timestamp":1761154836505}
{"data":{"asks":[["delete",3826.5,0.0],["change",3827.75,30776.0]],"bids":[],"change_id":46343820269,"instrument_name":"ETH-PERPETUAL","prev_change_id":46343820266,"timestamp":1761154835869,"type":"change"},"instrument":"ETH-PERPETUAL","timestamp":1761154836540}
{"data":{"asks":[],"bids":[["delete",3826.1,0.0],["change",3824.25,19083.0]],"change_id":46343820270,"instrument_name":"ETH-PERPETUAL","prev_change_id":46343820269,"timestamp":1761154835870,"type":"change"},"instrument":"ETH-PERPETUAL","timestamp":1761154836544}
{"data":{"asks":[["delete",3826.55,0.0],["change",3827.65,8896.0]],"bids":[],"change_id":46343820271,"instrument_name":"ETH-PERPETUAL","prev_change_id":46343820270,"timestamp":1761154835908,"type":"change"},"instrument":"ETH-PERPETUAL","timestamp":1761154836584}
{"data":{"asks":[],"bids":[["delete",3825.9,0.0],["change",3824.4,8129.0]],"change_id":46343820272,"instrument_name":"ETH-PERPETUAL","prev_change_id":46343820271,"timestamp":1761154835910,"type":"change"},"instrument":"ETH-PERPETUAL","timestamp":1761154836589}
{"data":{"asks":[],"bids":[["new",107668.0,80000.0],["delete",107636.5,0.0]],"change_id":67840120444,"instrument_name":"BTC-PERPETUAL","prev_change_id":67840119395,"timestamp":1761154835917,"type":"change"},"instrument":"BTC-PERPETUAL","timestamp":1761154836593}
{"data":{"asks":[["delete",3826.6,0.0],["change",3827.6,11842.0]],"bids":[],"change_id":46343820420,"instrument_name":"ETH-PERPETUAL","prev_change_id":46343820272,"timestamp":1761154835948,"type":"change"},"instrument":"ETH-PERPETUAL","timestamp":1761154836625}
{"data":{"asks":[],"bids":[["delete",3825.65,0.0],["change",3824.5,3331.0]],"change_id":46343820421,"instrument_name":"ETH-PERPETUAL","prev_change_id":46343820420,"timestamp":1761154835950,"type":"change"},"instrument":"ETH-PERPETUAL","timestamp":1761154836631}
{"data":{"asks":[["change",3826.8,6972069.0],["change",3827.55,13245.0]],"bids":[],"change_id":46343820424,"instrument_name":"ETH-PERPETUAL","prev_change_id":46343820421,"timestamp":1761154835989,"type":"change"},"instrument":"ETH-PERPETUAL","timestamp":1761154836668}
{"data":{"asks":[],"bids":[["delete",3825.6,0.0],["change",3824.55,3638.0]],"change_id":46343820425,"instrument_name":"ETH-PERPETUAL","prev_change_id":46343820424,"timestamp":1761154835990,"type":"change"},"instrument":"ETH-PERPETUAL","timestamp":1761154836672}
{"data":{"asks":[["delete",3826.95,0.0],["change",3827.45,25613.0]],"bids":[],"change_id":46343820484,"instrument_name":"ETH-PERPETUAL","prev_change_id":46343820425,"timestamp":1761154836029,"type":"change"},"instrument":"ETH-PERPETUAL","timestamp":1761154836711}
{"data":{"asks":[],"bids":[["delete",3825.55,0.0],["change",3824.65,2767.0]],"change_id":46343820485,"instrument_name":"ETH-PERPETUAL","prev_change_id":46343820484,"timestamp":1761154836031,"type":"change"},"instrument":"ETH-PERPETUAL","timestamp":1761154836717}
{"data":{"asks":[["delete",3827.05,0.0],["new",3827.3,16717.0]],"bids":[],"change_id":46343820488,"instrument_name":"ETH-PERPETUAL","prev_change_id":46343820485,"timestamp":1761154836068,"type":"change"},"instrument":"ETH-PERPETUAL","timestamp":1761154836755}
{"data":{"asks":[],"bids":[["delete",3825.4,0.0],["new",3824.75,19986.0]],"change_id":46343820489,"instrument_name":"ETH-PERPETUAL","prev_change_id":46343820488,"timestamp":1761154836070,"type":"change"},"instrument":"ETH-PERPETUAL","timestamp":1761154836759}
{"data":{"asks":[["delete",3827.1,0.0],["change",3827.25,8896.0]],"bids":[],"change_id":46343820494,"instrument_name":"ETH-PERPETUAL","prev_change_id":46343820489,"timestamp":1761154836108,"type":"change"},"instrument":"ETH-PERPETUAL","timestamp":1761154836795}
{"data":{"asks":[],"bids":[["delete",3825.35,0.0],["change",3824.85,28848.0]],"change_id":46343820495,"instrument_name":"ETH-PERPETUAL","prev_change_id":46343820494,"timestamp":1761154836110,"type":"change"},"instrument":"ETH-PERPETUAL","timestamp":1761154836799}
{"data":{"asks":[["delete",3827.15,0.0],["change",3827.2,7066.0]],"bids":[],"change_id":46343820611,"instrument_name":"ETH-PERPETUAL","prev_change_id":46343820495,"timestamp":1761154836149,"type":"change"},"instrument":"ETH-PERPETUAL","timestamp":1761154836836}
{"data":{"asks":[],"bids":[["delete",3825.15,0.0],["change",3824.9,34119.0]],"change_id":46343820612,"instrument_name":"ETH-PERPETUAL","prev_change_id":46343820611,"timestamp":1761154836151,"type":"change"},"instrument":"ETH-PERPETUAL","timestamp":1761154836849}
{"data":{"asks":[["new",3827.1,30000.0],["change",3827.2,1328.0]],"bids":[],"change_id":46343820743,"instrument_name":"ETH-PERPETUAL","prev_change_id":46343820612,"timestamp":1761154836189,"type":"change"},"instrument":"ETH-PERPETUAL","timestamp":1761154836881}
{"data":{"asks":[],"bids":[["delete",3825.1,0.0],["change",3825.0,11464.0]],"change_id":46343820745,"instrument_name":"ETH-PERPETUAL","prev_change_id":46343820743,"timestamp":1761154836190,"type":"change"},"instrument":"ETH-PERPETUAL","timestamp":1761154836890}
{"data":{"asks":[["new",3827.05,10619.0],["change",3827.25,4448.0]],"bids":[],"change_id":46343820753,"instrument_name":"ETH-PERPETUAL","prev_change_id":46343820745,"timestamp":1761154836229,"type":"change"},"instrument":"ETH-PERPETUAL","timestamp":1761154836928}
{"data":{"asks":[],"bids":[["new",3825.1,15129.0],["change",3825.0,3.0]],"change_id":46343820754,"instrument_name":"ETH-PERPETUAL","prev_change_id":46343820753,"timestamp":1761154836230,"type":"change"},"instrument":"ETH-PERPETUAL","timestamp":1761154836932}
{"data":{"asks":[["new",3827.0,16717.0],["delete",3827.4,0.0]],"bids":[],"change_id":46343820762,"instrument_name":"ETH-PERPETUAL","prev_change_id":46343820754,"timestamp":1761154836291,"type":"change"},"instrument":"ETH-PERPETUAL","timestamp":1761154836991}
{"data":{"asks":[],"bids":[["new",3825.15,11623.0],["change",3824.9,32455.0]],"change_id":46343820763,"instrument_name":"ETH-PERPETUAL","prev_change_id":46343820762,"timestamp":1761154836292,"type":"change"},"instrument":"ETH-PERPETUAL","timestamp":1761154836995}
{"data":{"asks":[["new",3826.95,18629.0],["change",3827.45,4448.0]],"bids":[],"change_id":46343820797,"instrument_name":"ETH-PERPETUAL","prev_change_id":46343820763,"timestamp":1761154836332,"type":"change"},"instrument":"ETH-PERPETUAL","timestamp":1761154837035}
{"data":{"asks":[],"bids":[["new",3825.3,1322.0],["change",3824.85,4431.0]],"change_id":46343820798,"instrument_name":"ETH-PERPETUAL","prev_change_id":46343820797,"timestamp":1761154836333,"type":"change"},"instrument":"ETH-PERPETUAL","timestamp":1761154837039}
{"data":{"asks":[["new",3826.9,4410.0],["change",3827.55,1584.0]],"bids":[],"change_id":46343820807,"instrument_name":"ETH-PERPETUAL","prev_change_id":46343820798,"timestamp":1761154836371,"type":"change"},"instrument":"ETH-PERPETUAL","timestamp":1761154837076}
{"data":{"asks":[],"bids":[["new",3825.35,15000.0],["delete",3824.8,0.0]],"change_id":46343820808,"instrument_name":"ETH-PERPETUAL","prev_change_id":46343820807,"timestamp":1761154836373,"type":"change"},"instrument":"ETH-PERPETUAL","timestamp":1761154837087}
{"data":{"asks":[["change",3826.8,6985519.0],["change",3827.6,5921.0]],"bids":[],"change_id":46343820817,"instrument_name":"ETH-PERPETUAL","prev_change_id":46343820808,"timestamp":1761154836413,"type":"change"},"instrument":"ETH-PERPETUAL","timestamp":1761154837126}
{"data":{"asks":[],"bids":[["new",3825.4,18354.0],["change",3824.65,2517.0]],"change_id":46343820818,"instrument_name":"ETH-PERPETUAL","prev_change_id":46343820817,"timestamp":1761154836415,"type":"change"},"instrument":"ETH-PERPETUAL","timestamp":1761154837131}
{"data":{"asks":[["new",3826.7,66717.0],["change",3827.65,4448.0]],"bids":[],"change_id":46343821064,"instrument_name":"ETH-PERPETUAL","prev_change_id":46343820818,"timestamp":1761154836453,"type":"change"},"instrument":"ETH-PERPETUAL","timestamp":1761154837166}
{"data":{"asks":[],"bids":[["new",3825.6,9412.0],["change",3824.55,1819.0]],"change_id":46343821065,"instrument_name":"ETH-PERPETUAL","prev_change_id":46343821064,"timestamp":1761154836455,"type":"change"},"instrument":"ETH-PERPETUAL","timestamp":1761154837172}
{"data":{"asks":[["new",3826.6,19277.0],["change",3827.75,15388.0]],"bids":[],"change_id":46343821076,"instrument_name":"ETH-PERPETUAL","prev_change_id":46343821065,"timestamp":1761154836494,"type":"change"},"instrument":"ETH-PERPETUAL","timestamp":1761154837211}
{"data":{"asks":[],"bids":[["new",3825.75,19994.0],["change",3824.5,1667.0]],"change_id":46343821077,"instrument_name":"ETH-PERPETUAL","prev_change_id":46343821076,"timestamp":1761154836495,"type":"change"},"instrument":"ETH-PERPETUAL","timestamp":1761154837214}
{"data":{"asks":[["new",3826.55,9700.0],["change",3827.8,2852.0]],"bids":[],"change_id":46343821088,"instrument_name":"ETH-PERPETUAL","prev_change_id":46343821077,"timestamp":1761154836534,"type":"change"},"instrument":"ETH-PERPETUAL","timestamp":1761154837251}
{"data":{"asks":[],"bids":[["new",3825.8,5235.0],["change",3824.4,4431.0]],"change_id":46343821089,"instrument_name":"ETH-PERPETUAL","prev_change_id":46343821088,"timestamp":1761154836535,"type":"change"},"instrument":"ETH-PERPETUAL","timestamp":1761154837256}
{"data":{"asks":[],"bids":[["change",107645.5,640000.0],["change",107637.0,20000.0]],"change_id":67840121383,"instrument_name":"BTC-PERPETUAL","prev_change_id":67840120444,"timestamp":1761154836562,"type":"change"},"instrument":"BTC-PERPETUAL","timestamp":1761154837288}
{"data":{"asks":[["new",3826.5,2895.0],["delete",3828.0,0.0]],"bids":[],"change_id":46343821409,"instrument_name":"ETH-PERPETUAL","prev_change_id":46343821089,"timestamp":1761154836573,"type":"change"},"instrument":"ETH-PERPETUAL","timestamp":1761154837293}
{"data":{"asks":[],"bids":[["new",3825.85,1423.0],["delete",3824.3,0.0]],"change_id":46343821410,"instrument_name":"ETH-PERPETUAL","prev_change_id":46343821409,"timestamp":1761154836574,"type":"change"},"instrument":"ETH-PERPETUAL","timestamp":1761154837297}
{"data":{"asks":[["new",3826.25,8966.0]],"bids":[],"change_id":46343821423,"instrument_name":"ETH-PERPETUAL","prev_change_id":46343821410,"timestamp":1761154836613,"type":"change"},"instrument":"ETH-PERPETUAL","timestamp":1761154837342}
{"data":{"asks":[],"bids":[["new",3826.15,4270.0],["change",3824.25,1323.0]],"change_id":46343821424,"instrument_name":"ETH-PERPETUAL","prev_change_id":46343821423,"timestamp":1761154836614,"type":"change"},"instrument":"ETH-PERPETUAL","timestamp":1761154837346}
{"data":{"asks":[["change",3826.8,13450.0],["change",3827.75,6987457.0]],"bids":[],"change_id":46343821503,"instrument_name":"ETH-PERPETUAL","prev_change_id":46343821424,"timestamp":1761154836715,"type":"change"},"instrument":"ETH-PERPETUAL","timestamp":1761154837446}
{"data":{"asks":[],"bids":[["new",107723.0,20000.0],["delete",107637.0,0.0]],"change_id":67840121837,"instrument_name":"BTC-PERPETUAL","prev_change_id":67840121383,"timestamp":1761154837280,"type":"change"},"instrument":"BTC-PERPETUAL","timestamp":1761154838052}
{"data":{"asks":[["delete",107909.5,0.0],["change",107939.5,27560.0]],"bids":[],"change_id":67840122540,"instrument_name":"BTC-PERPETUAL","prev_change_id":67840121837,"timestamp":1761154837540,"type":"change"},"instrument":"BTC-PERPETUAL","timestamp":1761154838332}
{"data":{"asks":[],"bids":[["delete",107909.0,0.0],["new",107882.5,38420.0]],"change_id":67840122541,"instrument_name":"BTC-PERPETUAL","prev_change_id":67840122540,"timestamp":1761154837549,"type":"change"},"instrument":"BTC-PERPETUAL","timestamp":1761154838338}
{"data":{"asks":[["delete",107914.0,0.0],["change",107939.0,27630.0]],"bids":[],"change_id":67840122694,"instrument_name":"BTC-PERPETUAL","prev_change_id":67840122541,"timestamp":1761154837583,"type":"change"},"instrument":"BTC-PERPETUAL","timestamp":1761154838377}
{"data":{"asks":[],"bids":[["delete",107908.5,0.0],["new",107883.5,50300.0]],"change_id":67840122695,"instrument_name":"BTC-PERPETUAL","prev_change_id":67840122694,"timestamp":1761154837590,"type":"change"},"instrument":"BTC-PERPETUAL","timestamp":1761154838394}
{"data":{"asks":[["delete",107922.5,0.0],["new",107938.5,18640.0]],"bids":[],"change_id":67840122696,"instrument_name":"BTC-PERPETUAL","prev_change_id":67840122695,"timestamp":1761154837623,"type":"change"},"instrument":"BTC-PERPETUAL","timestamp":1761154838419}
{"data":{"asks":[],"bids":[["delete",107908.0,0.0],["new",107884.0,20990.0]],"change_id":67840122697,"instrument_name":"BTC-PERPETUAL","prev_change_id":67840122696,"timestamp":1761154837630,"type":"change"},"instrument":"BTC-PERPETUAL","timestamp":1761154838428}
{"data":{"asks":[["delete",107923.0,0.0],["new",107937.0,8440.0]],"bids":[],"change_id":67840122699,"instrument_name":"BTC-PERPETUAL","prev_change_id":67840122697,"timestamp":1761154837663,"type":"change"},"instrument":"BTC-PERPETUAL","timestamp":1761154838467}
{"data":{"asks":[],"bids":[["delete",107903.5,0.0],["change",107886.5,4200.0]],"change_id":67840122701,"instrument_name":"BTC-PERPETUAL","prev_change_id":67840122699,"timestamp":1761154837669,"type":"change"},"instrument":"BTC-PERPETUAL","timestamp":1761154838470}
{"data":{"asks":[["delete",107925.0,0.0],["new",107936.5,500.0]],"bids":[],"change_id":67840122703,"instrument_name":"BTC-PERPETUAL","prev_change_id":67840122701,"timestamp":1761154837705,"type":"change"},"instrument":"BTC-PERPETUAL","timestamp":1761154838505}
{"data":{"asks":[],"bids":[["delete",107903.0,0.0],["change",107887.0,66300.0]],"change_id":67840122705,"instrument_name":"BTC-PERPETUAL","prev_change_id":67840122703,"timestamp":1761154837709,"type":"change"},"instrument":"BTC-PERPETUAL","timestamp":1761154838513}
{"data":{"asks":[["delete",107925.5,0.0],["new",107933.0,2670.0]],"bids":[],"change_id":67840122735,"instrument_name":"BTC-PERPETUAL","prev_change_id":67840122705,"timestamp":1761154837745,"type":"change"},"instrument":"BTC-PERPETUAL","timestamp":1761154838548}
{"data":{"asks":[],"bids":[["delete",107902.5,0.0],["change",107888.0,74190.0]],"change_id":67840122737,"instrument_name":"BTC-PERPETUAL","prev_change_id":67840122735,"timestamp":1761154837750,"type":"change"},"instrument":"BTC-PERPETUAL","timestamp":1761154838553}
{"data":{"asks":[["delete",107928.0,0.0],["change",107932.0,74760.0]],"bids":[],"change_id":67840122740,"instrument_name":"BTC-PERPETUAL","prev_change_id":67840122737,"timestamp":1761154837790,"type":"change"},"instrument":"BTC-PERPETUAL","timestamp":1761154838596}
{"data":{"asks":[],"bids":[["delete",107902.0,0.0],["new",107889.0,5000.0]],"change_id":67840122743,"instrument_name":"BTC-PERPETUAL","prev_change_id":67840122740,"timestamp":1761154837792,"type":"change"},"instrument":"BTC-PERPETUAL","timestamp":1761154838603}
{"data":{"asks":[["delete",107929.0,0.0],["new",107931.5,8620.0]],"bids":[],"change_id":67840122766,"instrument_name":"BTC-PERPETUAL","prev_change_id":67840122743,"timestamp":1761154837832,"type":"change"},"instrument":"BTC-PERPETUAL","timestamp":1761154838643}
{"data":{"asks":[],"bids":[["delete",107900.0,0.0],["new",107890.5,49260.0]],"change_id":67840122769,"instrument_name":"BTC-PERPETUAL","prev_change_id":67840122766,"timestamp":1761154837834,"type":"change"},"instrument":"BTC-PERPETUAL","timestamp":1761154838647}
{"data":{"asks":[["delete",107929.5,0.0],["change",107930.5,75200.0]],"bids":[],"change_id":67840122802,"instrument_name":"BTC-PERPETUAL","prev_change_id":67840122769,"timestamp":1761154837872,"type":"change"},"instrument":"BTC-PERPETUAL","timestamp":1761154838687}
{"data":{"asks":[],"bids":[["delete",107899.0,0.0],["new",107892.5,172620.0]],"change_id":67840122805,"instrument_name":"BTC-PERPETUAL","prev_change_id":67840122802,"timestamp":1761154837876,"type":"change"},"instrument":"BTC-PERPETUAL","timestamp":1761154838691}
{"data":{"asks":[["new",107926.5,31330.0],["change",107930.5,70200.0]],"bids":[],"change_id":67840122815,"instrument_name":"BTC-PERPETUAL","prev_change_id":67840122805,"timestamp":1761154837912,"type":"change"},"instrument":"BTC-PERPETUAL","timestamp":1761154838728}
{"data":{"asks":[],"bids":[["delete",107898.5,0.0],["change",107893.0,62300.0]],"change_id":67840122818,"instrument_name":"BTC-PERPETUAL","prev_change_id":67840122815,"timestamp":1761154837916,"type":"change"},"instrument":"BTC-PERPETUAL","timestamp":1761154838737}
{"data":{"asks":[["new",107925.0,20.0],["change",107932.0,33160.0]],"bids":[],"change_id":67840122823,"instrument_name":"BTC-PERPETUAL","prev_change_id":67840122818,"timestamp":1761154837952,"type":"change"},"instrument":"BTC-PERPETUAL","timestamp":1761154838781}
{"data":{"asks":[],"bids":[["delete",107898.0,0.0],["new",107897.5,50300.0]],"change_id":67840122826,"instrument_name":"BTC-PERPETUAL","prev_change_id":67840122823,"timestamp":1761154837956,"type":"change"},"instrument":"BTC-PERPETUAL","timestamp":1761154838785}
{"data":{"asks":[["new",107923.5,20.0],["delete",107935.5,0.0]],"bids":[],"change_id":67840122831,"instrument_name":"BTC-PERPETUAL","prev_change_id":67840122826,"timestamp":1761154837992,"type":"change"},"instrument":"BTC-PERPETUAL","timestamp":1761154838833}
{"data":{"asks":[],"bids":[["new",107898.0,8620.0],["delete",107894.0,0.0]],"change_id":67840122834,"instrument_name":"BTC-PERPETUAL","prev_change_id":67840122831,"timestamp":1761154837996,"type":"change"},"instrument":"BTC-PERPETUAL","timestamp":1761154838838}
{"data":{"asks":[["new",107923.0,20.0],["delete",107936.0,0.0]],"bids":[],"change_id":67840122957,"instrument_name":"BTC-PERPETUAL","prev_change_id":67840122834,"timestamp":1761154838031,"type":"change"},"instrument":"BTC-PERPETUAL","timestamp":1761154838857}
{"data":{"asks":[],"bids":[["new",107899.0,17590.0],["delete",107893.5,0.0]],"change_id":67840122960,"instrument_name":"BTC-PERPETUAL","prev_change_id":67840122957,"timestamp":1761154838036,"type":"change"},"instrument":"BTC-PERPETUAL","timestamp":1761154838867}
{"data":{"asks":[["new",107922.5,20.0],["change",107939.0,13820.0]],"bids":[],"change_id":67840122967,"instrument_name":"BTC-PERPETUAL","prev_change_id":67840122960,"timestamp":1761154838072,"type":"change"},"instrument":"BTC-PERPETUAL","timestamp":1761154838899}
{"data":{"asks":[],"bids":[["new",107900.0,2100.0],["change",107893.0,53700.0]],"change_id":67840122970,"instrument_name":"BTC-PERPETUAL","prev_change_id":67840122967,"timestamp":1761154838076,"type":"change"},"instrument":"BTC-PERPETUAL","timestamp":1761154838904}
{"data":{"asks":[["new",107922.0,20.0],["change",107939.5,11000.0]],"bids":[],"change_id":67840122978,"instrument_name":"BTC-PERPETUAL","prev_change_id":67840122970,"timestamp":1761154838113,"type":"change"},"instrument":"BTC-PERPETUAL","timestamp":1761154838946}
{"data":{"asks":[],"bids":[["new",107900.5,9230.0],["delete",107889.5,0.0]],"change_id":67840122981,"instrument_name":"BTC-PERPETUAL","prev_change_id":67840122978,"timestamp":1761154838118,"type":"change"},"instrument":"BTC-PERPETUAL","timestamp":1761154838951}
{"data":{"asks":[["new",107921.5,20.0],["delete",107940.5,0.0]],"bids":[],"change_id":67840122992,"instrument_name":"BTC-PERPETUAL","prev_change_id":67840122981,"timestamp":1761154838151,"type":"change"},"instrument":"BTC-PERPETUAL","timestamp":1761154838990}
{"data":{"asks":[],"bids":[["new",107904.0,8440.0],["change",107888.0,24190.0]],"change_id":67840122996,"instrument_name":"BTC-PERPETUAL","prev_change_id":67840122992,"timestamp":1761154838157,"type":"change"},"instrument":"BTC-PERPETUAL","timestamp":1761154838993}
{"data":{"asks":[["new",107917.5,6000.0],["delete",107941.5,0.0]],"bids":[],"change_id":67840123005,"instrument_name":"BTC-PERPETUAL","prev_change_id":67840122996,"timestamp":1761154838193,"type":"change"},"instrument":"BTC-PERPETUAL","timestamp":1761154839029}
{"data":{"asks":[],"bids":[["new",107904.5,5500.0],["delete",107887.5,0.0]],"change_id":67840123008,"instrument_name":"BTC-PERPETUAL","prev_change_id":67840123005,"timestamp":1761154838196,"type":"change"},"instrument":"BTC-PERPETUAL","timestamp":1761154839036}
{"data":{"asks":[["new",107916.0,10000.0],["delete",107942.5,0.0]],"bids":[],"change_id":67840123017,"instrument_name":"BTC-PERPETUAL","prev_change_id":67840123008,"timestamp":1761154838234,"type":"change"},"instrument":"BTC-PERPETUAL","timestamp":1761154839073}
{"data":{"asks":[],"bids":[["new",107908.0,40020.0],["change",107887.0,33150.0]],"change_id":67840123020,"instrument_name":"BTC-PERPETUAL","prev_change_id":67840123017,"timestamp":1761154838236,"type":"change"},"instrument":"BTC-PERPETUAL","timestamp":1761154839079}
{"data":{"asks":[["new",107914.0,25000.0],["delete",107946.5,0.0]],"bids":[],"change_id":67840123143,"instrument_name":"BTC-PERPETUAL","prev_change_id":67840123020,"timestamp":1761154838276,"type":"change"},"instrument":"BTC-PERPETUAL","timestamp":1761154839121}
{"data":{"asks":[],"bids":[["new",107908.5,11960.0],["change",107886.5,2100.0]],"change_id":67840123146,"instrument_name":"BTC-PERPETUAL","prev_change_id":67840123143,"timestamp":1761154838278,"type":"change"},"instrument":"BTC-PERPETUAL","timestamp":1761154839125}
{"data":{"asks":[["new",107909.5,67600.0],["delete",107947.0,0.0]],"bids":[],"change_id":67840123189,"instrument_name":"BTC-PERPETUAL","prev_change_id":67840123146,"timestamp":1761154838316,"type":"change"},"instrument":"BTC-PERPETUAL","timestamp":1761154839161}
{"data":{"asks":[],"bids":[["new",107909.0,493570.0],["delete",107885.0,0.0]],"change_id":67840123192,"instrument_name":"BTC-PERPETUAL","prev_change_id":67840123189,"timestamp":1761154838319,"type":"change"},"instrument":"BTC-PERPETUAL","timestamp":1761154839174}
{"data":{"asks":[["delete",3826.25,0.0],["new",3828.65,15596.0]],"bids":[],"change_id":46343826523,"instrument_name":"ETH-PERPETUAL","prev_change_id":46343821503,"timestamp":1761154841079,"type":"change"},"instrument":"ETH-PERPETUAL","timestamp":1761154842125}
{"data":{"asks":[],"bids":[["delete",3826.15,0.0],["change",3824.85,8862.0]],"change_id":46343826524,"instrument_name":"ETH-PERPETUAL","prev_change_id":46343826523,"timestamp":1761154841081,"type":"change"},"instrument":"ETH-PERPETUAL","timestamp":1761154842130}
{"data":{"asks":[["delete",3826.5,0.0],["new",3828.55,1240.0]],"bids":[],"change_id":46343826525,"instrument_name":"ETH-PERPETUAL","prev_change_id":46343826524,"timestamp":1761154841121,"type":"change"},"instrument":"ETH-PERPETUAL","timestamp":1761154842171}
{"data":{"asks":[],"bids":[["delete",3825.85,0.0],["change",3824.9,52973.0]],"change_id":46343826526,"instrument_name":"ETH-PERPETUAL","prev_change_id":46343826525,"timestamp":1761154841123,"type":"change"},"instrument":"ETH-PERPETUAL","timestamp":1761154842175}
{"data":{"asks":[["delete",3826.55,0.0],["new",3828.45,1598.0]],"bids":[],"change_id":46343826637,"instrument_name":"ETH-PERPETUAL","prev_change_id":46343826526,"timestamp":1761154841161,"type":"change"},"instrument":"ETH-PERPETUAL","timestamp":1761154842213}
{"data":{"asks":[],"bids":[["delete",3825.8,0.0],["change",3825.0,4339.0]],"change_id":46343826638,"instrument_name":"ETH-PERPETUAL","prev_change_id":46343826637,"timestamp":1761154841163,"type":"change"},"instrument":"ETH-PERPETUAL","timestamp":1761154842217}
{"data":{"asks":[["delete",3826.6,0.0],["new",3828.4,4463.0]],"bids":[],"change_id":46343826760,"instrument_name":"ETH-PERPETUAL","prev_change_id":46343826638,"timestamp":1761154841200,"type":"change"},"instrument":"ETH-PERPETUAL","timestamp":1761154842258}
{"data":{"asks":[],"bids":[["delete",3825.75,0.0],["change",3825.15,16051.0]],"change_id":46343826762,"instrument_name":"ETH-PERPETUAL","prev_change_id":46343826760,"timestamp":1761154841203,"type":"change"},"instrument":"ETH-PERPETUAL","timestamp":1761154842262}
{"data":{"asks":[["delete",3826.7,0.0],["new",3828.35,10081.0]],"bids":[],"change_id":46343826764,"instrument_name":"ETH-PERPETUAL","prev_change_id":46343826762,"timestamp":1761154841240,"type":"change"},"instrument":"ETH-PERPETUAL","timestamp":1761154842370}
{"data":{"asks":[],"bids":[["delete",3825.6,0.0],["new",3825.25,30397.0]],"change_id":46343826766,"instrument_name":"ETH-PERPETUAL","prev_change_id":46343826764,"timestamp":1761154841244,"type":"change"},"instrument":"ETH-PERPETUAL","timestamp":1761154842375}
{"data":{"asks":[["delete",3826.8,0.0],["new",3828.3,4171.0]],"bids":[],"change_id":46343826768,"instrument_name":"ETH-PERPETUAL","prev_change_id":46343826766,"timestamp":1761154841280,"type":"change"},"instrument":"ETH-PERPETUAL","timestamp":1761154842379}
{"data":{"asks":[],"bids":[["delete",3825.4,0.0],["change",3825.3,11717.0]],"change_id":46343826770,"instrument_name":"ETH-PERPETUAL","prev_change_id":46343826768,"timestamp":1761154841284,"type":"change"},"instrument":"ETH-PERPETUAL","timestamp":1761154842385}
{"data":{"asks":[["delete",3826.9,0.0],["new",3828.2,21182.0]],"bids":[],"change_id":46343826797,"instrument_name":"ETH-PERPETUAL","prev_change_id":46343826770,"timestamp":1761154841319,"type":"change"},"instrument":"ETH-PERPETUAL","timestamp":1761154842389}
{"data":{"asks":[],"bids":[["new",3825.4,1637.0],["delete",3825.35,0.0]],"change_id":46343826801,"instrument_name":"ETH-PERPETUAL","prev_change_id":46343826797,"timestamp":1761154841326,"type":"change"},"instrument":"ETH-PERPETUAL","timestamp":1761154842415}
{"data":{"asks":[["delete",3826.95,0.0],["new",3828.1,4414.0]],"bids":[],"change_id":46343826803,"instrument_name":"ETH-PERPETUAL","prev_change_id":46343826801,"timestamp":1761154841360,"type":"change"},"instrument":"ETH-PERPETUAL","timestamp":1761154842429}
{"data":{"asks":[],"bids":[["new",3825.6,4433.0],["change",3825.3,10395.0]],"change_id":46343826807,"instrument_name":"ETH-PERPETUAL","prev_change_id":46343826803,"timestamp":1761154841365,"type":"change"},"instrument":"ETH-PERPETUAL","timestamp":1761154842516}
{"data":{"asks":[["delete",3827.0,0.0],["new",3828.05,7423.0]],"bids":[],"change_id":46343826809,"instrument_name":"ETH-PERPETUAL","prev_change_id":46343826807,"timestamp":1761154841399,"type":"change"},"instrument":"ETH-PERPETUAL","timestamp":1761154842519}
{"data":{"asks":[],"bids":[["new",3825.65,19986.0],["change",3825.15,4428.0]],"change_id":46343826813,"instrument_name":"ETH-PERPETUAL","prev_change_id":46343826809,"timestamp":1761154841407,"type":"change"},"instrument":"ETH-PERPETUAL","timestamp":1761154842523}
{"data":{"asks":[["delete",3827.05,0.0],["new",3828.0,6126.0]],"bids":[],"change_id":46343826981,"instrument_name":"ETH-PERPETUAL","prev_change_id":46343826813,"timestamp":1761154841439,"type":"change"},"instrument":"ETH-PERPETUAL","timestamp":1761154842527}
{"data":{"asks":[],"bids":[["new",3825.8,19725.0],["delete",3825.1,0.0]],"change_id":46343826987,"instrument_name":"ETH-PERPETUAL","prev_change_id":46343826981,"timestamp":1761154841448,"type":"change"},"instrument":"ETH-PERPETUAL","timestamp":1761154842535}
{"data":{"asks":[["delete",3827.1,0.0],["new",3827.85,15388.0]],"bids":[],"change_id":46343827059,"instrument_name":"ETH-PERPETUAL","prev_change_id":46343826987,"timestamp":1761154841479,"type":"change"},"instrument":"ETH-PERPETUAL","timestamp":1761154842561}
{"data":{"asks":[],"bids":[["new",3825.85,32105.0],["change",3825.0,4336.0]],"change_id":46343827065,"instrument_name":"ETH-PERPETUAL","prev_change_id":46343827059,"timestamp":1761154841489,"type":"change"},"instrument":"ETH-PERPETUAL","timestamp":1761154842567}
{"data":{"asks":[["delete",3827.2,0.0],["change",3827.8,9635.0]],"bids":[],"change_id":46343827067,"instrument_name":"ETH-PERPETUAL","prev_change_id":46343827065,"timestamp":1761154841518,"type":"change"},"instrument":"ETH-PERPETUAL","timestamp":1761154842598}
{"data":{"asks":[],"bids":[["new",3825.9,4433.0],["change",3824.9,20518.0]],"change_id":46343827073,"instrument_name":"ETH-PERPETUAL","prev_change_id":46343827067,"timestamp":1761154841530,"type":"change"},"instrument":"ETH-PERPETUAL","timestamp":1761154842607}
{"data":{"asks":[["delete",3827.25,0.0],["change",3827.75,6988457.0]],"bids":[],"change_id":46343827075,"instrument_name":"ETH-PERPETUAL","prev_change_id":46343827073,"timestamp":1761154841558,"type":"change"},"instrument":"ETH-PERPETUAL","timestamp":1761154842639}
{"data":{"asks":[],"bids":[["new",3825.95,10907.0],["change",3824.85,4431.0]],"change_id":46343827083,"instrument_name":"ETH-PERPETUAL","prev_change_id":46343827075,"timestamp":1761154841571,"type":"change"},"instrument":"ETH-PERPETUAL","timestamp":1761154842657}
{"data":{"asks":[["delete",3827.3,0.0],["new",3827.7,16717.0]],"bids":[],"change_id":46343827393,"instrument_name":"ETH-PERPETUAL","prev_change_id":46343827083,"timestamp":1761154841597,"type":"change"},"instrument":"ETH-PERPETUAL","timestamp":1761154842681}
{"data":{"asks":[],"bids":[["new",3826.0,2205.0],["delete",3824.75,0.0]],"change_id":46343827414,"instrument_name":"ETH-PERPETUAL","prev_change_id":46343827393,"timestamp":1761154841612,"type":"change"},"instrument":"ETH-PERPETUAL","timestamp":1761154842697}
{"data":{"asks":[["delete",3827.45,0.0],["change",3827.65,8896.0]],"bids":[],"change_id":46343827427,"instrument_name":"ETH-PERPETUAL","prev_change_id":46343827414,"timestamp":1761154841636,"type":"change"},"instrument":"ETH-PERPETUAL","timestamp":1761154842724}
{"data":{"asks":[],"bids":[["delete",3824.65,0.0]],"change_id":46343827442,"instrument_name":"ETH-PERPETUAL","prev_change_id":46343827427,"timestamp":1761154841652,"type":"change"},"instrument":"ETH-PERPETUAL","timestamp":1761154842739}
{"data":{"asks":[["delete",3827.55,0.0],["change",3827.6,62537.0]],"bids":[],"change_id":46343827493,"instrument_name":"ETH-PERPETUAL","prev_change_id":46343827442,"timestamp":1761154841676,"type":"change"},"instrument":"ETH-PERPETUAL","timestamp":1761154842775}
{"data":{"asks":[],"bids":[["new",3826.1,22000.0],["delete",3824.55,0.0]],"change_id":46343827504,"instrument_name":"ETH-PERPETUAL","prev_change_id":46343827493,"timestamp":1761154841693,"type":"change"},"instrument":"ETH-PERPETUAL","timestamp":1761154842783}
{"data":{"asks":[["new",3827.55,14723.0],["change",3827.6,56616.0]],"bids":[],"change_id":46343827520,"instrument_name":"ETH-PERPETUAL","prev_change_id":46343827504,"timestamp":1761154841721,"type":"change"},"instrument":"ETH-PERPETUAL","timestamp":1761154842814}
{"data":{"asks":[],"bids":[["new",3826.15,28016.0],["delete",3824.5,0.0]],"change_id":46343827532,"instrument_name":"ETH-PERPETUAL","prev_change_id":46343827520,"timestamp":1761154841733,"type":"change"},"instrument":"ETH-PERPETUAL","timestamp":1761154842832}
{"data":{"asks":[["new",3827.3,26776.0],["change",3827.65,4448.0]],"bids":[],"change_id":46343827537,"instrument_name":"ETH-PERPETUAL","prev_change_id":46343827532,"timestamp":1761154841763,"type":"change"},"instrument":"ETH-PERPETUAL","timestamp":1761154842861}
{"data":{"asks":[],"bids":[["new",3826.4,19994.0],["delete",3824.4,0.0]],"change_id":46343827549,"instrument_name":"ETH-PERPETUAL","prev_change_id":46343827537,"timestamp":1761154841773,"type":"change"},"instrument":"ETH-PERPETUAL","timestamp":1761154842871}
{"data":{"asks":[["new",3827.25,7993.0],["change",3827.75,6973069.0]],"bids":[],"change_id":46343827625,"instrument_name":"ETH-PERPETUAL","prev_change_id":46343827549,"timestamp":1761154841804,"type":"change"},"instrument":"ETH-PERPETUAL","timestamp":1761154842907}
{"data":{"asks":[],"bids":[["new",3826.5,5968.0],["delete",3824.25,0.0]],"change_id":46343827636,"instrument_name":"ETH-PERPETUAL","prev_change_id":46343827625,"timestamp":1761154841814,"type":"change"},"instrument":"ETH-PERPETUAL","timestamp":1761154842914}
{"data":{"asks":[["new",3827.1,22158.0],["change",3827.8,6783.0]],"bids":[],"change_id":46343827641,"instrument_name":"ETH-PERPETUAL","prev_change_id":46343827636,"timestamp":1761154841844,"type":"change"},"instrument":"ETH-PERPETUAL","timestamp":1761154842950}
{"data":{"asks":[],"bids":[["new",3827.05,5539.0],["delete",3824.15,0.0]],"change_id":46343827652,"instrument_name":"ETH-PERPETUAL","prev_change_id":46343827641,"timestamp":1761154841854,"type":"change"},"instrument":"ETH-PERPETUAL","timestamp":1761154842956}
{"data":{"asks":[["delete",107909.5,0.0],["new",107960.5,7670.0]],"bids":[],"change_id":67840128973,"instrument_name":"BTC-PERPETUAL","prev_change_id":67840123192,"timestamp":1761154842790,"type":"change"},"instrument":"BTC-PERPETUAL","timestamp":1761154843966}
{"data":{"asks":[],"bids":[["new",107909.5,45000.0],["delete",107909.0,0.0]],"change_id":67840128974,"instrument_name":"BTC-PERPETUAL","prev_change_id":67840128973,"timestamp":1761154842792,"type":"change"},"instrument":"BTC-PERPETUAL","timestamp":1761154843972}
{"data":{"asks":[["delete",107914.0,0.0],["new",107959.5,10.0]],"bids":[],"change_id":67840128976,"instrument_name":"BTC-PERPETUAL","prev_change_id":67840128974,"timestamp":1761154842830,"type":"change"},"instrument":"BTC-PERPETUAL","timestamp":1761154844009}
{"data":{"asks":[],"bids":[["new",107910.0,59230.0],["delete",107908.5,0.0]],"change_id":67840128977,"instrument_name":"BTC-PERPETUAL","prev_change_id":67840128976,"timestamp":1761154842832,"type":"change"},"instrument":"BTC-PERPETUAL","timestamp":1761154844015}
{"data":{"asks":[["delete",107916.0,0.0],["new",107957.5,33090.0]],"bids":[],"change_id":67840129028,"instrument_name":"BTC-PERPETUAL","prev_change_id":67840128977,"timestamp":1761154842869,"type":"change"},"instrument":"BTC-PERPETUAL","timestamp":1761154844050}
{"data":{"asks":[],"bids":[["new",107912.5,33090.0],["delete",107908.0,0.0]],"change_id":67840129029,"instrument_name":"BTC-PERPETUAL","prev_change_id":67840129028,"timestamp":1761154842873,"type":"change"},"instrument":"BTC-PERPETUAL","timestamp":1761154844053}
{"data":{"asks":[["delete",107917.5,0.0],["new",107956.0,17800.0]],"bids":[],"change_id":67840129030,"instrument_name":"BTC-PERPETUAL","prev_change_id":67840129029,"timestamp":1761154842909,"type":"change"},"instrument":"BTC-PERPETUAL","timestamp":1761154844089}
{"data":{"asks":[],"bids":[["new",107913.5,500.0],["delete",107904.5,0.0]],"change_id":67840129033,"instrument_name":"BTC-PERPETUAL","prev_change_id":67840129030,"timestamp":1761154842912,"type":"change"},"instrument":"BTC-PERPETUAL","timestamp":1761154844093}
{"data":{"asks":[["delete",107921.5,0.0],["new",107954.5,16990.0]],"bids":[],"change_id":67840129035,"instrument_name":"BTC-PERPETUAL","prev_change_id":67840129033,"timestamp":1761154842951,"type":"change"},"instrument":"BTC-PERPETUAL","timestamp":1761154844134}
{"data":{"asks":[],"bids":[["new",107914.0,31070.0],["delete",107904.0,0.0]],"change_id":67840129037,"instrument_name":"BTC-PERPETUAL","prev_change_id":67840129035,"timestamp":1761154842953,"type":"change"},"instrument":"BTC-PERPETUAL","timestamp":1761154844143}
{"data":{"asks":[["delete",107922.0,0.0],["new",107954.0,2100.0]],"bids":[],"change_id":67840129039,"instrument_name":"BTC-PERPETUAL","prev_change_id":67840129037,"timestamp":1761154842990,"type":"change"},"instrument":"BTC-PERPETUAL","timestamp":1761154844177}
{"data":{"asks":[],"bids":[["new",107919.0,2100.0],["delete",107900.5,0.0]],"change_id":67840129041,"instrument_name":"BTC-PERPETUAL","prev_change_id":67840129039,"timestamp":1761154842994,"type":"change"},"instrument":"BTC-PERPETUAL","timestamp":1761154844182}
{"data":{"asks":[["delete",107922.5,0.0],["new",107953.5,31240.0]],"bids":[],"change_id":67840129157,"instrument_name":"BTC-PERPETUAL","prev_change_id":67840129041,"timestamp":1761154843032,"type":"change"},"instrument":"BTC-PERPETUAL","timestamp":1761154844225}
{"data":{"asks":[],"bids":[["new",107919.5,50300.0],["delete",107900.0,0.0]],"change_id":67840129163,"instrument_name":"BTC-PERPETUAL","prev_change_id":67840129157,"timestamp":1761154843036,"type":"change"},"instrument":"BTC-PERPETUAL","timestamp":1761154844229}
{"data":{"asks":[["delete",107923.0,0.0],["new",107951.0,25000.0]],"bids":[],"change_id":67840129167,"instrument_name":"BTC-PERPETUAL","prev_change_id":67840129163,"timestamp":1761154843073,"type":"change"},"instrument":"BTC-PERPETUAL","timestamp":1761154844269}
{"data":{"asks":[],"bids":[["new",107920.0,15640.0],["delete",107899.0,0.0]],"change_id":67840129171,"instrument_name":"BTC-PERPETUAL","prev_change_id":67840129167,"timestamp":1761154843077,"type":"change"},"instrument":"BTC-PERPETUAL","timestamp":1761154844274}
{"data":{"asks":[["delete",107923.5,0.0],["new",107950.0,20.0]],"bids":[],"change_id":67840129173,"instrument_name":"BTC-PERPETUAL","prev_change_id":67840129171,"timestamp":1761154843114,"type":"change"},"instrument":"BTC-PERPETUAL","timestamp":1761154844308}
{"data":{"asks":[],"bids":[["new",107921.5,8440.0],["delete",107898.0,0.0]],"change_id":67840129177,"instrument_name":"BTC-PERPETUAL","prev_change_id":67840129173,"timestamp":1761154843118,"type":"change"},"instrument":"BTC-PERPETUAL","timestamp":1761154844312}
{"data":{"asks":[["delete",107925.0,0.0],["new",107949.5,8440.0]],"bids":[],"change_id":67840129180,"instrument_name":"BTC-PERPETUAL","prev_change_id":67840129177,"timestamp":1761154843152,"type":"change"},"instrument":"BTC-PERPETUAL","timestamp":1761154844350}
{"data":{"asks":[],"bids":[["new",107922.0,61590.0],["delete",107897.5,0.0]],"change_id":67840129186,"instrument_name":"BTC-PERPETUAL","prev_change_id":67840129180,"timestamp":1761154843159,"type":"change"},"instrument":"BTC-PERPETUAL","timestamp":1761154844361}
{"data":{"asks":[["delete",107926.5,0.0],["new",107949.0,18800.0]],"bids":[],"change_id":67840129188,"instrument_name":"BTC-PERPETUAL","prev_change_id":67840129186,"timestamp":1761154843191,"type":"change"},"instrument":"BTC-PERPETUAL","timestamp":1761154844392}
{"data":{"asks":[],"bids":[["new",107923.5,8620.0],["delete",107893.0,0.0]],"change_id":67840129194,"instrument_name":"BTC-PERPETUAL","prev_change_id":67840129188,"timestamp":1761154843201,"type":"change"},"instrument":"BTC-PERPETUAL","timestamp":1761154844403}
{"data":{"asks":[["delete",107930.5,0.0],["new",107948.5,510.0]],"bids":[],"change_id":67840129197,"instrument_name":"BTC-PERPETUAL","prev_change_id":67840129194,"timestamp":1761154843231,"type":"change"},"instrument":"BTC-PERPETUAL","timestamp":1761154844439}
{"data":{"asks":[],"bids":[["new",107924.0,30.0],["delete",107892.5,0.0]],"change_id":67840129203,"instrument_name":"BTC-PERPETUAL","prev_change_id":67840129197,"timestamp":1761154843242,"type":"change"},"instrument":"BTC-PERPETUAL","timestamp":1761154844444}
{"data":{"asks":[["delete",107931.5,0.0],["new",107948.0,20.0]],"bids":[],"change_id":67840129206,"instrument_name":"BTC-PERPETUAL","prev_change_id":67840129203,"timestamp":1761154843270,"type":"change"},"instrument":"BTC-PERPETUAL","timestamp":1761154844479}
{"data":{"asks":[],"bids":[["new",107924.5,49340.0],["delete",107890.5,0.0]],"change_id":67840129318,"instrument_name":"BTC-PERPETUAL","prev_change_id":67840129206,"timestamp":1761154843283,"type":"change"},"instrument":"BTC-PERPETUAL","timestamp":1761154844489}
{"data":{"asks":[["delete",107932.0,0.0],["new",107946.5,70200.0]],"bids":[],"change_id":67840129352,"instrument_name":"BTC-PERPETUAL","prev_change_id":67840129318,"timestamp":1761154843310,"type":"change"},"instrument":"BTC-PERPETUAL","timestamp":1761154844521}
{"data":{"asks":[],"bids":[["new",107925.0,54800.0],["delete",107889.0,0.0]],"change_id":67840129360,"instrument_name":"BTC-PERPETUAL","prev_change_id":67840129352,"timestamp":1761154843323,"type":"change"},"instrument":"BTC-PERPETUAL","timestamp":1761154844545}
{"data":{"asks":[["delete",107933.0,0.0],["new",107946.0,8620.0]],"bids":[],"change_id":67840129362,"instrument_name":"BTC-PERPETUAL","prev_change_id":67840129360,"timestamp":1761154843350,"type":"change"},"instrument":"BTC-PERPETUAL","timestamp":1761154844562}
{"data":{"asks":[],"bids":[["new",107926.5,54790.0],["delete",107888.0,0.0]],"change_id":67840129379,"instrument_name":"BTC-PERPETUAL","prev_change_id":67840129362,"timestamp":1761154843364,"type":"change"},"instrument":"BTC-PERPETUAL","timestamp":1761154844576}
{"data":{"asks":[["delete",107936.5,0.0],["new",107945.5,23210.0]],"bids":[],"change_id":67840129944,"instrument_name":"BTC-PERPETUAL","prev_change_id":67840129379,"timestamp":1761154843389,"type":"change"},"instrument":"BTC-PERPETUAL","timestamp":1761154844604}
{"data":{"asks":[],"bids":[["new",107927.0,20.0],["delete",107887.0,0.0]],"change_id":67840129954,"instrument_name":"BTC-PERPETUAL","prev_change_id":67840129944,"timestamp":1761154843403,"type":"change"},"instrument":"BTC-PERPETUAL","timestamp":1761154844618}
{"data":{"asks":[["delete",107937.0,0.0],["new",107940.0,20.0]],"bids":[],"change_id":67840129956,"instrument_name":"BTC-PERPETUAL","prev_change_id":67840129954,"timestamp":1761154843432,"type":"change"},"instrument":"BTC-PERPETUAL","timestamp":1761154844653}
{"data":{"asks":[],"bids":[["new",107927.5,20.0],["delete",107886.5,0.0]],"change_id":67840129966,"instrument_name":"BTC-PERPETUAL","prev_change_id":67840129956,"timestamp":1761154843444,"type":"change"},"instrument":"BTC-PERPETUAL","timestamp":1761154844661}
{"data":{"asks":[["delete",107938.5,0.0],["change",107939.5,11020.0]],"bids":[],"change_id":67840129968,"instrument_name":"BTC-PERPETUAL","prev_change_id":67840129966,"timestamp":1761154843475,"type":"change"},"instrument":"BTC-PERPETUAL","timestamp":1761154844696}
{"data":{"asks":[],"bids":[["new",107928.5,50990.0],["delete",107884.0,0.0]],"change_id":67840129978,"instrument_name":"BTC-PERPETUAL","prev_change_id":67840129968,"timestamp":1761154843484,"type":"change"},"instrument":"BTC-PERPETUAL","timestamp":1761154844711}
{"data":{"asks":[["change",107939.0,20.0]],"bids":[],"change_id":67840130087,"instrument_name":"BTC-PERPETUAL","prev_change_id":67840129978,"timestamp":1761154843514,"type":"change"},"instrument":"BTC-PERPETUAL","timestamp":1761154844739}
{"data":{"asks":[],"bids":[["new",107929.0,55490.0],["delete",107883.5,0.0]],"change_id":67840130104,"instrument_name":"BTC-PERPETUAL","prev_change_id":67840130087,"timestamp":1761154843526,"type":"change"},"instrument":"BTC-PERPETUAL","timestamp":1761154844751}
{"data":{"asks":[["new",107935.0,72210.0],["change",107939.5,20.0]],"bids":[],"change_id":67840130106,"instrument_name":"BTC-PERPETUAL","prev_change_id":67840130104,"timestamp":1761154843552,"type":"change"},"instrument":"BTC-PERPETUAL","timestamp":1761154844778}
{"data":{"asks":[],"bids":[["new",107934.5,258770.0],["delete",107882.5,0.0]],"change_id":67840130118,"instrument_name":"BTC-PERPETUAL","prev_change_id":67840130106,"timestamp":1761154843568,"type":"change"},"instrument":"BTC-PERPETUAL","timestamp":1761154844796}
{"data":{"asks":[["change",3827.75,1000.0],["new",3829.4,6972069.0]],"bids":[],"change_id":46343829993,"instrument_name":"ETH-PERPETUAL","prev_change_id":46343827652,"timestamp":1761154843659,"type":"change"},"instrument":"ETH-PERPETUAL","timestamp":1761154844893}
{"data":{"asks":[["delete",3827.1,0.0],["new",3827.95,6075.0]],"bids":[],"change_id":46343832836,"instrument_name":"ETH-PERPETUAL","prev_change_id":46343829993,"timestamp":1761154846329,"type":"change"},"instrument":"ETH-PERPETUAL","timestamp":1761154847740}
{"data":{"asks":[],"bids":[["delete",3827.05,0.0],["new",3824.65,4429.0]],"change_id":46343832837,"instrument_name":"ETH-PERPETUAL","prev_change_id":46343832836,"timestamp":1761154846331,"type":"change"},"instrument":"ETH-PERPETUAL","timestamp":1761154847748}
{"data":{"asks":[["delete",3827.25,0.0],["new",3827.9,1840.0]],"bids":[],"change_id":46343832838,"instrument_name":"ETH-PERPETUAL","prev_change_id":46343832837,"timestamp":1761154846368,"type":"change"},"instrument":"ETH-PERPETUAL","timestamp":1761154847784}
{"data":{"asks":[],"bids":[["delete",3826.5,0.0],["change",3824.85,9706.0]],"change_id":46343832839,"instrument_name":"ETH-PERPETUAL","prev_change_id":46343832838,"timestamp":1761154846371,"type":"change"},"instrument":"ETH-PERPETUAL","timestamp":1761154847795}
{"data":{"asks":[["delete",3827.3,0.0],["change",3827.75,17717.0]],"bids":[],"change_id":46343832843,"instrument_name":"ETH-PERPETUAL","prev_change_id":46343832839,"timestamp":1761154846407,"type":"change"},"instrument":"ETH-PERPETUAL","timestamp":1761154847823}
{"data":{"asks":[],"bids":[["delete",3826.4,0.0],["change",3824.9,22182.0]],"change_id":46343832845,"instrument_name":"ETH-PERPETUAL","prev_change_id":46343832843,"timestamp":1761154846411,"type":"change"},"instrument":"ETH-PERPETUAL","timestamp":1761154847829}
{"data":{"asks":[["delete",3827.55,0.0],["change",3827.7,21707.0]],"bids":[],"change_id":46343833020,"instrument_name":"ETH-PERPETUAL","prev_change_id":46343832845,"timestamp":1761154846447,"type":"change"},"instrument":"ETH-PERPETUAL","timestamp":1761154847870}
{"data":{"asks":[],"bids":[["delete",3826.15,0.0],["change",3825.0,6486.0]],"change_id":46343833021,"instrument_name":"ETH-PERPETUAL","prev_change_id":46343833020,"timestamp":1761154846451,"type":"change"},"instrument":"ETH-PERPETUAL","timestamp":1761154847874}
{"data":{"asks":[["new",3827.55,4424.0],["delete",3827.6,0.0]],"bids":[],"change_id":46343833094,"instrument_name":"ETH-PERPETUAL","prev_change_id":46343833021,"timestamp":1761154846487,"type":"change"},"instrument":"ETH-PERPETUAL","timestamp":1761154847913}
{"data":{"asks":[],"bids":[["delete",3826.1,0.0],["new",3825.05,19986.0]],"change_id":46343833095,"instrument_name":"ETH-PERPETUAL","prev_change_id":46343833094,"timestamp":1761154846492,"type":"change"},"instrument":"ETH-PERPETUAL","timestamp":1761154847919}
{"data":{"asks":[],"bids":[["new",107881.0,6462890.0],["delete",107855.5,0.0]],"change_id":67840133848,"instrument_name":"BTC-PERPETUAL","prev_change_id":67840130118,"timestamp":1761154846512,"type":"change"},"instrument":"BTC-PERPETUAL","timestamp":1761154847935}
{"data":{"asks":[["new",3827.5,4438.0],["delete",3827.65,0.0]],"bids":[],"change_id":46343833102,"instrument_name":"ETH-PERPETUAL","prev_change_id":46343833095,"timestamp":1761154846528,"type":"change"},"instrument":"ETH-PERPETUAL","timestamp":1761154847950}
{"data":{"asks":[],"bids":[["delete",3826.0,0.0],["change",3825.15,8856.0]],"change_id":46343833103,"instrument_name":"ETH-PERPETUAL","prev_change_id":46343833102,"timestamp":1761154846532,"type":"change"},"instrument":"ETH-PERPETUAL","timestamp":1761154847957}
{"data":{"asks":[["new",3827.4,3645.0],["change",3827.7,4990.0]],"bids":[],"change_id":46343833106,"instrument_name":"ETH-PERPETUAL","prev_change_id":46343833103,"timestamp":1761154846568,"type":"change"},"instrument":"ETH-PERPETUAL","timestamp":1761154847995}
{"data":{"asks":[],"bids":[["delete",3825.95,0.0],["change",3825.25,30404.0]],"change_id":46343833108,"instrument_name":"ETH-PERPETUAL","prev_change_id":46343833106,"timestamp":1761154846576,"type":"change"},"instrument":"ETH-PERPETUAL","timestamp":1761154847999}
{"data":{"asks":[["new",3827.35,1604.0],["change",3827.75,16717.0]],"bids":[],"change_id":46343833408,"instrument_name":"ETH-PERPETUAL","prev_change_id":46343833108,"timestamp":1761154846608,"type":"change"},"instrument":"ETH-PERPETUAL","timestamp":1761154848040}
{"data":{"asks":[],"bids":[["delete",3825.9,0.0],["new",3825.35,15388.0]],"change_id":46343833413,"instrument_name":"ETH-PERPETUAL","prev_change_id":46343833408,"timestamp":1761154846616,"type":"change"},"instrument":"ETH-PERPETUAL","timestamp":1761154848046}
{"data":{"asks":[["new",3827.25,16717.0],["delete",3827.8,0.0]],"bids":[],"change_id":46343833438,"instrument_name":"ETH-PERPETUAL","prev_change_id":46343833413,"timestamp":1761154846647,"type":"change"},"instrument":"ETH-PERPETUAL","timestamp":1761154848077}
{"data":{"asks":[],"bids":[["delete",3825.85,0.0],["change",3825.4,24429.0]],"change_id":46343833443,"instrument_name":"ETH-PERPETUAL","prev_change_id":46343833438,"timestamp":1761154846656,"type":"change"},"instrument":"ETH-PERPETUAL","timestamp":1761154848085}
{"data":{"asks":[["new",3827.2,58930.0],["delete",3827.85,0.0]],"bids":[],"change_id":46343833503,"instrument_name":"ETH-PERPETUAL","prev_change_id":46343833443,"timestamp":1761154846687,"type":"change"},"instrument":"ETH-PERPETUAL","timestamp":1761154848118}
{"data":{"asks":[],"bids":[["delete",3825.8,0.0],["new",3825.5,625.0]],"change_id":46343833507,"instrument_name":"ETH-PERPETUAL","prev_change_id":46343833503,"timestamp":1761154846697,"type":"change"},"instrument":"ETH-PERPETUAL","timestamp":1761154848138}
{"data":{"asks":[["new",3827.1,55080.0],["delete",3828.0,0.0]],"bids":[],"change_id":46343833520,"instrument_name":"ETH-PERPETUAL","prev_change_id":46343833507,"timestamp":1761154846726,"type":"change"},"instrument":"ETH-PERPETUAL","timestamp":1761154848162}
{"data":{"asks":[],"bids":[["delete",3825.65,0.0],["change",3825.6,8866.0]],"change_id":46343833523,"instrument_name":"ETH-PERPETUAL","prev_change_id":46343833520,"timestamp":1761154846738,"type":"change"},"instrument":"ETH-PERPETUAL","timestamp":1761154848173}
{"data":{"asks":[["new",3827.05,55080.0],["delete",3828.05,0.0]],"bids":[],"change_id":46343833528,"instrument_name":"ETH-PERPETUAL","prev_change_id":46343833523,"timestamp":1761154846766,"type":"change"},"instrument":"ETH-PERPETUAL","timestamp":1761154848203}
{"data":{"asks":[],"bids":[["new",3825.65,1323.0],["change",3825.6,4433.0]],"change_id":46343833533,"instrument_name":"ETH-PERPETUAL","prev_change_id":46343833528,"timestamp":1761154846779,"type":"change"},"instrument":"ETH-PERPETUAL","timestamp":1761154848216}
{"data":{"asks":[["new",3827.0,117294.0],["delete",3828.1,0.0]],"bids":[],"change_id":46343833612,"instrument_name":"ETH-PERPETUAL","prev_change_id":46343833533,"timestamp":1761154846807,"type":"change"},"instrument":"ETH-PERPETUAL","timestamp":1761154848247}
{"data":{"asks":[],"bids":[["new",3825.8,16717.0],["change",3825.4,22792.0]],"change_id":46343833617,"instrument_name":"ETH-PERPETUAL","prev_change_id":46343833612,"timestamp":1761154846820,"type":"change"},"instrument":"ETH-PERPETUAL","timestamp":1761154848260}
{"data":{"asks":[["delete",107963.0,0.0],["new",107988.5,5625750.0]],"bids":[],"change_id":67840134050,"instrument_name":"BTC-PERPETUAL","prev_change_id":67840133848,"timestamp":1761154846844,"type":"change"},"instrument":"BTC-PERPETUAL","timestamp":1761154848287}
{"data":{"asks":[["new",3826.95,55080.0],["delete",3828.2,0.0]],"bids":[],"change_id":46343833622,"instrument_name":"ETH-PERPETUAL","prev_change_id":46343833617,"timestamp":1761154846846,"type":"change"},"instrument":"ETH-PERPETUAL","timestamp":1761154848294}
{"data":{"asks":[],"bids":[["new",3825.85,15000.0],["delete",3825.3,0.0]],"change_id":46343833627,"instrument_name":"ETH-PERPETUAL","prev_change_id":46343833622,"timestamp":1761154846861,"type":"change"},"instrument":"ETH-PERPETUAL","timestamp":1761154848303}
{"data":{"asks":[["new",3826.9,85080.0],["delete",3828.3,0.0]],"bids":[],"change_id":46343833632,"instrument_name":"ETH-PERPETUAL","prev_change_id":46343833627,"timestamp":1761154846887,"type":"change"},"instrument":"ETH-PERPETUAL","timestamp":1761154848331}
{"data":{"asks":[],"bids":[["new",3825.9,19993.0],["change",3825.25,7.0]],"change_id":46343833637,"instrument_name":"ETH-PERPETUAL","prev_change_id":46343833632,"timestamp":1761154846901,"type":"change"},"instrument":"ETH-PERPETUAL","timestamp":1761154848347}
{"data":{"asks":[["new",3826.85,63094.0],["delete",3828.35,0.0]],"bids":[],"change_id":46343833642,"instrument_name":"ETH-PERPETUAL","prev_change_id":46343833637,"timestamp":1761154846928,"type":"change"},"instrument":"ETH-PERPETUAL","timestamp":1761154848374}
{"data":{"asks":[],"bids":[["new",3826.0,15435.0],["change",3825.15,4428.0]],"change_id":46343833649,"instrument_name":"ETH-PERPETUAL","prev_change_id":46343833642,"timestamp":1761154846942,"type":"change"},"instrument":"ETH-PERPETUAL","timestamp":1761154848390}
{"data":{"asks":[["new",3826.8,9600.0],["delete",3828.4,0.0]],"bids":[],"change_id":46343833800,"instrument_name":"ETH-PERPETUAL","prev_change_id":46343833649,"timestamp":1761154846969,"type":"change"},"instrument":"ETH-PERPETUAL","timestamp":1761154848421}
{"data":{"asks":[],"bids":[["new",3826.15,2852.0],["change",3825.0,2150.0]],"change_id":46343833807,"instrument_name":"ETH-PERPETUAL","prev_change_id":46343833800,"timestamp":1761154846982,"type":"change"},"instrument":"ETH-PERPETUAL","timestamp":1761154848439}
{"data":{"asks":[["new",3826.75,2866.0],["delete",3828.45,0.0]],"bids":[],"change_id":46343833812,"instrument_name":"ETH-PERPETUAL","prev_change_id":46343833807,"timestamp":1761154847007,"type":"change"},"instrument":"ETH-PERPETUAL","timestamp":1761154848460}
{"data":{"asks":[],"bids":[["new",3826.3,1070.0],["change",3824.9,1664.0]],"change_id":46343833875,"instrument_name":"ETH-PERPETUAL","prev_change_id":46343833812,"timestamp":1761154847022,"type":"change"},"instrument":"ETH-PERPETUAL","timestamp":1761154848475}
{"data":{"asks":[["new",3826.6,5000.0],["delete",3828.55,0.0]],"bids":[],"change_id":46343833880,"instrument_name":"ETH-PERPETUAL","prev_change_id":46343833875,"timestamp":1761154847048,"type":"change"},"instrument":"ETH-PERPETUAL","timestamp":1761154848505}
{"data":{"asks":[],"bids":[["new",3826.4,1000.0],["change",3824.85,5275.0]],"change_id":46343833887,"instrument_name":"ETH-PERPETUAL","prev_change_id":46343833880,"timestamp":1761154847061,"type":"change"},"instrument":"ETH-PERPETUAL","timestamp":1761154848518}
{"data":{"asks":[["new",3826.55,11848.0],["delete",3828.65,0.0]],"bids":[],"change_id":46343833894,"instrument_name":"ETH-PERPETUAL","prev_change_id":46343833887,"timestamp":1761154847088,"type":"change"},"instrument":"ETH-PERPETUAL","timestamp":1761154848543}
{"data":{"asks":[],"bids":[["new",3826.5,22386.0]],"change_id":46343833901,"instrument_name":"ETH-PERPETUAL","prev_change_id":46343833894,"timestamp":1761154847103,"type":"change"},"instrument":"ETH-PERPETUAL","timestamp":1761154848559}
{"data":{"asks":[],"bids":[["new",107670.5,8008500.0],["delete",107645.0,0.0]],"change_id":67840134332,"instrument_name":"BTC-PERPETUAL","prev_change_id":67840134050,"timestamp":1761154847347,"type":"change"},"instrument":"BTC-PERPETUAL","timestamp":1761154848820}
{"data":{"asks":[],"bids":[["delete",3826.2,0.0]],"change_id":46343834507,"instrument_name":"ETH-PERPETUAL","prev_change_id":46343833901,"timestamp":1761154847478,"type":"change"},"instrument":"ETH-PERPETUAL","timestamp":1761154848960}
{"data":{"asks":[["delete",108173.5,0.0],["new",108199.0,7087000.0]],"bids":[],"change_id":67840135176,"instrument_name":"BTC-PERPETUAL","prev_change_id":67840134332,"timestamp":1761154847716,"type":"change"},"instrument":"BTC-PERPETUAL","timestamp":1761154849215}
{"data":{"asks":[["delete",107935.0,0.0],["change",107966.5,33100.0]],"bids":[],"change_id":67840135370,"instrument_name":"BTC-PERPETUAL","prev_change_id":67840135176,"timestamp":1761154848039,"type":"change"},"instrument":"BTC-PERPETUAL","timestamp":1761154849560}
{"data":{"asks":[],"bids":[["delete",107934.5,0.0],["change",107909.5,95290.0]],"change_id":67840135371,"instrument_name":"BTC-PERPETUAL","prev_change_id":67840135370,"timestamp":1761154848040,"type":"change"},"instrument":"BTC-PERPETUAL","timestamp":1761154849569}
{"data":{"asks":[["delete",107939.0,0.0],["new",107965.5,17290.0]],"bids":[],"change_id":67840135372,"instrument_name":"BTC-PERPETUAL","prev_change_id":67840135371,"timestamp":1761154848080,"type":"change"},"instrument":"BTC-PERPETUAL","timestamp":1761154849610}
{"data":{"asks":[],"bids":[["delete",107929.0,0.0],["change",107910.0,231870.0]],"change_id":67840135373,"instrument_name":"BTC-PERPETUAL","prev_change_id":67840135372,"timestamp":1761154848081,"type":"change"},"instrument":"BTC-PERPETUAL","timestamp":1761154849614}
{"data":{"asks":[["delete",107939.5,0.0],["new",107963.0,13800.0]],"bids":[],"change_id":67840135374,"instrument_name":"BTC-PERPETUAL","prev_change_id":67840135373,"timestamp":1761154848121,"type":"change"},"instrument":"BTC-PERPETUAL","timestamp":1761154849651}
{"data":{"asks":[],"bids":[["delete",107928.5,0.0],["new",107911.0,50000.0]],"change_id":67840135375,"instrument_name":"BTC-PERPETUAL","prev_change_id":67840135374,"timestamp":1761154848122,"type":"change"},"instrument":"BTC-PERPETUAL","timestamp":1761154849655}
{"data":{"asks":[["delete",107940.0,0.0],["new",107961.0,6880.0]],"bids":[],"change_id":67840135378,"instrument_name":"BTC-PERPETUAL","prev_change_id":67840135375,"timestamp":1761154848161,"type":"change"},"instrument":"BTC-PERPETUAL","timestamp":1761154849688}
{"data":{"asks":[],"bids":[["delete",107927.5,0.0],["change",107912.5,66180.0]],"change_id":67840135380,"instrument_name":"BTC-PERPETUAL","prev_change_id":67840135378,"timestamp":1761154848162,"type":"change"},"instrument":"BTC-PERPETUAL","timestamp":1761154849693}
{"data":{"asks":[["delete",107945.5,0.0],["new",107960.0,7670.0]],"bids":[],"change_id":67840135383,"instrument_name":"BTC-PERPETUAL","prev_change_id":67840135380,"timestamp":1761154848201,"type":"change"},"instrument":"BTC-PERPETUAL","timestamp":1761154849732}
{"data":{"asks":[],"bids":[["delete",107927.0,0.0],["new",107915.0,58520.0]],"change_id":67840135385,"instrument_name":"BTC-PERPETUAL","prev_change_id":67840135383,"timestamp":1761154848203,"type":"change"},"instrument":"BTC-PERPETUAL","timestamp":1761154849744}
{"data":{"asks":[["delete",107946.0,0.0],["change",107959.5,20.0]],"bids":[],"change_id":67840135388,"instrument_name":"BTC-PERPETUAL","prev_change_id":67840135385,"timestamp":1761154848242,"type":"change"},"instrument":"BTC-PERPETUAL","timestamp":1761154849774}
{"data":{"asks":[],"bids":[["delete",107926.5,0.0],["new",107915.5,9230.0]],"change_id":67840135390,"instrument_name":"BTC-PERPETUAL","prev_change_id":67840135388,"timestamp":1761154848243,"type":"change"},"instrument":"BTC-PERPETUAL","timestamp":1761154849780}
{"data":{"asks":[["delete",107946.5,0.0],["new",107958.0,5000.0]],"bids":[],"change_id":67840135497,"instrument_name":"BTC-PERPETUAL","prev_change_id":67840135390,"timestamp":1761154848284,"type":"change"},"instrument":"BTC-PERPETUAL","timestamp":1761154849825}
{"data":{"asks":[],"bids":[["delete",107925.0,0.0],["change",107919.0,4200.0]],"change_id":67840135500,"instrument_name":"BTC-PERPETUAL","prev_change_id":67840135497,"timestamp":1761154848285,"type":"change"},"instrument":"BTC-PERPETUAL","timestamp":1761154849830}
{"data":{"asks":[["delete",107948.0,0.0],["change",107957.5,66180.0]],"bids":[],"change_id":67840135536,"instrument_name":"BTC-PERPETUAL","prev_change_id":67840135500,"timestamp":1761154848322,"type":"change"},"instrument":"BTC-PERPETUAL","timestamp":1761154849861}
{"data":{"asks":[],"bids":[["delete",107924.5,0.0],["change",107919.5,99860.0]],"change_id":67840135539,"instrument_name":"BTC-PERPETUAL","prev_change_id":67840135536,"timestamp":1761154848325,"type":"change"},"instrument":"BTC-PERPETUAL","timestamp":1761154849864}
{"data":{"asks":[["delete",107948.5,0.0],["new",107957.0,31240.0]],"bids":[],"change_id":67840135543,"instrument_name":"BTC-PERPETUAL","prev_change_id":67840135539,"timestamp":1761154848364,"type":"change"},"instrument":"BTC-PERPETUAL","timestamp":1761154849906}
{"data":{"asks":[],"bids":[["delete",107924.0,0.0],["new",107921.0,15640.0]],"change_id":67840135546,"instrument_name":"BTC-PERPETUAL","prev_change_id":67840135543,"timestamp":1761154848366,"type":"change"},"instrument":"BTC-PERPETUAL","timestamp":1761154849910}
{"data":{"asks":[["delete",107949.0,0.0],["change",107956.0,35600.0]],"bids":[],"change_id":67840136120,"instrument_name":"BTC-PERPETUAL","prev_change_id":67840135546,"timestamp":1761154848412,"type":"change"},"instrument":"BTC-PERPETUAL","timestamp":1761154849955}
{"data":{"asks":[],"bids":[["delete",107923.5,0.0],["new",107922.5,8440.0]],"change_id":67840136124,"instrument_name":"BTC-PERPETUAL","prev_change_id":67840136120,"timestamp":1761154848414,"type":"change"},"instrument":"BTC-PERPETUAL","timestamp":1761154849963}
{"data":{"asks":[["delete",107949.5,0.0],["change",107954.5,40830.0]],"bids":[],"change_id":67840136137,"instrument_name":"BTC-PERPETUAL","prev_change_id":67840136124,"timestamp":1761154848458,"type":"change"},"instrument":"BTC-PERPETUAL","timestamp":1761154850005}
{"data":{"asks":[],"bids":[["new",107923.5,8620.0],["delete",107922.0,0.0]],"change_id":67840136139,"instrument_name":"BTC-PERPETUAL","prev_change_id":67840136137,"timestamp":1761154848460,"type":"change"},"instrument":"BTC-PERPETUAL","timestamp":1761154850011}
{"data":{"asks":[["delete",107950.0,0.0],["change",107954.0,4200.0]],"bids":[],"change_id":67840136245,"instrument_name":"BTC-PERPETUAL","prev_change_id":67840136139,"timestamp":1761154848500,"type":"change"},"instrument":"BTC-PERPETUAL","timestamp":1761154850051}
{"data":{"asks":[],"bids":[["new",107926.5,5110.0],["delete",107921.5,0.0]],"change_id":67840136247,"instrument_name":"BTC-PERPETUAL","prev_change_id":67840136245,"timestamp":1761154848503,"type":"change"},"instrument":"BTC-PERPETUAL","timestamp":1761154850056}
{"data":{"asks":[["delete",107951.0,0.0],["new",107952.0,8440.0]],"bids":[],"change_id":67840136256,"instrument_name":"BTC-PERPETUAL","prev_change_id":67840136247,"timestamp":1761154848542,"type":"change"},"instrument":"BTC-PERPETUAL","timestamp":1761154850095}
{"data":{"asks":[],"bids":[["new",107928.0,61620.0],["delete",107920.0,0.0]],"change_id":67840136258,"instrument_name":"BTC-PERPETUAL","prev_change_id":67840136256,"timestamp":1761154848544,"type":"change"},"instrument":"BTC-PERPETUAL","timestamp":1761154850106}
{"data":{"asks":[["new",107950.5,25000.0],["delete",107953.5,0.0]],"bids":[],"change_id":67840136419,"instrument_name":"BTC-PERPETUAL","prev_change_id":67840136258,"timestamp":1761154848584,"type":"change"},"instrument":"BTC-PERPETUAL","timestamp":1761154850138}
{"data":{"asks":[],"bids":[["new",107929.5,20.0],["change",107919.5,49560.0]],"change_id":67840136421,"instrument_name":"BTC-PERPETUAL","prev_change_id":67840136419,"timestamp":1761154848585,"type":"change"},"instrument":"BTC-PERPETUAL","timestamp":1761154850142}
{"data":{"asks":[["new",107950.0,520.0],["change",107954.0,2100.0]],"bids":[],"change_id":67840136429,"instrument_name":"BTC-PERPETUAL","prev_change_id":67840136421,"timestamp":1761154848624,"type":"change"},"instrument":"BTC-PERPETUAL","timestamp":1761154850183}
{"data":{"asks":[],"bids":[["new",107930.0,54800.0],["change",107919.0,2100.0]],"change_id":67840136431,"instrument_name":"BTC-PERPETUAL","prev_change_id":67840136429,"timestamp":1761154848626,"type":"change"},"instrument":"BTC-PERPETUAL","timestamp":1761154850187}
{"data":{"asks":[["new",107948.5,13520.0],["change",107954.5,23840.0]],"bids":[],"change_id":67840136442,"instrument_name":"BTC-PERPETUAL","prev_change_id":67840136431,"timestamp":1761154848664,"type":"change"},"instrument":"BTC-PERPETUAL","timestamp":1761154850224}
{"data":{"asks":[],"bids":[["new",107930.5,20.0],["delete",107914.0,0.0]],"change_id":67840136444,"instrument_name":"BTC-PERPETUAL","prev_change_id":67840136442,"timestamp":1761154848666,"type":"change"},"instrument":"BTC-PERPETUAL","timestamp":1761154850229}
{"data":{"asks":[["new",107945.5,70200.0],["change",107956.0,17800.0]],"bids":[],"change_id":67840136454,"instrument_name":"BTC-PERPETUAL","prev_change_id":67840136444,"timestamp":1761154848704,"type":"change"},"instrument":"BTC-PERPETUAL","timestamp":1761154850266}
{"data":{"asks":[],"bids":[["new",107931.0,54820.0],["delete",107913.5,0.0]],"change_id":67840136456,"instrument_name":"BTC-PERPETUAL","prev_change_id":67840136454,"timestamp":1761154848705,"type":"change"},"instrument":"BTC-PERPETUAL","timestamp":1761154850274}
{"data":{"asks":[["new",107945.0,33260.0],["change",107957.5,33090.0]],"bids":[],"change_id":67840136466,"instrument_name":"BTC-PERPETUAL","prev_change_id":67840136456,"timestamp":1761154848744,"type":"change"},"instrument":"BTC-PERPETUAL","timestamp":1761154850312}
{"data":{"asks":[],"bids":[["new",107931.5,62170.0],["change",107912.5,33090.0]],"change_id":67840136468,"instrument_name":"BTC-PERPETUAL","prev_change_id":67840136466,"timestamp":1761154848745,"type":"change"},"instrument":"BTC-PERPETUAL","timestamp":1761154850317}
{"data":{"asks":[["new",107938.5,6000.0],["change",107959.5,10.0]],"bids":[],"change_id":67840136509,"instrument_name":"BTC-PERPETUAL","prev_change_id":67840136468,"timestamp":1761154848784,"type":"change"},"instrument":"BTC-PERPETUAL","timestamp":1761154850357}
{"data":{"asks":[],"bids":[["new",107933.5,40000.0],["change",107910.0,172640.0]],"change_id":67840136511,"instrument_name":"BTC-PERPETUAL","prev_change_id":67840136509,"timestamp":1761154848786,"type":"change"},"instrument":"BTC-PERPETUAL","timestamp":1761154850362}
{"data":{"asks":[["new",107935.0,26520.0],["delete",107960.5,0.0]],"bids":[],"change_id":67840136523,"instrument_name":"BTC-PERPETUAL","prev_change_id":67840136511,"timestamp":1761154848824,"type":"change"},"instrument":"BTC-PERPETUAL","timestamp":1761154850394}
{"data":{"asks":[],"bids":[["new",107934.5,332260.0],["change",107909.5,50290.0]],"change_id":67840136525,"instrument_name":"BTC-PERPETUAL","prev_change_id":67840136523,"timestamp":1761154848829,"type":"change"},"instrument":"BTC-PERPETUAL","timestamp":1761154850399}
{"data":{"asks":[],"bids":[["new",107692.0,80000.0],["delete",107668.0,0.0]],"change_id":67840136804,"instrument_name":"BTC-PERPETUAL","prev_change_id":67840136525,"timestamp":1761154849229,"type":"change"},"instrument":"BTC-PERPETUAL","timestamp":1761154850826}
{"data":{"asks":[],"bids":[["new",107671.0,320000.0],["change",107645.5,320000.0]],"change_id":67840138165,"instrument_name":"BTC-PERPETUAL","prev_change_id":67840136804,"timestamp":1761154850391,"type":"change"},"instrument":"BTC-PERPETUAL","timestamp":1761154852063}
{"data":{"asks":[],"bids":[["change",107671.0,640000.0],["delete",107645.5,0.0]],"change_id":67840138738,"instrument_name":"BTC-PERPETUAL","prev_change_id":67840138165,"timestamp":1761154850427,"type":"change"},"instrument":"BTC-PERPETUAL","timestamp":1761154852101}
{"data":{"asks":[["new",3828.75,6972069.0],["delete",3829.4,0.0]],"bids":[],"change_id":46343837973,"instrument_name":"ETH-PERPETUAL","prev_change_id":46343834507,"timestamp":1761154850562,"type":"change"},"instrument":"ETH-PERPETUAL","timestamp":1761154852245}
{"data":{"asks":[["delete",107997.0,0.0],["new",108157.0,5000.0]],"bids":[],"change_id":67840139962,"instrument_name":"BTC-PERPETUAL","prev_change_id":67840138738,"timestamp":1761154851456,"type":"change"},"instrument":"BTC-PERPETUAL","timestamp":1761154853195}
{"data":{"asks":[["delete",3826.55,0.0],["new",3828.45,34326.0]],"bids":[],"change_id":46343839115,"instrument_name":"ETH-PERPETUAL","prev_change_id":46343837973,"timestamp":1761154851582,"type":"change"},"instrument":"ETH-PERPETUAL","timestamp":1761154853331}
{"data":{"asks":[],"bids":[["delete",3826.5,0.0],["change",3824.9,3328.0]],"change_id":46343839116,"instrument_name":"ETH-PERPETUAL","prev_change_id":46343839115,"timestamp":1761154851583,"type":"change"},"instrument":"ETH-PERPETUAL","timestamp":1761154853340}
{"data":{"asks":[["delete",3826.6,0.0],["new",3828.4,17719.0]],"bids":[],"change_id":46343839415,"instrument_name":"ETH-PERPETUAL","prev_change_id":46343839116,"timestamp":1761154851622,"type":"change"},"instrument":"ETH-PERPETUAL","timestamp":1761154853376}
{"data":{"asks":[],"bids":[["delete",3826.4,0.0],["change",3825.0,4296.0]],"change_id":46343839416,"instrument_name":"ETH-PERPETUAL","prev_change_id":46343839415,"timestamp":1761154851623,"type":"change"},"instrument":"ETH-PERPETUAL","timestamp":1761154853382}
{"data":{"asks":[["delete",3826.75,0.0],["new",3828.25,1339.0]],"bids":[],"change_id":46343839431,"instrument_name":"ETH-PERPETUAL","prev_change_id":46343839416,"timestamp":1761154851664,"type":"change"},"instrument":"ETH-PERPETUAL","timestamp":1761154853418}
{"data":{"asks":[],"bids":[["delete",3826.3,0.0],["change",3825.05,37746.0]],"change_id":46343839432,"instrument_name":"ETH-PERPETUAL","prev_change_id":46343839431,"timestamp":1761154851668,"type":"change"},"instrument":"ETH-PERPETUAL","timestamp":1761154853423}
{"data":{"asks":[["delete",3826.8,0.0],["new",3828.2,4465.0]],"bids":[],"change_id":46343839501,"instrument_name":"ETH-PERPETUAL","prev_change_id":46343839432,"timestamp":1761154851707,"type":"change"},"instrument":"ETH-PERPETUAL","timestamp":1761154853465}
{"data":{"asks":[],"bids":[["delete",3826.15,0.0],["change",3825.15,8123.0]],"change_id":46343839503,"instrument_name":"ETH-PERPETUAL","prev_change_id":46343839501,"timestamp":1761154851708,"type":"change"},"instrument":"ETH-PERPETUAL","timestamp":1761154853469}
{"data":{"asks":[["delete",3826.85,0.0],["new",3828.15,1333.0]],"bids":[],"change_id":46343839517,"instrument_name":"ETH-PERPETUAL","prev_change_id":46343839503,"timestamp":1761154851747,"type":"change"},"instrument":"ETH-PERPETUAL","timestamp":1761154853510}
{"data":{"asks":[],"bids":[["delete",3826.0,0.0],["change",3825.35,30776.0]],"change_id":46343839518,"instrument_name":"ETH-PERPETUAL","prev_change_id":46343839517,"timestamp":1761154851748,"type":"change"},"instrument":"ETH-PERPETUAL","timestamp":1761154853515}
{"data":{"asks":[["delete",3826.9,0.0],["new",3828.0,16807.0]],"bids":[],"change_id":46343839526,"instrument_name":"ETH-PERPETUAL","prev_change_id":46343839518,"timestamp":1761154851786,"type":"change"},"instrument":"ETH-PERPETUAL","timestamp":1761154853612}
{"data":{"asks":[],"bids":[["delete",3825.9,0.0],["change",3825.4,28867.0]],"change_id":46343839527,"instrument_name":"ETH-PERPETUAL","prev_change_id":46343839526,"timestamp":1761154851789,"type":"change"},"instrument":"ETH-PERPETUAL","timestamp":1761154853615}
{"data":{"asks":[["delete",3826.95,0.0],["change",3827.95,60513.0]],"bids":[],"change_id":46343839610,"instrument_name":"ETH-PERPETUAL","prev_change_id":46343839527,"timestamp":1761154851826,"type":"change"},"instrument":"ETH-PERPETUAL","timestamp":1761154853617}
{"data":{"asks":[],"bids":[["delete",3825.85,0.0],["change",3825.65,18040.0]],"change_id":46343839613,"instrument_name":"ETH-PERPETUAL","prev_change_id":46343839610,"timestamp":1761154851829,"type":"change"},"instrument":"ETH-PERPETUAL","timestamp":1761154853621}
{"data":{"asks":[["delete",3827.0,0.0],["change",3827.9,7278.0]],"bids":[],"change_id":46343839616,"instrument_name":"ETH-PERPETUAL","prev_change_id":46343839613,"timestamp":1761154851868,"type":"change"},"instrument":"ETH-PERPETUAL","timestamp":1761154853635}
{"data":{"asks":[],"bids":[["delete",3825.8,0.0],["new",3825.75,19986.0]],"change_id":46343839619,"instrument_name":"ETH-PERPETUAL","prev_change_id":46343839616,"timestamp":1761154851870,"type":"change"},"instrument":"ETH-PERPETUAL","timestamp":1761154853655}
{"data":{"asks":[["delete",3827.05,0.0],["new",3827.8,20087.0]],"bids":[],"change_id":46343839622,"instrument_name":"ETH-PERPETUAL","prev_change_id":46343839619,"timestamp":1761154851908,"type":"change"},"instrument":"ETH-PERPETUAL","timestamp":1761154853676}
{"data":{"asks":[],"bids":[["new",3825.8,10956.0],["change",3825.65,16717.0]],"change_id":46343839625,"instrument_name":"ETH-PERPETUAL","prev_change_id":46343839622,"timestamp":1761154851912,"type":"change"},"instrument":"ETH-PERPETUAL","timestamp":1761154853766}
{"data":{"asks":[["delete",3827.1,0.0],["change",3827.75,33434.0]],"bids":[],"change_id":46343839630,"instrument_name":"ETH-PERPETUAL","prev_change_id":46343839625,"timestamp":1761154851949,"type":"change"},"instrument":"ETH-PERPETUAL","timestamp":1761154853770}
{"data":{"asks":[],"bids":[["new",3825.9,6665.0],["delete",3825.6,0.0]],"change_id":46343839633,"instrument_name":"ETH-PERPETUAL","prev_change_id":46343839630,"timestamp":1761154851952,"type":"change"},"instrument":"ETH-PERPETUAL","timestamp":1761154853774}
{"data":{"asks":[["delete",3827.2,0.0],["change",3827.7,11584.0]],"bids":[],"change_id":46343839784,"instrument_name":"ETH-PERPETUAL","prev_change_id":46343839633,"timestamp":1761154851991,"type":"change"},"instrument":"ETH-PERPETUAL","timestamp":1761154853786}
{"data":{"asks":[],"bids":[["delete",3825.5,0.0]],"change_id":46343839787,"instrument_name":"ETH-PERPETUAL","prev_change_id":46343839784,"timestamp":1761154851993,"type":"change"},"instrument":"ETH-PERPETUAL","timestamp":1761154853792}
{"data":{"asks":[["delete",3827.25,0.0],["new",3827.6,68280.0]],"bids":[],"change_id":46343839848,"instrument_name":"ETH-PERPETUAL","prev_change_id":46343839787,"timestamp":1761154852032,"type":"change"},"instrument":"ETH-PERPETUAL","timestamp":1761154853807}
{"data":{"asks":[],"bids":[["new",3826.05,1604.0],["change",3825.4,6075.0]],"change_id":46343839851,"instrument_name":"ETH-PERPETUAL","prev_change_id":46343839848,"timestamp":1761154852035,"type":"change"},"instrument":"ETH-PERPETUAL","timestamp":1761154853813}
{"data":{"asks":[["delete",3827.35,0.0],["change",3827.55,59504.0]],"bids":[],"change_id":46343839859,"instrument_name":"ETH-PERPETUAL","prev_change_id":46343839851,"timestamp":1761154852073,"type":"change"},"instrument":"ETH-PERPETUAL","timestamp":1761154853851}
{"data":{"asks":[],"bids":[["new",3826.1,16717.0],["change",3825.35,15388.0]],"change_id":46343839862,"instrument_name":"ETH-PERPETUAL","prev_change_id":46343839859,"timestamp":1761154852075,"type":"change"},"instrument":"ETH-PERPETUAL","timestamp":1761154853855}
{"data":{"asks":[["delete",3827.4,0.0],["change",3827.5,59522.0]],"bids":[],"change_id":46343839869,"instrument_name":"ETH-PERPETUAL","prev_change_id":46343839862,"timestamp":1761154852114,"type":"change"},"instrument":"ETH-PERPETUAL","timestamp":1761154853902}
{"data":{"asks":[],"bids":[["new",3826.15,8909.0],["delete",3825.25,0.0]],"change_id":46343839872,"instrument_name":"ETH-PERPETUAL","prev_change_id":46343839869,"timestamp":1761154852116,"type":"change"},"instrument":"ETH-PERPETUAL","timestamp":1761154853906}
{"data":{"asks":[["new",3827.45,55080.0],["change",3827.5,55084.0]],"bids":[],"change_id":46343839878,"instrument_name":"ETH-PERPETUAL","prev_change_id":46343839872,"timestamp":1761154852155,"type":"change"},"instrument":"ETH-PERPETUAL","timestamp":1761154853939}
{"data":{"asks":[],"bids":[["new",3826.3,15000.0],["change",3825.15,3695.0]],"change_id":46343839882,"instrument_name":"ETH-PERPETUAL","prev_change_id":46343839878,"timestamp":1761154852159,"type":"change"},"instrument":"ETH-PERPETUAL","timestamp":1761154853943}
{"data":{"asks":[["new",3827.4,134575.0],["change",3827.55,55080.0]],"bids":[],"change_id":46343840121,"instrument_name":"ETH-PERPETUAL","prev_change_id":46343839882,"timestamp":1761154852196,"type":"change"},"instrument":"ETH-PERPETUAL","timestamp":1761154853983}
{"data":{"asks":[],"bids":[["new",3826.35,5373.0],["change",3825.05,17760.0]],"change_id":46343840125,"instrument_name":"ETH-PERPETUAL","prev_change_id":46343840121,"timestamp":1761154852200,"type":"change"},"instrument":"ETH-PERPETUAL","timestamp":1761154853988}
{"data":{"asks":[["new",3827.35,23475.0],["change",3827.7,6594.0]],"bids":[],"change_id":46343840133,"instrument_name":"ETH-PERPETUAL","prev_change_id":46343840125,"timestamp":1761154852236,"type":"change"},"instrument":"ETH-PERPETUAL","timestamp":1761154854024}
{"data":{"asks":[],"bids":[["new",3826.4,19994.0],["change",3825.0,2146.0]],"change_id":46343840137,"instrument_name":"ETH-PERPETUAL","prev_change_id":46343840133,"timestamp":1761154852240,"type":"change"},"instrument":"ETH-PERPETUAL","timestamp":1761154854029}
{"data":{"asks":[["new",3827.3,9700.0],["change",3827.75,16717.0]],"bids":[],"change_id":46343840146,"instrument_name":"ETH-PERPETUAL","prev_change_id":46343840137,"timestamp":1761154852277,"type":"change"},"instrument":"ETH-PERPETUAL","timestamp":1761154854073}
{"data":{"asks":[],"bids":[["new",3826.5,5968.0],["change",3824.9,1664.0]],"change_id":46343840150,"instrument_name":"ETH-PERPETUAL","prev_change_id":46343840146,"timestamp":1761154852282,"type":"change"},"instrument":"ETH-PERPETUAL","timestamp":1761154854077}
{"data":{"asks":[["new",3827.25,4.0],["change",3827.9,5438.0]],"bids":[],"change_id":46343840184,"instrument_name":"ETH-PERPETUAL","prev_change_id":46343840150,"timestamp":1761154852317,"type":"change"},"instrument":"ETH-PERPETUAL","timestamp":1761154854113}
{"data":{"asks":[],"bids":[["new",3826.8,1000.0],["delete",3824.85,0.0]],"change_id":46343840188,"instrument_name":"ETH-PERPETUAL","prev_change_id":46343840184,"timestamp":1761154852321,"type":"change"},"instrument":"ETH-PERPETUAL","timestamp":1761154854117}
