1761154849610 {"jsonrpc":"2.0","method":"subscription","params":{"channel":"book.BTC-PERPETUAL.raw","data":{"timestamp":1761154848081,"type":"change","change_id":67840135373,"instrument_name":"BTC-PERPETUAL","bids":[["delete",107929.0,0.0],["change",107910.0,231870.0]],"asks":[],"prev_change_id":67840135372}}}
1761154849646 {"jsonrpc":"2.0","method":"subscription","params":{"channel":"book.BTC-PERPETUAL.raw","data":{"timestamp":1761154848121,"type":"change","change_id":67840135374,"instrument_name":"BTC-PERPETUAL","bids":[],"asks":[["delete",107939.5,0.0],["new",107963.0,1.38e4]],"prev_change_id":67840135373}}}
1761154849651 {"jsonrpc":"2.0","method":"subscription","params":{"channel":"book.BTC-PERPETUAL.raw","data":{"timestamp":1761154848122,"type":"change","change_id":67840135375,"instrument_name":"BTC-PERPETUAL","bids":[["delete",107928.5,0.0],["new",107911.0,5.0e4]],"asks":[],"prev_change_id":67840135374}}}
1761154849683 {"jsonrpc":"2.0","method":"subscription","params":{"channel":"book.BTC-PERPETUAL.raw","data":{"timestamp":1761154848161,"type":"change","change_id":67840135378,"instrument_name":"BTC-PERPETUAL","bids":[],"asks":[["delete",107940.0,0.0],["new",107961.0,6880.0]],"prev_change_id":67840135375}}}
1761154849689 {"jsonrpc":"2.0","method":"subscription","params":{"channel":"book.BTC-PERPETUAL.raw","data":{"timestamp":1761154848162,"type":"change","change_id":67840135380,"instrument_name":"BTC-PERPETUAL","bids":[["delete",107927.5,0.0],["change",107912.5,66180.0]],"asks":[],"prev_change_id":67840135378}}}
1761154849727 {"jsonrpc":"2.0","method":"subscription","params":{"channel":"book.BTC-PERPETUAL.raw","data":{"timestamp":1761154848201,"type":"change","change_id":67840135383,"instrument_name":"BTC-PERPETUAL","bids":[],"asks":[["delete",107945.5,0.0],["new",107960.0,7670.0]],"prev_change_id":67840135380}}}
1761154849739 {"jsonrpc":"2.0","method":"subscription","params":{"channel":"book.BTC-PERPETUAL.raw","data":{"timestamp":1761154848203,"type":"change","change_id":67840135385,"instrument_name":"BTC-PERPETUAL","bids":[["delete",107927.0,0.0],["new",107915.0,58520.0]],"asks":[],"prev_change_id":67840135383}}}
1761154849769 {"jsonrpc":"2.0","method":"subscription","params":{"channel":"book.BTC-PERPETUAL.raw","data":{"timestamp":1761154848242,"type":"change","change_id":67840135388,"instrument_name":"BTC-PERPETUAL","bids":[],"asks":[["delete",107946.0,0.0],["change",107959.5,20.0]],"prev_change_id":67840135385}}}
1761154849776 {"jsonrpc":"2.0","method":"subscription","params":{"channel":"book.BTC-PERPETUAL.raw","data":{"timestamp":1761154848243,"type":"change","change_id":67840135390,"instrument_name":"BTC-PERPETUAL","bids":[["delete",107926.5,0.0],["new",107915.5,9230.0]],"asks":[],"prev_change_id":67840135388}}}
1761154849818 {"jsonrpc":"2.0","method":"subscription","params":{"channel":"book.BTC-PERPETUAL.raw","data":{"timestamp":1761154848284,"type":"change","change_id":67840135497,"instrument_name":"BTC-PERPETUAL","bids":[],"asks":[["delete",107946.5,0.0],["new",107958.0,5.0e3]],"prev_change_id":67840135390}}}
1761154849826 {"jsonrpc":"2.0","method":"subscription","params":{"channel":"book.BTC-PERPETUAL.raw","data":{"timestamp":1761154848285,"type":"change","change_id":67840135500,"instrument_name":"BTC-PERPETUAL","bids":[["delete",107925.0,0.0],["change",107919.0,4.2e3]],"asks":[],"prev_change_id":67840135497}}}
1761154849856 {"jsonrpc":"2.0","method":"subscription","params":{"channel":"book.BTC-PERPETUAL.raw","data":{"timestamp":1761154848322,"type":"change","change_id":67840135536,"instrument_name":"BTC-PERPETUAL","bids":[],"asks":[["delete",107948.0,0.0],["change",107957.5,66180.0]],"prev_change_id":67840135500}}}
1761154849861 {"jsonrpc":"2.0","method":"subscription","params":{"channel":"book.BTC-PERPETUAL.raw","data":{"timestamp":1761154848325,"type":"change","change_id":67840135539,"instrument_name":"BTC-PERPETUAL","bids":[["delete",107924.5,0.0],["change",107919.5,99860.0]],"asks":[],"prev_change_id":67840135536}}}
1761154849899 {"jsonrpc":"2.0","method":"subscription","params":{"channel":"book.BTC-PERPETUAL.raw","data":{"timestamp":1761154848364,"type":"change","change_id":67840135543,"instrument_name":"BTC-PERPETUAL","bids":[],"asks":[["delete",107948.5,0.0],["new",107957.0,31240.0]],"prev_change_id":67840135539}}}
1761154849906 {"jsonrpc":"2.0","method":"subscription","params":{"channel":"book.BTC-PERPETUAL.raw","data":{"timestamp":1761154848366,"type":"change","change_id":67840135546,"instrument_name":"BTC-PERPETUAL","bids":[["delete",107924.0,0.0],["new",107921.0,15640.0]],"asks":[],"prev_change_id":67840135543}}}
1761154849951 {"jsonrpc":"2.0","method":"subscription","params":{"channel":"book.BTC-PERPETUAL.raw","data":{"timestamp":1761154848412,"type":"change","change_id":67840136120,"instrument_name":"BTC-PERPETUAL","bids":[],"asks":[["delete",107949.0,0.0],["change",107956.0,3.56e4]],"prev_change_id":67840135546}}}
1761154849959 {"jsonrpc":"2.0","method":"subscription","params":{"channel":"book.BTC-PERPETUAL.raw","data":{"timestamp":1761154848414,"type":"change","change_id":67840136124,"instrument_name":"BTC-PERPETUAL","bids":[["delete",107923.5,0.0],["new",107922.5,8440.0]],"asks":[],"prev_change_id":67840136120}}}
1761154849999 {"jsonrpc":"2.0","method":"subscription","params":{"channel":"book.BTC-PERPETUAL.raw","data":{"timestamp":1761154848458,"type":"change","change_id":67840136137,"instrument_name":"BTC-PERPETUAL","bids":[],"asks":[["delete",107949.5,0.0],["change",107954.5,40830.0]],"prev_change_id":67840136124}}}
1761154850006 {"jsonrpc":"2.0","method":"subscription","params":{"channel":"book.BTC-PERPETUAL.raw","data":{"timestamp":1761154848460,"type":"change","change_id":67840136139,"instrument_name":"BTC-PERPETUAL","bids":[["new",107923.5,8620.0],["delete",107922.0,0.0]],"asks":[],"prev_change_id":67840136137}}}
1761154850046 {"jsonrpc":"2.0","method":"subscription","params":{"channel":"book.BTC-PERPETUAL.raw","data":{"timestamp":1761154848500,"type":"change","change_id":67840136245,"instrument_name":"BTC-PERPETUAL","bids":[],"asks":[["delete",107950.0,0.0],["change",107954.0,4.2e3]],"prev_change_id":67840136139}}}
1761154850052 {"jsonrpc":"2.0","method":"subscription","params":{"channel":"book.BTC-PERPETUAL.raw","data":{"timestamp":1761154848503,"type":"change","change_id":67840136247,"instrument_name":"BTC-PERPETUAL","bids":[["new",107926.5,5110.0],["delete",107921.5,0.0]],"asks":[],"prev_change_id":67840136245}}}
1761154850089 {"jsonrpc":"2.0","method":"subscription","params":{"channel":"book.BTC-PERPETUAL.raw","data":{"timestamp":1761154848542,"type":"change","change_id":67840136256,"instrument_name":"BTC-PERPETUAL","bids":[],"asks":[["delete",107951.0,0.0],["new",107952.0,8440.0]],"prev_change_id":67840136247}}}
1761154850101 {"jsonrpc":"2.0","method":"subscription","params":{"channel":"book.BTC-PERPETUAL.raw","data":{"timestamp":1761154848544,"type":"change","change_id":67840136258,"instrument_name":"BTC-PERPETUAL","bids":[["new",107928.0,61620.0],["delete",107920.0,0.0]],"asks":[],"prev_change_id":67840136256}}}
1761154850133 {"jsonrpc":"2.0","method":"subscription","params":{"channel":"book.BTC-PERPETUAL.raw","data":{"timestamp":1761154848584,"type":"change","change_id":67840136419,"instrument_name":"BTC-PERPETUAL","bids":[],"asks":[["new",107950.5,2.5e4],["delete",107953.5,0.0]],"prev_change_id":67840136258}}}
1761154850139 {"jsonrpc":"2.0","method":"subscription","params":{"channel":"book.BTC-PERPETUAL.raw","data":{"timestamp":1761154848585,"type":"change","change_id":67840136421,"instrument_name":"BTC-PERPETUAL","bids":[["new",107929.5,20.0],["change",107919.5,49560.0]],"asks":[],"prev_change_id":67840136419}}}
1761154850179 {"jsonrpc":"2.0","method":"subscription","params":{"channel":"book.BTC-PERPETUAL.raw","data":{"timestamp":1761154848624,"type":"change","change_id":67840136429,"instrument_name":"BTC-PERPETUAL","bids":[],"asks":[["new",107950.0,520.0],["change",107954.0,2.1e3]],"prev_change_id":67840136421}}}
1761154850184 {"jsonrpc":"2.0","method":"subscription","params":{"channel":"book.BTC-PERPETUAL.raw","data":{"timestamp":1761154848626,"type":"change","change_id":67840136431,"instrument_name":"BTC-PERPETUAL","bids":[["new",107930.0,5.48e4],["change",107919.0,2.1e3]],"asks":[],"prev_change_id":67840136429}}}
1761154850220 {"jsonrpc":"2.0","method":"subscription","params":{"channel":"book.BTC-PERPETUAL.raw","data":{"timestamp":1761154848664,"type":"change","change_id":67840136442,"instrument_name":"BTC-PERPETUAL","bids":[],"asks":[["new",107948.5,13520.0],["change",107954.5,23840.0]],"prev_change_id":67840136431}}}
1761154850224 {"jsonrpc":"2.0","method":"subscription","params":{"channel":"book.BTC-PERPETUAL.raw","data":{"timestamp":1761154848666,"type":"change","change_id":67840136444,"instrument_name":"BTC-PERPETUAL","bids":[["new",107930.5,20.0],["delete",107914.0,0.0]],"asks":[],"prev_change_id":67840136442}}}
1761154850261 {"jsonrpc":"2.0","method":"subscription","params":{"channel":"book.BTC-PERPETUAL.raw","data":{"timestamp":1761154848704,"type":"change","change_id":67840136454,"instrument_name":"BTC-PERPETUAL","bids":[],"asks":[["new",107945.5,7.02e4],["change",107956.0,1.78e4]],"prev_change_id":67840136444}}}
1761154850270 {"jsonrpc":"2.0","method":"subscription","params":{"channel":"book.BTC-PERPETUAL.raw","data":{"timestamp":1761154848705,"type":"change","change_id":67840136456,"instrument_name":"BTC-PERPETUAL","bids":[["new",107931.0,54820.0],["delete",107913.5,0.0]],"asks":[],"prev_change_id":67840136454}}}
1761154850307 {"jsonrpc":"2.0","method":"subscription","params":{"channel":"book.BTC-PERPETUAL.raw","data":{"timestamp":1761154848744,"type":"change","change_id":67840136466,"instrument_name":"BTC-PERPETUAL","bids":[],"asks":[["new",107945.0,33260.0],["change",107957.5,33090.0]],"prev_change_id":67840136456}}}
1761154850313 {"jsonrpc":"2.0","method":"subscription","params":{"channel":"book.BTC-PERPETUAL.raw","data":{"timestamp":1761154848745,"type":"change","change_id":67840136468,"instrument_name":"BTC-PERPETUAL","bids":[["new",107931.5,62170.0],["change",107912.5,33090.0]],"asks":[],"prev_change_id":67840136466}}}
1761154850352 {"jsonrpc":"2.0","method":"subscription","params":{"channel":"book.BTC-PERPETUAL.raw","data":{"timestamp":1761154848784,"type":"change","change_id":67840136509,"instrument_name":"BTC-PERPETUAL","bids":[],"asks":[["new",107938.5,6.0e3],["change",107959.5,10.0]],"prev_change_id":67840136468}}}
1761154850358 {"jsonrpc":"2.0","method":"subscription","params":{"channel":"book.BTC-PERPETUAL.raw","data":{"timestamp":1761154848786,"type":"change","change_id":67840136511,"instrument_name":"BTC-PERPETUAL","bids":[["new",107933.5,4.0e4],["change",107910.0,172640.0]],"asks":[],"prev_change_id":67840136509}}}
1761154850389 {"jsonrpc":"2.0","method":"subscription","params":{"channel":"book.BTC-PERPETUAL.raw","data":{"timestamp":1761154848824,"type":"change","change_id":67840136523,"instrument_name":"BTC-PERPETUAL","bids":[],"asks":[["new",107935.0,26520.0],["delete",107960.5,0.0]],"prev_change_id":67840136511}}}
1761154850395 {"jsonrpc":"2.0","method":"subscription","params":{"channel":"book.BTC-PERPETUAL.raw","data":{"timestamp":1761154848829,"type":"change","change_id":67840136525,"instrument_name":"BTC-PERPETUAL","bids":[["new",107934.5,332260.0],["change",107909.5,50290.0]],"asks":[],"prev_change_id":67840136523}}}
1761154850820 {"jsonrpc":"2.0","method":"subscription","params":{"channel":"book.BTC-PERPETUAL.raw","data":{"timestamp":1761154849229,"type":"change","change_id":67840136804,"instrument_name":"BTC-PERPETUAL","bids":[["new",107692.0,8.0e4],["delete",107668.0,0.0]],"asks":[],"prev_change_id":67840136525}}}
1761154852058 {"jsonrpc":"2.0","method":"subscription","params":{"channel":"book.BTC-PERPETUAL.raw","data":{"timestamp":1761154850391,"type":"change","change_id":67840138165,"instrument_name":"BTC-PERPETUAL","bids":[["new",107671.0,3.2e5],["change",107645.5,3.2e5]],"asks":[],"prev_change_id":67840136804}}}
1761154852096 {"jsonrpc":"2.0","method":"subscription","params":{"channel":"book.BTC-PERPETUAL.raw","data":{"timestamp":1761154850427,"type":"change","change_id":67840138738,"instrument_name":"BTC-PERPETUAL","bids":[["change",107671.0,6.4e5],["delete",107645.5,0.0]],"asks":[],"prev_change_id":67840138165}}}
1761154852240 {"jsonrpc":"2.0","method":"subscription","params":{"channel":"book.ETH-PERPETUAL.raw","data":{"timestamp":1761154850562,"type":"change","change_id":46343837973,"instrument_name":"ETH-PERPETUAL","bids":[],"asks":[["new",3828.75,6972069.0],["delete",3829.4,0.0]],"prev_change_id":46343834507}}}
1761154853192 {"jsonrpc":"2.0","method":"subscription","params":{"channel":"book.BTC-PERPETUAL.raw","data":{"timestamp":1761154851456,"type":"change","change_id":67840139962,"instrument_name":"BTC-PERPETUAL","bids":[],"asks":[["delete",107997.0,0.0],["new",108157.0,5.0e3]],"prev_change_id":67840138738}}}
1761154853328 {"jsonrpc":"2.0","method":"subscription","params":{"channel":"book.ETH-PERPETUAL.raw","data":{"timestamp":1761154851582,"type":"change","change_id":46343839115,"instrument_name":"ETH-PERPETUAL","bids":[],"asks":[["delete",3826.55,0.0],["new",3828.45,34326.0]],"prev_change_id":46343837973}}}
1761154853336 {"jsonrpc":"2.0","method":"subscription","params":{"channel":"book.ETH-PERPETUAL.raw","data":{"timestamp":1761154851583,"type":"change","change_id":46343839116,"instrument_name":"ETH-PERPETUAL","bids":[["delete",3826.5,0.0],["change",3824.9,3328.0]],"asks":[],"prev_change_id":46343839115}}}
1761154853372 {"jsonrpc":"2.0","method":"subscription","params":{"channel":"book.ETH-PERPETUAL.raw","data":{"timestamp":1761154851622,"type":"change","change_id":46343839415,"instrument_name":"ETH-PERPETUAL","bids":[],"asks":[["delete",3826.6,0.0],["new",3828.4,17719.0]],"prev_change_id":46343839116}}}
1761154853378 {"jsonrpc":"2.0","method":"subscription","params":{"channel":"book.ETH-PERPETUAL.raw","data":{"timestamp":1761154851623,"type":"change","change_id":46343839416,"instrument_name":"ETH-PERPETUAL","bids":[["delete",3826.4,0.0],["change",3825.0,4296.0]],"asks":[],"prev_change_id":46343839415}}}
1761154853413 {"jsonrpc":"2.0","method":"subscription","params":{"channel":"book.ETH-PERPETUAL.raw","data":{"timestamp":1761154851664,"type":"change","change_id":46343839431,"instrument_name":"ETH-PERPETUAL","bids":[],"asks":[["delete",3826.75,0.0],["new",3828.25,1339.0]],"prev_change_id":46343839416}}}
1761154853419 {"jsonrpc":"2.0","method":"subscription","params":{"channel":"book.ETH-PERPETUAL.raw","data":{"timestamp":1761154851668,"type":"change","change_id":46343839432,"instrument_name":"ETH-PERPETUAL","bids":[["delete",3826.3,0.0],["change",3825.05,37746.0]],"asks":[],"prev_change_id":46343839431}}}
1761154853460 {"jsonrpc":"2.0","method":"subscription","params":{"channel":"book.ETH-PERPETUAL.raw","data":{"timestamp":1761154851707,"type":"change","change_id":46343839501,"instrument_name":"ETH-PERPETUAL","bids":[],"asks":[["delete",3826.8,0.0],["new",3828.2,4465.0]],"prev_change_id":46343839432}}}
1761154853466 {"jsonrpc":"2.0","method":"subscription","params":{"channel":"book.ETH-PERPETUAL.raw","data":{"timestamp":1761154851708,"type":"change","change_id":46343839503,"instrument_name":"ETH-PERPETUAL","bids":[["delete",3826.15,0.0],["change",3825.15,8123.0]],"asks":[],"prev_change_id":46343839501}}}
1761154853506 {"jsonrpc":"2.0","method":"subscription","params":{"channel":"book.ETH-PERPETUAL.raw","data":{"timestamp":1761154851747,"type":"change","change_id":46343839517,"instrument_name":"ETH-PERPETUAL","bids":[],"asks":[["delete",3826.85,0.0],["new",3828.15,1333.0]],"prev_change_id":46343839503}}}
1761154853510 {"jsonrpc":"2.0","method":"subscription","params":{"channel":"book.ETH-PERPETUAL.raw","data":{"timestamp":1761154851748,"type":"change","change_id":46343839518,"instrument_name":"ETH-PERPETUAL","bids":[["delete",3826.0,0.0],["change",3825.35,30776.0]],"asks":[],"prev_change_id":46343839517}}}
1761154853609 {"jsonrpc":"2.0","method":"subscription","params":{"channel":"book.ETH-PERPETUAL.raw","data":{"timestamp":1761154851786,"type":"change","change_id":46343839526,"instrument_name":"ETH-PERPETUAL","bids":[],"asks":[["delete",3826.9,0.0],["new",3828.0,16807.0]],"prev_change_id":46343839518}}}
1761154853612 {"jsonrpc":"2.0","method":"subscription","params":{"channel":"book.ETH-PERPETUAL.raw","data":{"timestamp":1761154851789,"type":"change","change_id":46343839527,"instrument_name":"ETH-PERPETUAL","bids":[["delete",3825.9,0.0],["change",3825.4,28867.0]],"asks":[],"prev_change_id":46343839526}}}
1761154853615 {"jsonrpc":"2.0","method":"subscription","params":{"channel":"book.ETH-PERPETUAL.raw","data":{"timestamp":1761154851826,"type":"change","change_id":46343839610,"instrument_name":"ETH-PERPETUAL","bids":[],"asks":[["delete",3826.95,0.0],["change",3827.95,60513.0]],"prev_change_id":46343839527}}}
1761154853618 {"jsonrpc":"2.0","method":"subscription","params":{"channel":"book.ETH-PERPETUAL.raw","data":{"timestamp":1761154851829,"type":"change","change_id":46343839613,"instrument_name":"ETH-PERPETUAL","bids":[["delete",3825.85,0.0],["change",3825.65,18040.0]],"asks":[],"prev_change_id":46343839610}}}
1761154853630 {"jsonrpc":"2.0","method":"subscription","params":{"channel":"book.ETH-PERPETUAL.raw","data":{"timestamp":1761154851868,"type":"change","change_id":46343839616,"instrument_name":"ETH-PERPETUAL","bids":[],"asks":[["delete",3827.0,0.0],["change",3827.9,7278.0]],"prev_change_id":46343839613}}}
1761154853651 {"jsonrpc":"2.0","method":"subscription","params":{"channel":"book.ETH-PERPETUAL.raw","data":{"timestamp":1761154851870,"type":"change","change_id":46343839619,"instrument_name":"ETH-PERPETUAL","bids":[["delete",3825.8,0.0],["new",3825.75,19986.0]],"asks":[],"prev_change_id":46343839616}}}
1761154853672 {"jsonrpc":"2.0","method":"subscription","params":{"channel":"book.ETH-PERPETUAL.raw","data":{"timestamp":1761154851908,"type":"change","change_id":46343839622,"instrument_name":"ETH-PERPETUAL","bids":[],"asks":[["delete",3827.05,0.0],["new",3827.8,20087.0]],"prev_change_id":46343839619}}}
1761154853761 {"jsonrpc":"2.0","method":"subscription","params":{"channel":"book.ETH-PERPETUAL.raw","data":{"timestamp":1761154851912,"type":"change","change_id":46343839625,"instrument_name":"ETH-PERPETUAL","bids":[["new",3825.8,10956.0],["change",3825.65,16717.0]],"asks":[],"prev_change_id":46343839622}}}
1761154853766 {"jsonrpc":"2.0","method":"subscription","params":{"channel":"book.ETH-PERPETUAL.raw","data":{"timestamp":1761154851949,"type":"change","change_id":46343839630,"instrument_name":"ETH-PERPETUAL","bids":[],"asks":[["delete",3827.1,0.0],["change",3827.75,33434.0]],"prev_change_id":46343839625}}}
1761154853771 {"jsonrpc":"2.0","method":"subscription","params":{"channel":"book.ETH-PERPETUAL.raw","data":{"timestamp":1761154851952,"type":"change","change_id":46343839633,"instrument_name":"ETH-PERPETUAL","bids":[["new",3825.9,6665.0],["delete",3825.6,0.0]],"asks":[],"prev_change_id":46343839630}}}
1761154853781 {"jsonrpc":"2.0","method":"subscription","params":{"channel":"book.ETH-PERPETUAL.raw","data":{"timestamp":1761154851991,"type":"change","change_id":46343839784,"instrument_name":"ETH-PERPETUAL","bids":[],"asks":[["delete",3827.2,0.0],["change",3827.7,11584.0]],"prev_change_id":46343839633}}}
1761154853787 {"jsonrpc":"2.0","method":"subscription","params":{"channel":"book.ETH-PERPETUAL.raw","data":{"timestamp":1761154851993,"type":"change","change_id":46343839787,"instrument_name":"ETH-PERPETUAL","bids":[["delete",3825.5,0.0]],"asks":[],"prev_change_id":46343839784}}}
1761154853803 {"jsonrpc":"2.0","method":"subscription","params":{"channel":"book.ETH-PERPETUAL.raw","data":{"timestamp":1761154852032,"type":"change","change_id":46343839848,"instrument_name":"ETH-PERPETUAL","bids":[],"asks":[["delete",3827.25,0.0],["new",3827.6,68280.0]],"prev_change_id":46343839787}}}
1761154853809 {"jsonrpc":"2.0","method":"subscription","params":{"channel":"book.ETH-PERPETUAL.raw","data":{"timestamp":1761154852035,"type":"change","change_id":46343839851,"instrument_name":"ETH-PERPETUAL","bids":[["new",3826.05,1604.0],["change",3825.4,6075.0]],"asks":[],"prev_change_id":46343839848}}}
1761154853846 {"jsonrpc":"2.0","method":"subscription","params":{"channel":"book.ETH-PERPETUAL.raw","data":{"timestamp":1761154852073,"type":"change","change_id":46343839859,"instrument_name":"ETH-PERPETUAL","bids":[],"asks":[["delete",3827.35,0.0],["change",3827.55,59504.0]],"prev_change_id":46343839851}}}
1761154853852 {"jsonrpc":"2.0","method":"subscription","params":{"channel":"book.ETH-PERPETUAL.raw","data":{"timestamp":1761154852075,"type":"change","change_id":46343839862,"instrument_name":"ETH-PERPETUAL","bids":[["new",3826.1,16717.0],["change",3825.35,15388.0]],"asks":[],"prev_change_id":46343839859}}}
1761154853897 {"jsonrpc":"2.0","method":"subscription","params":{"channel":"book.ETH-PERPETUAL.raw","data":{"timestamp":1761154852114,"type":"change","change_id":46343839869,"instrument_name":"ETH-PERPETUAL","bids":[],"asks":[["delete",3827.4,0.0],["change",3827.5,59522.0]],"prev_change_id":46343839862}}}
1761154853903 {"jsonrpc":"2.0","method":"subscription","params":{"channel":"book.ETH-PERPETUAL.raw","data":{"timestamp":1761154852116,"type":"change","change_id":46343839872,"instrument_name":"ETH-PERPETUAL","bids":[["new",3826.15,8909.0],["delete",3825.25,0.0]],"asks":[],"prev_change_id":46343839869}}}
1761154853934 {"jsonrpc":"2.0","method":"subscription","params":{"channel":"book.ETH-PERPETUAL.raw","data":{"timestamp":1761154852155,"type":"change","change_id":46343839878,"instrument_name":"ETH-PERPETUAL","bids":[],"asks":[["new",3827.45,55080.0],["change",3827.5,55084.0]],"prev_change_id":46343839872}}}
1761154853940 {"jsonrpc":"2.0","method":"subscription","params":{"channel":"book.ETH-PERPETUAL.raw","data":{"timestamp":1761154852159,"type":"change","change_id":46343839882,"instrument_name":"ETH-PERPETUAL","bids":[["new",3826.3,1.5e4],["change",3825.15,3695.0]],"asks":[],"prev_change_id":46343839878}}}
1761154853978 {"jsonrpc":"2.0","method":"subscription","params":{"channel":"book.ETH-PERPETUAL.raw","data":{"timestamp":1761154852196,"type":"change","change_id":46343840121,"instrument_name":"ETH-PERPETUAL","bids":[],"asks":[["new",3827.4,134575.0],["change",3827.55,55080.0]],"prev_change_id":46343839882}}}
1761154853984 {"jsonrpc":"2.0","method":"subscription","params":{"channel":"book.ETH-PERPETUAL.raw","data":{"timestamp":1761154852200,"type":"change","change_id":46343840125,"instrument_name":"ETH-PERPETUAL","bids":[["new",3826.35,5373.0],["change",3825.05,17760.0]],"asks":[],"prev_change_id":46343840121}}}
1761154854020 {"jsonrpc":"2.0","method":"subscription","params":{"channel":"book.ETH-PERPETUAL.raw","data":{"timestamp":1761154852236,"type":"change","change_id":46343840133,"instrument_name":"ETH-PERPETUAL","bids":[],"asks":[["new",3827.35,23475.0],["change",3827.7,6594.0]],"prev_change_id":46343840125}}}
1761154854025 {"jsonrpc":"2.0","method":"subscription","params":{"channel":"book.ETH-PERPETUAL.raw","data":{"timestamp":1761154852240,"type":"change","change_id":46343840137,"instrument_name":"ETH-PERPETUAL","bids":[["new",3826.4,19994.0],["change",3825.0,2146.0]],"asks":[],"prev_change_id":46343840133}}}
1761154854068 {"jsonrpc":"2.0","method":"subscription","params":{"channel":"book.ETH-PERPETUAL.raw","data":{"timestamp":1761154852277,"type":"change","change_id":46343840146,"instrument_name":"ETH-PERPETUAL","bids":[],"asks":[["new",3827.3,9.7e3],["change",3827.75,16717.0]],"prev_change_id":46343840137}}}
1761154854074 {"jsonrpc":"2.0","method":"subscription","params":{"channel":"book.ETH-PERPETUAL.raw","data":{"timestamp":1761154852282,"type":"change","change_id":46343840150,"instrument_name":"ETH-PERPETUAL","bids":[["new",3826.5,5968.0],["change",3824.9,1664.0]],"asks":[],"prev_change_id":46343840146}}}
1761154854108 {"jsonrpc":"2.0","method":"subscription","params":{"channel":"book.ETH-PERPETUAL.raw","data":{"timestamp":1761154852317,"type":"change","change_id":46343840184,"instrument_name":"ETH-PERPETUAL","bids":[],"asks":[["new",3827.25,4.0],["change",3827.9,5438.0]],"prev_change_id":46343840150}}}
1761154854113 {"jsonrpc":"2.0","method":"subscription","params":{"channel":"book.ETH-PERPETUAL.raw","data":{"timestamp":1761154852321,"type":"change","change_id":46343840188,"instrument_name":"ETH-PERPETUAL","bids":[["new",3826.8,1.0e3],["delete",3824.85,0.0]],"asks":[],"prev_change_id":46343840184}}}
