1761154814906 {"jsonrpc":"2.0","id":1,"result":{"enabled_features":[],"access_token":"1792690813700.1TgRpyc_.WS5btcxLOCbxA9iH5ItIpqidELs8OJSQ1h8aJwklWwCWSCPusLNG6E2CclhbzprsVjAPZeCPpwC0esOq_8dGJ_mtGitRxGvFB7KUaYvXRjdo33Ho76shW0u-s2QoV72q67lpaSYbYV_7frh--d4NHcsdW_Rmoz5mlOdbsWCo5v5GEk2mfnauxhUv8Or7AY5bAxQxRHUWOBaF9PiCPBsIlzE1XxA05AzGrx166icDmNkz9_k8Z-42a4otcfh-2jU8IqLzGZ1On198UY7A7h8nDhDsnAJkoIJavmBlmk_cRA41kU3kdUeXRGUoBL5G2w","expires_in":31536000,"refresh_token":"1792690813700.1eJ5BiXi.6g-mVvZUZblRSGQj5-fnapf_bYIpX9dal85OICtPxpvIuqP9h9r6cbnJTfmhULfj3Yxo3YUYfx405aovq-U7h77sZ0UmOonx3r1Wi92UCeWZU0Z30yMcodlTk9AShGNflwkrV906DzM5Xod8douxMm46QO_1P2q6LCiC3sUhtu6i6bBr-PB4QBr3TLgwKwyp48bhYEKOvaxXg1o52eVKSfv_qbeaLDy5iL9-nlyuYZSfV2xUWeupjU7LZs8po2P0PKa06gYQr5kZQR6MWKpW3QlKgKBJZ6lRykCHrQOYHY3iutsMimU3cYYzgl9F","scope":"block_rfq:read block_trade:read connection trade:read custody:read account:read wallet:read mainaccount","token_type":"bearer"},"usIn":1761154813700723,"usOut":1761154813700929,"usDiff":206,"testnet":true}
1761154815167 {"jsonrpc":"2.0","id":2,"result":["trades.ETH-PERPETUAL.raw","trades.BTC-PERPETUAL.raw","book.ETH-PERPETUAL.raw","book.BTC-PERPETUAL.raw"],"usIn":1761154813945733,"usOut":1761154813945994,"usDiff":261,"testnet":true}
1761154815179 {"jsonrpc":"2.0","method":"subscription","params":{"channel":"book.ETH-PERPETUAL.raw","data":{"timestamp":1761154813378,"type":"snapshot","change_id":46343789656,"instrument_name":"ETH-PERPETUAL","bids":[["new",3824.3,2717.0],["new",3824.15,520.0],["new",3824.1,1.0e3],["new",3823.9,9.7e3],["new",3823.8,17525.0],["new",3823.75,2.2e4],["new",3823.65,19994.0],["new",3823.6,16717.0],["new",3823.55,1584.0],["new",3823.4,5355.0],["new",3823.35,27629.0],["new",3823.3,2216.0],["new",3823.25,4454.0],["new",3823.15,360.0],["new",3823.1,17030.0],["new",3823.0,1327.0],["new",3822.9,4447.0],["new",3822.8,2060.0],["new",3822.75,4451.0],["new",3817.25,1.05e5],["new",3817.2,1.05e5],["new",3806.9,3.2e5],["new",3806.85,3.2e5],["new",3778.1,50.0],["new",3769.95,50.0],["new",3767.45,50.0],["new",3761.8,50.0],["new",3741.4,50.0],["new",3725.4,50.0],["new",3721.0,50.0],["new",3705.55,50.0],["new",3672.8,50.0],["new",3664.9,50.0],["new",3659.8,50.0],["new",3657.0,50.0],["new",3637.25,50.0],["new",3617.5,50.0],["new",3558.2,50.0],["new",3.3e3,1.0e6],["new",3.0e3,2.5e3],["new",2621.55,1.0],["new",2619.55,3.0],["new",2618.55,26.0],["new",2550.0,250.0],["new",2.5e3,150.0],["new",2006.4,23.0],["new",2.0e3,5.0],["new",1.8e3,1.0],["new",1.7e3,231.0],["new",1.5e3,13.0],["new",1435.0,50.0],["new",1405.3,1386.0],["new",1.4e3,14.0],["new",1.3e3,22.0],["new",1242.0,64580.0],["new",1234.0,120.0],["new",1215.1,223.0],["new",1.2e3,713.0],["new",1199.9,1.0e4],["new",1193.9,2.0e4],["new",1102.0,43740.0],["new",1050.0,2.0],["new",1.0e3,41050.0],["new",942.0,131220.0],["new",900.0,4.6e3],["new",800.0,1.74e4],["new",762.0,393660.0],["new",750.8,386.0],["new",701.0,45.0],["new",691.0,49.0],["new",681.0,53.0],["new",671.0,56.0],["new",661.0,59.0],["new",651.0,61.0],["new",641.0,61.0],["new",631.0,62.0],["new",623.45,915.0],["new",621.0,62.0],["new",611.0,60.0],["new",601.0,58.0],["new",600.0,2509.0],["new",591.0,55.0],["new",581.0,52.0],["new",571.0,47.0],["new",561.0,43.0],["new",551.0,37.0],["new",541.0,32.0],["new",531.0,27.0],["new",524.0,87474.0],["new",521.0,22.0],["new",520.0,2.0],["new",511.0,17.0],["new",501.0,13.0],["new",500.0,3121.0],["new",400.0,250039.0],["new",350.0,240.0],["new",345.0,50.0],["new",300.0,251006.0],["new",260.0,5.0e5],["new",222.0,20.0],["new",212.0,2.0],["new",203.0,280.0],["new",200.0,64.0],["new",199.0,100.0],["new",195.0,2.0e3],["new",192.0,2.0],["new",181.0,1.2e5],["new",172.05,30.0],["new",150.0,30.0],["new",143.55,20.0],["new",140.0,1.0e5],["new",135.0,200010.0],["new",130.0,300020.0],["new",125.0,400020.0],["new",121.0,12.0],["new",120.0,130.0],["new",115.0,20.0],["new",110.0,30.0],["new",105.0,20.0],["new",101.0,10.0],["new",100.0,1051.0],["new",92.0,34.0],["new",90.0,25.0],["new",60.0,220.0],["new",58.0,1.0],["new",55.0,45.0],["new",50.0,913.0],["new",45.0,10000005.0],["new",40.0,40.0],["new",32.0,5.0],["new",30.0,70.0],["new",29.0,220.0],["new",25.0,20.0],["new",23.0,100.0],["new",22.2,1.0],["new",21.0,10.0],["new",20.0,2230.0],["new",10.0,370.0],["new",9.95,1.0],["new",8.0,2.0],["new",6.0,200.0],["new",5.0,43.0],["new",4.0,1844.0],["new",1.45,1330.0],["new",1.1,7.0],["new",1.0,90.0],["new",0.5,1.0],["new",0.2,2.0]],"asks":[["new",3824.35,108039.0],["new",3824.45,1424.0],["new",3824.6,4771.0],["new",3824.95,1.0e3],["new",3825.0,5485.0],["new",3825.05,16717.0],["new",3825.15,1658.0],["new",3825.3,8972.0],["new",3825.35,14134.0],["new",3825.4,7110.0],["new",3825.45,32105.0],["new",3825.65,3.0],["new",3825.7,4443.0],["new",3825.8,11655.0],["new",3825.9,38403.0],["new",3826.0,4531.0],["new",3826.1,1658.0],["new",3826.15,4446.0],["new",3826.2,10077.0],["new",3826.6,6972069.0],["new",3843.3,5.0e3],["new",3844.4,2.0e4],["new",3844.45,5.0e3],["new",3845.25,2.0e4],["new",3850.9,8.0e4],["new",3850.95,8.0e4],["new",3863.35,3.2e5],["new",3863.85,3.2e5],["new",3891.25,50.0],["new",3891.35,50.0],["new",3904.6,50.0],["new",3912.05,50.0],["new",3953.15,50.0],["new",3974.3,50.0],["new",3992.9,50.0],["new",3994.1,50.0],["new",4.0e3,1151205.0],["new",4007.75,50.0],["new",4034.0,50.0],["new",4.2e3,2.11e6],["new",4650.0,4656.0],["new",5050.0,4634.0],["new",5555.0,10001.0],["new",7180.4,1.0],["new",9999.0,2.0],["new",9999.95,1.0],["new",1.0e4,16.0],["new",1.1e4,20.0],["new",18285.0,3.0e4],["new",2.0e4,3.4e3],["new",3.85e4,40.0],["new",4.0e4,1.0e6],["new",5.0e4,11.0],["new",51853.0,10.0],["new",9.0e4,2.0e3]]}}}
1761154815318 {"jsonrpc":"2.0","method":"subscription","params":{"channel":"book.BTC-PERPETUAL.raw","data":{"timestamp":1761154813145,"type":"snapshot","change_id":67840091761,"instrument_name":"BTC-PERPETUAL","bids":[["new",107869.5,171460.0],["new",107864.0,15220.0],["new",107863.5,5.0e4],["new",107862.5,1.0e3],["new",107860.5,1.35e4],["new",107856.0,25990.0],["new",107855.5,21980.0],["new",107855.0,2.41e4],["new",107852.5,30.0],["new",107852.0,61590.0],["new",107851.5,8770.0],["new",107850.5,2.1e3],["new",107850.0,20.0],["new",107849.5,13880.0],["new",107849.0,16620.0],["new",107848.0,8440.0],["new",107846.5,13870.0],["new",107845.0,33360.0],["new",107839.0,13880.0],["new",107838.0,26940.0],["new",107816.0,6462890.0],["new",107810.0,10.0],["new",107761.5,10.0],["new",107713.0,10.0],["new",107693.0,5.0e3],["new",107664.5,10.0],["new",107637.0,2.0e4],["new",107636.5,1.85e5],["new",107616.0,10.0],["new",107605.5,8.0085e6],["new",107568.0,10.0],["new",107519.5,10.0],["new",107471.0,10.0],["new",107422.5,10.0],["new",107401.0,3.2e5],["new",107374.0,10.0],["new",107325.5,10.0],["new",107277.0,10.0],["new",107268.5,3.2e5],["new",107228.5,10.0],["new",107180.0,10.0],["new",107145.0,50.0],["new",107131.5,10.0],["new",107083.0,10.0],["new",107034.5,10.0],["new",106986.0,10.0],["new",106937.5,10.0],["new",106889.0,10.0],["new",105390.0,50.0],["new",1.053e5,300.0],["new",104909.0,50.0],["new",104510.5,50.0],["new",1.03e5,10.0],["new",1.025e5,10.0],["new",102055.0,1050.0],["new",1.02e5,10.0],["new",1.015e5,10.0],["new",101156.5,1.0e3],["new",1.01e5,10.0],["new",1.006e5,1390.0],["new",1.005e5,10.0],["new",1.0e5,10492390.0],["new",9.95e4,10.0],["new",9.9e4,10.0],["new",98549.0,10.0],["new",9.85e4,10.0],["new",9.8e4,10.0],["new",9.75e4,10.0],["new",9.7e4,10.0],["new",96566.0,100.0],["new",9.65e4,10.0],["new",9.6e4,10.0],["new",95635.0,58730.0],["new",95620.0,20.0],["new",9.55e4,10.0],["new",95385.0,58550.0],["new",9.5e4,30000380.0],["new",94665.0,58020.0],["new",94511.0,58010.0],["new",9.45e4,10.0],["new",94498.0,57950.0],["new",94236.0,57730.0],["new",9.4e4,10.0],["new",9.35e4,10.0],["new",9.3e4,10.0],["new",9.25e4,60.0],["new",9.2e4,10.0],["new",9.15e4,10.0],["new",9.1e4,10.0],["new",90976.5,20.0],["new",9.05e4,10.0],["new",90403.5,50.0],["new",9.0e4,50.0],["new",8.95e4,10.0],["new",8.9e4,160.0],["new",8.85e4,10.0],["new",8.8e4,10.0],["new",8.75e4,10.0],["new",8.7e4,10.0],["new",8.65e4,10.0],["new",8.6e4,10.0],["new",8.55e4,70.0],["new",85332.0,52020.0],["new",8.5e4,10.0],["new",84552.0,48090.0],["new",8.45e4,10.0],["new",8.4e4,10.0],["new",8.35e4,10.0],["new",8.3e4,10.0],["new",8.25e4,10.0],["new",8.2e4,10.0],["new",8.15e4,10.0],["new",81152.0,250.0],["new",8.1e4,10.0],["new",80978.0,10.0],["new",80957.5,5.0e5],["new",80940.0,60.0],["new",80746.0,250.0],["new",8.05e4,10.0],["new",80496.0,250.0],["new",80183.0,100.0],["new",80168.0,10.0],["new",8.0e4,130.0],["new",79691.0,250.0],["new",7.95e4,10.0],["new",79426.0,170.0],["new",79366.0,10.0],["new",79041.5,100.0],["new",79017.5,100.0],["new",7.9e4,10.0],["new",78668.5,300.0],["new",7.85e4,10.0],["new",7.8e4,10.0],["new",77911.5,520.0],["new",7.75e4,10.0],["new",77132.5,5.0e5],["new",7.7e4,10.0],["new",7.65e4,10.0],["new",7.6e4,10.0],["new",7.55e4,10.0],["new",7.5e4,10.0],["new",7.45e4,10.0],["new",74113.0,5.0e5],["new",7.4e4,60.0],["new",7.35e4,10.0],["new",73273.5,10.0],["new",73246.5,10.0],["new",7.3e4,10.0],["new",7.25e4,10.0],["new",7.2e4,10.0],["new",7.15e4,10.0],["new",7.1e4,10.0],["new",70708.5,10.0],["new",7.05e4,10.0],["new",7.0e4,100520.0],["new",6.95e4,10.0],["new",6.9e4,10.0],["new",6.85e4,10.0],["new",6.8e4,240.0],["new",6.75e4,50.0],["new",6.7e4,10.0],["new",66823.5,70.0],["new",66805.5,50.0],["new",66794.0,50.0],["new",66755.0,50.0],["new",6.65e4,10.0],["new",6.6e4,10.0],["new",6.55e4,50.0],["new",6.5e4,90.0],["new",6.45e4,10.0],["new",64483.5,90.0],["new",6.4e4,64090.0],["new",6.39e4,150.0],["new",63755.5,160.0],["new",6.35e4,10.0],["new",63027.5,290.0],["new",6.3e4,10.0],["new",6.25e4,10.0],["new",62299.5,500.0],["new",6.21e4,6.0e4],["new",6.2e4,10.0],["new",6.15e4,10.0],["new",61028.5,5.0e5],["new",6.1e4,10.0],["new",60686.0,50.0],["new",6.05e4,30.0],["new",6.0e4,73680.0],["new",5.95e4,10.0],["new",5.9e4,10.0],["new",5.85e4,10.0],["new",5.8e4,10.0],["new",5.75e4,10.0],["new",5.7e4,142510.0],["new",5.65e4,10.0],["new",5.6e4,140010.0],["new",5.55e4,10.0],["new",55000.5,500.0],["new",5.5e4,290.0],["new",5.45e4,10.0],["new",54224.5,5420.0],["new",5.4e4,10.0],["new",53580.5,5.0e5],["new",5.35e4,10.0],["new",5.3e4,10.0],["new",52718.5,10.0],["new",52683.0,10.0],["new",52635.0,10.0],["new",52629.5,10.0],["new",52620.5,10.0],["new",52610.0,10.0],["new",52547.0,10.0],["new",5.25e4,10.0],["new",52130.5,10.0],["new",5.2e4,20.0],["new",51567.5,20.0],["new",5.15e4,10.0],["new",5.1e4,740.0],["new",5.05e4,10.0],["new",50023.0,10.0],["new",50022.0,10.0],["new",50021.0,10.0],["new",50020.0,10.0],["new",50019.0,10.0],["new",50018.0,10.0],["new",50017.0,10.0],["new",50016.0,10.0],["new",50015.0,10.0],["new",50014.0,10.0],["new",50013.0,10.0],["new",50012.0,10.0],["new",50011.0,10.0],["new",50010.0,20.0],["new",50009.0,20.0],["new",50008.0,20.0],["new",50007.0,20.0],["new",50006.0,20.0],["new",50005.0,20.0],["new",50004.0,20.0],["new",50003.0,20.0],["new",50002.0,20.0],["new",50001.0,20.0],["new",5.0e4,13750.0],["new",4.95e4,10.0],["new",49133.5,2.5e4],["new",4.9e4,210.0],["new",4.85e4,10.0],["new",4.8e4,30.0],["new",4.75e4,10.0],["new",4.7e4,10.0],["new",46605.0,10.0],["new",46580.0,10.0],["new",4.65e4,10.0],["new",4.6e4,10.0],["new",4.55e4,10.0],["new",45000.5,30.0],["new",4.5e4,500.0],["new",4.49e4,30.0],["new",4.45e4,10.0],["new",4.4e4,160.0],["new",4.35e4,10.0],["new",4.3e4,10.0],["new",4.25e4,10.0],["new",4.2e4,10.0],["new",4.15e4,10.0],["new",4.1e4,10.0],["new",40575.0,40.0],["new",4.05e4,30.0],["new",4.0e4,2250.0],["new",3.95e4,10.0],["new",3.9e4,10.0],["new",3.85e4,10.0],["new",3.8e4,600010.0],["new",3.75e4,10.0],["new",3.7e4,40010.0],["new",3.65e4,10.0],["new",3.6e4,10.0],["new",3.55e4,10.0],["new",3.5e4,401870.0],["new",3.45e4,10.0],["new",3.4e4,10.0],["new",3.35e4,10.0],["new",3.3e4,30.0],["new",3.25e4,10.0],["new",3.2e4,30.0],["new",3.15e4,10.0],["new",31313.0,10.0],["new",3.1e4,1040.0],["new",3.05e4,10.0],["new",30049.0,10.0],["new",30048.0,10.0],["new",30047.0,10.0],["new",30046.0,10.0],["new",30045.0,10.0],["new",30044.0,10.0],["new",30043.0,10.0],["new",30042.0,10.0],["new",30041.0,10.0],["new",30040.0,10.0],["new",30039.0,10.0],["new",30038.0,10.0],["new",30037.0,10.0],["new",30036.0,10.0],["new",30035.0,10.0],["new",30034.0,10.0],["new",30033.0,10.0],["new",30032.0,10.0],["new",30031.0,10.0],["new",30030.0,10.0],["new",30029.0,10.0],["new",30028.0,10.0],["new",30027.0,10.0],["new",30026.0,10.0],["new",30025.0,10.0],["new",30024.0,10.0],["new",30023.0,10.0],["new",30022.0,10.0],["new",30021.0,10.0],["new",30020.0,10.0],["new",30019.0,10.0],["new",30018.0,10.0],["new",30017.0,10.0],["new",30016.0,10.0],["new",30015.0,10.0],["new",30014.0,10.0],["new",30013.0,10.0],["new",30012.0,10.0],["new",30011.0,10.0],["new",30010.0,10.0],["new",30009.0,10.0],["new",30008.0,10.0],["new",30007.0,10.0],["new",30006.0,10.0],["new",30005.0,10.0],["new",30004.0,10.0],["new",30003.0,10.0],["new",30002.0,10.0],["new",30001.0,10.0],["new",3.0e4,2460.0],["new",2.95e4,10.0],["new",2.9e4,10.0],["new",2.85e4,10.0],["new",2.8e4,10.0],["new",2.75e4,10.0],["new",2.7e4,10.0],["new",2.65e4,10.0],["new",2.6e4,10.0],["new",2.55e4,10.0],["new",2.5e4,330.0],["new",2.45e4,10.0],["new",2.4e4,10.0],["new",2.35e4,10.0],["new",2.3e4,10.0],["new",22706.0,13850.0],["new",2.25e4,108010.0],["new",22392.5,8.0e4],["new",22310.5,10.0],["new",22284.5,300.0],["new",22250.0,1.08e5],["new",22222.0,8.26e4],["new",22209.0,5.0e5],["new",2.2e4,20.0],["new",21795.0,300.0],["new",2.15e4,10.0],["new",21375.0,5.0e5],["new",21305.5,300.0],["new",2.1e4,20110.0],["new",20949.5,40.0],["new",20816.0,300.0],["new",2.05e4,10.0],["new",20326.5,300.0],["new",2.02e4,1.0e3],["new",2.01e4,1.0e3],["new",2.0e4,2680.0],["new",19940.0,10.0],["new",19582.0,120.0],["new",1.95e4,50.0],["new",1.94e4,10.0],["new",19373.0,300.0],["new",19347.5,600.0],["new",19288.5,5.0e5],["new",19129.0,180.0],["new",1.9e4,20.0],["new",1.85e4,10.0],["new",18368.5,600.0],["new",18328.0,5.0e5],["new",1.8e4,90.0],["new",17612.5,5.0e5],["new",17503.0,10.0],["new",1.75e4,10.0],["new",17389.5,600.0],["new",17135.0,160.0],["new",1.7e4,160.0],["new",16926.0,5.0e5],["new",1.69e4,20.0],["new",16625.0,92610.0],["new",1.66e4,1.0e5],["new",16575.0,1.0e5],["new",16550.0,1.0e5],["new",16525.0,1.0e5],["new",16515.0,10.0],["new",1.65e4,10.0],["new",16410.5,600.0],["new",16328.0,5.0e5],["new",16141.5,2890.0],["new",16134.0,1080.0],["new",16088.0,2890.0],["new",16080.5,1080.0],["new",16034.5,2890.0],["new",16026.5,1080.0],["new",1.6e4,240.0],["new",15973.0,1080.0],["new",15919.5,1080.0],["new",15866.0,1110.0],["new",15704.5,5.0e5],["new",15620.0,1.0e3],["new",1.55e4,310010.0],["new",15444.0,100.0],["new",15431.5,600.0],["new",1.54e4,10050.0],["new",15285.0,270.0],["new",15263.0,110.0],["new",15165.0,1.0e4],["new",15162.5,1.0e4],["new",1.51e4,10.0],["new",15063.0,270.0],["new",15045.0,810.0],["new",1.5e4,1100920.0],["new",14899.0,200.0],["new",14888.0,148880.0],["new",14864.5,2430.0],["new",14823.5,270.0],["new",14823.0,810.0],["new",14681.0,4.8e3],["new",14565.0,2430.0],["new",1.45e4,20.0],["new",14343.0,2430.0],["new",1.42e4,14210.0],["new",14090.0,400.0],["new",1.4e4,340.0],["new",13964.0,1.5e5],["new",13835.0,13840.0],["new",1.37e4,100.0],["new",1.35e4,10.0],["new",13360.0,100.0],["new",13078.5,9.8e4],["new",1.3e4,540.0],["new",12839.0,23040.0],["new",1.28e4,111360.0],["new",12510.5,1.5e5],["new",1.25e4,12510.0],["new",12345.0,550.0],["new",12334.0,500.0],["new",12304.5,7290.0],["new",1.23e4,125880.0],["new",12232.5,30.0],["new",1.22e4,5.0e5],["new",12189.5,1220.0],["new",12104.0,2.0e3],["new",1.2e4,5030.0],["new",11937.5,2.0e3],["new",11867.5,2.0e3],["new",11797.5,2.0e3],["new",11728.0,2.0e3],["new",1.17e4,4120.0],["new",11659.0,2.0e3],["new",11522.0,2.0e3],["new",1.15e4,10.0],["new",11454.0,2.0e3],["new",11450.5,20.0],["new",11420.5,30.0],["new",11360.5,90.0],["new",11240.5,270.0],["new",11230.0,200.0],["new",1.12e4,10.0],["new",11187.0,2.0e3],["new",11121.0,2.0e3],["new",1.11e4,10.0],["new",11055.5,2.0e3],["new",11000.5,810.0],["new",1.1e4,500410.0],["new",10990.5,2.0e3],["new",10926.0,2.0e3],["new",10861.5,2.0e3],["new",10797.5,2.0e3],["new",10734.0,2.0e3],["new",10682.5,2430.0],["new",10682.0,2430.0],["new",1.06e4,10.0],["new",10520.5,2430.0],["new",1.05e4,20.0],["new",10399.0,10.0],["new",1.02e4,130.0],["new",10179.0,50.0],["new",10172.5,810.0],["new",10164.5,2430.0],["new",10142.0,1.0e5],["new",10027.5,90.0],["new",10026.0,810.0],["new",10022.0,26730.0],["new",10009.5,150.0],["new",10001.0,10.0],["new",1.0e4,2087280.0],["new",9951.5,2.2e3],["new",9876.0,2430.0],["new",9874.0,2430.0],["new",9866.0,1.0e5],["new",9811.5,2430.0],["new",9785.5,7290.0],["new",9775.5,2430.0],["new",9743.5,2430.0],["new",9693.5,2430.0],["new",9692.5,2430.0],["new",9687.5,2430.0],["new",9687.0,2.43e4],["new",9674.0,3660.0],["new",9657.5,100.0],["new",9650.0,2430.0],["new",9640.5,7290.0],["new",9632.5,1.0e3],["new",9607.5,1.0e4],["new",9.6e3,100.0],["new",9597.0,2430.0],["new",9595.5,2430.0],["new",9582.5,9.7e4],["new",9546.0,2430.0],["new",9524.5,7290.0],["new",9.5e3,95010.0],["new",9411.0,8560.0],["new",9362.0,43740.0],["new",9326.5,1.5e5],["new",9317.5,890.0],["new",9274.0,1.0e5],["new",9250.5,7290.0],["new",9250.0,167450.0],["new",9234.0,7290.0],["new",9210.0,7.368e5],["new",9155.5,5.5e5],["new",9142.5,40.0],["new",9127.0,330.0],["new",9103.5,7290.0],["new",9102.5,160.0],["new",9.1e3,2.73e5],["new",9053.5,7290.0],["new",9047.5,7290.0],["new",9022.5,640.0],["new",9010.0,7290.0],["new",9.0e3,1230.0],["new",8957.0,7290.0],["new",8.9e3,100.0],["new",8878.0,2560.0],["new",8862.5,2560.0],["new",8854.0,1.5e5],["new",8839.0,600.0],["new",8802.0,2560.0],["new",8.8e3,100.0],["new",8785.0,9740.0],["new",8761.5,1040.0],["new",8760.0,1.0e5],["new",8735.0,9.0e3],["new",8.7e3,100.0],["new",8685.0,9.0e3],["new",8651.5,1560.0],["new",8638.5,10.0],["new",8635.0,9.0e3],["new",8.6e3,100.0],["new",8599.0,720.0],["new",8585.0,9.0e3],["new",8571.0,1250.0],["new",8546.0,2430.0],["new",8535.0,9.0e3],["new",8.5e3,89310.0],["new",8485.0,9.0e3],["new",8450.0,2110.0],["new",8435.0,9.0e3],["new",8.4e3,100.0],["new",8393.0,14630.0],["new",8385.0,9.0e3],["new",8350.0,2090.0],["new",8338.5,320.0],["new",8335.0,9.0e3],["new",8.3e3,100.0],["new",8290.0,1.6e3],["new",8285.0,9.0e3],["new",8241.5,4120.0],["new",8235.0,9.0e3],["new",8218.0,8.1e3],["new",8.2e3,100.0],["new",8185.0,9.0e3],["new",8135.0,9.0e3],["new",8.1e3,100.0],["new",8085.0,9.0e3],["new",8066.5,17120.0],["new",8035.0,9.0e3],["new",8.0e3,1220.0],["new",7987.5,900.0],["new",7985.0,9.0e3],["new",7973.0,29260.0],["new",7.9e3,100.0],["new",7892.0,7.0e5],["new",7890.5,640.0],["new",7876.0,58520.0],["new",7809.0,5.0e5],["new",7.8e3,1.01e4],["new",7777.0,10.0],["new",7.7e3,100.0],["new",7672.0,150.0],["new",7659.5,150.0],["new",7.6e3,100.0],["new",7555.5,10.0],["new",7523.5,40.0],["new",7.5e3,2250.0],["new",7472.0,160.0],["new",7447.0,450.0],["new",7434.5,450.0],["new",7420.5,10.0],["new",7.4e3,100.0],["new",7390.0,640.0],["new",7353.0,1280.0],["new",7.3e3,100.0],["new",7.2e3,1.1e3],["new",7190.0,450.0],["new",7170.5,500.0],["new",7160.0,7160.0],["new",7.1e3,1.001e5],["new",7048.5,10240.0],["new",7005.5,3.2e4],["new",7.0e3,1110.0],["new",6931.0,5.0e3],["new",6.9e3,100.0],["new",6.8e3,100.0],["new",6735.5,1.28e5],["new",6708.0,2560.0],["new",6.7e3,100.0],["new",6.6e3,100.0],["new",6590.0,8620.0],["new",6589.0,6470.0],["new",6588.0,28390.0],["new",6587.0,24480.0],["new",6551.0,20.0],["new",6550.0,20.0],["new",6512.0,35850.0],["new",6511.0,69260.0],["new",6510.0,221750.0],["new",6509.0,35860.0],["new",6.5e3,1.6e3],["new",6418.5,10.0],["new",6.4e3,100.0],["new",6395.0,64660.0],["new",6394.0,92760.0],["new",6393.0,217970.0],["new",6392.0,66110.0],["new",6390.5,10.0],["new",6.3e3,100.0],["new",6295.0,100.0],["new",6286.5,1.383e5],["new",6285.5,286720.0],["new",6284.5,211380.0],["new",6283.5,246610.0],["new",6259.5,750.0],["new",6.2e3,100.0],["new",6186.5,73690.0],["new",6185.5,340510.0],["new",6184.5,21880.0],["new",6183.5,186350.0],["new",6169.5,450.0],["new",6.1e3,100.0],["new",6050.0,40.0],["new",6.0e3,2520.0],["new",5999.0,5.0e3],["new",5934.0,5120.0],["new",5925.5,5.12e5],["new",5.9e3,210.0],["new",5.8e3,100.0],["new",5.7e3,100.0],["new",5.6e3,100.0],["new",5.5e3,2.1e3],["new",5.4e3,100.0],["new",5359.5,2250.0],["new",5346.0,7290.0],["new",5309.0,50.0],["new",5.3e3,100.0],["new",5.2e3,100.0],["new",5118.0,2560.0],["new",5.1e3,100.0],["new",5050.5,450.0],["new",5044.5,150.0],["new",5005.0,10240.0],["new",5.0e3,9760.0],["new",4999.0,20520.0],["new",4964.0,10.0],["new",4922.0,450.0],["new",4757.5,200.0],["new",4690.0,1.0e3],["new",4610.0,1.0e4],["new",4.6e3,2.0e3],["new",4597.0,1.6e3],["new",4594.5,450.0],["new",4514.5,1.0e6],["new",4.5e3,2810.0],["new",4414.0,46280.0],["new",4003.0,40.0],["new",4001.0,20.0],["new",4.0e3,640.0],["new",3921.0,23040.0],["new",3845.0,40.0],["new",3.8e3,10050.0],["new",3777.5,6.4e3],["new",3774.0,3.0e3],["new",3773.0,1.0e3],["new",3754.5,1.0e3],["new",3708.0,2.7e4],["new",3.7e3,30.0],["new",3680.0,10.0],["new",3655.0,20.0],["new",3650.0,10.0],["new",3.6e3,3.6e4],["new",3590.0,1.0e4],["new",3567.0,500.0],["new",3.5e3,230.0],["new",3.4e3,80.0],["new",3230.0,10.0],["new",3228.0,10.0],["new",3.2e3,20.0],["new",3001.0,20.0],["new",3.0e3,7.2e3],["new",2999.0,40.0],["new",2879.0,300.0],["new",2601.0,20.0],["new",2544.0,10.0],["new",2.5e3,20.0],["new",2467.0,2.56e4],["new",2.4e3,1.0e3],["new",2309.0,250.0],["new",2.3e3,20.0],["new",2222.0,680.0],["new",2211.0,40.0],["new",2005.0,140.0],["new",2.0e3,21250.0],["new",1999.0,10.0],["new",1994.5,5.0e3],["new",1979.0,60.0],["new",1.9e3,30.0],["new",1.7e3,300.0],["new",1675.0,200.0],["new",1.4e3,40.0],["new",1225.0,1.0e5],["new",1205.0,40.0],["new",1160.0,10.0],["new",1.1e3,20.0],["new",1099.0,10.0],["new",1002.5,70.0],["new",1001.5,60.0],["new",1000.5,80.0],["new",1.0e3,13520.0],["new",900.0,10.0],["new",800.0,10.0],["new",648.0,40.0],["new",600.0,560.0],["new",541.5,1.0e4],["new",502.0,1350.0],["new",500.0,2520.0],["new",400.0,150.0],["new",300.0,540.0],["new",288.0,10.0],["new",287.0,10.0],["new",281.0,100.0],["new",234.0,20.0],["new",222.0,300.0],["new",200.0,1220.0],["new",150.0,100.0],["new",123.0,1.0e3],["new",120.0,190.0],["new",113.0,10.0],["new",110.0,100.0],["new",101.0,110.0],["new",100.0,123910.0],["new",80.0,10.0],["new",78.0,100.0],["new",70.0,20.0],["new",60.0,660.0],["new",58.0,10.0],["new",50.0,1.0e3],["new",40.0,120.0],["new",35.5,20.0],["new",30.0,1.04e4],["new",25.0,30.0],["new",20.0,2150.0],["new",16.5,10.0],["new",15.0,20.0],["new",13.0,30.0],["new",12.0,2160.0],["new",11.0,10.0],["new",10.0,4150.0],["new",9.0,20.0],["new",6.5,10.0],["new",6.0,40.0],["new",5.0,250.0],["new",4.0,40.0],["new",3.0,20.0],["new",2.0,10.0],["new",1.0,950.0],["new",0.5,61250.0]],"asks":[["new",107870.0,254560.0],["new",107870.5,12630.0],["new",107871.0,20.0],["new",107871.5,20.0],["new",107872.0,20.0],["new",107872.5,20.0],["new",107873.0,20.0],["new",107873.5,21620.0],["new",107874.0,2.5e4],["new",107875.5,6.0e3],["new",107876.5,490.0],["new",107877.0,12310.0],["new",107877.5,2.1e3],["new",107881.0,8550.0],["new",107881.5,13440.0],["new",107882.0,20240.0],["new",107882.5,22340.0],["new",107886.5,1.1e4],["new",107887.5,5.0e4],["new",107923.5,5625750.0],["new",107955.0,100.0],["new",107966.5,10.0],["new",107997.0,5.0e3],["new",108015.0,10.0],["new",108063.5,10.0],["new",108112.0,10.0],["new",108134.0,7.087e6],["new",108140.5,5.0e3],["new",108160.5,20010.0],["new",108209.0,10.0],["new",108257.5,10.0],["new",108306.0,10.0],["new",108354.5,10.0],["new",108391.0,8.0e4],["new",108403.5,10.0],["new",108412.5,2.0e4],["new",108452.0,10.0],["new",108500.5,10.0],["new",108549.0,10.0],["new",108597.5,10.0],["new",108631.0,8.0e4],["new",108643.5,3.2e5],["new",108646.0,10.0],["new",108694.0,10.0],["new",108742.5,10.0],["new",108791.0,10.0],["new",108816.0,3.2e5],["new",108839.5,10.0],["new",108888.5,10.0],["new",108937.0,10.0],["new",108985.5,10.0],["new",109034.0,10.0],["new",109082.5,10.0],["new",109131.0,10.0],["new",109250.5,50.0],["new",109407.0,50.0],["new",109484.5,50.0],["new",109568.5,50.0],["new",109705.5,50.0],["new",109969.0,50.0],["new",110069.5,50.0],["new",110116.0,50.0],["new",110150.5,50.0],["new",110617.0,300.0],["new",110654.0,50.0],["new",110694.5,50.0],["new",1.113e5,300.0],["new",111437.5,50.0],["new",111507.5,50.0],["new",111656.5,50.0],["new",111868.0,50.0],["new",111870.0,50.0],["new",111898.0,50.0],["new",112409.0,50.0],["new",1.15e5,110.0],["new",1.155e5,10.0],["new",1.157e5,2151520.0],["new",1.16e5,10.0],["new",1.165e5,10.0],["new",1.17e5,10.0],["new",1.175e5,10.0],["new",1.18e5,10.0],["new",1.185e5,10.0],["new",1.19e5,10.0],["new",1.195e5,10.0],["new",1.2e5,10.0],["new",1.205e5,10.0],["new",120653.0,10.0],["new",1.21e5,10.0],["new",1.215e5,10.0],["new",1.22e5,10.0],["new",1.225e5,10.0],["new",1.23e5,10.0],["new",1.235e5,10.0],["new",123737.5,1.2e3],["new",1.24e5,10.0],["new",1.245e5,10.0],["new",124926.0,2730.0],["new",124974.5,540.0],["new",1.25e5,110.0],["new",1.255e5,10.0],["new",1.26e5,10.0],["new",1.265e5,10.0],["new",1.27e5,10.0],["new",127351.5,2730.0],["new",127449.5,630.0],["new",1.275e5,10.0],["new",1.28e5,10.0],["new",1.285e5,10.0],["new",1.29e5,10.0],["new",129458.5,840.0],["new",1.295e5,10.0],["new",129559.5,1.5e3],["new",129924.0,630.0],["new",130976.5,10.0],["new",131091.0,111030.0],["new",139042.0,80.0],["new",1.5e5,38101030.0]]}}}
1761154815447 {"jsonrpc":"2.0","method":"subscription","params":{"channel":"book.ETH-PERPETUAL.raw","data":{"timestamp":1761154814207,"type":"change","change_id":46343793749,"instrument_name":"ETH-PERPETUAL","bids":[["change",3824.15,109.0]],"asks":[],"prev_change_id":46343789656}}}
1761154816376 {"jsonrpc":"2.0","method":"subscription","params":{"channel":"book.ETH-PERPETUAL.raw","data":{"timestamp":1761154815077,"type":"change","change_id":46343794670,"instrument_name":"ETH-PERPETUAL","bids":[],"asks":[["delete",3824.35,0.0],["change",3825.8,87982.0]],"prev_change_id":46343793749}}}
1761154816382 {"jsonrpc":"2.0","method":"subscription","params":{"channel":"book.ETH-PERPETUAL.raw","data":{"timestamp":1761154815078,"type":"change","change_id":46343794671,"instrument_name":"ETH-PERPETUAL","bids":[["delete",3824.3,0.0],["new",3821.85,4546.0]],"asks":[],"prev_change_id":46343794670}}}
1761154816418 {"jsonrpc":"2.0","method":"subscription","params":{"channel":"book.ETH-PERPETUAL.raw","data":{"timestamp":1761154815117,"type":"change","change_id":46343794674,"instrument_name":"ETH-PERPETUAL","bids":[],"asks":[["delete",3824.45,0.0],["new",3825.75,17779.0]],"prev_change_id":46343794671}}}
1761154816426 {"jsonrpc":"2.0","method":"subscription","params":{"channel":"book.ETH-PERPETUAL.raw","data":{"timestamp":1761154815119,"type":"change","change_id":46343794675,"instrument_name":"ETH-PERPETUAL","bids":[["delete",3824.15,0.0],["new",3821.9,21601.0]],"asks":[],"prev_change_id":46343794674}}}
1761154816463 {"jsonrpc":"2.0","method":"subscription","params":{"channel":"book.ETH-PERPETUAL.raw","data":{"timestamp":1761154815156,"type":"change","change_id":46343794907,"instrument_name":"ETH-PERPETUAL","bids":[],"asks":[["delete",3824.6,0.0],["change",3825.7,12711.0]],"prev_change_id":46343794675}}}
1761154816469 {"jsonrpc":"2.0","method":"subscription","params":{"channel":"book.ETH-PERPETUAL.raw","data":{"timestamp":1761154815158,"type":"change","change_id":46343794908,"instrument_name":"ETH-PERPETUAL","bids":[["delete",3824.1,0.0],["new",3822.05,4578.0]],"asks":[],"prev_change_id":46343794907}}}
1761154816507 {"jsonrpc":"2.0","method":"subscription","params":{"channel":"book.ETH-PERPETUAL.raw","data":{"timestamp":1761154815196,"type":"change","change_id":46343794911,"instrument_name":"ETH-PERPETUAL","bids":[],"asks":[["delete",3824.95,0.0],["change",3825.65,39014.0]],"prev_change_id":46343794908}}}
1761154816512 {"jsonrpc":"2.0","method":"subscription","params":{"channel":"book.ETH-PERPETUAL.raw","data":{"timestamp":1761154815200,"type":"change","change_id":46343794914,"instrument_name":"ETH-PERPETUAL","bids":[["delete",3823.9,0.0],["new",3822.1,1367.0]],"asks":[],"prev_change_id":46343794911}}}
1761154816546 {"jsonrpc":"2.0","method":"subscription","params":{"channel":"book.ETH-PERPETUAL.raw","data":{"timestamp":1761154815236,"type":"change","change_id":46343794915,"instrument_name":"ETH-PERPETUAL","bids":[],"asks":[["delete",3825.0,0.0],["new",3825.6,36467.0]],"prev_change_id":46343794914}}}
1761154816551 {"jsonrpc":"2.0","method":"subscription","params":{"channel":"book.ETH-PERPETUAL.raw","data":{"timestamp":1761154815240,"type":"change","change_id":46343794918,"instrument_name":"ETH-PERPETUAL","bids":[["delete",3823.8,0.0],["new",3822.15,15388.0]],"asks":[],"prev_change_id":46343794915}}}
1761154816599 {"jsonrpc":"2.0","method":"subscription","params":{"channel":"book.ETH-PERPETUAL.raw","data":{"timestamp":1761154815276,"type":"change","change_id":46343794921,"instrument_name":"ETH-PERPETUAL","bids":[],"asks":[["delete",3825.05,0.0],["change",3825.45,64210.0]],"prev_change_id":46343794918}}}
1761154816603 {"jsonrpc":"2.0","method":"subscription","params":{"channel":"book.ETH-PERPETUAL.raw","data":{"timestamp":1761154815280,"type":"change","change_id":46343794924,"instrument_name":"ETH-PERPETUAL","bids":[["delete",3823.75,0.0],["new",3822.25,4596.0]],"asks":[],"prev_change_id":46343794921}}}
1761154816630 {"jsonrpc":"2.0","method":"subscription","params":{"channel":"book.ETH-PERPETUAL.raw","data":{"timestamp":1761154815315,"type":"change","change_id":46343794951,"instrument_name":"ETH-PERPETUAL","bids":[],"asks":[["delete",3825.15,0.0],["change",3825.4,26670.0]],"prev_change_id":46343794924}}}
1761154816639 {"jsonrpc":"2.0","method":"subscription","params":{"channel":"book.ETH-PERPETUAL.raw","data":{"timestamp":1761154815321,"type":"change","change_id":46343794955,"instrument_name":"ETH-PERPETUAL","bids":[["delete",3823.65,0.0],["new",3822.3,1615.0]],"asks":[],"prev_change_id":46343794951}}}
1761154816682 {"jsonrpc":"2.0","method":"subscription","params":{"channel":"book.ETH-PERPETUAL.raw","data":{"timestamp":1761154815356,"type":"change","change_id":46343794961,"instrument_name":"ETH-PERPETUAL","bids":[],"asks":[["change",3825.3,4447.0]],"prev_change_id":46343794955}}}
1761154816688 {"jsonrpc":"2.0","method":"subscription","params":{"channel":"book.ETH-PERPETUAL.raw","data":{"timestamp":1761154815362,"type":"change","change_id":46343794964,"instrument_name":"ETH-PERPETUAL","bids":[["delete",3823.6,0.0],["new",3822.4,6445.0]],"asks":[],"prev_change_id":46343794961}}}
1761154816743 {"jsonrpc":"2.0","method":"subscription","params":{"channel":"book.ETH-PERPETUAL.raw","data":{"timestamp":1761154815399,"type":"change","change_id":46343794988,"instrument_name":"ETH-PERPETUAL","bids":[],"asks":[["new",3825.2,4425.0],["delete",3825.35,0.0]],"prev_change_id":46343794964}}}
1761154816750 {"jsonrpc":"2.0","method":"subscription","params":{"channel":"book.ETH-PERPETUAL.raw","data":{"timestamp":1761154815403,"type":"change","change_id":46343795012,"instrument_name":"ETH-PERPETUAL","bids":[["delete",3823.55,0.0],["new",3822.6,1445.0]],"asks":[],"prev_change_id":46343794988}}}
1761154816788 {"jsonrpc":"2.0","method":"subscription","params":{"channel":"book.ETH-PERPETUAL.raw","data":{"timestamp":1761154815440,"type":"change","change_id":46343795368,"instrument_name":"ETH-PERPETUAL","bids":[],"asks":[["new",3825.15,11734.0],["change",3825.4,19560.0]],"prev_change_id":46343795012}}}
1761154816795 {"jsonrpc":"2.0","method":"subscription","params":{"channel":"book.ETH-PERPETUAL.raw","data":{"timestamp":1761154815445,"type":"change","change_id":46343795373,"instrument_name":"ETH-PERPETUAL","bids":[["delete",3823.4,0.0],["new",3822.65,16592.0]],"asks":[],"prev_change_id":46343795368}}}
1761154816830 {"jsonrpc":"2.0","method":"subscription","params":{"channel":"book.ETH-PERPETUAL.raw","data":{"timestamp":1761154815480,"type":"change","change_id":46343795382,"instrument_name":"ETH-PERPETUAL","bids":[],"asks":[["new",3825.05,16717.0],["change",3825.45,32105.0]],"prev_change_id":46343795373}}}
1761154816836 {"jsonrpc":"2.0","method":"subscription","params":{"channel":"book.ETH-PERPETUAL.raw","data":{"timestamp":1761154815485,"type":"change","change_id":46343795387,"instrument_name":"ETH-PERPETUAL","bids":[["delete",3823.35,0.0],["change",3822.75,7314.0]],"asks":[],"prev_change_id":46343795382}}}
1761154816861 {"jsonrpc":"2.0","method":"subscription","params":{"channel":"book.ETH-PERPETUAL.raw","data":{"timestamp":1761154815521,"type":"change","change_id":46343795512,"instrument_name":"ETH-PERPETUAL","bids":[],"asks":[["new",3825.0,6193.0],["change",3825.65,39011.0]],"prev_change_id":46343795387}}}
1761154816866 {"jsonrpc":"2.0","method":"subscription","params":{"channel":"book.ETH-PERPETUAL.raw","data":{"timestamp":1761154815525,"type":"change","change_id":46343795537,"instrument_name":"ETH-PERPETUAL","bids":[["delete",3823.3,0.0],["change",3822.8,11072.0]],"asks":[],"prev_change_id":46343795512}}}
1761154816891 {"jsonrpc":"2.0","method":"subscription","params":{"channel":"book.ETH-PERPETUAL.raw","data":{"timestamp":1761154815559,"type":"change","change_id":46343795540,"instrument_name":"ETH-PERPETUAL","bids":[],"asks":[["new",3824.75,1658.0],["change",3825.7,8268.0]],"prev_change_id":46343795537}}}
1761154816900 {"jsonrpc":"2.0","method":"subscription","params":{"channel":"book.ETH-PERPETUAL.raw","data":{"timestamp":1761154815566,"type":"change","change_id":46343795547,"instrument_name":"ETH-PERPETUAL","bids":[["delete",3823.25,0.0],["new",3822.85,1.25e4]],"asks":[],"prev_change_id":46343795540}}}
1761154816932 {"jsonrpc":"2.0","method":"subscription","params":{"channel":"book.ETH-PERPETUAL.raw","data":{"timestamp":1761154815598,"type":"change","change_id":46343795551,"instrument_name":"ETH-PERPETUAL","bids":[],"asks":[["new",3824.6,5771.0],["change",3825.8,76327.0]],"prev_change_id":46343795547}}}
1761154816941 {"jsonrpc":"2.0","method":"subscription","params":{"channel":"book.ETH-PERPETUAL.raw","data":{"timestamp":1761154815607,"type":"change","change_id":46343795562,"instrument_name":"ETH-PERPETUAL","bids":[["delete",3823.15,0.0],["change",3822.9,21164.0]],"asks":[],"prev_change_id":46343795551}}}
1761154816976 {"jsonrpc":"2.0","method":"subscription","params":{"channel":"book.ETH-PERPETUAL.raw","data":{"timestamp":1761154815638,"type":"change","change_id":46343795565,"instrument_name":"ETH-PERPETUAL","bids":[],"asks":[["new",3824.55,9.7e3],["delete",3825.9,0.0]],"prev_change_id":46343795562}}}
1761154816984 {"jsonrpc":"2.0","method":"subscription","params":{"channel":"book.ETH-PERPETUAL.raw","data":{"timestamp":1761154815646,"type":"change","change_id":46343795579,"instrument_name":"ETH-PERPETUAL","bids":[["delete",3823.1,0.0],["change",3823.0,30703.0]],"asks":[],"prev_change_id":46343795565}}}
1761154817022 {"jsonrpc":"2.0","method":"subscription","params":{"channel":"book.ETH-PERPETUAL.raw","data":{"timestamp":1761154815677,"type":"change","change_id":46343795622,"instrument_name":"ETH-PERPETUAL","bids":[],"asks":[["new",3824.4,4618.0],["delete",3826.0,0.0]],"prev_change_id":46343795579}}}
1761154817030 {"jsonrpc":"2.0","method":"subscription","params":{"channel":"book.ETH-PERPETUAL.raw","data":{"timestamp":1761154815688,"type":"change","change_id":46343795631,"instrument_name":"ETH-PERPETUAL","bids":[["new",3823.1,2.2e4],["change",3823.0,29376.0]],"asks":[],"prev_change_id":46343795622}}}
1761154817175 {"jsonrpc":"2.0","method":"subscription","params":{"channel":"book.ETH-PERPETUAL.raw","data":{"timestamp":1761154815719,"type":"change","change_id":46343795636,"instrument_name":"ETH-PERPETUAL","bids":[],"asks":[["new",3824.35,25272.0],["delete",3826.1,0.0]],"prev_change_id":46343795631}}}
1761154817192 {"jsonrpc":"2.0","method":"subscription","params":{"channel":"book.ETH-PERPETUAL.raw","data":{"timestamp":1761154815732,"type":"change","change_id":46343795643,"instrument_name":"ETH-PERPETUAL","bids":[["new",3823.15,360.0],["change",3822.9,16717.0]],"asks":[],"prev_change_id":46343795636}}}
1761154817261 {"jsonrpc":"2.0","method":"subscription","params":{"channel":"book.ETH-PERPETUAL.raw","data":{"timestamp":1761154815766,"type":"change","change_id":46343795720,"instrument_name":"ETH-PERPETUAL","bids":[],"asks":[["new",3824.3,11350.0],["delete",3826.15,0.0]],"prev_change_id":46343795643}}}
1761154817267 {"jsonrpc":"2.0","method":"subscription","params":{"channel":"book.ETH-PERPETUAL.raw","data":{"timestamp":1761154815772,"type":"change","change_id":46343795727,"instrument_name":"ETH-PERPETUAL","bids":[["new",3823.25,1.0e3],["change",3822.8,9012.0]],"asks":[],"prev_change_id":46343795720}}}
1761154817271 {"jsonrpc":"2.0","method":"subscription","params":{"channel":"book.ETH-PERPETUAL.raw","data":{"timestamp":1761154815806,"type":"change","change_id":46343795733,"instrument_name":"ETH-PERPETUAL","bids":[],"asks":[["new",3824.25,12670.0],["delete",3826.2,0.0]],"prev_change_id":46343795727}}}
1761154817275 {"jsonrpc":"2.0","method":"subscription","params":{"channel":"book.ETH-PERPETUAL.raw","data":{"timestamp":1761154815812,"type":"change","change_id":46343795742,"instrument_name":"ETH-PERPETUAL","bids":[["new",3823.75,8.0],["change",3822.75,2863.0]],"asks":[],"prev_change_id":46343795733}}}
1761154817282 {"jsonrpc":"2.0","method":"subscription","params":{"channel":"book.ETH-PERPETUAL.raw","data":{"timestamp":1761154815845,"type":"change","change_id":46343795749,"instrument_name":"ETH-PERPETUAL","bids":[],"asks":[["new",3824.2,129298.0]],"prev_change_id":46343795742}}}
1761154817291 {"jsonrpc":"2.0","method":"subscription","params":{"channel":"book.ETH-PERPETUAL.raw","data":{"timestamp":1761154815853,"type":"change","change_id":46343795758,"instrument_name":"ETH-PERPETUAL","bids":[["new",3824.15,42.0]],"asks":[],"prev_change_id":46343795749}}}
1761154817325 {"jsonrpc":"2.0","method":"subscription","params":{"channel":"book.ETH-PERPETUAL.raw","data":{"timestamp":1761154815931,"type":"change","change_id":46343795929,"instrument_name":"ETH-PERPETUAL","bids":[],"asks":[["new",3826.2,6972069.0],["delete",3826.6,0.0]],"prev_change_id":46343795758}}}
1761154818256 {"jsonrpc":"2.0","method":"subscription","params":{"channel":"book.ETH-PERPETUAL.raw","data":{"timestamp":1761154816784,"type":"change","change_id":46343797069,"instrument_name":"ETH-PERPETUAL","bids":[],"asks":[["change",3824.6,7683.0]],"prev_change_id":46343795929}}}
1761154818264 {"jsonrpc":"2.0","method":"subscription","params":{"channel":"book.BTC-PERPETUAL.raw","data":{"timestamp":1761154816785,"type":"change","change_id":67840096521,"instrument_name":"BTC-PERPETUAL","bids":[],"asks":[["delete",107870.0,0.0],["new",107898.5,5.0e4]],"prev_change_id":67840091761}}}
1761154818267 {"jsonrpc":"2.0","method":"subscription","params":{"channel":"book.BTC-PERPETUAL.raw","data":{"timestamp":1761154816786,"type":"change","change_id":67840096522,"instrument_name":"BTC-PERPETUAL","bids":[["delete",107869.5,0.0],["new",107837.5,10870.0]],"asks":[],"prev_change_id":67840096521}}}
1761154818272 {"jsonrpc":"2.0","method":"subscription","params":{"channel":"book.BTC-PERPETUAL.raw","data":{"timestamp":1761154816825,"type":"change","change_id":67840096574,"instrument_name":"BTC-PERPETUAL","bids":[],"asks":[["delete",107870.5,0.0],["new",107897.5,95080.0]],"prev_change_id":67840096522}}}
1761154818283 {"jsonrpc":"2.0","method":"subscription","params":{"channel":"book.BTC-PERPETUAL.raw","data":{"timestamp":1761154816827,"type":"change","change_id":67840096575,"instrument_name":"BTC-PERPETUAL","bids":[["delete",107864.0,0.0],["change",107839.0,27760.0]],"asks":[],"prev_change_id":67840096574}}}
1761154818313 {"jsonrpc":"2.0","method":"subscription","params":{"channel":"book.BTC-PERPETUAL.raw","data":{"timestamp":1761154816865,"type":"change","change_id":67840096576,"instrument_name":"BTC-PERPETUAL","bids":[],"asks":[["delete",107871.0,0.0],["new",107894.5,1.0e3]],"prev_change_id":67840096575}}}
1761154818343 {"jsonrpc":"2.0","method":"subscription","params":{"channel":"book.BTC-PERPETUAL.raw","data":{"timestamp":1761154816867,"type":"change","change_id":67840096577,"instrument_name":"BTC-PERPETUAL","bids":[["delete",107863.5,0.0],["new",107841.0,5.03e4]],"asks":[],"prev_change_id":67840096576}}}
1761154818402 {"jsonrpc":"2.0","method":"subscription","params":{"channel":"book.BTC-PERPETUAL.raw","data":{"timestamp":1761154816905,"type":"change","change_id":67840096582,"instrument_name":"BTC-PERPETUAL","bids":[],"asks":[["delete",107871.5,0.0],["new",107893.5,57710.0]],"prev_change_id":67840096577}}}
1761154818427 {"jsonrpc":"2.0","method":"subscription","params":{"channel":"book.BTC-PERPETUAL.raw","data":{"timestamp":1761154816907,"type":"change","change_id":67840096585,"instrument_name":"BTC-PERPETUAL","bids":[["delete",107862.5,0.0],["new",107841.5,9230.0]],"asks":[],"prev_change_id":67840096582}}}
1761154818440 {"jsonrpc":"2.0","method":"subscription","params":{"channel":"book.BTC-PERPETUAL.raw","data":{"timestamp":1761154816944,"type":"change","change_id":67840096587,"instrument_name":"BTC-PERPETUAL","bids":[],"asks":[["delete",107872.0,0.0],["new",107892.5,33290.0]],"prev_change_id":67840096585}}}
1761154818445 {"jsonrpc":"2.0","method":"subscription","params":{"channel":"book.BTC-PERPETUAL.raw","data":{"timestamp":1761154816949,"type":"change","change_id":67840096589,"instrument_name":"BTC-PERPETUAL","bids":[["delete",107860.5,0.0],["change",107845.0,66720.0]],"asks":[],"prev_change_id":67840096587}}}
1761154818473 {"jsonrpc":"2.0","method":"subscription","params":{"channel":"book.BTC-PERPETUAL.raw","data":{"timestamp":1761154816984,"type":"change","change_id":67840096591,"instrument_name":"BTC-PERPETUAL","bids":[],"asks":[["delete",107872.5,0.0],["new",107889.5,1.27e4]],"prev_change_id":67840096589}}}
1761154818479 {"jsonrpc":"2.0","method":"subscription","params":{"channel":"book.BTC-PERPETUAL.raw","data":{"timestamp":1761154816989,"type":"change","change_id":67840096593,"instrument_name":"BTC-PERPETUAL","bids":[["delete",107856.0,0.0],["change",107846.5,27740.0]],"asks":[],"prev_change_id":67840096591}}}
1761154818483 {"jsonrpc":"2.0","method":"subscription","params":{"channel":"book.BTC-PERPETUAL.raw","data":{"timestamp":1761154817024,"type":"change","change_id":67840096708,"instrument_name":"BTC-PERPETUAL","bids":[],"asks":[["delete",107873.0,0.0],["new",107888.5,2.1e3]],"prev_change_id":67840096593}}}
1761154818492 {"jsonrpc":"2.0","method":"subscription","params":{"channel":"book.BTC-PERPETUAL.raw","data":{"timestamp":1761154817028,"type":"change","change_id":67840096712,"instrument_name":"BTC-PERPETUAL","bids":[["delete",107855.5,0.0],["new",107847.5,8440.0]],"asks":[],"prev_change_id":67840096708}}}
1761154818530 {"jsonrpc":"2.0","method":"subscription","params":{"channel":"book.BTC-PERPETUAL.raw","data":{"timestamp":1761154817063,"type":"change","change_id":67840096715,"instrument_name":"BTC-PERPETUAL","bids":[],"asks":[["delete",107873.5,0.0],["new",107888.0,1.1e4]],"prev_change_id":67840096712}}}
1761154818537 {"jsonrpc":"2.0","method":"subscription","params":{"channel":"book.BTC-PERPETUAL.raw","data":{"timestamp":1761154817068,"type":"change","change_id":67840096718,"instrument_name":"BTC-PERPETUAL","bids":[["delete",107855.0,0.0],["change",107849.0,3.25e4]],"asks":[],"prev_change_id":67840096715}}}
1761154818586 {"jsonrpc":"2.0","method":"subscription","params":{"channel":"book.BTC-PERPETUAL.raw","data":{"timestamp":1761154817103,"type":"change","change_id":67840096721,"instrument_name":"BTC-PERPETUAL","bids":[],"asks":[["delete",107874.0,0.0],["change",107887.5,1.0e5]],"prev_change_id":67840096718}}}
1761154818591 {"jsonrpc":"2.0","method":"subscription","params":{"channel":"book.BTC-PERPETUAL.raw","data":{"timestamp":1761154817108,"type":"change","change_id":67840096724,"instrument_name":"BTC-PERPETUAL","bids":[["delete",107852.5,0.0],["change",107849.5,15980.0]],"asks":[],"prev_change_id":67840096721}}}
1761154818612 {"jsonrpc":"2.0","method":"subscription","params":{"channel":"book.BTC-PERPETUAL.raw","data":{"timestamp":1761154817143,"type":"change","change_id":67840096728,"instrument_name":"BTC-PERPETUAL","bids":[],"asks":[["delete",107875.5,0.0],["new",107887.0,20740.0]],"prev_change_id":67840096724}}}
1761154818623 {"jsonrpc":"2.0","method":"subscription","params":{"channel":"book.BTC-PERPETUAL.raw","data":{"timestamp":1761154817148,"type":"change","change_id":67840096731,"instrument_name":"BTC-PERPETUAL","bids":[["delete",107852.0,0.0],["change",107850.0,61630.0]],"asks":[],"prev_change_id":67840096728}}}
1761154818665 {"jsonrpc":"2.0","method":"subscription","params":{"channel":"book.BTC-PERPETUAL.raw","data":{"timestamp":1761154817185,"type":"change","change_id":67840096854,"instrument_name":"BTC-PERPETUAL","bids":[],"asks":[["delete",107876.5,0.0],["change",107882.5,44830.0]],"prev_change_id":67840096731}}}
1761154818678 {"jsonrpc":"2.0","method":"subscription","params":{"channel":"book.BTC-PERPETUAL.raw","data":{"timestamp":1761154817193,"type":"change","change_id":67840097071,"instrument_name":"BTC-PERPETUAL","bids":[["delete",107851.5,0.0],["change",107850.5,21120.0]],"asks":[],"prev_change_id":67840096854}}}
1761154818774 {"jsonrpc":"2.0","method":"subscription","params":{"channel":"book.BTC-PERPETUAL.raw","data":{"timestamp":1761154817226,"type":"change","change_id":67840097096,"instrument_name":"BTC-PERPETUAL","bids":[],"asks":[["delete",107877.0,0.0],["new",107880.5,13440.0]],"prev_change_id":67840097071}}}
1761154818821 {"jsonrpc":"2.0","method":"subscription","params":{"channel":"book.BTC-PERPETUAL.raw","data":{"timestamp":1761154817236,"type":"change","change_id":67840097146,"instrument_name":"BTC-PERPETUAL","bids":[["new",107855.0,20.0],["change",107850.5,19020.0]],"asks":[],"prev_change_id":67840097096}}}
1761154818865 {"jsonrpc":"2.0","method":"subscription","params":{"channel":"book.BTC-PERPETUAL.raw","data":{"timestamp":1761154817266,"type":"change","change_id":67840097232,"instrument_name":"BTC-PERPETUAL","bids":[],"asks":[["delete",107877.5,0.0],["new",107880.0,3690.0]],"prev_change_id":67840097146}}}
1761154818871 {"jsonrpc":"2.0","method":"subscription","params":{"channel":"book.BTC-PERPETUAL.raw","data":{"timestamp":1761154817275,"type":"change","change_id":67840097237,"instrument_name":"BTC-PERPETUAL","bids":[["new",107858.5,8650.0],["change",107850.0,61610.0]],"asks":[],"prev_change_id":67840097232}}}
1761154818875 {"jsonrpc":"2.0","method":"subscription","params":{"channel":"book.BTC-PERPETUAL.raw","data":{"timestamp":1761154817306,"type":"change","change_id":67840097274,"instrument_name":"BTC-PERPETUAL","bids":[],"asks":[["new",107877.5,2.1e3],["delete",107881.0,0.0]],"prev_change_id":67840097237}}}
1761154818879 {"jsonrpc":"2.0","method":"subscription","params":{"channel":"book.BTC-PERPETUAL.raw","data":{"timestamp":1761154817315,"type":"change","change_id":67840097279,"instrument_name":"BTC-PERPETUAL","bids":[["new",107860.5,2590.0],["change",107849.5,2.1e3]],"asks":[],"prev_change_id":67840097274}}}
1761154818886 {"jsonrpc":"2.0","method":"subscription","params":{"channel":"book.BTC-PERPETUAL.raw","data":{"timestamp":1761154817346,"type":"change","change_id":67840097284,"instrument_name":"BTC-PERPETUAL","bids":[],"asks":[["new",107875.5,6.0e3],["delete",107881.5,0.0]],"prev_change_id":67840097279}}}
1761154818890 {"jsonrpc":"2.0","method":"subscription","params":{"channel":"book.BTC-PERPETUAL.raw","data":{"timestamp":1761154817355,"type":"change","change_id":67840097350,"instrument_name":"BTC-PERPETUAL","bids":[["new",107861.0,11020.0],["change",107849.0,15880.0]],"asks":[],"prev_change_id":67840097284}}}
1761154818901 {"jsonrpc":"2.0","method":"subscription","params":{"channel":"book.BTC-PERPETUAL.raw","data":{"timestamp":1761154817387,"type":"change","change_id":67840097537,"instrument_name":"BTC-PERPETUAL","bids":[],"asks":[["new",107874.0,20.0],["delete",107882.0,0.0]],"prev_change_id":67840097350}}}
1761154818910 {"jsonrpc":"2.0","method":"subscription","params":{"channel":"book.BTC-PERPETUAL.raw","data":{"timestamp":1761154817409,"type":"change","change_id":67840097544,"instrument_name":"BTC-PERPETUAL","bids":[["new",107861.5,36980.0],["delete",107848.0,0.0]],"asks":[],"prev_change_id":67840097537}}}
1761154818926 {"jsonrpc":"2.0","method":"subscription","params":{"channel":"book.BTC-PERPETUAL.raw","data":{"timestamp":1761154817428,"type":"change","change_id":67840097549,"instrument_name":"BTC-PERPETUAL","bids":[],"asks":[["new",107873.5,25020.0],["change",107882.5,22490.0]],"prev_change_id":67840097544}}}
1761154818932 {"jsonrpc":"2.0","method":"subscription","params":{"channel":"book.BTC-PERPETUAL.raw","data":{"timestamp":1761154817450,"type":"change","change_id":67840097556,"instrument_name":"BTC-PERPETUAL","bids":[["new",107862.0,13330.0],["change",107846.5,13870.0]],"asks":[],"prev_change_id":67840097549}}}
1761154818952 {"jsonrpc":"2.0","method":"subscription","params":{"channel":"book.BTC-PERPETUAL.raw","data":{"timestamp":1761154817467,"type":"change","change_id":67840097661,"instrument_name":"BTC-PERPETUAL","bids":[],"asks":[["new",107873.0,20.0],["delete",107886.5,0.0]],"prev_change_id":67840097556}}}
1761154818994 {"jsonrpc":"2.0","method":"subscription","params":{"channel":"book.BTC-PERPETUAL.raw","data":{"timestamp":1761154817490,"type":"change","change_id":67840097668,"instrument_name":"BTC-PERPETUAL","bids":[["new",107862.5,1.0e3],["change",107845.0,33360.0]],"asks":[],"prev_change_id":67840097661}}}
1761154819028 {"jsonrpc":"2.0","method":"subscription","params":{"channel":"book.BTC-PERPETUAL.raw","data":{"timestamp":1761154817507,"type":"change","change_id":67840097673,"instrument_name":"BTC-PERPETUAL","bids":[],"asks":[["new",107872.5,20.0],["change",107887.5,5.0e4]],"prev_change_id":67840097668}}}
1761154819096 {"jsonrpc":"2.0","method":"subscription","params":{"channel":"book.BTC-PERPETUAL.raw","data":{"timestamp":1761154817530,"type":"change","change_id":67840097681,"instrument_name":"BTC-PERPETUAL","bids":[["new",107869.0,500.0],["change",107839.0,13880.0]],"asks":[],"prev_change_id":67840097673}}}
1761154819150 {"jsonrpc":"2.0","method":"subscription","params":{"channel":"book.BTC-PERPETUAL.raw","data":{"timestamp":1761154817546,"type":"change","change_id":67840097687,"instrument_name":"BTC-PERPETUAL","bids":[],"asks":[["new",107870.0,138750.0]],"prev_change_id":67840097681}}}
1761154819189 {"jsonrpc":"2.0","method":"subscription","params":{"channel":"book.BTC-PERPETUAL.raw","data":{"timestamp":1761154817570,"type":"change","change_id":67840097847,"instrument_name":"BTC-PERPETUAL","bids":[["new",107869.5,219580.0],["delete",107838.0,0.0]],"asks":[],"prev_change_id":67840097687}}}
1761154819231 {"jsonrpc":"2.0","method":"subscription","params":{"channel":"book.ETH-PERPETUAL.raw","data":{"timestamp":1761154817674,"type":"change","change_id":46343798160,"instrument_name":"ETH-PERPETUAL","bids":[["new",3806.95,3.2e5],["delete",3806.85,0.0]],"asks":[],"prev_change_id":46343797069}}}
1761154819237 {"jsonrpc":"2.0","method":"subscription","params":{"channel":"book.ETH-PERPETUAL.raw","data":{"timestamp":1761154817675,"type":"change","change_id":46343798161,"instrument_name":"ETH-PERPETUAL","bids":[["change",3817.2,2.5e4],["change",3806.95,4.0e5]],"asks":[],"prev_change_id":46343798160}}}
1761154819240 {"jsonrpc":"2.0","method":"subscription","params":{"channel":"book.ETH-PERPETUAL.raw","data":{"timestamp":1761154817676,"type":"change","change_id":46343798162,"instrument_name":"ETH-PERPETUAL","bids":[["new",3817.3,2.0e4],["change",3817.2,5.0e3]],"asks":[],"prev_change_id":46343798161}}}
1761154819243 {"jsonrpc":"2.0","method":"subscription","params":{"channel":"book.ETH-PERPETUAL.raw","data":{"timestamp":1761154817677,"type":"change","change_id":46343798163,"instrument_name":"ETH-PERPETUAL","bids":[["change",3817.3,2.5e4],["delete",3817.2,0.0]],"asks":[],"prev_change_id":46343798162}}}
1761154821176 {"jsonrpc":"2.0","method":"subscription","params":{"channel":"book.BTC-PERPETUAL.raw","data":{"timestamp":1761154819479,"type":"change","change_id":67840100293,"instrument_name":"BTC-PERPETUAL","bids":[["new",107629.0,8.0085e6],["delete",107605.5,0.0]],"asks":[],"prev_change_id":67840097847}}}
1761154821179 {"jsonrpc":"2.0","method":"subscription","params":{"channel":"book.BTC-PERPETUAL.raw","data":{"timestamp":1761154819528,"type":"change","change_id":67840100294,"instrument_name":"BTC-PERPETUAL","bids":[["new",107614.0,3.2e5],["delete",107401.0,0.0]],"asks":[],"prev_change_id":67840100293}}}
1761154821515 {"jsonrpc":"2.0","method":"subscription","params":{"channel":"book.BTC-PERPETUAL.raw","data":{"timestamp":1761154819824,"type":"change","change_id":67840100515,"instrument_name":"BTC-PERPETUAL","bids":[],"asks":[["delete",108134.0,0.0],["new",108157.5,7.087e6]],"prev_change_id":67840100294}}}
1761154821860 {"jsonrpc":"2.0","method":"subscription","params":{"channel":"book.ETH-PERPETUAL.raw","data":{"timestamp":1761154820220,"type":"change","change_id":46343801059,"instrument_name":"ETH-PERPETUAL","bids":[],"asks":[["change",3824.2,131210.0]],"prev_change_id":46343798163}}}
1761154821976 {"jsonrpc":"2.0","method":"subscription","params":{"channel":"book.ETH-PERPETUAL.raw","data":{"timestamp":1761154820328,"type":"change","change_id":46343801084,"instrument_name":"ETH-PERPETUAL","bids":[],"asks":[["change",3824.2,1912.0],["new",3826.9,1328.0]],"prev_change_id":46343801059}}}
1761154821981 {"jsonrpc":"2.0","method":"subscription","params":{"channel":"book.ETH-PERPETUAL.raw","data":{"timestamp":1761154820329,"type":"change","change_id":46343801085,"instrument_name":"ETH-PERPETUAL","bids":[["delete",3824.15,0.0],["new",3823.4,1926.0]],"asks":[],"prev_change_id":46343801084}}}
1761154822001 {"jsonrpc":"2.0","method":"subscription","params":{"channel":"book.BTC-PERPETUAL.raw","data":{"timestamp":1761154820352,"type":"change","change_id":67840101173,"instrument_name":"BTC-PERPETUAL","bids":[["change",107637.0,3.4e5],["delete",107268.5,0.0]],"asks":[],"prev_change_id":67840100515}}}
1761154822019 {"jsonrpc":"2.0","method":"subscription","params":{"channel":"book.ETH-PERPETUAL.raw","data":{"timestamp":1761154820369,"type":"change","change_id":46343801086,"instrument_name":"ETH-PERPETUAL","bids":[],"asks":[["delete",3824.25,0.0],["new",3826.7,6032.0]],"prev_change_id":46343801085}}}
1761154822030 {"jsonrpc":"2.0","method":"subscription","params":{"channel":"book.ETH-PERPETUAL.raw","data":{"timestamp":1761154820370,"type":"change","change_id":46343801087,"instrument_name":"ETH-PERPETUAL","bids":[["delete",3823.75,0.0],["new",3823.55,4439.0]],"asks":[],"prev_change_id":46343801086}}}
1761154822086 {"jsonrpc":"2.0","method":"subscription","params":{"channel":"book.ETH-PERPETUAL.raw","data":{"timestamp":1761154820414,"type":"change","change_id":46343801252,"instrument_name":"ETH-PERPETUAL","bids":[],"asks":[["delete",3824.3,0.0],["new",3826.6,3012.0]],"prev_change_id":46343801087}}}
1761154822096 {"jsonrpc":"2.0","method":"subscription","params":{"channel":"book.ETH-PERPETUAL.raw","data":{"timestamp":1761154820418,"type":"change","change_id":46343801254,"instrument_name":"ETH-PERPETUAL","bids":[["new",3823.6,21311.0],["delete",3823.25,0.0]],"asks":[],"prev_change_id":46343801252}}}
1761154822149 {"jsonrpc":"2.0","method":"subscription","params":{"channel":"book.ETH-PERPETUAL.raw","data":{"timestamp":1761154820454,"type":"change","change_id":46343801495,"instrument_name":"ETH-PERPETUAL","bids":[],"asks":[["delete",3824.35,0.0],["new",3826.55,10076.0]],"prev_change_id":46343801254}}}
1761154822154 {"jsonrpc":"2.0","method":"subscription","params":{"channel":"book.ETH-PERPETUAL.raw","data":{"timestamp":1761154820463,"type":"change","change_id":46343801503,"instrument_name":"ETH-PERPETUAL","bids":[["new",3823.7,8.0],["delete",3823.15,0.0]],"asks":[],"prev_change_id":46343801495}}}
1761154822159 {"jsonrpc":"2.0","method":"subscription","params":{"channel":"book.ETH-PERPETUAL.raw","data":{"timestamp":1761154820493,"type":"change","change_id":46343801520,"instrument_name":"ETH-PERPETUAL","bids":[],"asks":[["delete",3824.4,0.0],["new",3826.4,4445.0]],"prev_change_id":46343801503}}}
1761154822164 {"jsonrpc":"2.0","method":"subscription","params":{"channel":"book.ETH-PERPETUAL.raw","data":{"timestamp":1761154820502,"type":"change","change_id":46343801522,"instrument_name":"ETH-PERPETUAL","bids":[["new",3823.75,1650.0],["delete",3823.1,0.0]],"asks":[],"prev_change_id":46343801520}}}
1761154822243 {"jsonrpc":"2.0","method":"subscription","params":{"channel":"book.ETH-PERPETUAL.raw","data":{"timestamp":1761154820534,"type":"change","change_id":46343801667,"instrument_name":"ETH-PERPETUAL","bids":[],"asks":[["delete",3824.55,0.0],["change",3826.2,7006195.0]],"prev_change_id":46343801522}}}
1761154822255 {"jsonrpc":"2.0","method":"subscription","params":{"channel":"book.BTC-PERPETUAL.raw","data":{"timestamp":1761154820545,"type":"change","change_id":67840101516,"instrument_name":"BTC-PERPETUAL","bids":[["change",107637.0,6.6e5],["delete",107614.0,0.0]],"asks":[],"prev_change_id":67840101173}}}
1761154822284 {"jsonrpc":"2.0","method":"subscription","params":{"channel":"book.ETH-PERPETUAL.raw","data":{"timestamp":1761154820543,"type":"change","change_id":46343801668,"instrument_name":"ETH-PERPETUAL","bids":[["new",3823.8,4445.0],["delete",3823.0,0.0]],"asks":[],"prev_change_id":46343801667}}}
1761154822294 {"jsonrpc":"2.0","method":"subscription","params":{"channel":"book.ETH-PERPETUAL.raw","data":{"timestamp":1761154820574,"type":"change","change_id":46343801673,"instrument_name":"ETH-PERPETUAL","bids":[],"asks":[["change",3824.6,1912.0],["new",3826.15,4446.0]],"prev_change_id":46343801668}}}
1761154822302 {"jsonrpc":"2.0","method":"subscription","params":{"channel":"book.ETH-PERPETUAL.raw","data":{"timestamp":1761154820583,"type":"change","change_id":46343801674,"instrument_name":"ETH-PERPETUAL","bids":[["new",3823.85,16717.0],["delete",3822.9,0.0]],"asks":[],"prev_change_id":46343801673}}}
1761154822307 {"jsonrpc":"2.0","method":"subscription","params":{"channel":"book.ETH-PERPETUAL.raw","data":{"timestamp":1761154820614,"type":"change","change_id":46343801680,"instrument_name":"ETH-PERPETUAL","bids":[],"asks":[["delete",3824.75,0.0],["new",3826.1,1658.0]],"prev_change_id":46343801674}}}
1761154822311 {"jsonrpc":"2.0","method":"subscription","params":{"channel":"book.ETH-PERPETUAL.raw","data":{"timestamp":1761154820623,"type":"change","change_id":46343801681,"instrument_name":"ETH-PERPETUAL","bids":[["new",3823.9,4029.0],["delete",3822.85,0.0]],"asks":[],"prev_change_id":46343801680}}}
1761154822322 {"jsonrpc":"2.0","method":"subscription","params":{"channel":"book.ETH-PERPETUAL.raw","data":{"timestamp":1761154820655,"type":"change","change_id":46343801726,"instrument_name":"ETH-PERPETUAL","bids":[],"asks":[["delete",3825.0,0.0],["new",3826.05,15119.0]],"prev_change_id":46343801681}}}
1761154822330 {"jsonrpc":"2.0","method":"subscription","params":{"channel":"book.ETH-PERPETUAL.raw","data":{"timestamp":1761154820661,"type":"change","change_id":46343801727,"instrument_name":"ETH-PERPETUAL","bids":[["new",3824.1,16943.0],["delete",3822.8,0.0]],"asks":[],"prev_change_id":46343801726}}}
1761154822388 {"jsonrpc":"2.0","method":"subscription","params":{"channel":"book.ETH-PERPETUAL.raw","data":{"timestamp":1761154820696,"type":"change","change_id":46343801735,"instrument_name":"ETH-PERPETUAL","bids":[],"asks":[["delete",3825.05,0.0],["new",3826.0,38134.0]],"prev_change_id":46343801727}}}
1761154822394 {"jsonrpc":"2.0","method":"subscription","params":{"channel":"book.ETH-PERPETUAL.raw","data":{"timestamp":1761154820700,"type":"change","change_id":46343801736,"instrument_name":"ETH-PERPETUAL","bids":[["new",3824.15,3469.0],["delete",3822.75,0.0]],"asks":[],"prev_change_id":46343801735}}}
1761154822413 {"jsonrpc":"2.0","method":"subscription","params":{"channel":"book.ETH-PERPETUAL.raw","data":{"timestamp":1761154820737,"type":"change","change_id":46343801743,"instrument_name":"ETH-PERPETUAL","bids":[],"asks":[["delete",3825.15,0.0],["new",3825.85,7105.0]],"prev_change_id":46343801736}}}
1761154822418 {"jsonrpc":"2.0","method":"subscription","params":{"channel":"book.ETH-PERPETUAL.raw","data":{"timestamp":1761154820739,"type":"change","change_id":46343801744,"instrument_name":"ETH-PERPETUAL","bids":[["new",3824.25,13072.0],["delete",3822.65,0.0]],"asks":[["delete",3824.2,0.0]],"prev_change_id":46343801743}}}
1761154822422 {"jsonrpc":"2.0","method":"subscription","params":{"channel":"trades.ETH-PERPETUAL.raw","data":[{"timestamp":1761154820739,"price":3824.2,"direction":"buy","index_price":3825.72,"instrument_name":"ETH-PERPETUAL","trade_seq":24030123,"amount":1912.0,"mark_price":3824.79,"tick_direction":2,"trade_id":"ETH-43543883","contracts":1912.0}]}}
1761154822453 {"jsonrpc":"2.0","method":"subscription","params":{"channel":"book.ETH-PERPETUAL.raw","data":{"timestamp":1761154820777,"type":"change","change_id":46343801825,"instrument_name":"ETH-PERPETUAL","bids":[],"asks":[["delete",3825.2,0.0],["change",3825.8,77327.0]],"prev_change_id":46343801744}}}
1761154822459 {"jsonrpc":"2.0","method":"subscription","params":{"channel":"book.ETH-PERPETUAL.raw","data":{"timestamp":1761154820779,"type":"change","change_id":46343801826,"instrument_name":"ETH-PERPETUAL","bids":[["new",3824.3,1650.0],["delete",3822.6,0.0]],"asks":[],"prev_change_id":46343801825}}}
1761154822507 {"jsonrpc":"2.0","method":"subscription","params":{"channel":"book.ETH-PERPETUAL.raw","data":{"timestamp":1761154820820,"type":"change","change_id":46343801836,"instrument_name":"ETH-PERPETUAL","bids":[],"asks":[["delete",3825.3,0.0],["change",3825.75,34496.0]],"prev_change_id":46343801826}}}
1761154822511 {"jsonrpc":"2.0","method":"subscription","params":{"channel":"book.ETH-PERPETUAL.raw","data":{"timestamp":1761154820821,"type":"change","change_id":46343801838,"instrument_name":"ETH-PERPETUAL","bids":[["new",3824.35,5483.0],["delete",3822.4,0.0]],"asks":[],"prev_change_id":46343801836}}}
1761154822542 {"jsonrpc":"2.0","method":"subscription","params":{"channel":"book.ETH-PERPETUAL.raw","data":{"timestamp":1761154820861,"type":"change","change_id":46343801847,"instrument_name":"ETH-PERPETUAL","bids":[],"asks":[["delete",3825.4,0.0],["change",3825.7,13557.0]],"prev_change_id":46343801838}}}
1761154822549 {"jsonrpc":"2.0","method":"subscription","params":{"channel":"book.ETH-PERPETUAL.raw","data":{"timestamp":1761154820862,"type":"change","change_id":46343801848,"instrument_name":"ETH-PERPETUAL","bids":[["new",3824.4,19994.0],["delete",3822.3,0.0]],"asks":[],"prev_change_id":46343801847}}}
1761154822586 {"jsonrpc":"2.0","method":"subscription","params":{"channel":"book.ETH-PERPETUAL.raw","data":{"timestamp":1761154820902,"type":"change","change_id":46343801857,"instrument_name":"ETH-PERPETUAL","bids":[],"asks":[["delete",3825.45,0.0],["new",3825.5,6.0]],"prev_change_id":46343801848}}}
1761154822592 {"jsonrpc":"2.0","method":"subscription","params":{"channel":"book.ETH-PERPETUAL.raw","data":{"timestamp":1761154820903,"type":"change","change_id":46343801858,"instrument_name":"ETH-PERPETUAL","bids":[["new",3824.55,5968.0],["delete",3822.25,0.0]],"asks":[],"prev_change_id":46343801857}}}
1761154822629 {"jsonrpc":"2.0","method":"subscription","params":{"channel":"book.ETH-PERPETUAL.raw","data":{"timestamp":1761154820942,"type":"change","change_id":46343802015,"instrument_name":"ETH-PERPETUAL","bids":[],"asks":[["new",3825.45,11172.0],["delete",3825.6,0.0]],"prev_change_id":46343801858}}}
1761154822634 {"jsonrpc":"2.0","method":"subscription","params":{"channel":"book.ETH-PERPETUAL.raw","data":{"timestamp":1761154820943,"type":"change","change_id":46343802016,"instrument_name":"ETH-PERPETUAL","bids":[["new",3824.6,7788.0],["delete",3822.15,0.0]],"asks":[["delete",3824.6,0.0]],"prev_change_id":46343802015}}}
1761154822639 {"jsonrpc":"2.0","method":"subscription","params":{"channel":"trades.ETH-PERPETUAL.raw","data":[{"timestamp":1761154820943,"price":3824.6,"direction":"buy","index_price":3825.72,"instrument_name":"ETH-PERPETUAL","trade_seq":24030124,"amount":1912.0,"mark_price":3824.79,"tick_direction":0,"trade_id":"ETH-43543884","contracts":1912.0}]}}
1761154822675 {"jsonrpc":"2.0","method":"subscription","params":{"channel":"book.ETH-PERPETUAL.raw","data":{"timestamp":1761154820982,"type":"change","change_id":46343802029,"instrument_name":"ETH-PERPETUAL","bids":[],"asks":[["new",3825.4,3285.0],["delete",3825.65,0.0]],"prev_change_id":46343802016}}}
1761154822681 {"jsonrpc":"2.0","method":"subscription","params":{"channel":"book.ETH-PERPETUAL.raw","data":{"timestamp":1761154820983,"type":"change","change_id":46343802030,"instrument_name":"ETH-PERPETUAL","bids":[["new",3824.65,9.7e3],["delete",3822.1,0.0]],"asks":[],"prev_change_id":46343802029}}}
1761154822784 {"jsonrpc":"2.0","method":"subscription","params":{"channel":"book.ETH-PERPETUAL.raw","data":{"timestamp":1761154821023,"type":"change","change_id":46343802097,"instrument_name":"ETH-PERPETUAL","bids":[],"asks":[["new",3825.3,5.0e4],["change",3825.7,5289.0]],"prev_change_id":46343802030}}}
1761154822791 {"jsonrpc":"2.0","method":"subscription","params":{"channel":"book.ETH-PERPETUAL.raw","data":{"timestamp":1761154821024,"type":"change","change_id":46343802098,"instrument_name":"ETH-PERPETUAL","bids":[["new",3824.75,4009.0],["delete",3822.05,0.0]],"asks":[],"prev_change_id":46343802097}}}
1761154822800 {"jsonrpc":"2.0","method":"subscription","params":{"channel":"book.ETH-PERPETUAL.raw","data":{"timestamp":1761154821066,"type":"change","change_id":46343802111,"instrument_name":"ETH-PERPETUAL","bids":[],"asks":[["new",3825.25,18985.0],["change",3825.75,16717.0]],"prev_change_id":46343802098}}}
1761154822813 {"jsonrpc":"2.0","method":"subscription","params":{"channel":"book.ETH-PERPETUAL.raw","data":{"timestamp":1761154821067,"type":"change","change_id":46343802112,"instrument_name":"ETH-PERPETUAL","bids":[["new",3824.85,1.0e3],["delete",3821.9,0.0]],"asks":[],"prev_change_id":46343802111}}}
1761154822909 {"jsonrpc":"2.0","method":"subscription","params":{"channel":"book.ETH-PERPETUAL.raw","data":{"timestamp":1761154821106,"type":"change","change_id":46343802126,"instrument_name":"ETH-PERPETUAL","bids":[],"asks":[["new",3825.0,4010.0],["change",3825.8,1.0e3]],"prev_change_id":46343802112}}}
1761154822919 {"jsonrpc":"2.0","method":"subscription","params":{"channel":"book.ETH-PERPETUAL.raw","data":{"timestamp":1761154821107,"type":"change","change_id":46343802127,"instrument_name":"ETH-PERPETUAL","bids":[["new",3824.9,29214.0],["delete",3821.85,0.0]],"asks":[],"prev_change_id":46343802126}}}
1761154823093 {"jsonrpc":"2.0","method":"subscription","params":{"channel":"book.ETH-PERPETUAL.raw","data":{"timestamp":1761154821268,"type":"change","change_id":46343802415,"instrument_name":"ETH-PERPETUAL","bids":[["new",3807.0,3.2e5],["delete",3806.9,0.0]],"asks":[],"prev_change_id":46343802127}}}
1761154823790 {"jsonrpc":"2.0","method":"subscription","params":{"channel":"book.BTC-PERPETUAL.raw","data":{"timestamp":1761154822036,"type":"change","change_id":67840103060,"instrument_name":"BTC-PERPETUAL","bids":[],"asks":[["delete",107870.0,0.0],["new",107932.5,2360.0]],"prev_change_id":67840101516}}}
1761154823796 {"jsonrpc":"2.0","method":"subscription","params":{"channel":"book.BTC-PERPETUAL.raw","data":{"timestamp":1761154822037,"type":"change","change_id":67840103061,"instrument_name":"BTC-PERPETUAL","bids":[["delete",107869.5,0.0],["new",107863.5,50010.0]],"asks":[],"prev_change_id":67840103060}}}
1761154823833 {"jsonrpc":"2.0","method":"subscription","params":{"channel":"book.BTC-PERPETUAL.raw","data":{"timestamp":1761154822075,"type":"change","change_id":67840103062,"instrument_name":"BTC-PERPETUAL","bids":[],"asks":[["delete",107872.5,0.0],["new",107932.0,1.1e4]],"prev_change_id":67840103061}}}
1761154823839 {"jsonrpc":"2.0","method":"subscription","params":{"channel":"book.BTC-PERPETUAL.raw","data":{"timestamp":1761154822077,"type":"change","change_id":67840103063,"instrument_name":"BTC-PERPETUAL","bids":[["delete",107869.0,0.0],["new",107864.0,13840.0]],"asks":[],"prev_change_id":67840103062}}}
1761154823874 {"jsonrpc":"2.0","method":"subscription","params":{"channel":"book.BTC-PERPETUAL.raw","data":{"timestamp":1761154822115,"type":"change","change_id":67840103064,"instrument_name":"BTC-PERPETUAL","bids":[],"asks":[["delete",107873.0,0.0],["new",107929.5,1.0e3]],"prev_change_id":67840103063}}}
1761154823884 {"jsonrpc":"2.0","method":"subscription","params":{"channel":"book.BTC-PERPETUAL.raw","data":{"timestamp":1761154822117,"type":"change","change_id":67840103065,"instrument_name":"BTC-PERPETUAL","bids":[["new",107865.0,25090.0],["delete",107862.5,0.0]],"asks":[],"prev_change_id":67840103064}}}
1761154823922 {"jsonrpc":"2.0","method":"subscription","params":{"channel":"book.BTC-PERPETUAL.raw","data":{"timestamp":1761154822156,"type":"change","change_id":67840103067,"instrument_name":"BTC-PERPETUAL","bids":[],"asks":[["delete",107873.5,0.0],["new",107929.0,6.9e3]],"prev_change_id":67840103065}}}
1761154823927 {"jsonrpc":"2.0","method":"subscription","params":{"channel":"book.BTC-PERPETUAL.raw","data":{"timestamp":1761154822158,"type":"change","change_id":67840103069,"instrument_name":"BTC-PERPETUAL","bids":[["new",107871.0,33260.0],["delete",107862.0,0.0]],"asks":[],"prev_change_id":67840103067}}}
1761154823964 {"jsonrpc":"2.0","method":"subscription","params":{"channel":"book.BTC-PERPETUAL.raw","data":{"timestamp":1761154822195,"type":"change","change_id":67840103072,"instrument_name":"BTC-PERPETUAL","bids":[],"asks":[["delete",107874.0,0.0],["new",107928.0,1.1e4]],"prev_change_id":67840103069}}}
1761154823969 {"jsonrpc":"2.0","method":"subscription","params":{"channel":"book.BTC-PERPETUAL.raw","data":{"timestamp":1761154822200,"type":"change","change_id":67840103074,"instrument_name":"BTC-PERPETUAL","bids":[["new",107871.5,16120.0],["delete",107861.5,0.0]],"asks":[],"prev_change_id":67840103072}}}
1761154824003 {"jsonrpc":"2.0","method":"subscription","params":{"channel":"book.BTC-PERPETUAL.raw","data":{"timestamp":1761154822235,"type":"change","change_id":67840103430,"instrument_name":"BTC-PERPETUAL","bids":[],"asks":[["delete",107875.5,0.0],["new",107927.5,8.2e3]],"prev_change_id":67840103074}}}
1761154824009 {"jsonrpc":"2.0","method":"subscription","params":{"channel":"book.BTC-PERPETUAL.raw","data":{"timestamp":1761154822241,"type":"change","change_id":67840103527,"instrument_name":"BTC-PERPETUAL","bids":[["new",107872.0,5.0e3],["delete",107861.0,0.0]],"asks":[],"prev_change_id":67840103430}}}
1761154824045 {"jsonrpc":"2.0","method":"subscription","params":{"channel":"book.BTC-PERPETUAL.raw","data":{"timestamp":1761154822276,"type":"change","change_id":67840103531,"instrument_name":"BTC-PERPETUAL","bids":[],"asks":[["delete",107877.5,0.0],["new",107925.0,8690.0]],"prev_change_id":67840103527}}}
1761154824049 {"jsonrpc":"2.0","method":"subscription","params":{"channel":"book.BTC-PERPETUAL.raw","data":{"timestamp":1761154822281,"type":"change","change_id":67840103535,"instrument_name":"BTC-PERPETUAL","bids":[["new",107873.0,2.5e4],["delete",107860.5,0.0]],"asks":[],"prev_change_id":67840103531}}}
1761154824087 {"jsonrpc":"2.0","method":"subscription","params":{"channel":"book.BTC-PERPETUAL.raw","data":{"timestamp":1761154822315,"type":"change","change_id":67840103569,"instrument_name":"BTC-PERPETUAL","bids":[],"asks":[["delete",107880.0,0.0],["new",107924.0,2.1e3]],"prev_change_id":67840103535}}}
1761154824096 {"jsonrpc":"2.0","method":"subscription","params":{"channel":"book.BTC-PERPETUAL.raw","data":{"timestamp":1761154822321,"type":"change","change_id":67840103573,"instrument_name":"BTC-PERPETUAL","bids":[["new",107875.0,2.1e3],["delete",107858.5,0.0]],"asks":[],"prev_change_id":67840103569}}}
1761154824132 {"jsonrpc":"2.0","method":"subscription","params":{"channel":"book.BTC-PERPETUAL.raw","data":{"timestamp":1761154822354,"type":"change","change_id":67840103576,"instrument_name":"BTC-PERPETUAL","bids":[],"asks":[["delete",107880.5,0.0],["change",107923.5,5626750.0]],"prev_change_id":67840103573}}}
1761154824140 {"jsonrpc":"2.0","method":"subscription","params":{"channel":"book.BTC-PERPETUAL.raw","data":{"timestamp":1761154822363,"type":"change","change_id":67840103737,"instrument_name":"BTC-PERPETUAL","bids":[["new",107876.0,2120.0],["delete",107855.0,0.0]],"asks":[],"prev_change_id":67840103576}}}
1761154824170 {"jsonrpc":"2.0","method":"subscription","params":{"channel":"book.BTC-PERPETUAL.raw","data":{"timestamp":1761154822393,"type":"change","change_id":67840103843,"instrument_name":"BTC-PERPETUAL","bids":[],"asks":[["delete",107882.5,0.0],["new",107923.0,8440.0]],"prev_change_id":67840103737}}}
1761154824182 {"jsonrpc":"2.0","method":"subscription","params":{"channel":"book.BTC-PERPETUAL.raw","data":{"timestamp":1761154822404,"type":"change","change_id":67840103853,"instrument_name":"BTC-PERPETUAL","bids":[["new",107877.5,5.03e4],["delete",107850.5,0.0]],"asks":[],"prev_change_id":67840103843}}}
1761154824221 {"jsonrpc":"2.0","method":"subscription","params":{"channel":"book.BTC-PERPETUAL.raw","data":{"timestamp":1761154822442,"type":"change","change_id":67840103859,"instrument_name":"BTC-PERPETUAL","bids":[],"asks":[["delete",107887.0,0.0],["new",107922.5,2.5e4]],"prev_change_id":67840103853}}}
1761154824234 {"jsonrpc":"2.0","method":"subscription","params":{"channel":"book.BTC-PERPETUAL.raw","data":{"timestamp":1761154822451,"type":"change","change_id":67840103863,"instrument_name":"BTC-PERPETUAL","bids":[["new",107878.0,20990.0],["delete",107850.0,0.0]],"asks":[],"prev_change_id":67840103859}}}
1761154824269 {"jsonrpc":"2.0","method":"subscription","params":{"channel":"book.BTC-PERPETUAL.raw","data":{"timestamp":1761154822485,"type":"change","change_id":67840103967,"instrument_name":"BTC-PERPETUAL","bids":[],"asks":[["delete",107887.5,0.0],["new",107922.0,13650.0]],"prev_change_id":67840103863}}}
1761154824275 {"jsonrpc":"2.0","method":"subscription","params":{"channel":"book.BTC-PERPETUAL.raw","data":{"timestamp":1761154822493,"type":"change","change_id":67840103971,"instrument_name":"BTC-PERPETUAL","bids":[["new",107880.0,8650.0],["delete",107849.5,0.0]],"asks":[],"prev_change_id":67840103967}}}
1761154824309 {"jsonrpc":"2.0","method":"subscription","params":{"channel":"book.BTC-PERPETUAL.raw","data":{"timestamp":1761154822524,"type":"change","change_id":67840103985,"instrument_name":"BTC-PERPETUAL","bids":[],"asks":[["delete",107888.0,0.0],["new",107919.0,1.0e4]],"prev_change_id":67840103971}}}
1761154824317 {"jsonrpc":"2.0","method":"subscription","params":{"channel":"book.BTC-PERPETUAL.raw","data":{"timestamp":1761154822532,"type":"change","change_id":67840103989,"instrument_name":"BTC-PERPETUAL","bids":[["new",107882.5,18970.0],["delete",107849.0,0.0]],"asks":[],"prev_change_id":67840103985}}}
1761154824351 {"jsonrpc":"2.0","method":"subscription","params":{"channel":"book.BTC-PERPETUAL.raw","data":{"timestamp":1761154822563,"type":"change","change_id":67840104147,"instrument_name":"BTC-PERPETUAL","bids":[],"asks":[["delete",107888.5,0.0],["new",107918.5,2990.0]],"prev_change_id":67840103989}}}
1761154824359 {"jsonrpc":"2.0","method":"subscription","params":{"channel":"book.BTC-PERPETUAL.raw","data":{"timestamp":1761154822572,"type":"change","change_id":67840104151,"instrument_name":"BTC-PERPETUAL","bids":[["new",107885.0,5.0e4],["delete",107847.5,0.0]],"asks":[],"prev_change_id":67840104147}}}
1761154824394 {"jsonrpc":"2.0","method":"subscription","params":{"channel":"book.BTC-PERPETUAL.raw","data":{"timestamp":1761154822605,"type":"change","change_id":67840104157,"instrument_name":"BTC-PERPETUAL","bids":[],"asks":[["delete",107889.5,0.0],["new",107915.0,6.0e3]],"prev_change_id":67840104151}}}
1761154824403 {"jsonrpc":"2.0","method":"subscription","params":{"channel":"book.BTC-PERPETUAL.raw","data":{"timestamp":1761154822612,"type":"change","change_id":67840104161,"instrument_name":"BTC-PERPETUAL","bids":[["new",107887.0,2.1e3],["delete",107846.5,0.0]],"asks":[],"prev_change_id":67840104157}}}
1761154824437 {"jsonrpc":"2.0","method":"subscription","params":{"channel":"book.BTC-PERPETUAL.raw","data":{"timestamp":1761154822645,"type":"change","change_id":67840104181,"instrument_name":"BTC-PERPETUAL","bids":[],"asks":[["delete",107892.5,0.0],["new",107914.5,1790.0]],"prev_change_id":67840104161}}}
1761154824444 {"jsonrpc":"2.0","method":"subscription","params":{"channel":"book.BTC-PERPETUAL.raw","data":{"timestamp":1761154822651,"type":"change","change_id":67840104191,"instrument_name":"BTC-PERPETUAL","bids":[["new",107887.5,9230.0],["delete",107845.0,0.0]],"asks":[],"prev_change_id":67840104181}}}
1761154824482 {"jsonrpc":"2.0","method":"subscription","params":{"channel":"book.BTC-PERPETUAL.raw","data":{"timestamp":1761154822684,"type":"change","change_id":67840104204,"instrument_name":"BTC-PERPETUAL","bids":[],"asks":[["delete",107893.5,0.0],["new",107904.5,3.2e4]],"prev_change_id":67840104191}}}
1761154824487 {"jsonrpc":"2.0","method":"subscription","params":{"channel":"book.BTC-PERPETUAL.raw","data":{"timestamp":1761154822692,"type":"change","change_id":67840104210,"instrument_name":"BTC-PERPETUAL","bids":[["new",107888.0,17870.0],["delete",107841.5,0.0]],"asks":[],"prev_change_id":67840104204}}}
1761154824522 {"jsonrpc":"2.0","method":"subscription","params":{"channel":"book.BTC-PERPETUAL.raw","data":{"timestamp":1761154822726,"type":"change","change_id":67840104244,"instrument_name":"BTC-PERPETUAL","bids":[],"asks":[["delete",107894.5,0.0],["new",107900.5,1.8e3]],"prev_change_id":67840104210}}}
1761154824533 {"jsonrpc":"2.0","method":"subscription","params":{"channel":"book.BTC-PERPETUAL.raw","data":{"timestamp":1761154822732,"type":"change","change_id":67840104251,"instrument_name":"BTC-PERPETUAL","bids":[["new",107892.0,20.0],["delete",107841.0,0.0]],"asks":[],"prev_change_id":67840104244}}}
1761154824575 {"jsonrpc":"2.0","method":"subscription","params":{"channel":"book.BTC-PERPETUAL.raw","data":{"timestamp":1761154822771,"type":"change","change_id":67840104257,"instrument_name":"BTC-PERPETUAL","bids":[],"asks":[["delete",107897.5,0.0],["new",1.079e5,20.0]],"prev_change_id":67840104251}}}
1761154824580 {"jsonrpc":"2.0","method":"subscription","params":{"channel":"book.BTC-PERPETUAL.raw","data":{"timestamp":1761154822776,"type":"change","change_id":67840104265,"instrument_name":"BTC-PERPETUAL","bids":[["new",107892.5,94920.0],["delete",107839.0,0.0]],"asks":[],"prev_change_id":67840104257}}}
1761154824614 {"jsonrpc":"2.0","method":"subscription","params":{"channel":"book.BTC-PERPETUAL.raw","data":{"timestamp":1761154822811,"type":"change","change_id":67840104271,"instrument_name":"BTC-PERPETUAL","bids":[],"asks":[["new",107893.5,5.6e3],["delete",107898.5,0.0]],"prev_change_id":67840104265}}}
1761154824620 {"jsonrpc":"2.0","method":"subscription","params":{"channel":"book.BTC-PERPETUAL.raw","data":{"timestamp":1761154822818,"type":"change","change_id":67840104299,"instrument_name":"BTC-PERPETUAL","bids":[["new",107893.0,403490.0],["delete",107837.5,0.0]],"asks":[],"prev_change_id":67840104271}}}
1761154824655 {"jsonrpc":"2.0","method":"subscription","params":{"channel":"book.ETH-PERPETUAL.raw","data":{"timestamp":1761154822849,"type":"change","change_id":46343804429,"instrument_name":"ETH-PERPETUAL","bids":[],"asks":[["change",3826.2,34126.0],["new",3827.25,6972069.0]],"prev_change_id":46343802415}}}
1761154825587 {"jsonrpc":"2.0","method":"subscription","params":{"channel":"book.ETH-PERPETUAL.raw","data":{"timestamp":1761154823674,"type":"change","change_id":46343805543,"instrument_name":"ETH-PERPETUAL","bids":[],"asks":[["new",3824.95,733.0]],"prev_change_id":46343804429}}}
1761154827353 {"jsonrpc":"2.0","method":"subscription","params":{"channel":"book.BTC-PERPETUAL.raw","data":{"timestamp":1761154825367,"type":"change","change_id":67840107636,"instrument_name":"BTC-PERPETUAL","bids":[["new",107839.5,6462890.0],["delete",107816.0,0.0]],"asks":[],"prev_change_id":67840104299}}}
1761154827502 {"jsonrpc":"2.0","method":"subscription","params":{"channel":"book.ETH-PERPETUAL.raw","data":{"timestamp":1761154825525,"type":"change","change_id":46343807670,"instrument_name":"ETH-PERPETUAL","bids":[["change",3817.3,1.05e5],["change",3806.95,3.2e5]],"asks":[],"prev_change_id":46343805543}}}
1761154827553 {"jsonrpc":"2.0","method":"subscription","params":{"channel":"book.ETH-PERPETUAL.raw","data":{"timestamp":1761154825579,"type":"change","change_id":46343807780,"instrument_name":"ETH-PERPETUAL","bids":[],"asks":[["delete",3825.0,0.0],["new",3827.1,1584.0]],"prev_change_id":46343807670}}}
1761154827559 {"jsonrpc":"2.0","method":"subscription","params":{"channel":"book.ETH-PERPETUAL.raw","data":{"timestamp":1761154825580,"type":"change","change_id":46343807781,"instrument_name":"ETH-PERPETUAL","bids":[["delete",3824.9,0.0],["change",3823.6,22636.0]],"asks":[],"prev_change_id":46343807780}}}
1761154827596 {"jsonrpc":"2.0","method":"subscription","params":{"channel":"book.ETH-PERPETUAL.raw","data":{"timestamp":1761154825619,"type":"change","change_id":46343807782,"instrument_name":"ETH-PERPETUAL","bids":[],"asks":[["delete",3825.25,0.0],["new",3826.95,37796.0]],"prev_change_id":46343807781}}}
1761154827602 {"jsonrpc":"2.0","method":"subscription","params":{"channel":"book.ETH-PERPETUAL.raw","data":{"timestamp":1761154825621,"type":"change","change_id":46343807783,"instrument_name":"ETH-PERPETUAL","bids":[["delete",3824.85,0.0],["change",3823.7,16.0]],"asks":[],"prev_change_id":46343807782}}}
1761154827640 {"jsonrpc":"2.0","method":"subscription","params":{"channel":"book.ETH-PERPETUAL.raw","data":{"timestamp":1761154825660,"type":"change","change_id":46343807825,"instrument_name":"ETH-PERPETUAL","bids":[],"asks":[["delete",3825.3,0.0],["change",3826.9,12440.0]],"prev_change_id":46343807783}}}
1761154827645 {"jsonrpc":"2.0","method":"subscription","params":{"channel":"book.ETH-PERPETUAL.raw","data":{"timestamp":1761154825661,"type":"change","change_id":46343807826,"instrument_name":"ETH-PERPETUAL","bids":[["delete",3824.75,0.0],["change",3823.75,3.3e3]],"asks":[],"prev_change_id":46343807825}}}
1761154827684 {"jsonrpc":"2.0","method":"subscription","params":{"channel":"book.ETH-PERPETUAL.raw","data":{"timestamp":1761154825702,"type":"change","change_id":46343807828,"instrument_name":"ETH-PERPETUAL","bids":[],"asks":[["delete",3825.4,0.0],["new",3826.85,1211.0]],"prev_change_id":46343807826}}}
1761154827691 {"jsonrpc":"2.0","method":"subscription","params":{"channel":"book.BTC-PERPETUAL.raw","data":{"timestamp":1761154825703,"type":"change","change_id":67840107975,"instrument_name":"BTC-PERPETUAL","bids":[],"asks":[["change",107923.5,1.0e3],["new",107947.0,5625750.0]],"prev_change_id":67840107636}}}
1761154827694 {"jsonrpc":"2.0","method":"subscription","params":{"channel":"book.ETH-PERPETUAL.raw","data":{"timestamp":1761154825704,"type":"change","change_id":46343807830,"instrument_name":"ETH-PERPETUAL","bids":[["delete",3824.65,0.0],["change",3823.8,8890.0]],"asks":[],"prev_change_id":46343807828}}}
1761154827730 {"jsonrpc":"2.0","method":"subscription","params":{"channel":"book.ETH-PERPETUAL.raw","data":{"timestamp":1761154825742,"type":"change","change_id":46343807832,"instrument_name":"ETH-PERPETUAL","bids":[],"asks":[["delete",3825.45,0.0],["change",3826.7,22141.0]],"prev_change_id":46343807830}}}
1761154827735 {"jsonrpc":"2.0","method":"subscription","params":{"channel":"book.ETH-PERPETUAL.raw","data":{"timestamp":1761154825745,"type":"change","change_id":46343807834,"instrument_name":"ETH-PERPETUAL","bids":[["delete",3824.6,0.0],["change",3823.85,34791.0]],"asks":[],"prev_change_id":46343807832}}}
1761154827770 {"jsonrpc":"2.0","method":"subscription","params":{"channel":"book.ETH-PERPETUAL.raw","data":{"timestamp":1761154825782,"type":"change","change_id":46343807910,"instrument_name":"ETH-PERPETUAL","bids":[],"asks":[["delete",3825.5,0.0],["change",3826.6,4813.0]],"prev_change_id":46343807834}}}
1761154827776 {"jsonrpc":"2.0","method":"subscription","params":{"channel":"book.ETH-PERPETUAL.raw","data":{"timestamp":1761154825787,"type":"change","change_id":46343807912,"instrument_name":"ETH-PERPETUAL","bids":[["delete",3824.55,0.0],["change",3823.9,5848.0]],"asks":[],"prev_change_id":46343807910}}}
1761154827826 {"jsonrpc":"2.0","method":"subscription","params":{"channel":"book.ETH-PERPETUAL.raw","data":{"timestamp":1761154825824,"type":"change","change_id":46343807916,"instrument_name":"ETH-PERPETUAL","bids":[],"asks":[["delete",3825.7,0.0],["change",3826.55,26793.0]],"prev_change_id":46343807912}}}
1761154827833 {"jsonrpc":"2.0","method":"subscription","params":{"channel":"book.ETH-PERPETUAL.raw","data":{"timestamp":1761154825828,"type":"change","change_id":46343807918,"instrument_name":"ETH-PERPETUAL","bids":[["delete",3824.4,0.0],["new",3824.05,15388.0]],"asks":[],"prev_change_id":46343807916}}}
1761154827856 {"jsonrpc":"2.0","method":"subscription","params":{"channel":"book.ETH-PERPETUAL.raw","data":{"timestamp":1761154825863,"type":"change","change_id":46343807922,"instrument_name":"ETH-PERPETUAL","bids":[],"asks":[["delete",3825.75,0.0],["new",3826.5,19829.0]],"prev_change_id":46343807918}}}
1761154827862 {"jsonrpc":"2.0","method":"subscription","params":{"channel":"book.ETH-PERPETUAL.raw","data":{"timestamp":1761154825868,"type":"change","change_id":46343807924,"instrument_name":"ETH-PERPETUAL","bids":[["delete",3824.35,0.0],["change",3824.1,21386.0]],"asks":[],"prev_change_id":46343807922}}}
1761154827903 {"jsonrpc":"2.0","method":"subscription","params":{"channel":"book.ETH-PERPETUAL.raw","data":{"timestamp":1761154825904,"type":"change","change_id":46343807928,"instrument_name":"ETH-PERPETUAL","bids":[],"asks":[["delete",3825.8,0.0],["new",3826.45,1320.0]],"prev_change_id":46343807924}}}
1761154827909 {"jsonrpc":"2.0","method":"subscription","params":{"channel":"book.ETH-PERPETUAL.raw","data":{"timestamp":1761154825910,"type":"change","change_id":46343807930,"instrument_name":"ETH-PERPETUAL","bids":[["delete",3824.3,0.0],["change",3824.15,15969.0]],"asks":[],"prev_change_id":46343807928}}}
1761154827943 {"jsonrpc":"2.0","method":"subscription","params":{"channel":"book.ETH-PERPETUAL.raw","data":{"timestamp":1761154825946,"type":"change","change_id":46343808082,"instrument_name":"ETH-PERPETUAL","bids":[],"asks":[["delete",3825.85,0.0],["new",3826.3,1650.0]],"prev_change_id":46343807930}}}
1761154827948 {"jsonrpc":"2.0","method":"subscription","params":{"channel":"book.ETH-PERPETUAL.raw","data":{"timestamp":1761154825949,"type":"change","change_id":46343808085,"instrument_name":"ETH-PERPETUAL","bids":[["delete",3824.25,0.0]],"asks":[],"prev_change_id":46343808082}}}
1761154827989 {"jsonrpc":"2.0","method":"subscription","params":{"channel":"book.ETH-PERPETUAL.raw","data":{"timestamp":1761154825987,"type":"change","change_id":46343808090,"instrument_name":"ETH-PERPETUAL","bids":[],"asks":[["delete",3826.0,0.0],["new",3826.25,4449.0]],"prev_change_id":46343808085}}}
1761154827995 {"jsonrpc":"2.0","method":"subscription","params":{"channel":"book.ETH-PERPETUAL.raw","data":{"timestamp":1761154825990,"type":"change","change_id":46343808093,"instrument_name":"ETH-PERPETUAL","bids":[["new",3824.35,15129.0],["change",3824.15,1.25e4]],"asks":[],"prev_change_id":46343808090}}}
1761154828030 {"jsonrpc":"2.0","method":"subscription","params":{"channel":"book.ETH-PERPETUAL.raw","data":{"timestamp":1761154826027,"type":"change","change_id":46343808154,"instrument_name":"ETH-PERPETUAL","bids":[],"asks":[["delete",3826.05,0.0],["change",3826.2,34349.0]],"prev_change_id":46343808093}}}
1761154828037 {"jsonrpc":"2.0","method":"subscription","params":{"channel":"book.ETH-PERPETUAL.raw","data":{"timestamp":1761154826030,"type":"change","change_id":46343808157,"instrument_name":"ETH-PERPETUAL","bids":[["new",3824.4,12783.0],["change",3824.1,4443.0]],"asks":[],"prev_change_id":46343808154}}}
1761154828074 {"jsonrpc":"2.0","method":"subscription","params":{"channel":"book.ETH-PERPETUAL.raw","data":{"timestamp":1761154826068,"type":"change","change_id":46343808165,"instrument_name":"ETH-PERPETUAL","bids":[],"asks":[["change",3826.1,4422.0]],"prev_change_id":46343808157}}}
1761154828079 {"jsonrpc":"2.0","method":"subscription","params":{"channel":"book.ETH-PERPETUAL.raw","data":{"timestamp":1761154826071,"type":"change","change_id":46343808168,"instrument_name":"ETH-PERPETUAL","bids":[["new",3824.55,1708.0],["change",3823.9,1819.0]],"asks":[],"prev_change_id":46343808165}}}
1761154828117 {"jsonrpc":"2.0","method":"subscription","params":{"channel":"book.ETH-PERPETUAL.raw","data":{"timestamp":1761154826109,"type":"change","change_id":46343808175,"instrument_name":"ETH-PERPETUAL","bids":[],"asks":[["new",3826.05,4441.0],["delete",3826.15,0.0]],"prev_change_id":46343808168}}}
1761154828126 {"jsonrpc":"2.0","method":"subscription","params":{"channel":"book.ETH-PERPETUAL.raw","data":{"timestamp":1761154826111,"type":"change","change_id":46343808178,"instrument_name":"ETH-PERPETUAL","bids":[["new",3824.6,16717.0],["change",3823.85,18074.0]],"asks":[],"prev_change_id":46343808175}}}
1761154828158 {"jsonrpc":"2.0","method":"subscription","params":{"channel":"book.ETH-PERPETUAL.raw","data":{"timestamp":1761154826149,"type":"change","change_id":46343808295,"instrument_name":"ETH-PERPETUAL","bids":[],"asks":[["new",3826.0,19453.0],["change",3826.2,223.0]],"prev_change_id":46343808178}}}
1761154828170 {"jsonrpc":"2.0","method":"subscription","params":{"channel":"book.ETH-PERPETUAL.raw","data":{"timestamp":1761154826151,"type":"change","change_id":46343808298,"instrument_name":"ETH-PERPETUAL","bids":[["new",3824.65,2.2e4],["change",3823.8,4445.0]],"asks":[],"prev_change_id":46343808295}}}
1761154828211 {"jsonrpc":"2.0","method":"subscription","params":{"channel":"book.ETH-PERPETUAL.raw","data":{"timestamp":1761154826191,"type":"change","change_id":46343808432,"instrument_name":"ETH-PERPETUAL","bids":[],"asks":[["new",3825.8,6573.0],["delete",3826.4,0.0]],"prev_change_id":46343808298}}}
1761154828217 {"jsonrpc":"2.0","method":"subscription","params":{"channel":"book.ETH-PERPETUAL.raw","data":{"timestamp":1761154826194,"type":"change","change_id":46343808435,"instrument_name":"ETH-PERPETUAL","bids":[["new",3824.8,10794.0],["change",3823.75,1650.0]],"asks":[],"prev_change_id":46343808432}}}
1761154828249 {"jsonrpc":"2.0","method":"subscription","params":{"channel":"book.ETH-PERPETUAL.raw","data":{"timestamp":1761154826233,"type":"change","change_id":46343808444,"instrument_name":"ETH-PERPETUAL","bids":[],"asks":[["new",3825.75,6.2e4],["change",3826.55,16717.0]],"prev_change_id":46343808435}}}
1761154828255 {"jsonrpc":"2.0","method":"subscription","params":{"channel":"book.ETH-PERPETUAL.raw","data":{"timestamp":1761154826236,"type":"change","change_id":46343808447,"instrument_name":"ETH-PERPETUAL","bids":[["new",3824.85,19994.0],["change",3823.7,8.0]],"asks":[],"prev_change_id":46343808444}}}
1761154826354 {"jsonrpc":"2.0","method":"subscription","params":{"channel":"book.ETH-PERPETUAL.raw","data":{"timestamp":1761154826274,"type":"change","change_id":46343808456,"instrument_name":"ETH-PERPETUAL","bids":[],"asks":[["new",3825.7,16466.0],["change",3826.6,1801.0]],"prev_change_id":46343808447}}}
1761154826360 {"jsonrpc":"2.0","method":"subscription","params":{"channel":"book.ETH-PERPETUAL.raw","data":{"timestamp":1761154826276,"type":"change","change_id":46343808459,"instrument_name":"ETH-PERPETUAL","bids":[["new",3825.05,377.0],["change",3823.6,1325.0]],"asks":[["delete",3824.95,0.0]],"prev_change_id":46343808456}}}
1761154826363 {"jsonrpc":"2.0","method":"subscription","params":{"channel":"trades.ETH-PERPETUAL.raw","data":[{"timestamp":1761154826276,"price":3824.95,"direction":"buy","index_price":3825.95,"instrument_name":"ETH-PERPETUAL","trade_seq":24030125,"amount":733.0,"mark_price":3825.03,"tick_direction":0,"trade_id":"ETH-43543885","contracts":733.0}]}}
1761154826398 {"jsonrpc":"2.0","method":"subscription","params":{"channel":"book.ETH-PERPETUAL.raw","data":{"timestamp":1761154826316,"type":"change","change_id":46343808494,"instrument_name":"ETH-PERPETUAL","bids":[],"asks":[["new",3825.5,6.0],["change",3826.7,16109.0]],"prev_change_id":46343808459}}}
1761154826407 {"jsonrpc":"2.0","method":"subscription","params":{"channel":"book.ETH-PERPETUAL.raw","data":{"timestamp":1761154826318,"type":"change","change_id":46343808497,"instrument_name":"ETH-PERPETUAL","bids":[["new",3825.15,266.0],["delete",3823.55,0.0]],"asks":[],"prev_change_id":46343808494}}}
1761154826440 {"jsonrpc":"2.0","method":"subscription","params":{"channel":"book.ETH-PERPETUAL.raw","data":{"timestamp":1761154826355,"type":"change","change_id":46343808508,"instrument_name":"ETH-PERPETUAL","bids":[],"asks":[["new",3825.4,8958.0],["change",3826.9,11112.0]],"prev_change_id":46343808497}}}
1761154826446 {"jsonrpc":"2.0","method":"subscription","params":{"channel":"book.ETH-PERPETUAL.raw","data":{"timestamp":1761154826359,"type":"change","change_id":46343808511,"instrument_name":"ETH-PERPETUAL","bids":[["new",3825.35,10562.0],["delete",3823.4,0.0]],"asks":[],"prev_change_id":46343808508}}}
1761154827304 {"jsonrpc":"2.0","method":"subscription","params":{"channel":"book.ETH-PERPETUAL.raw","data":{"timestamp":1761154827115,"type":"change","change_id":46343809543,"instrument_name":"ETH-PERPETUAL","bids":[],"asks":[["change",3825.4,9382.0]],"prev_change_id":46343808511}}}
1761154827312 {"jsonrpc":"2.0","method":"subscription","params":{"channel":"book.ETH-PERPETUAL.raw","data":{"timestamp":1761154827175,"type":"change","change_id":46343809778,"instrument_name":"ETH-PERPETUAL","bids":[["new",3807.05,3.2e5],["delete",3806.95,0.0]],"asks":[],"prev_change_id":46343809543}}}
1761154827429 {"jsonrpc":"2.0","method":"subscription","params":{"channel":"book.BTC-PERPETUAL.raw","data":{"timestamp":1761154827287,"type":"change","change_id":67840109769,"instrument_name":"BTC-PERPETUAL","bids":[],"asks":[["delete",107893.5,0.0],["new",107921.0,18260.0]],"prev_change_id":67840107975}}}
1761154827434 {"jsonrpc":"2.0","method":"subscription","params":{"channel":"book.BTC-PERPETUAL.raw","data":{"timestamp":1761154827288,"type":"change","change_id":67840109770,"instrument_name":"BTC-PERPETUAL","bids":[["delete",107893.0,0.0],["change",107865.0,55180.0]],"asks":[],"prev_change_id":67840109769}}}
1761154827472 {"jsonrpc":"2.0","method":"subscription","params":{"channel":"book.BTC-PERPETUAL.raw","data":{"timestamp":1761154827326,"type":"change","change_id":67840109819,"instrument_name":"BTC-PERPETUAL","bids":[],"asks":[["delete",1.079e5,0.0],["new",107916.0,33150.0]],"prev_change_id":67840109770}}}
1761154827482 {"jsonrpc":"2.0","method":"subscription","params":{"channel":"book.BTC-PERPETUAL.raw","data":{"timestamp":1761154827327,"type":"change","change_id":67840109821,"instrument_name":"BTC-PERPETUAL","bids":[["delete",107892.5,0.0],["new",107865.5,9230.0]],"asks":[],"prev_change_id":67840109819}}}
1761154827519 {"jsonrpc":"2.0","method":"subscription","params":{"channel":"book.BTC-PERPETUAL.raw","data":{"timestamp":1761154827366,"type":"change","change_id":67840109980,"instrument_name":"BTC-PERPETUAL","bids":[],"asks":[["delete",107900.5,0.0],["new",107915.5,17070.0]],"prev_change_id":67840109821}}}
1761154827523 {"jsonrpc":"2.0","method":"subscription","params":{"channel":"book.BTC-PERPETUAL.raw","data":{"timestamp":1761154827368,"type":"change","change_id":67840109981,"instrument_name":"BTC-PERPETUAL","bids":[["delete",107892.0,0.0],["new",107866.5,10.0]],"asks":[],"prev_change_id":67840109980}}}
1761154827559 {"jsonrpc":"2.0","method":"subscription","params":{"channel":"book.BTC-PERPETUAL.raw","data":{"timestamp":1761154827406,"type":"change","change_id":67840110068,"instrument_name":"BTC-PERPETUAL","bids":[],"asks":[["delete",107904.5,0.0],["new",107912.5,2.1e3]],"prev_change_id":67840109981}}}
1761154827564 {"jsonrpc":"2.0","method":"subscription","params":{"channel":"book.BTC-PERPETUAL.raw","data":{"timestamp":1761154827408,"type":"change","change_id":67840110069,"instrument_name":"BTC-PERPETUAL","bids":[["delete",107888.0,0.0],["change",107871.0,68520.0]],"asks":[],"prev_change_id":67840110068}}}
1761154827599 {"jsonrpc":"2.0","method":"subscription","params":{"channel":"book.BTC-PERPETUAL.raw","data":{"timestamp":1761154827446,"type":"change","change_id":67840110072,"instrument_name":"BTC-PERPETUAL","bids":[],"asks":[["new",107912.0,20240.0],["delete",107914.5,0.0]],"prev_change_id":67840110069}}}
1761154827604 {"jsonrpc":"2.0","method":"subscription","params":{"channel":"book.BTC-PERPETUAL.raw","data":{"timestamp":1761154827448,"type":"change","change_id":67840110073,"instrument_name":"BTC-PERPETUAL","bids":[["delete",107887.5,0.0],["change",107871.5,28140.0]],"asks":[],"prev_change_id":67840110072}}}
1761154827641 {"jsonrpc":"2.0","method":"subscription","params":{"channel":"book.BTC-PERPETUAL.raw","data":{"timestamp":1761154827486,"type":"change","change_id":67840110176,"instrument_name":"BTC-PERPETUAL","bids":[],"asks":[["new",107909.0,8440.0],["delete",107915.0,0.0]],"prev_change_id":67840110073}}}
1761154827652 {"jsonrpc":"2.0","method":"subscription","params":{"channel":"book.BTC-PERPETUAL.raw","data":{"timestamp":1761154827488,"type":"change","change_id":67840110177,"instrument_name":"BTC-PERPETUAL","bids":[["delete",107887.0,0.0],["change",107873.0,7.53e4]],"asks":[],"prev_change_id":67840110176}}}
1761154827688 {"jsonrpc":"2.0","method":"subscription","params":{"channel":"book.BTC-PERPETUAL.raw","data":{"timestamp":1761154827527,"type":"change","change_id":67840110180,"instrument_name":"BTC-PERPETUAL","bids":[],"asks":[["new",107908.5,3.6e4],["delete",107918.5,0.0]],"prev_change_id":67840110177}}}
1761154827694 {"jsonrpc":"2.0","method":"subscription","params":{"channel":"book.BTC-PERPETUAL.raw","data":{"timestamp":1761154827532,"type":"change","change_id":67840110181,"instrument_name":"BTC-PERPETUAL","bids":[["delete",107885.0,0.0],["change",107875.0,4.2e3]],"asks":[],"prev_change_id":67840110180}}}
1761154827733 {"jsonrpc":"2.0","method":"subscription","params":{"channel":"book.BTC-PERPETUAL.raw","data":{"timestamp":1761154827567,"type":"change","change_id":67840110338,"instrument_name":"BTC-PERPETUAL","bids":[],"asks":[["new",107904.5,8620.0],["delete",107919.0,0.0]],"prev_change_id":67840110181}}}
1761154827737 {"jsonrpc":"2.0","method":"subscription","params":{"channel":"book.BTC-PERPETUAL.raw","data":{"timestamp":1761154827571,"type":"change","change_id":67840110339,"instrument_name":"BTC-PERPETUAL","bids":[["delete",107882.5,0.0],["new",107876.5,1.49e4]],"asks":[],"prev_change_id":67840110338}}}
1761154827771 {"jsonrpc":"2.0","method":"subscription","params":{"channel":"book.BTC-PERPETUAL.raw","data":{"timestamp":1761154827606,"type":"change","change_id":67840110344,"instrument_name":"BTC-PERPETUAL","bids":[],"asks":[["new",107904.0,490.0],["delete",107922.0,0.0]],"prev_change_id":67840110339}}}
1761154827782 {"jsonrpc":"2.0","method":"subscription","params":{"channel":"book.BTC-PERPETUAL.raw","data":{"timestamp":1761154827611,"type":"change","change_id":67840110345,"instrument_name":"BTC-PERPETUAL","bids":[["delete",107880.0,0.0],["new",107877.0,61610.0]],"asks":[],"prev_change_id":67840110344}}}
1761154827813 {"jsonrpc":"2.0","method":"subscription","params":{"channel":"book.BTC-PERPETUAL.raw","data":{"timestamp":1761154827647,"type":"change","change_id":67840110351,"instrument_name":"BTC-PERPETUAL","bids":[],"asks":[["new",107900.5,1.8e3],["delete",107922.5,0.0]],"prev_change_id":67840110345}}}
1761154827818 {"jsonrpc":"2.0","method":"subscription","params":{"channel":"book.BTC-PERPETUAL.raw","data":{"timestamp":1761154827651,"type":"change","change_id":67840110352,"instrument_name":"BTC-PERPETUAL","bids":[["new",107880.0,8650.0],["delete",107878.0,0.0]],"asks":[],"prev_change_id":67840110351}}}
1761154827855 {"jsonrpc":"2.0","method":"subscription","params":{"channel":"book.BTC-PERPETUAL.raw","data":{"timestamp":1761154827686,"type":"change","change_id":67840110359,"instrument_name":"BTC-PERPETUAL","bids":[],"asks":[["new",1.079e5,20.0],["delete",107923.0,0.0]],"prev_change_id":67840110352}}}
1761154827861 {"jsonrpc":"2.0","method":"subscription","params":{"channel":"book.BTC-PERPETUAL.raw","data":{"timestamp":1761154827691,"type":"change","change_id":67840110360,"instrument_name":"BTC-PERPETUAL","bids":[["new",107882.0,500.0],["delete",107877.5,0.0]],"asks":[],"prev_change_id":67840110359}}}
1761154827897 {"jsonrpc":"2.0","method":"subscription","params":{"channel":"book.BTC-PERPETUAL.raw","data":{"timestamp":1761154827726,"type":"change","change_id":67840110367,"instrument_name":"BTC-PERPETUAL","bids":[],"asks":[["new",107898.5,20.0],["delete",107923.5,0.0]],"prev_change_id":67840110360}}}
1761154827907 {"jsonrpc":"2.0","method":"subscription","params":{"channel":"book.BTC-PERPETUAL.raw","data":{"timestamp":1761154827730,"type":"change","change_id":67840110396,"instrument_name":"BTC-PERPETUAL","bids":[["new",107882.5,20770.0],["delete",107876.0,0.0]],"asks":[],"prev_change_id":67840110367}}}
1761154827939 {"jsonrpc":"2.0","method":"subscription","params":{"channel":"book.BTC-PERPETUAL.raw","data":{"timestamp":1761154827766,"type":"change","change_id":67840110404,"instrument_name":"BTC-PERPETUAL","bids":[],"asks":[["new",107898.0,30020.0],["delete",107924.0,0.0]],"prev_change_id":67840110396}}}
1761154827957 {"jsonrpc":"2.0","method":"subscription","params":{"channel":"book.BTC-PERPETUAL.raw","data":{"timestamp":1761154827775,"type":"change","change_id":67840110405,"instrument_name":"BTC-PERPETUAL","bids":[["new",107884.5,20.0],["change",107875.0,2.1e3]],"asks":[],"prev_change_id":67840110404}}}
1761154827989 {"jsonrpc":"2.0","method":"subscription","params":{"channel":"book.BTC-PERPETUAL.raw","data":{"timestamp":1761154827812,"type":"change","change_id":67840110414,"instrument_name":"BTC-PERPETUAL","bids":[],"asks":[["new",107897.5,23920.0],["delete",107925.0,0.0]],"prev_change_id":67840110405}}}
1761154827998 {"jsonrpc":"2.0","method":"subscription","params":{"channel":"book.BTC-PERPETUAL.raw","data":{"timestamp":1761154827814,"type":"change","change_id":67840110415,"instrument_name":"BTC-PERPETUAL","bids":[["new",107885.0,36980.0],["change",107873.0,5.03e4]],"asks":[],"prev_change_id":67840110414}}}
1761154828039 {"jsonrpc":"2.0","method":"subscription","params":{"channel":"book.BTC-PERPETUAL.raw","data":{"timestamp":1761154827852,"type":"change","change_id":67840110474,"instrument_name":"BTC-PERPETUAL","bids":[],"asks":[["new",107897.0,1810.0],["delete",107927.5,0.0]],"prev_change_id":67840110415}}}
1761154828046 {"jsonrpc":"2.0","method":"subscription","params":{"channel":"book.BTC-PERPETUAL.raw","data":{"timestamp":1761154827854,"type":"change","change_id":67840110475,"instrument_name":"BTC-PERPETUAL","bids":[["new",107888.0,11040.0],["delete",107872.0,0.0]],"asks":[],"prev_change_id":67840110474}}}
1761154828072 {"jsonrpc":"2.0","method":"subscription","params":{"channel":"book.BTC-PERPETUAL.raw","data":{"timestamp":1761154827891,"type":"change","change_id":67840110485,"instrument_name":"BTC-PERPETUAL","bids":[],"asks":[["new",107896.5,10020.0],["delete",107928.0,0.0]],"prev_change_id":67840110475}}}
1761154828079 {"jsonrpc":"2.0","method":"subscription","params":{"channel":"book.BTC-PERPETUAL.raw","data":{"timestamp":1761154827894,"type":"change","change_id":67840110486,"instrument_name":"BTC-PERPETUAL","bids":[["new",107888.5,50990.0],["change",107871.5,12020.0]],"asks":[],"prev_change_id":67840110485}}}
1761154828116 {"jsonrpc":"2.0","method":"subscription","params":{"channel":"book.BTC-PERPETUAL.raw","data":{"timestamp":1761154827931,"type":"change","change_id":67840110497,"instrument_name":"BTC-PERPETUAL","bids":[],"asks":[["new",107896.0,20.0],["delete",107929.0,0.0]],"prev_change_id":67840110486}}}
1761154828122 {"jsonrpc":"2.0","method":"subscription","params":{"channel":"book.BTC-PERPETUAL.raw","data":{"timestamp":1761154827935,"type":"change","change_id":67840110498,"instrument_name":"BTC-PERPETUAL","bids":[["new",107889.0,5.0e4],["change",107871.0,35260.0]],"asks":[],"prev_change_id":67840110497}}}
1761154828157 {"jsonrpc":"2.0","method":"subscription","params":{"channel":"book.BTC-PERPETUAL.raw","data":{"timestamp":1761154827971,"type":"change","change_id":67840110509,"instrument_name":"BTC-PERPETUAL","bids":[],"asks":[["new",107895.5,20.0],["delete",107929.5,0.0]],"prev_change_id":67840110498}}}
1761154828163 {"jsonrpc":"2.0","method":"subscription","params":{"channel":"book.BTC-PERPETUAL.raw","data":{"timestamp":1761154827975,"type":"change","change_id":67840110510,"instrument_name":"BTC-PERPETUAL","bids":[["new",107891.5,5.49e4],["change",107865.0,30090.0]],"asks":[],"prev_change_id":67840110509}}}
1761154828199 {"jsonrpc":"2.0","method":"subscription","params":{"channel":"book.BTC-PERPETUAL.raw","data":{"timestamp":1761154828011,"type":"change","change_id":67840110635,"instrument_name":"BTC-PERPETUAL","bids":[],"asks":[["new",107895.0,20.0],["delete",107932.0,0.0]],"prev_change_id":67840110510}}}
1761154828206 {"jsonrpc":"2.0","method":"subscription","params":{"channel":"book.BTC-PERPETUAL.raw","data":{"timestamp":1761154828017,"type":"change","change_id":67840110636,"instrument_name":"BTC-PERPETUAL","bids":[["new",107892.0,31310.0],["delete",107864.0,0.0]],"asks":[],"prev_change_id":67840110635}}}
1761154828243 {"jsonrpc":"2.0","method":"subscription","params":{"channel":"book.BTC-PERPETUAL.raw","data":{"timestamp":1761154828052,"type":"change","change_id":67840110649,"instrument_name":"BTC-PERPETUAL","bids":[],"asks":[["new",107893.5,166760.0],["delete",107932.5,0.0]],"prev_change_id":67840110636}}}
1761154828254 {"jsonrpc":"2.0","method":"subscription","params":{"channel":"book.BTC-PERPETUAL.raw","data":{"timestamp":1761154828057,"type":"change","change_id":67840110650,"instrument_name":"BTC-PERPETUAL","bids":[["new",107893.0,240220.0],["delete",107863.5,0.0]],"asks":[],"prev_change_id":67840110649}}}
1761154830063 {"jsonrpc":"2.0","method":"subscription","params":{"channel":"book.ETH-PERPETUAL.raw","data":{"timestamp":1761154829761,"type":"change","change_id":46343812734,"instrument_name":"ETH-PERPETUAL","bids":[],"asks":[["new",3826.8,6972069.0],["delete",3827.25,0.0]],"prev_change_id":46343809778}}}
1761154830925 {"jsonrpc":"2.0","method":"subscription","params":{"channel":"book.ETH-PERPETUAL.raw","data":{"timestamp":1761154830580,"type":"change","change_id":46343813850,"instrument_name":"ETH-PERPETUAL","bids":[],"asks":[["change",3825.4,424.0],["new",3828.0,6126.0]],"prev_change_id":46343812734}}}
1761154830930 {"jsonrpc":"2.0","method":"subscription","params":{"channel":"book.ETH-PERPETUAL.raw","data":{"timestamp":1761154830581,"type":"change","change_id":46343813851,"instrument_name":"ETH-PERPETUAL","bids":[],"asks":[["delete",3825.4,0.0]],"prev_change_id":46343813850}}}
1761154830933 {"jsonrpc":"2.0","method":"subscription","params":{"channel":"book.ETH-PERPETUAL.raw","data":{"timestamp":1761154830581,"type":"change","change_id":46343813852,"instrument_name":"ETH-PERPETUAL","bids":[["delete",3825.35,0.0],["new",3824.25,17760.0]],"asks":[],"prev_change_id":46343813851}}}
1761154830971 {"jsonrpc":"2.0","method":"subscription","params":{"channel":"book.ETH-PERPETUAL.raw","data":{"timestamp":1761154830619,"type":"change","change_id":46343813872,"instrument_name":"ETH-PERPETUAL","bids":[],"asks":[["delete",3825.5,0.0],["new",3827.8,1829.0]],"prev_change_id":46343813852}}}
1761154830977 {"jsonrpc":"2.0","method":"subscription","params":{"channel":"book.ETH-PERPETUAL.raw","data":{"timestamp":1761154830622,"type":"change","change_id":46343813875,"instrument_name":"ETH-PERPETUAL","bids":[["delete",3825.15,0.0],["new",3824.3,6455.0]],"asks":[],"prev_change_id":46343813872}}}
1761154831010 {"jsonrpc":"2.0","method":"subscription","params":{"channel":"book.ETH-PERPETUAL.raw","data":{"timestamp":1761154830658,"type":"change","change_id":46343813894,"instrument_name":"ETH-PERPETUAL","bids":[],"asks":[["delete",3825.7,0.0],["new",3827.75,15388.0]],"prev_change_id":46343813875}}}
1761154831016 {"jsonrpc":"2.0","method":"subscription","params":{"channel":"book.ETH-PERPETUAL.raw","data":{"timestamp":1761154830662,"type":"change","change_id":46343813931,"instrument_name":"ETH-PERPETUAL","bids":[["delete",3825.05,0.0],["change",3824.4,16481.0]],"asks":[],"prev_change_id":46343813894}}}
1761154831049 {"jsonrpc":"2.0","method":"subscription","params":{"channel":"book.ETH-PERPETUAL.raw","data":{"timestamp":1761154830698,"type":"change","change_id":46343813959,"instrument_name":"ETH-PERPETUAL","bids":[],"asks":[["delete",3825.75,0.0],["new",3827.65,4448.0]],"prev_change_id":46343813931}}}
1761154831059 {"jsonrpc":"2.0","method":"subscription","params":{"channel":"book.ETH-PERPETUAL.raw","data":{"timestamp":1761154830700,"type":"change","change_id":46343813961,"instrument_name":"ETH-PERPETUAL","bids":[["delete",3824.85,0.0],["new",3824.5,1664.0]],"asks":[],"prev_change_id":46343813959}}}
1761154831100 {"jsonrpc":"2.0","method":"subscription","params":{"channel":"book.ETH-PERPETUAL.raw","data":{"timestamp":1761154830739,"type":"change","change_id":46343813979,"instrument_name":"ETH-PERPETUAL","bids":[],"asks":[["delete",3825.8,0.0],["new",3827.6,5921.0]],"prev_change_id":46343813961}}}
1761154831106 {"jsonrpc":"2.0","method":"subscription","params":{"channel":"book.ETH-PERPETUAL.raw","data":{"timestamp":1761154830740,"type":"change","change_id":46343813981,"instrument_name":"ETH-PERPETUAL","bids":[["delete",3824.8,0.0],["change",3824.55,3527.0]],"asks":[],"prev_change_id":46343813979}}}
1761154831138 {"jsonrpc":"2.0","method":"subscription","params":{"channel":"book.ETH-PERPETUAL.raw","data":{"timestamp":1761154830780,"type":"change","change_id":46343814060,"instrument_name":"ETH-PERPETUAL","bids":[],"asks":[["delete",3826.0,0.0],["new",3827.55,11661.0]],"prev_change_id":46343813981}}}
1761154831144 {"jsonrpc":"2.0","method":"subscription","params":{"channel":"book.ETH-PERPETUAL.raw","data":{"timestamp":1761154830782,"type":"change","change_id":46343814062,"instrument_name":"ETH-PERPETUAL","bids":[["change",3824.65,250.0]],"asks":[],"prev_change_id":46343814060}}}
1761154831182 {"jsonrpc":"2.0","method":"subscription","params":{"channel":"book.ETH-PERPETUAL.raw","data":{"timestamp":1761154830822,"type":"change","change_id":46343814064,"instrument_name":"ETH-PERPETUAL","bids":[],"asks":[["delete",3826.05,0.0],["new",3827.45,21165.0]],"prev_change_id":46343814062}}}
1761154831187 {"jsonrpc":"2.0","method":"subscription","params":{"channel":"book.ETH-PERPETUAL.raw","data":{"timestamp":1761154830824,"type":"change","change_id":46343814066,"instrument_name":"ETH-PERPETUAL","bids":[["new",3824.8,21111.0],["delete",3824.6,0.0]],"asks":[],"prev_change_id":46343814064}}}
1761154831223 {"jsonrpc":"2.0","method":"subscription","params":{"channel":"book.ETH-PERPETUAL.raw","data":{"timestamp":1761154830861,"type":"change","change_id":46343814070,"instrument_name":"ETH-PERPETUAL","bids":[],"asks":[["delete",3826.1,0.0],["new",3827.4,9213.0]],"prev_change_id":46343814066}}}
1761154831230 {"jsonrpc":"2.0","method":"subscription","params":{"channel":"book.ETH-PERPETUAL.raw","data":{"timestamp":1761154830864,"type":"change","change_id":46343814072,"instrument_name":"ETH-PERPETUAL","bids":[["new",3824.85,24417.0],["change",3824.55,1819.0]],"asks":[],"prev_change_id":46343814070}}}
1761154831266 {"jsonrpc":"2.0","method":"subscription","params":{"channel":"book.ETH-PERPETUAL.raw","data":{"timestamp":1761154830900,"type":"change","change_id":46343814077,"instrument_name":"ETH-PERPETUAL","bids":[],"asks":[["delete",3826.2,0.0]],"prev_change_id":46343814072}}}
1761154831273 {"jsonrpc":"2.0","method":"subscription","params":{"channel":"book.ETH-PERPETUAL.raw","data":{"timestamp":1761154830903,"type":"change","change_id":46343814079,"instrument_name":"ETH-PERPETUAL","bids":[["new",3824.9,1664.0],["change",3824.4,3698.0]],"asks":[],"prev_change_id":46343814077}}}
1761154831307 {"jsonrpc":"2.0","method":"subscription","params":{"channel":"book.ETH-PERPETUAL.raw","data":{"timestamp":1761154830940,"type":"change","change_id":46343814229,"instrument_name":"ETH-PERPETUAL","bids":[],"asks":[["delete",3826.25,0.0],["new",3827.25,4448.0]],"prev_change_id":46343814079}}}
1761154831313 {"jsonrpc":"2.0","method":"subscription","params":{"channel":"book.ETH-PERPETUAL.raw","data":{"timestamp":1761154830944,"type":"change","change_id":46343814231,"instrument_name":"ETH-PERPETUAL","bids":[["new",3825.0,11461.0],["delete",3824.35,0.0]],"asks":[],"prev_change_id":46343814229}}}
1761154831351 {"jsonrpc":"2.0","method":"subscription","params":{"channel":"book.ETH-PERPETUAL.raw","data":{"timestamp":1761154830981,"type":"change","change_id":46343814241,"instrument_name":"ETH-PERPETUAL","bids":[],"asks":[["delete",3826.3,0.0],["new",3827.2,5738.0]],"prev_change_id":46343814231}}}
1761154831357 {"jsonrpc":"2.0","method":"subscription","params":{"channel":"book.ETH-PERPETUAL.raw","data":{"timestamp":1761154830984,"type":"change","change_id":46343814243,"instrument_name":"ETH-PERPETUAL","bids":[["new",3825.1,16717.0],["delete",3824.15,0.0]],"asks":[],"prev_change_id":46343814241}}}
1761154831399 {"jsonrpc":"2.0","method":"subscription","params":{"channel":"book.ETH-PERPETUAL.raw","data":{"timestamp":1761154831020,"type":"change","change_id":46343814305,"instrument_name":"ETH-PERPETUAL","bids":[],"asks":[["delete",3826.45,0.0],["new",3827.15,1.0e3]],"prev_change_id":46343814243}}}
1761154831405 {"jsonrpc":"2.0","method":"subscription","params":{"channel":"book.ETH-PERPETUAL.raw","data":{"timestamp":1761154831024,"type":"change","change_id":46343814307,"instrument_name":"ETH-PERPETUAL","bids":[["new",3825.15,9421.0],["delete",3824.1,0.0]],"asks":[],"prev_change_id":46343814305}}}
1761154831436 {"jsonrpc":"2.0","method":"subscription","params":{"channel":"book.ETH-PERPETUAL.raw","data":{"timestamp":1761154831060,"type":"change","change_id":46343814313,"instrument_name":"ETH-PERPETUAL","bids":[],"asks":[["delete",3826.5,0.0],["change",3827.1,3168.0]],"prev_change_id":46343814307}}}
1761154831444 {"jsonrpc":"2.0","method":"subscription","params":{"channel":"book.ETH-PERPETUAL.raw","data":{"timestamp":1761154831065,"type":"change","change_id":46343814315,"instrument_name":"ETH-PERPETUAL","bids":[["new",3825.35,1323.0],["delete",3824.05,0.0]],"asks":[],"prev_change_id":46343814313}}}
1761154831478 {"jsonrpc":"2.0","method":"subscription","params":{"channel":"book.ETH-PERPETUAL.raw","data":{"timestamp":1761154831101,"type":"change","change_id":46343814323,"instrument_name":"ETH-PERPETUAL","bids":[],"asks":[["delete",3826.55,0.0],["new",3827.05,2088.0]],"prev_change_id":46343814315}}}
1761154831484 {"jsonrpc":"2.0","method":"subscription","params":{"channel":"book.ETH-PERPETUAL.raw","data":{"timestamp":1761154831105,"type":"change","change_id":46343814325,"instrument_name":"ETH-PERPETUAL","bids":[["new",3825.4,16717.0],["delete",3823.9,0.0]],"asks":[],"prev_change_id":46343814323}}}
1761154831520 {"jsonrpc":"2.0","method":"subscription","params":{"channel":"book.ETH-PERPETUAL.raw","data":{"timestamp":1761154831142,"type":"change","change_id":46343814333,"instrument_name":"ETH-PERPETUAL","bids":[],"asks":[["delete",3826.6,0.0],["change",3826.95,104513.0]],"prev_change_id":46343814325}}}
1761154831527 {"jsonrpc":"2.0","method":"subscription","params":{"channel":"book.ETH-PERPETUAL.raw","data":{"timestamp":1761154831145,"type":"change","change_id":46343814445,"instrument_name":"ETH-PERPETUAL","bids":[["new",3825.55,16522.0],["delete",3823.85,0.0]],"asks":[],"prev_change_id":46343814333}}}
1761154831564 {"jsonrpc":"2.0","method":"subscription","params":{"channel":"book.ETH-PERPETUAL.raw","data":{"timestamp":1761154831182,"type":"change","change_id":46343814574,"instrument_name":"ETH-PERPETUAL","bids":[],"asks":[["delete",3826.7,0.0],["change",3826.8,7003601.0]],"prev_change_id":46343814445}}}
1761154831572 {"jsonrpc":"2.0","method":"subscription","params":{"channel":"book.ETH-PERPETUAL.raw","data":{"timestamp":1761154831184,"type":"change","change_id":46343814576,"instrument_name":"ETH-PERPETUAL","bids":[["new",3825.6,27537.0],["delete",3823.8,0.0]],"asks":[],"prev_change_id":46343814574}}}
1761154831610 {"jsonrpc":"2.0","method":"subscription","params":{"channel":"book.ETH-PERPETUAL.raw","data":{"timestamp":1761154831223,"type":"change","change_id":46343814586,"instrument_name":"ETH-PERPETUAL","bids":[],"asks":[["new",3826.6,5263.0],["delete",3826.85,0.0]],"prev_change_id":46343814576}}}
1761154831616 {"jsonrpc":"2.0","method":"subscription","params":{"channel":"book.ETH-PERPETUAL.raw","data":{"timestamp":1761154831224,"type":"change","change_id":46343814588,"instrument_name":"ETH-PERPETUAL","bids":[["new",3825.65,5968.0],["delete",3823.75,0.0]],"asks":[],"prev_change_id":46343814586}}}
1761154831652 {"jsonrpc":"2.0","method":"subscription","params":{"channel":"book.ETH-PERPETUAL.raw","data":{"timestamp":1761154831263,"type":"change","change_id":46343814598,"instrument_name":"ETH-PERPETUAL","bids":[],"asks":[["new",3826.55,9.7e3],["delete",3826.9,0.0]],"prev_change_id":46343814588}}}
1761154831658 {"jsonrpc":"2.0","method":"subscription","params":{"channel":"book.ETH-PERPETUAL.raw","data":{"timestamp":1761154831264,"type":"change","change_id":46343814600,"instrument_name":"ETH-PERPETUAL","bids":[["new",3825.9,1.0e3],["delete",3823.7,0.0]],"asks":[],"prev_change_id":46343814598}}}
1761154831690 {"jsonrpc":"2.0","method":"subscription","params":{"channel":"book.ETH-PERPETUAL.raw","data":{"timestamp":1761154831302,"type":"change","change_id":46343814611,"instrument_name":"ETH-PERPETUAL","bids":[],"asks":[["new",3826.5,2895.0],["change",3826.95,66717.0]],"prev_change_id":46343814600}}}
1761154831696 {"jsonrpc":"2.0","method":"subscription","params":{"channel":"book.ETH-PERPETUAL.raw","data":{"timestamp":1761154831305,"type":"change","change_id":46343814627,"instrument_name":"ETH-PERPETUAL","bids":[["new",3826.1,2.2e4],["delete",3823.6,0.0]],"asks":[],"prev_change_id":46343814611}}}
1761154831733 {"jsonrpc":"2.0","method":"subscription","params":{"channel":"book.ETH-PERPETUAL.raw","data":{"timestamp":1761154831342,"type":"change","change_id":46343814649,"instrument_name":"ETH-PERPETUAL","bids":[],"asks":[["new",3826.25,8.0],["change",3827.1,1584.0]],"prev_change_id":46343814627}}}
1761154831744 {"jsonrpc":"2.0","method":"subscription","params":{"channel":"book.ETH-PERPETUAL.raw","data":{"timestamp":1761154831346,"type":"change","change_id":46343814651,"instrument_name":"ETH-PERPETUAL","bids":[["new",3826.15,10487.0]],"asks":[],"prev_change_id":46343814649}}}
1761154832351 {"jsonrpc":"2.0","method":"subscription","params":{"channel":"book.ETH-PERPETUAL.raw","data":{"timestamp":1761154831919,"type":"change","change_id":46343815613,"instrument_name":"ETH-PERPETUAL","bids":[["new",3808.3,3.2e5],["delete",3807.0,0.0]],"asks":[],"prev_change_id":46343814651}}}
1761154832741 {"jsonrpc":"2.0","method":"subscription","params":{"channel":"book.BTC-PERPETUAL.raw","data":{"timestamp":1761154832291,"type":"change","change_id":67840115885,"instrument_name":"BTC-PERPETUAL","bids":[],"asks":[["delete",107893.5,0.0],["change",107947.0,5634520.0]],"prev_change_id":67840110650}}}
1761154832747 {"jsonrpc":"2.0","method":"subscription","params":{"channel":"book.BTC-PERPETUAL.raw","data":{"timestamp":1761154832295,"type":"change","change_id":67840115976,"instrument_name":"BTC-PERPETUAL","bids":[["delete",107893.0,0.0],["change",107885.0,41690.0]],"asks":[],"prev_change_id":67840115885}}}
1761154832783 {"jsonrpc":"2.0","method":"subscription","params":{"channel":"book.BTC-PERPETUAL.raw","data":{"timestamp":1761154832332,"type":"change","change_id":67840116022,"instrument_name":"BTC-PERPETUAL","bids":[],"asks":[["delete",107895.0,0.0],["new",107946.5,3620.0]],"prev_change_id":67840115976}}}
1761154832789 {"jsonrpc":"2.0","method":"subscription","params":{"channel":"book.BTC-PERPETUAL.raw","data":{"timestamp":1761154832334,"type":"change","change_id":67840116024,"instrument_name":"BTC-PERPETUAL","bids":[["delete",107892.0,0.0],["new",107886.5,2.1e3]],"asks":[],"prev_change_id":67840116022}}}
1761154832825 {"jsonrpc":"2.0","method":"subscription","params":{"channel":"book.BTC-PERPETUAL.raw","data":{"timestamp":1761154832371,"type":"change","change_id":67840116195,"instrument_name":"BTC-PERPETUAL","bids":[],"asks":[["delete",107895.5,0.0],["new",107942.5,33150.0]],"prev_change_id":67840116024}}}
1761154832830 {"jsonrpc":"2.0","method":"subscription","params":{"channel":"book.BTC-PERPETUAL.raw","data":{"timestamp":1761154832374,"type":"change","change_id":67840116196,"instrument_name":"BTC-PERPETUAL","bids":[["delete",107891.5,0.0],["new",107887.0,33150.0]],"asks":[],"prev_change_id":67840116195}}}
1761154832868 {"jsonrpc":"2.0","method":"subscription","params":{"channel":"book.BTC-PERPETUAL.raw","data":{"timestamp":1761154832412,"type":"change","change_id":67840116285,"instrument_name":"BTC-PERPETUAL","bids":[],"asks":[["delete",107896.0,0.0],["new",107941.5,1.0e3]],"prev_change_id":67840116196}}}
1761154832880 {"jsonrpc":"2.0","method":"subscription","params":{"channel":"book.BTC-PERPETUAL.raw","data":{"timestamp":1761154832414,"type":"change","change_id":67840116286,"instrument_name":"BTC-PERPETUAL","bids":[["delete",107889.0,0.0],["new",107887.5,11120.0]],"asks":[],"prev_change_id":67840116285}}}
1761154832914 {"jsonrpc":"2.0","method":"subscription","params":{"channel":"book.BTC-PERPETUAL.raw","data":{"timestamp":1761154832452,"type":"change","change_id":67840116289,"instrument_name":"BTC-PERPETUAL","bids":[],"asks":[["delete",107896.5,0.0],["new",107940.5,8990.0]],"prev_change_id":67840116286}}}
1761154832917 {"jsonrpc":"2.0","method":"subscription","params":{"channel":"book.BTC-PERPETUAL.raw","data":{"timestamp":1761154832454,"type":"change","change_id":67840116291,"instrument_name":"BTC-PERPETUAL","bids":[["delete",107888.5,0.0],["change",107888.0,61040.0]],"asks":[],"prev_change_id":67840116289}}}
1761154832955 {"jsonrpc":"2.0","method":"subscription","params":{"channel":"book.BTC-PERPETUAL.raw","data":{"timestamp":1761154832494,"type":"change","change_id":67840116393,"instrument_name":"BTC-PERPETUAL","bids":[],"asks":[["delete",107897.0,0.0],["new",107939.5,16560.0]],"prev_change_id":67840116291}}}
1761154832960 {"jsonrpc":"2.0","method":"subscription","params":{"channel":"book.BTC-PERPETUAL.raw","data":{"timestamp":1761154832498,"type":"change","change_id":67840116395,"instrument_name":"BTC-PERPETUAL","bids":[["new",107889.5,5.03e4],["change",107888.0,5.0e4]],"asks":[],"prev_change_id":67840116393}}}
1761154833000 {"jsonrpc":"2.0","method":"subscription","params":{"channel":"book.BTC-PERPETUAL.raw","data":{"timestamp":1761154832536,"type":"change","change_id":67840116399,"instrument_name":"BTC-PERPETUAL","bids":[],"asks":[["delete",107897.5,0.0],["new",107939.0,13810.0]],"prev_change_id":67840116395}}}
1761154833006 {"jsonrpc":"2.0","method":"subscription","params":{"channel":"book.BTC-PERPETUAL.raw","data":{"timestamp":1761154832539,"type":"change","change_id":67840116401,"instrument_name":"BTC-PERPETUAL","bids":[["new",107893.0,8.6e3],["change",107885.0,4710.0]],"asks":[],"prev_change_id":67840116399}}}
1761154833042 {"jsonrpc":"2.0","method":"subscription","params":{"channel":"book.BTC-PERPETUAL.raw","data":{"timestamp":1761154832576,"type":"change","change_id":67840116560,"instrument_name":"BTC-PERPETUAL","bids":[],"asks":[["delete",107898.0,0.0],["new",107936.0,8770.0]],"prev_change_id":67840116401}}}
1761154833051 {"jsonrpc":"2.0","method":"subscription","params":{"channel":"book.BTC-PERPETUAL.raw","data":{"timestamp":1761154832580,"type":"change","change_id":67840116562,"instrument_name":"BTC-PERPETUAL","bids":[["new",107893.5,33280.0],["delete",107884.5,0.0]],"asks":[],"prev_change_id":67840116560}}}
1761154833090 {"jsonrpc":"2.0","method":"subscription","params":{"channel":"book.BTC-PERPETUAL.raw","data":{"timestamp":1761154832616,"type":"change","change_id":67840116566,"instrument_name":"BTC-PERPETUAL","bids":[],"asks":[["delete",107898.5,0.0],["new",107935.5,31240.0]],"prev_change_id":67840116562}}}
1761154833096 {"jsonrpc":"2.0","method":"subscription","params":{"channel":"book.BTC-PERPETUAL.raw","data":{"timestamp":1761154832619,"type":"change","change_id":67840116568,"instrument_name":"BTC-PERPETUAL","bids":[["new",107894.0,9230.0],["delete",107882.5,0.0]],"asks":[],"prev_change_id":67840116566}}}
1761154833099 {"jsonrpc":"2.0","method":"subscription","params":{"channel":"book.BTC-PERPETUAL.raw","data":{"timestamp":1761154832630,"type":"change","change_id":67840116569,"instrument_name":"BTC-PERPETUAL","bids":[["new",107855.5,6462890.0],["delete",107839.5,0.0]],"asks":[],"prev_change_id":67840116568}}}
1761154833134 {"jsonrpc":"2.0","method":"subscription","params":{"channel":"book.BTC-PERPETUAL.raw","data":{"timestamp":1761154832658,"type":"change","change_id":67840116575,"instrument_name":"BTC-PERPETUAL","bids":[],"asks":[["delete",1.079e5,0.0],["new",107932.0,4.16e4]],"prev_change_id":67840116569}}}
1761154833139 {"jsonrpc":"2.0","method":"subscription","params":{"channel":"book.BTC-PERPETUAL.raw","data":{"timestamp":1761154832659,"type":"change","change_id":67840116577,"instrument_name":"BTC-PERPETUAL","bids":[["new",107898.0,8620.0],["delete",107882.0,0.0]],"asks":[],"prev_change_id":67840116575}}}
1761154833173 {"jsonrpc":"2.0","method":"subscription","params":{"channel":"book.BTC-PERPETUAL.raw","data":{"timestamp":1761154832698,"type":"change","change_id":67840116583,"instrument_name":"BTC-PERPETUAL","bids":[],"asks":[["delete",107900.5,0.0],["new",107930.5,5.0e3]],"prev_change_id":67840116577}}}
1761154833178 {"jsonrpc":"2.0","method":"subscription","params":{"channel":"book.BTC-PERPETUAL.raw","data":{"timestamp":1761154832700,"type":"change","change_id":67840116585,"instrument_name":"BTC-PERPETUAL","bids":[["new",107898.5,172620.0],["delete",107880.0,0.0]],"asks":[],"prev_change_id":67840116583}}}
1761154833216 {"jsonrpc":"2.0","method":"subscription","params":{"channel":"book.BTC-PERPETUAL.raw","data":{"timestamp":1761154832739,"type":"change","change_id":67840116619,"instrument_name":"BTC-PERPETUAL","bids":[],"asks":[["delete",107904.0,0.0],["new",107929.5,2.1e3]],"prev_change_id":67840116585}}}
1761154833226 {"jsonrpc":"2.0","method":"subscription","params":{"channel":"book.BTC-PERPETUAL.raw","data":{"timestamp":1761154832741,"type":"change","change_id":67840116621,"instrument_name":"BTC-PERPETUAL","bids":[["new",107899.0,65060.0],["delete",107877.0,0.0]],"asks":[],"prev_change_id":67840116619}}}
1761154833260 {"jsonrpc":"2.0","method":"subscription","params":{"channel":"book.BTC-PERPETUAL.raw","data":{"timestamp":1761154832781,"type":"change","change_id":67840116630,"instrument_name":"BTC-PERPETUAL","bids":[],"asks":[["delete",107904.5,0.0],["new",107929.0,500.0]],"prev_change_id":67840116621}}}
1761154833267 {"jsonrpc":"2.0","method":"subscription","params":{"channel":"book.BTC-PERPETUAL.raw","data":{"timestamp":1761154832783,"type":"change","change_id":67840116632,"instrument_name":"BTC-PERPETUAL","bids":[["new",1.079e5,1360.0],["delete",107876.5,0.0]],"asks":[],"prev_change_id":67840116630}}}
1761154833310 {"jsonrpc":"2.0","method":"subscription","params":{"channel":"book.BTC-PERPETUAL.raw","data":{"timestamp":1761154832823,"type":"change","change_id":67840116660,"instrument_name":"BTC-PERPETUAL","bids":[],"asks":[["delete",107908.5,0.0],["new",107928.0,13290.0]],"prev_change_id":67840116632}}}
1761154833315 {"jsonrpc":"2.0","method":"subscription","params":{"channel":"book.BTC-PERPETUAL.raw","data":{"timestamp":1761154832824,"type":"change","change_id":67840116662,"instrument_name":"BTC-PERPETUAL","bids":[["new",107902.0,30.0],["delete",107875.0,0.0]],"asks":[],"prev_change_id":67840116660}}}
1761154833349 {"jsonrpc":"2.0","method":"subscription","params":{"channel":"book.BTC-PERPETUAL.raw","data":{"timestamp":1761154832865,"type":"change","change_id":67840116700,"instrument_name":"BTC-PERPETUAL","bids":[],"asks":[["delete",107909.0,0.0],["new",107925.5,8440.0]],"prev_change_id":67840116662}}}
1761154833356 {"jsonrpc":"2.0","method":"subscription","params":{"channel":"book.BTC-PERPETUAL.raw","data":{"timestamp":1761154832867,"type":"change","change_id":67840116702,"instrument_name":"BTC-PERPETUAL","bids":[["new",107902.5,4.0e4],["delete",107873.0,0.0]],"asks":[],"prev_change_id":67840116700}}}
1761154833396 {"jsonrpc":"2.0","method":"subscription","params":{"channel":"book.BTC-PERPETUAL.raw","data":{"timestamp":1761154832906,"type":"change","change_id":67840116713,"instrument_name":"BTC-PERPETUAL","bids":[],"asks":[["delete",107912.0,0.0],["new",107925.0,20.0]],"prev_change_id":67840116702}}}
1761154833401 {"jsonrpc":"2.0","method":"subscription","params":{"channel":"book.BTC-PERPETUAL.raw","data":{"timestamp":1761154832908,"type":"change","change_id":67840116715,"instrument_name":"BTC-PERPETUAL","bids":[["new",107903.0,61590.0],["delete",107871.5,0.0]],"asks":[],"prev_change_id":67840116713}}}
1761154833443 {"jsonrpc":"2.0","method":"subscription","params":{"channel":"book.BTC-PERPETUAL.raw","data":{"timestamp":1761154832947,"type":"change","change_id":67840116725,"instrument_name":"BTC-PERPETUAL","bids":[],"asks":[["delete",107912.5,0.0],["new",107923.0,9.52e4]],"prev_change_id":67840116715}}}
1761154833449 {"jsonrpc":"2.0","method":"subscription","params":{"channel":"book.BTC-PERPETUAL.raw","data":{"timestamp":1761154832949,"type":"change","change_id":67840116727,"instrument_name":"BTC-PERPETUAL","bids":[["new",107903.5,30960.0],["delete",107871.0,0.0]],"asks":[],"prev_change_id":67840116725}}}
1761154833454 {"jsonrpc":"2.0","method":"subscription","params":{"channel":"book.BTC-PERPETUAL.raw","data":{"timestamp":1761154832963,"type":"change","change_id":67840116729,"instrument_name":"BTC-PERPETUAL","bids":[],"asks":[["change",107947.0,8770.0],["new",107963.0,5625750.0]],"prev_change_id":67840116727}}}
1761154833479 {"jsonrpc":"2.0","method":"subscription","params":{"channel":"book.BTC-PERPETUAL.raw","data":{"timestamp":1761154832987,"type":"change","change_id":67840116739,"instrument_name":"BTC-PERPETUAL","bids":[],"asks":[["delete",107915.5,0.0],["new",107922.5,33630.0]],"prev_change_id":67840116729}}}
1761154833484 {"jsonrpc":"2.0","method":"subscription","params":{"channel":"book.BTC-PERPETUAL.raw","data":{"timestamp":1761154832989,"type":"change","change_id":67840116741,"instrument_name":"BTC-PERPETUAL","bids":[["new",107908.0,5.49e4],["delete",107866.5,0.0]],"asks":[],"prev_change_id":67840116739}}}
1761154833528 {"jsonrpc":"2.0","method":"subscription","params":{"channel":"book.BTC-PERPETUAL.raw","data":{"timestamp":1761154833028,"type":"change","change_id":67840116867,"instrument_name":"BTC-PERPETUAL","bids":[],"asks":[["new",107914.0,6.0e3],["delete",107916.0,0.0]],"prev_change_id":67840116741}}}
1761154833533 {"jsonrpc":"2.0","method":"subscription","params":{"channel":"book.BTC-PERPETUAL.raw","data":{"timestamp":1761154833030,"type":"change","change_id":67840116869,"instrument_name":"BTC-PERPETUAL","bids":[["new",107908.5,1.64e4],["delete",107865.5,0.0]],"asks":[],"prev_change_id":67840116867}}}
1761154833569 {"jsonrpc":"2.0","method":"subscription","params":{"channel":"book.BTC-PERPETUAL.raw","data":{"timestamp":1761154833070,"type":"change","change_id":67840116881,"instrument_name":"BTC-PERPETUAL","bids":[],"asks":[["new",107909.5,40380.0],["delete",107921.0,0.0]],"prev_change_id":67840116869}}}
1761154833574 {"jsonrpc":"2.0","method":"subscription","params":{"channel":"book.BTC-PERPETUAL.raw","data":{"timestamp":1761154833072,"type":"change","change_id":67840116883,"instrument_name":"BTC-PERPETUAL","bids":[["new",107909.0,413380.0],["delete",107865.0,0.0]],"asks":[],"prev_change_id":67840116881}}}
1761154833668 {"jsonrpc":"2.0","method":"subscription","params":{"channel":"book.ETH-PERPETUAL.raw","data":{"timestamp":1761154833161,"type":"change","change_id":46343817110,"instrument_name":"ETH-PERPETUAL","bids":[["new",3826.2,715.0]],"asks":[],"prev_change_id":46343815613}}}
1761154833961 {"jsonrpc":"2.0","method":"subscription","params":{"channel":"book.BTC-PERPETUAL.raw","data":{"timestamp":1761154833442,"type":"change","change_id":67840117724,"instrument_name":"BTC-PERPETUAL","bids":[["new",107645.0,8.0085e6],["delete",107629.0,0.0]],"asks":[],"prev_change_id":67840116883}}}
1761154834306 {"jsonrpc":"2.0","method":"subscription","params":{"channel":"book.BTC-PERPETUAL.raw","data":{"timestamp":1761154833766,"type":"change","change_id":67840118063,"instrument_name":"BTC-PERPETUAL","bids":[],"asks":[["delete",108157.5,0.0],["new",108173.5,7.087e6]],"prev_change_id":67840117724}}}
1761154834571 {"jsonrpc":"2.0","method":"subscription","params":{"channel":"book.BTC-PERPETUAL.raw","data":{"timestamp":1761154834017,"type":"change","change_id":67840118236,"instrument_name":"BTC-PERPETUAL","bids":[["new",107717.0,2.0e4],["change",107636.5,1.65e5]],"asks":[],"prev_change_id":67840118063}}}
1761154835061 {"jsonrpc":"2.0","method":"subscription","params":{"channel":"book.BTC-PERPETUAL.raw","data":{"timestamp":1761154834477,"type":"change","change_id":67840118949,"instrument_name":"BTC-PERPETUAL","bids":[["new",107677.0,8.0e4],["change",107636.5,8.5e4]],"asks":[],"prev_change_id":67840118236}}}
1761154835488 {"jsonrpc":"2.0","method":"subscription","params":{"channel":"book.BTC-PERPETUAL.raw","data":{"timestamp":1761154834882,"type":"change","change_id":67840119281,"instrument_name":"BTC-PERPETUAL","bids":[["new",107727.5,5.0e3],["change",107636.5,8.0e4]],"asks":[],"prev_change_id":67840118949}}}
1761154835758 {"jsonrpc":"2.0","method":"subscription","params":{"channel":"book.BTC-PERPETUAL.raw","data":{"timestamp":1761154835136,"type":"change","change_id":67840119395,"instrument_name":"BTC-PERPETUAL","bids":[["new",107645.5,3.2e5],["change",107637.0,3.4e5]],"asks":[],"prev_change_id":67840119281}}}
1761154836496 {"jsonrpc":"2.0","method":"subscription","params":{"channel":"book.ETH-PERPETUAL.raw","data":{"timestamp":1761154835829,"type":"change","change_id":46343820265,"instrument_name":"ETH-PERPETUAL","bids":[],"asks":[["delete",3826.25,0.0],["change",3827.8,4681.0]],"prev_change_id":46343817110}}}
1761154836502 {"jsonrpc":"2.0","method":"subscription","params":{"channel":"book.ETH-PERPETUAL.raw","data":{"timestamp":1761154835830,"type":"change","change_id":46343820266,"instrument_name":"ETH-PERPETUAL","bids":[["delete",3826.15,0.0],["new",3824.15,4431.0]],"asks":[],"prev_change_id":46343820265}}}
1761154836535 {"jsonrpc":"2.0","method":"subscription","params":{"channel":"book.ETH-PERPETUAL.raw","data":{"timestamp":1761154835869,"type":"change","change_id":46343820269,"instrument_name":"ETH-PERPETUAL","bids":[],"asks":[["delete",3826.5,0.0],["change",3827.75,30776.0]],"prev_change_id":46343820266}}}
1761154836541 {"jsonrpc":"2.0","method":"subscription","params":{"channel":"book.ETH-PERPETUAL.raw","data":{"timestamp":1761154835870,"type":"change","change_id":46343820270,"instrument_name":"ETH-PERPETUAL","bids":[["delete",3826.1,0.0],["change",3824.25,19083.0]],"asks":[],"prev_change_id":46343820269}}}
1761154836578 {"jsonrpc":"2.0","method":"subscription","params":{"channel":"book.ETH-PERPETUAL.raw","data":{"timestamp":1761154835908,"type":"change","change_id":46343820271,"instrument_name":"ETH-PERPETUAL","bids":[],"asks":[["delete",3826.55,0.0],["change",3827.65,8896.0]],"prev_change_id":46343820270}}}
1761154836585 {"jsonrpc":"2.0","method":"subscription","params":{"channel":"book.ETH-PERPETUAL.raw","data":{"timestamp":1761154835910,"type":"change","change_id":46343820272,"instrument_name":"ETH-PERPETUAL","bids":[["delete",3825.9,0.0],["change",3824.4,8129.0]],"asks":[],"prev_change_id":46343820271}}}
1761154836590 {"jsonrpc":"2.0","method":"subscription","params":{"channel":"book.BTC-PERPETUAL.raw","data":{"timestamp":1761154835917,"type":"change","change_id":67840120444,"instrument_name":"BTC-PERPETUAL","bids":[["new",107668.0,8.0e4],["delete",107636.5,0.0]],"asks":[],"prev_change_id":67840119395}}}
1761154836620 {"jsonrpc":"2.0","method":"subscription","params":{"channel":"book.ETH-PERPETUAL.raw","data":{"timestamp":1761154835948,"type":"change","change_id":46343820420,"instrument_name":"ETH-PERPETUAL","bids":[],"asks":[["delete",3826.6,0.0],["change",3827.6,11842.0]],"prev_change_id":46343820272}}}
1761154836628 {"jsonrpc":"2.0","method":"subscription","params":{"channel":"book.ETH-PERPETUAL.raw","data":{"timestamp":1761154835950,"type":"change","change_id":46343820421,"instrument_name":"ETH-PERPETUAL","bids":[["delete",3825.65,0.0],["change",3824.5,3331.0]],"asks":[],"prev_change_id":46343820420}}}
1761154836663 {"jsonrpc":"2.0","method":"subscription","params":{"channel":"book.ETH-PERPETUAL.raw","data":{"timestamp":1761154835989,"type":"change","change_id":46343820424,"instrument_name":"ETH-PERPETUAL","bids":[],"asks":[["change",3826.8,6972069.0],["change",3827.55,13245.0]],"prev_change_id":46343820421}}}
1761154836668 {"jsonrpc":"2.0","method":"subscription","params":{"channel":"book.ETH-PERPETUAL.raw","data":{"timestamp":1761154835990,"type":"change","change_id":46343820425,"instrument_name":"ETH-PERPETUAL","bids":[["delete",3825.6,0.0],["change",3824.55,3638.0]],"asks":[],"prev_change_id":46343820424}}}
1761154836706 {"jsonrpc":"2.0","method":"subscription","params":{"channel":"book.ETH-PERPETUAL.raw","data":{"timestamp":1761154836029,"type":"change","change_id":46343820484,"instrument_name":"ETH-PERPETUAL","bids":[],"asks":[["delete",3826.95,0.0],["change",3827.45,25613.0]],"prev_change_id":46343820425}}}
1761154836713 {"jsonrpc":"2.0","method":"subscription","params":{"channel":"book.ETH-PERPETUAL.raw","data":{"timestamp":1761154836031,"type":"change","change_id":46343820485,"instrument_name":"ETH-PERPETUAL","bids":[["delete",3825.55,0.0],["change",3824.65,2767.0]],"asks":[],"prev_change_id":46343820484}}}
1761154836750 {"jsonrpc":"2.0","method":"subscription","params":{"channel":"book.ETH-PERPETUAL.raw","data":{"timestamp":1761154836068,"type":"change","change_id":46343820488,"instrument_name":"ETH-PERPETUAL","bids":[],"asks":[["delete",3827.05,0.0],["new",3827.3,16717.0]],"prev_change_id":46343820485}}}
1761154836755 {"jsonrpc":"2.0","method":"subscription","params":{"channel":"book.ETH-PERPETUAL.raw","data":{"timestamp":1761154836070,"type":"change","change_id":46343820489,"instrument_name":"ETH-PERPETUAL","bids":[["delete",3825.4,0.0],["new",3824.75,19986.0]],"asks":[],"prev_change_id":46343820488}}}
1761154836790 {"jsonrpc":"2.0","method":"subscription","params":{"channel":"book.ETH-PERPETUAL.raw","data":{"timestamp":1761154836108,"type":"change","change_id":46343820494,"instrument_name":"ETH-PERPETUAL","bids":[],"asks":[["delete",3827.1,0.0],["change",3827.25,8896.0]],"prev_change_id":46343820489}}}
1761154836796 {"jsonrpc":"2.0","method":"subscription","params":{"channel":"book.ETH-PERPETUAL.raw","data":{"timestamp":1761154836110,"type":"change","change_id":46343820495,"instrument_name":"ETH-PERPETUAL","bids":[["delete",3825.35,0.0],["change",3824.85,28848.0]],"asks":[],"prev_change_id":46343820494}}}
1761154836834 {"jsonrpc":"2.0","method":"subscription","params":{"channel":"book.ETH-PERPETUAL.raw","data":{"timestamp":1761154836149,"type":"change","change_id":46343820611,"instrument_name":"ETH-PERPETUAL","bids":[],"asks":[["delete",3827.15,0.0],["change",3827.2,7066.0]],"prev_change_id":46343820495}}}
1761154836846 {"jsonrpc":"2.0","method":"subscription","params":{"channel":"book.ETH-PERPETUAL.raw","data":{"timestamp":1761154836151,"type":"change","change_id":46343820612,"instrument_name":"ETH-PERPETUAL","bids":[["delete",3825.15,0.0],["change",3824.9,34119.0]],"asks":[],"prev_change_id":46343820611}}}
1761154836876 {"jsonrpc":"2.0","method":"subscription","params":{"channel":"book.ETH-PERPETUAL.raw","data":{"timestamp":1761154836189,"type":"change","change_id":46343820743,"instrument_name":"ETH-PERPETUAL","bids":[],"asks":[["new",3827.1,3.0e4],["change",3827.2,1328.0]],"prev_change_id":46343820612}}}
1761154836886 {"jsonrpc":"2.0","method":"subscription","params":{"channel":"book.ETH-PERPETUAL.raw","data":{"timestamp":1761154836190,"type":"change","change_id":46343820745,"instrument_name":"ETH-PERPETUAL","bids":[["delete",3825.1,0.0],["change",3825.0,11464.0]],"asks":[],"prev_change_id":46343820743}}}
1761154836923 {"jsonrpc":"2.0","method":"subscription","params":{"channel":"book.ETH-PERPETUAL.raw","data":{"timestamp":1761154836229,"type":"change","change_id":46343820753,"instrument_name":"ETH-PERPETUAL","bids":[],"asks":[["new",3827.05,10619.0],["change",3827.25,4448.0]],"prev_change_id":46343820745}}}
1761154836929 {"jsonrpc":"2.0","method":"subscription","params":{"channel":"book.ETH-PERPETUAL.raw","data":{"timestamp":1761154836230,"type":"change","change_id":46343820754,"instrument_name":"ETH-PERPETUAL","bids":[["new",3825.1,15129.0],["change",3825.0,3.0]],"asks":[],"prev_change_id":46343820753}}}
1761154836986 {"jsonrpc":"2.0","method":"subscription","params":{"channel":"book.ETH-PERPETUAL.raw","data":{"timestamp":1761154836291,"type":"change","change_id":46343820762,"instrument_name":"ETH-PERPETUAL","bids":[],"asks":[["new",3827.0,16717.0],["delete",3827.4,0.0]],"prev_change_id":46343820754}}}
1761154836992 {"jsonrpc":"2.0","method":"subscription","params":{"channel":"book.ETH-PERPETUAL.raw","data":{"timestamp":1761154836292,"type":"change","change_id":46343820763,"instrument_name":"ETH-PERPETUAL","bids":[["new",3825.15,11623.0],["change",3824.9,32455.0]],"asks":[],"prev_change_id":46343820762}}}
1761154837030 {"jsonrpc":"2.0","method":"subscription","params":{"channel":"book.ETH-PERPETUAL.raw","data":{"timestamp":1761154836332,"type":"change","change_id":46343820797,"instrument_name":"ETH-PERPETUAL","bids":[],"asks":[["new",3826.95,18629.0],["change",3827.45,4448.0]],"prev_change_id":46343820763}}}
1761154837036 {"jsonrpc":"2.0","method":"subscription","params":{"channel":"book.ETH-PERPETUAL.raw","data":{"timestamp":1761154836333,"type":"change","change_id":46343820798,"instrument_name":"ETH-PERPETUAL","bids":[["new",3825.3,1322.0],["change",3824.85,4431.0]],"asks":[],"prev_change_id":46343820797}}}
1761154837072 {"jsonrpc":"2.0","method":"subscription","params":{"channel":"book.ETH-PERPETUAL.raw","data":{"timestamp":1761154836371,"type":"change","change_id":46343820807,"instrument_name":"ETH-PERPETUAL","bids":[],"asks":[["new",3826.9,4410.0],["change",3827.55,1584.0]],"prev_change_id":46343820798}}}
1761154837082 {"jsonrpc":"2.0","method":"subscription","params":{"channel":"book.ETH-PERPETUAL.raw","data":{"timestamp":1761154836373,"type":"change","change_id":46343820808,"instrument_name":"ETH-PERPETUAL","bids":[["new",3825.35,1.5e4],["delete",3824.8,0.0]],"asks":[],"prev_change_id":46343820807}}}
1761154837122 {"jsonrpc":"2.0","method":"subscription","params":{"channel":"book.ETH-PERPETUAL.raw","data":{"timestamp":1761154836413,"type":"change","change_id":46343820817,"instrument_name":"ETH-PERPETUAL","bids":[],"asks":[["change",3826.8,6985519.0],["change",3827.6,5921.0]],"prev_change_id":46343820808}}}
1761154837127 {"jsonrpc":"2.0","method":"subscription","params":{"channel":"book.ETH-PERPETUAL.raw","data":{"timestamp":1761154836415,"type":"change","change_id":46343820818,"instrument_name":"ETH-PERPETUAL","bids":[["new",3825.4,18354.0],["change",3824.65,2517.0]],"asks":[],"prev_change_id":46343820817}}}
1761154837161 {"jsonrpc":"2.0","method":"subscription","params":{"channel":"book.ETH-PERPETUAL.raw","data":{"timestamp":1761154836453,"type":"change","change_id":46343821064,"instrument_name":"ETH-PERPETUAL","bids":[],"asks":[["new",3826.7,66717.0],["change",3827.65,4448.0]],"prev_change_id":46343820818}}}
1761154837168 {"jsonrpc":"2.0","method":"subscription","params":{"channel":"book.ETH-PERPETUAL.raw","data":{"timestamp":1761154836455,"type":"change","change_id":46343821065,"instrument_name":"ETH-PERPETUAL","bids":[["new",3825.6,9412.0],["change",3824.55,1819.0]],"asks":[],"prev_change_id":46343821064}}}
1761154837206 {"jsonrpc":"2.0","method":"subscription","params":{"channel":"book.ETH-PERPETUAL.raw","data":{"timestamp":1761154836494,"type":"change","change_id":46343821076,"instrument_name":"ETH-PERPETUAL","bids":[],"asks":[["new",3826.6,19277.0],["change",3827.75,15388.0]],"prev_change_id":46343821065}}}
1761154837211 {"jsonrpc":"2.0","method":"subscription","params":{"channel":"book.ETH-PERPETUAL.raw","data":{"timestamp":1761154836495,"type":"change","change_id":46343821077,"instrument_name":"ETH-PERPETUAL","bids":[["new",3825.75,19994.0],["change",3824.5,1667.0]],"asks":[],"prev_change_id":46343821076}}}
1761154837247 {"jsonrpc":"2.0","method":"subscription","params":{"channel":"book.ETH-PERPETUAL.raw","data":{"timestamp":1761154836534,"type":"change","change_id":46343821088,"instrument_name":"ETH-PERPETUAL","bids":[],"asks":[["new",3826.55,9.7e3],["change",3827.8,2852.0]],"prev_change_id":46343821077}}}
1761154837253 {"jsonrpc":"2.0","method":"subscription","params":{"channel":"book.ETH-PERPETUAL.raw","data":{"timestamp":1761154836535,"type":"change","change_id":46343821089,"instrument_name":"ETH-PERPETUAL","bids":[["new",3825.8,5235.0],["change",3824.4,4431.0]],"asks":[],"prev_change_id":46343821088}}}
1761154837283 {"jsonrpc":"2.0","method":"subscription","params":{"channel":"book.BTC-PERPETUAL.raw","data":{"timestamp":1761154836562,"type":"change","change_id":67840121383,"instrument_name":"BTC-PERPETUAL","bids":[["change",107645.5,6.4e5],["change",107637.0,2.0e4]],"asks":[],"prev_change_id":67840120444}}}
1761154837289 {"jsonrpc":"2.0","method":"subscription","params":{"channel":"book.ETH-PERPETUAL.raw","data":{"timestamp":1761154836573,"type":"change","change_id":46343821409,"instrument_name":"ETH-PERPETUAL","bids":[],"asks":[["new",3826.5,2895.0],["delete",3828.0,0.0]],"prev_change_id":46343821089}}}
1761154837293 {"jsonrpc":"2.0","method":"subscription","params":{"channel":"book.ETH-PERPETUAL.raw","data":{"timestamp":1761154836574,"type":"change","change_id":46343821410,"instrument_name":"ETH-PERPETUAL","bids":[["new",3825.85,1423.0],["delete",3824.3,0.0]],"asks":[],"prev_change_id":46343821409}}}
1761154837337 {"jsonrpc":"2.0","method":"subscription","params":{"channel":"book.ETH-PERPETUAL.raw","data":{"timestamp":1761154836613,"type":"change","change_id":46343821423,"instrument_name":"ETH-PERPETUAL","bids":[],"asks":[["new",3826.25,8966.0]],"prev_change_id":46343821410}}}
1761154837343 {"jsonrpc":"2.0","method":"subscription","params":{"channel":"book.ETH-PERPETUAL.raw","data":{"timestamp":1761154836614,"type":"change","change_id":46343821424,"instrument_name":"ETH-PERPETUAL","bids":[["new",3826.15,4270.0],["change",3824.25,1323.0]],"asks":[],"prev_change_id":46343821423}}}
1761154837442 {"jsonrpc":"2.0","method":"subscription","params":{"channel":"book.ETH-PERPETUAL.raw","data":{"timestamp":1761154836715,"type":"change","change_id":46343821503,"instrument_name":"ETH-PERPETUAL","bids":[],"asks":[["change",3826.8,13450.0],["change",3827.75,6987457.0]],"prev_change_id":46343821424}}}
1761154838046 {"jsonrpc":"2.0","method":"subscription","params":{"channel":"book.BTC-PERPETUAL.raw","data":{"timestamp":1761154837280,"type":"change","change_id":67840121837,"instrument_name":"BTC-PERPETUAL","bids":[["new",107723.0,2.0e4],["delete",107637.0,0.0]],"asks":[],"prev_change_id":67840121383}}}
1761154838328 {"jsonrpc":"2.0","method":"subscription","params":{"channel":"book.BTC-PERPETUAL.raw","data":{"timestamp":1761154837540,"type":"change","change_id":67840122540,"instrument_name":"BTC-PERPETUAL","bids":[],"asks":[["delete",107909.5,0.0],["change",107939.5,27560.0]],"prev_change_id":67840121837}}}
1761154838335 {"jsonrpc":"2.0","method":"subscription","params":{"channel":"book.BTC-PERPETUAL.raw","data":{"timestamp":1761154837549,"type":"change","change_id":67840122541,"instrument_name":"BTC-PERPETUAL","bids":[["delete",107909.0,0.0],["new",107882.5,38420.0]],"asks":[],"prev_change_id":67840122540}}}
1761154838372 {"jsonrpc":"2.0","method":"subscription","params":{"channel":"book.BTC-PERPETUAL.raw","data":{"timestamp":1761154837583,"type":"change","change_id":67840122694,"instrument_name":"BTC-PERPETUAL","bids":[],"asks":[["delete",107914.0,0.0],["change",107939.0,27630.0]],"prev_change_id":67840122541}}}
1761154838389 {"jsonrpc":"2.0","method":"subscription","params":{"channel":"book.BTC-PERPETUAL.raw","data":{"timestamp":1761154837590,"type":"change","change_id":67840122695,"instrument_name":"BTC-PERPETUAL","bids":[["delete",107908.5,0.0],["new",107883.5,5.03e4]],"asks":[],"prev_change_id":67840122694}}}
1761154838415 {"jsonrpc":"2.0","method":"subscription","params":{"channel":"book.BTC-PERPETUAL.raw","data":{"timestamp":1761154837623,"type":"change","change_id":67840122696,"instrument_name":"BTC-PERPETUAL","bids":[],"asks":[["delete",107922.5,0.0],["new",107938.5,18640.0]],"prev_change_id":67840122695}}}
1761154838424 {"jsonrpc":"2.0","method":"subscription","params":{"channel":"book.BTC-PERPETUAL.raw","data":{"timestamp":1761154837630,"type":"change","change_id":67840122697,"instrument_name":"BTC-PERPETUAL","bids":[["delete",107908.0,0.0],["new",107884.0,20990.0]],"asks":[],"prev_change_id":67840122696}}}
1761154838463 {"jsonrpc":"2.0","method":"subscription","params":{"channel":"book.BTC-PERPETUAL.raw","data":{"timestamp":1761154837663,"type":"change","change_id":67840122699,"instrument_name":"BTC-PERPETUAL","bids":[],"asks":[["delete",107923.0,0.0],["new",107937.0,8440.0]],"prev_change_id":67840122697}}}
1761154838468 {"jsonrpc":"2.0","method":"subscription","params":{"channel":"book.BTC-PERPETUAL.raw","data":{"timestamp":1761154837669,"type":"change","change_id":67840122701,"instrument_name":"BTC-PERPETUAL","bids":[["delete",107903.5,0.0],["change",107886.5,4.2e3]],"asks":[],"prev_change_id":67840122699}}}
1761154838502 {"jsonrpc":"2.0","method":"subscription","params":{"channel":"book.BTC-PERPETUAL.raw","data":{"timestamp":1761154837705,"type":"change","change_id":67840122703,"instrument_name":"BTC-PERPETUAL","bids":[],"asks":[["delete",107925.0,0.0],["new",107936.5,500.0]],"prev_change_id":67840122701}}}
1761154838508 {"jsonrpc":"2.0","method":"subscription","params":{"channel":"book.BTC-PERPETUAL.raw","data":{"timestamp":1761154837709,"type":"change","change_id":67840122705,"instrument_name":"BTC-PERPETUAL","bids":[["delete",107903.0,0.0],["change",107887.0,6.63e4]],"asks":[],"prev_change_id":67840122703}}}
1761154838545 {"jsonrpc":"2.0","method":"subscription","params":{"channel":"book.BTC-PERPETUAL.raw","data":{"timestamp":1761154837745,"type":"change","change_id":67840122735,"instrument_name":"BTC-PERPETUAL","bids":[],"asks":[["delete",107925.5,0.0],["new",107933.0,2670.0]],"prev_change_id":67840122705}}}
1761154838550 {"jsonrpc":"2.0","method":"subscription","params":{"channel":"book.BTC-PERPETUAL.raw","data":{"timestamp":1761154837750,"type":"change","change_id":67840122737,"instrument_name":"BTC-PERPETUAL","bids":[["delete",107902.5,0.0],["change",107888.0,74190.0]],"asks":[],"prev_change_id":67840122735}}}
1761154838593 {"jsonrpc":"2.0","method":"subscription","params":{"channel":"book.BTC-PERPETUAL.raw","data":{"timestamp":1761154837790,"type":"change","change_id":67840122740,"instrument_name":"BTC-PERPETUAL","bids":[],"asks":[["delete",107928.0,0.0],["change",107932.0,74760.0]],"prev_change_id":67840122737}}}
1761154838600 {"jsonrpc":"2.0","method":"subscription","params":{"channel":"book.BTC-PERPETUAL.raw","data":{"timestamp":1761154837792,"type":"change","change_id":67840122743,"instrument_name":"BTC-PERPETUAL","bids":[["delete",107902.0,0.0],["new",107889.0,5.0e3]],"asks":[],"prev_change_id":67840122740}}}
1761154838639 {"jsonrpc":"2.0","method":"subscription","params":{"channel":"book.BTC-PERPETUAL.raw","data":{"timestamp":1761154837832,"type":"change","change_id":67840122766,"instrument_name":"BTC-PERPETUAL","bids":[],"asks":[["delete",107929.0,0.0],["new",107931.5,8620.0]],"prev_change_id":67840122743}}}
1761154838644 {"jsonrpc":"2.0","method":"subscription","params":{"channel":"book.BTC-PERPETUAL.raw","data":{"timestamp":1761154837834,"type":"change","change_id":67840122769,"instrument_name":"BTC-PERPETUAL","bids":[["delete",1.079e5,0.0],["new",107890.5,49260.0]],"asks":[],"prev_change_id":67840122766}}}
1761154838683 {"jsonrpc":"2.0","method":"subscription","params":{"channel":"book.BTC-PERPETUAL.raw","data":{"timestamp":1761154837872,"type":"change","change_id":67840122802,"instrument_name":"BTC-PERPETUAL","bids":[],"asks":[["delete",107929.5,0.0],["change",107930.5,7.52e4]],"prev_change_id":67840122769}}}
1761154838688 {"jsonrpc":"2.0","method":"subscription","params":{"channel":"book.BTC-PERPETUAL.raw","data":{"timestamp":1761154837876,"type":"change","change_id":67840122805,"instrument_name":"BTC-PERPETUAL","bids":[["delete",107899.0,0.0],["new",107892.5,172620.0]],"asks":[],"prev_change_id":67840122802}}}
1761154838725 {"jsonrpc":"2.0","method":"subscription","params":{"channel":"book.BTC-PERPETUAL.raw","data":{"timestamp":1761154837912,"type":"change","change_id":67840122815,"instrument_name":"BTC-PERPETUAL","bids":[],"asks":[["new",107926.5,31330.0],["change",107930.5,7.02e4]],"prev_change_id":67840122805}}}
1761154838734 {"jsonrpc":"2.0","method":"subscription","params":{"channel":"book.BTC-PERPETUAL.raw","data":{"timestamp":1761154837916,"type":"change","change_id":67840122818,"instrument_name":"BTC-PERPETUAL","bids":[["delete",107898.5,0.0],["change",107893.0,6.23e4]],"asks":[],"prev_change_id":67840122815}}}
1761154838772 {"jsonrpc":"2.0","method":"subscription","params":{"channel":"book.BTC-PERPETUAL.raw","data":{"timestamp":1761154837952,"type":"change","change_id":67840122823,"instrument_name":"BTC-PERPETUAL","bids":[],"asks":[["new",107925.0,20.0],["change",107932.0,33160.0]],"prev_change_id":67840122818}}}
1761154838782 {"jsonrpc":"2.0","method":"subscription","params":{"channel":"book.BTC-PERPETUAL.raw","data":{"timestamp":1761154837956,"type":"change","change_id":67840122826,"instrument_name":"BTC-PERPETUAL","bids":[["delete",107898.0,0.0],["new",107897.5,5.03e4]],"asks":[],"prev_change_id":67840122823}}}
1761154838818 {"jsonrpc":"2.0","method":"subscription","params":{"channel":"book.BTC-PERPETUAL.raw","data":{"timestamp":1761154837992,"type":"change","change_id":67840122831,"instrument_name":"BTC-PERPETUAL","bids":[],"asks":[["new",107923.5,20.0],["delete",107935.5,0.0]],"prev_change_id":67840122826}}}
1761154838834 {"jsonrpc":"2.0","method":"subscription","params":{"channel":"book.BTC-PERPETUAL.raw","data":{"timestamp":1761154837996,"type":"change","change_id":67840122834,"instrument_name":"BTC-PERPETUAL","bids":[["new",107898.0,8620.0],["delete",107894.0,0.0]],"asks":[],"prev_change_id":67840122831}}}
1761154838853 {"jsonrpc":"2.0","method":"subscription","params":{"channel":"book.BTC-PERPETUAL.raw","data":{"timestamp":1761154838031,"type":"change","change_id":67840122957,"instrument_name":"BTC-PERPETUAL","bids":[],"asks":[["new",107923.0,20.0],["delete",107936.0,0.0]],"prev_change_id":67840122834}}}
1761154838863 {"jsonrpc":"2.0","method":"subscription","params":{"channel":"book.BTC-PERPETUAL.raw","data":{"timestamp":1761154838036,"type":"change","change_id":67840122960,"instrument_name":"BTC-PERPETUAL","bids":[["new",107899.0,17590.0],["delete",107893.5,0.0]],"asks":[],"prev_change_id":67840122957}}}
1761154838896 {"jsonrpc":"2.0","method":"subscription","params":{"channel":"book.BTC-PERPETUAL.raw","data":{"timestamp":1761154838072,"type":"change","change_id":67840122967,"instrument_name":"BTC-PERPETUAL","bids":[],"asks":[["new",107922.5,20.0],["change",107939.0,13820.0]],"prev_change_id":67840122960}}}
1761154838901 {"jsonrpc":"2.0","method":"subscription","params":{"channel":"book.BTC-PERPETUAL.raw","data":{"timestamp":1761154838076,"type":"change","change_id":67840122970,"instrument_name":"BTC-PERPETUAL","bids":[["new",1.079e5,2.1e3],["change",107893.0,5.37e4]],"asks":[],"prev_change_id":67840122967}}}
1761154838942 {"jsonrpc":"2.0","method":"subscription","params":{"channel":"book.BTC-PERPETUAL.raw","data":{"timestamp":1761154838113,"type":"change","change_id":67840122978,"instrument_name":"BTC-PERPETUAL","bids":[],"asks":[["new",107922.0,20.0],["change",107939.5,1.1e4]],"prev_change_id":67840122970}}}
1761154838948 {"jsonrpc":"2.0","method":"subscription","params":{"channel":"book.BTC-PERPETUAL.raw","data":{"timestamp":1761154838118,"type":"change","change_id":67840122981,"instrument_name":"BTC-PERPETUAL","bids":[["new",107900.5,9230.0],["delete",107889.5,0.0]],"asks":[],"prev_change_id":67840122978}}}
1761154838986 {"jsonrpc":"2.0","method":"subscription","params":{"channel":"book.BTC-PERPETUAL.raw","data":{"timestamp":1761154838151,"type":"change","change_id":67840122992,"instrument_name":"BTC-PERPETUAL","bids":[],"asks":[["new",107921.5,20.0],["delete",107940.5,0.0]],"prev_change_id":67840122981}}}
1761154838990 {"jsonrpc":"2.0","method":"subscription","params":{"channel":"book.BTC-PERPETUAL.raw","data":{"timestamp":1761154838157,"type":"change","change_id":67840122996,"instrument_name":"BTC-PERPETUAL","bids":[["new",107904.0,8440.0],["change",107888.0,24190.0]],"asks":[],"prev_change_id":67840122992}}}
1761154839026 {"jsonrpc":"2.0","method":"subscription","params":{"channel":"book.BTC-PERPETUAL.raw","data":{"timestamp":1761154838193,"type":"change","change_id":67840123005,"instrument_name":"BTC-PERPETUAL","bids":[],"asks":[["new",107917.5,6.0e3],["delete",107941.5,0.0]],"prev_change_id":67840122996}}}
1761154839032 {"jsonrpc":"2.0","method":"subscription","params":{"channel":"book.BTC-PERPETUAL.raw","data":{"timestamp":1761154838196,"type":"change","change_id":67840123008,"instrument_name":"BTC-PERPETUAL","bids":[["new",107904.5,5.5e3],["delete",107887.5,0.0]],"asks":[],"prev_change_id":67840123005}}}
1761154839070 {"jsonrpc":"2.0","method":"subscription","params":{"channel":"book.BTC-PERPETUAL.raw","data":{"timestamp":1761154838234,"type":"change","change_id":67840123017,"instrument_name":"BTC-PERPETUAL","bids":[],"asks":[["new",107916.0,1.0e4],["delete",107942.5,0.0]],"prev_change_id":67840123008}}}
1761154839076 {"jsonrpc":"2.0","method":"subscription","params":{"channel":"book.BTC-PERPETUAL.raw","data":{"timestamp":1761154838236,"type":"change","change_id":67840123020,"instrument_name":"BTC-PERPETUAL","bids":[["new",107908.0,40020.0],["change",107887.0,33150.0]],"asks":[],"prev_change_id":67840123017}}}
1761154839118 {"jsonrpc":"2.0","method":"subscription","params":{"channel":"book.BTC-PERPETUAL.raw","data":{"timestamp":1761154838276,"type":"change","change_id":67840123143,"instrument_name":"BTC-PERPETUAL","bids":[],"asks":[["new",107914.0,2.5e4],["delete",107946.5,0.0]],"prev_change_id":67840123020}}}
1761154839122 {"jsonrpc":"2.0","method":"subscription","params":{"channel":"book.BTC-PERPETUAL.raw","data":{"timestamp":1761154838278,"type":"change","change_id":67840123146,"instrument_name":"BTC-PERPETUAL","bids":[["new",107908.5,11960.0],["change",107886.5,2.1e3]],"asks":[],"prev_change_id":67840123143}}}
1761154839158 {"jsonrpc":"2.0","method":"subscription","params":{"channel":"book.BTC-PERPETUAL.raw","data":{"timestamp":1761154838316,"type":"change","change_id":67840123189,"instrument_name":"BTC-PERPETUAL","bids":[],"asks":[["new",107909.5,6.76e4],["delete",107947.0,0.0]],"prev_change_id":67840123146}}}
1761154839171 {"jsonrpc":"2.0","method":"subscription","params":{"channel":"book.BTC-PERPETUAL.raw","data":{"timestamp":1761154838319,"type":"change","change_id":67840123192,"instrument_name":"BTC-PERPETUAL","bids":[["new",107909.0,493570.0],["delete",107885.0,0.0]],"asks":[],"prev_change_id":67840123189}}}
1761154842121 {"jsonrpc":"2.0","method":"subscription","params":{"channel":"book.ETH-PERPETUAL.raw","data":{"timestamp":1761154841079,"type":"change","change_id":46343826523,"instrument_name":"ETH-PERPETUAL","bids":[],"asks":[["delete",3826.25,0.0],["new",3828.65,15596.0]],"prev_change_id":46343821503}}}
1761154842128 {"jsonrpc":"2.0","method":"subscription","params":{"channel":"book.ETH-PERPETUAL.raw","data":{"timestamp":1761154841081,"type":"change","change_id":46343826524,"instrument_name":"ETH-PERPETUAL","bids":[["delete",3826.15,0.0],["change",3824.85,8862.0]],"asks":[],"prev_change_id":46343826523}}}
1761154842167 {"jsonrpc":"2.0","method":"subscription","params":{"channel":"book.ETH-PERPETUAL.raw","data":{"timestamp":1761154841121,"type":"change","change_id":46343826525,"instrument_name":"ETH-PERPETUAL","bids":[],"asks":[["delete",3826.5,0.0],["new",3828.55,1240.0]],"prev_change_id":46343826524}}}
1761154842172 {"jsonrpc":"2.0","method":"subscription","params":{"channel":"book.ETH-PERPETUAL.raw","data":{"timestamp":1761154841123,"type":"change","change_id":46343826526,"instrument_name":"ETH-PERPETUAL","bids":[["delete",3825.85,0.0],["change",3824.9,52973.0]],"asks":[],"prev_change_id":46343826525}}}
1761154842208 {"jsonrpc":"2.0","method":"subscription","params":{"channel":"book.ETH-PERPETUAL.raw","data":{"timestamp":1761154841161,"type":"change","change_id":46343826637,"instrument_name":"ETH-PERPETUAL","bids":[],"asks":[["delete",3826.55,0.0],["new",3828.45,1598.0]],"prev_change_id":46343826526}}}
1761154842214 {"jsonrpc":"2.0","method":"subscription","params":{"channel":"book.ETH-PERPETUAL.raw","data":{"timestamp":1761154841163,"type":"change","change_id":46343826638,"instrument_name":"ETH-PERPETUAL","bids":[["delete",3825.8,0.0],["change",3825.0,4339.0]],"asks":[],"prev_change_id":46343826637}}}
1761154842254 {"jsonrpc":"2.0","method":"subscription","params":{"channel":"book.ETH-PERPETUAL.raw","data":{"timestamp":1761154841200,"type":"change","change_id":46343826760,"instrument_name":"ETH-PERPETUAL","bids":[],"asks":[["delete",3826.6,0.0],["new",3828.4,4463.0]],"prev_change_id":46343826638}}}
1761154842259 {"jsonrpc":"2.0","method":"subscription","params":{"channel":"book.ETH-PERPETUAL.raw","data":{"timestamp":1761154841203,"type":"change","change_id":46343826762,"instrument_name":"ETH-PERPETUAL","bids":[["delete",3825.75,0.0],["change",3825.15,16051.0]],"asks":[],"prev_change_id":46343826760}}}
1761154842365 {"jsonrpc":"2.0","method":"subscription","params":{"channel":"book.ETH-PERPETUAL.raw","data":{"timestamp":1761154841240,"type":"change","change_id":46343826764,"instrument_name":"ETH-PERPETUAL","bids":[],"asks":[["delete",3826.7,0.0],["new",3828.35,10081.0]],"prev_change_id":46343826762}}}
1761154842371 {"jsonrpc":"2.0","method":"subscription","params":{"channel":"book.ETH-PERPETUAL.raw","data":{"timestamp":1761154841244,"type":"change","change_id":46343826766,"instrument_name":"ETH-PERPETUAL","bids":[["delete",3825.6,0.0],["new",3825.25,30397.0]],"asks":[],"prev_change_id":46343826764}}}
1761154842375 {"jsonrpc":"2.0","method":"subscription","params":{"channel":"book.ETH-PERPETUAL.raw","data":{"timestamp":1761154841280,"type":"change","change_id":46343826768,"instrument_name":"ETH-PERPETUAL","bids":[],"asks":[["delete",3826.8,0.0],["new",3828.3,4171.0]],"prev_change_id":46343826766}}}
1761154842380 {"jsonrpc":"2.0","method":"subscription","params":{"channel":"book.ETH-PERPETUAL.raw","data":{"timestamp":1761154841284,"type":"change","change_id":46343826770,"instrument_name":"ETH-PERPETUAL","bids":[["delete",3825.4,0.0],["change",3825.3,11717.0]],"asks":[],"prev_change_id":46343826768}}}
1761154842385 {"jsonrpc":"2.0","method":"subscription","params":{"channel":"book.ETH-PERPETUAL.raw","data":{"timestamp":1761154841319,"type":"change","change_id":46343826797,"instrument_name":"ETH-PERPETUAL","bids":[],"asks":[["delete",3826.9,0.0],["new",3828.2,21182.0]],"prev_change_id":46343826770}}}
1761154842411 {"jsonrpc":"2.0","method":"subscription","params":{"channel":"book.ETH-PERPETUAL.raw","data":{"timestamp":1761154841326,"type":"change","change_id":46343826801,"instrument_name":"ETH-PERPETUAL","bids":[["new",3825.4,1637.0],["delete",3825.35,0.0]],"asks":[],"prev_change_id":46343826797}}}
1761154842425 {"jsonrpc":"2.0","method":"subscription","params":{"channel":"book.ETH-PERPETUAL.raw","data":{"timestamp":1761154841360,"type":"change","change_id":46343826803,"instrument_name":"ETH-PERPETUAL","bids":[],"asks":[["delete",3826.95,0.0],["new",3828.1,4414.0]],"prev_change_id":46343826801}}}
1761154842512 {"jsonrpc":"2.0","method":"subscription","params":{"channel":"book.ETH-PERPETUAL.raw","data":{"timestamp":1761154841365,"type":"change","change_id":46343826807,"instrument_name":"ETH-PERPETUAL","bids":[["new",3825.6,4433.0],["change",3825.3,10395.0]],"asks":[],"prev_change_id":46343826803}}}
1761154842516 {"jsonrpc":"2.0","method":"subscription","params":{"channel":"book.ETH-PERPETUAL.raw","data":{"timestamp":1761154841399,"type":"change","change_id":46343826809,"instrument_name":"ETH-PERPETUAL","bids":[],"asks":[["delete",3827.0,0.0],["new",3828.05,7423.0]],"prev_change_id":46343826807}}}
1761154842520 {"jsonrpc":"2.0","method":"subscription","params":{"channel":"book.ETH-PERPETUAL.raw","data":{"timestamp":1761154841407,"type":"change","change_id":46343826813,"instrument_name":"ETH-PERPETUAL","bids":[["new",3825.65,19986.0],["change",3825.15,4428.0]],"asks":[],"prev_change_id":46343826809}}}
1761154842523 {"jsonrpc":"2.0","method":"subscription","params":{"channel":"book.ETH-PERPETUAL.raw","data":{"timestamp":1761154841439,"type":"change","change_id":46343826981,"instrument_name":"ETH-PERPETUAL","bids":[],"asks":[["delete",3827.05,0.0],["new",3828.0,6126.0]],"prev_change_id":46343826813}}}
1761154842530 {"jsonrpc":"2.0","method":"subscription","params":{"channel":"book.ETH-PERPETUAL.raw","data":{"timestamp":1761154841448,"type":"change","change_id":46343826987,"instrument_name":"ETH-PERPETUAL","bids":[["new",3825.8,19725.0],["delete",3825.1,0.0]],"asks":[],"prev_change_id":46343826981}}}
1761154842556 {"jsonrpc":"2.0","method":"subscription","params":{"channel":"book.ETH-PERPETUAL.raw","data":{"timestamp":1761154841479,"type":"change","change_id":46343827059,"instrument_name":"ETH-PERPETUAL","bids":[],"asks":[["delete",3827.1,0.0],["new",3827.85,15388.0]],"prev_change_id":46343826987}}}
1761154842561 {"jsonrpc":"2.0","method":"subscription","params":{"channel":"book.ETH-PERPETUAL.raw","data":{"timestamp":1761154841489,"type":"change","change_id":46343827065,"instrument_name":"ETH-PERPETUAL","bids":[["new",3825.85,32105.0],["change",3825.0,4336.0]],"asks":[],"prev_change_id":46343827059}}}
1761154842594 {"jsonrpc":"2.0","method":"subscription","params":{"channel":"book.ETH-PERPETUAL.raw","data":{"timestamp":1761154841518,"type":"change","change_id":46343827067,"instrument_name":"ETH-PERPETUAL","bids":[],"asks":[["delete",3827.2,0.0],["change",3827.8,9635.0]],"prev_change_id":46343827065}}}
1761154842604 {"jsonrpc":"2.0","method":"subscription","params":{"channel":"book.ETH-PERPETUAL.raw","data":{"timestamp":1761154841530,"type":"change","change_id":46343827073,"instrument_name":"ETH-PERPETUAL","bids":[["new",3825.9,4433.0],["change",3824.9,20518.0]],"asks":[],"prev_change_id":46343827067}}}
1761154842634 {"jsonrpc":"2.0","method":"subscription","params":{"channel":"book.ETH-PERPETUAL.raw","data":{"timestamp":1761154841558,"type":"change","change_id":46343827075,"instrument_name":"ETH-PERPETUAL","bids":[],"asks":[["delete",3827.25,0.0],["change",3827.75,6988457.0]],"prev_change_id":46343827073}}}
1761154842652 {"jsonrpc":"2.0","method":"subscription","params":{"channel":"book.ETH-PERPETUAL.raw","data":{"timestamp":1761154841571,"type":"change","change_id":46343827083,"instrument_name":"ETH-PERPETUAL","bids":[["new",3825.95,10907.0],["change",3824.85,4431.0]],"asks":[],"prev_change_id":46343827075}}}
1761154842677 {"jsonrpc":"2.0","method":"subscription","params":{"channel":"book.ETH-PERPETUAL.raw","data":{"timestamp":1761154841597,"type":"change","change_id":46343827393,"instrument_name":"ETH-PERPETUAL","bids":[],"asks":[["delete",3827.3,0.0],["new",3827.7,16717.0]],"prev_change_id":46343827083}}}
1761154842693 {"jsonrpc":"2.0","method":"subscription","params":{"channel":"book.ETH-PERPETUAL.raw","data":{"timestamp":1761154841612,"type":"change","change_id":46343827414,"instrument_name":"ETH-PERPETUAL","bids":[["new",3826.0,2205.0],["delete",3824.75,0.0]],"asks":[],"prev_change_id":46343827393}}}
1761154842719 {"jsonrpc":"2.0","method":"subscription","params":{"channel":"book.ETH-PERPETUAL.raw","data":{"timestamp":1761154841636,"type":"change","change_id":46343827427,"instrument_name":"ETH-PERPETUAL","bids":[],"asks":[["delete",3827.45,0.0],["change",3827.65,8896.0]],"prev_change_id":46343827414}}}
1761154842735 {"jsonrpc":"2.0","method":"subscription","params":{"channel":"book.ETH-PERPETUAL.raw","data":{"timestamp":1761154841652,"type":"change","change_id":46343827442,"instrument_name":"ETH-PERPETUAL","bids":[["delete",3824.65,0.0]],"asks":[],"prev_change_id":46343827427}}}
1761154842771 {"jsonrpc":"2.0","method":"subscription","params":{"channel":"book.ETH-PERPETUAL.raw","data":{"timestamp":1761154841676,"type":"change","change_id":46343827493,"instrument_name":"ETH-PERPETUAL","bids":[],"asks":[["delete",3827.55,0.0],["change",3827.6,62537.0]],"prev_change_id":46343827442}}}
1761154842780 {"jsonrpc":"2.0","method":"subscription","params":{"channel":"book.ETH-PERPETUAL.raw","data":{"timestamp":1761154841693,"type":"change","change_id":46343827504,"instrument_name":"ETH-PERPETUAL","bids":[["new",3826.1,2.2e4],["delete",3824.55,0.0]],"asks":[],"prev_change_id":46343827493}}}
1761154842809 {"jsonrpc":"2.0","method":"subscription","params":{"channel":"book.ETH-PERPETUAL.raw","data":{"timestamp":1761154841721,"type":"change","change_id":46343827520,"instrument_name":"ETH-PERPETUAL","bids":[],"asks":[["new",3827.55,14723.0],["change",3827.6,56616.0]],"prev_change_id":46343827504}}}
1761154842827 {"jsonrpc":"2.0","method":"subscription","params":{"channel":"book.ETH-PERPETUAL.raw","data":{"timestamp":1761154841733,"type":"change","change_id":46343827532,"instrument_name":"ETH-PERPETUAL","bids":[["new",3826.15,28016.0],["delete",3824.5,0.0]],"asks":[],"prev_change_id":46343827520}}}
1761154842857 {"jsonrpc":"2.0","method":"subscription","params":{"channel":"book.ETH-PERPETUAL.raw","data":{"timestamp":1761154841763,"type":"change","change_id":46343827537,"instrument_name":"ETH-PERPETUAL","bids":[],"asks":[["new",3827.3,26776.0],["change",3827.65,4448.0]],"prev_change_id":46343827532}}}
1761154842867 {"jsonrpc":"2.0","method":"subscription","params":{"channel":"book.ETH-PERPETUAL.raw","data":{"timestamp":1761154841773,"type":"change","change_id":46343827549,"instrument_name":"ETH-PERPETUAL","bids":[["new",3826.4,19994.0],["delete",3824.4,0.0]],"asks":[],"prev_change_id":46343827537}}}
1761154842902 {"jsonrpc":"2.0","method":"subscription","params":{"channel":"book.ETH-PERPETUAL.raw","data":{"timestamp":1761154841804,"type":"change","change_id":46343827625,"instrument_name":"ETH-PERPETUAL","bids":[],"asks":[["new",3827.25,7993.0],["change",3827.75,6973069.0]],"prev_change_id":46343827549}}}
1761154842910 {"jsonrpc":"2.0","method":"subscription","params":{"channel":"book.ETH-PERPETUAL.raw","data":{"timestamp":1761154841814,"type":"change","change_id":46343827636,"instrument_name":"ETH-PERPETUAL","bids":[["new",3826.5,5968.0],["delete",3824.25,0.0]],"asks":[],"prev_change_id":46343827625}}}
1761154842946 {"jsonrpc":"2.0","method":"subscription","params":{"channel":"book.ETH-PERPETUAL.raw","data":{"timestamp":1761154841844,"type":"change","change_id":46343827641,"instrument_name":"ETH-PERPETUAL","bids":[],"asks":[["new",3827.1,22158.0],["change",3827.8,6783.0]],"prev_change_id":46343827636}}}
1761154842952 {"jsonrpc":"2.0","method":"subscription","params":{"channel":"book.ETH-PERPETUAL.raw","data":{"timestamp":1761154841854,"type":"change","change_id":46343827652,"instrument_name":"ETH-PERPETUAL","bids":[["new",3827.05,5539.0],["delete",3824.15,0.0]],"asks":[],"prev_change_id":46343827641}}}
1761154843412 {"jsonrpc":"2.0","id":999,"result":{"version":"1.2.26"},"usIn":1761154842276838,"usOut":1761154842276881,"usDiff":43,"testnet":true}
1761154843962 {"jsonrpc":"2.0","method":"subscription","params":{"channel":"book.BTC-PERPETUAL.raw","data":{"timestamp":1761154842790,"type":"change","change_id":67840128973,"instrument_name":"BTC-PERPETUAL","bids":[],"asks":[["delete",107909.5,0.0],["new",107960.5,7670.0]],"prev_change_id":67840123192}}}
1761154843967 {"jsonrpc":"2.0","method":"subscription","params":{"channel":"book.BTC-PERPETUAL.raw","data":{"timestamp":1761154842792,"type":"change","change_id":67840128974,"instrument_name":"BTC-PERPETUAL","bids":[["new",107909.5,4.5e4],["delete",107909.0,0.0]],"asks":[],"prev_change_id":67840128973}}}
1761154844003 {"jsonrpc":"2.0","method":"subscription","params":{"channel":"book.BTC-PERPETUAL.raw","data":{"timestamp":1761154842830,"type":"change","change_id":67840128976,"instrument_name":"BTC-PERPETUAL","bids":[],"asks":[["delete",107914.0,0.0],["new",107959.5,10.0]],"prev_change_id":67840128974}}}
1761154844010 {"jsonrpc":"2.0","method":"subscription","params":{"channel":"book.BTC-PERPETUAL.raw","data":{"timestamp":1761154842832,"type":"change","change_id":67840128977,"instrument_name":"BTC-PERPETUAL","bids":[["new",107910.0,59230.0],["delete",107908.5,0.0]],"asks":[],"prev_change_id":67840128976}}}
1761154844045 {"jsonrpc":"2.0","method":"subscription","params":{"channel":"book.BTC-PERPETUAL.raw","data":{"timestamp":1761154842869,"type":"change","change_id":67840129028,"instrument_name":"BTC-PERPETUAL","bids":[],"asks":[["delete",107916.0,0.0],["new",107957.5,33090.0]],"prev_change_id":67840128977}}}
1761154844050 {"jsonrpc":"2.0","method":"subscription","params":{"channel":"book.BTC-PERPETUAL.raw","data":{"timestamp":1761154842873,"type":"change","change_id":67840129029,"instrument_name":"BTC-PERPETUAL","bids":[["new",107912.5,33090.0],["delete",107908.0,0.0]],"asks":[],"prev_change_id":67840129028}}}
1761154844083 {"jsonrpc":"2.0","method":"subscription","params":{"channel":"book.BTC-PERPETUAL.raw","data":{"timestamp":1761154842909,"type":"change","change_id":67840129030,"instrument_name":"BTC-PERPETUAL","bids":[],"asks":[["delete",107917.5,0.0],["new",107956.0,1.78e4]],"prev_change_id":67840129029}}}
1761154844089 {"jsonrpc":"2.0","method":"subscription","params":{"channel":"book.BTC-PERPETUAL.raw","data":{"timestamp":1761154842912,"type":"change","change_id":67840129033,"instrument_name":"BTC-PERPETUAL","bids":[["new",107913.5,500.0],["delete",107904.5,0.0]],"asks":[],"prev_change_id":67840129030}}}
1761154844129 {"jsonrpc":"2.0","method":"subscription","params":{"channel":"book.BTC-PERPETUAL.raw","data":{"timestamp":1761154842951,"type":"change","change_id":67840129035,"instrument_name":"BTC-PERPETUAL","bids":[],"asks":[["delete",107921.5,0.0],["new",107954.5,16990.0]],"prev_change_id":67840129033}}}
1761154844139 {"jsonrpc":"2.0","method":"subscription","params":{"channel":"book.BTC-PERPETUAL.raw","data":{"timestamp":1761154842953,"type":"change","change_id":67840129037,"instrument_name":"BTC-PERPETUAL","bids":[["new",107914.0,31070.0],["delete",107904.0,0.0]],"asks":[],"prev_change_id":67840129035}}}
1761154844171 {"jsonrpc":"2.0","method":"subscription","params":{"channel":"book.BTC-PERPETUAL.raw","data":{"timestamp":1761154842990,"type":"change","change_id":67840129039,"instrument_name":"BTC-PERPETUAL","bids":[],"asks":[["delete",107922.0,0.0],["new",107954.0,2.1e3]],"prev_change_id":67840129037}}}
1761154844177 {"jsonrpc":"2.0","method":"subscription","params":{"channel":"book.BTC-PERPETUAL.raw","data":{"timestamp":1761154842994,"type":"change","change_id":67840129041,"instrument_name":"BTC-PERPETUAL","bids":[["new",107919.0,2.1e3],["delete",107900.5,0.0]],"asks":[],"prev_change_id":67840129039}}}
1761154844220 {"jsonrpc":"2.0","method":"subscription","params":{"channel":"book.BTC-PERPETUAL.raw","data":{"timestamp":1761154843032,"type":"change","change_id":67840129157,"instrument_name":"BTC-PERPETUAL","bids":[],"asks":[["delete",107922.5,0.0],["new",107953.5,31240.0]],"prev_change_id":67840129041}}}
1761154844225 {"jsonrpc":"2.0","method":"subscription","params":{"channel":"book.BTC-PERPETUAL.raw","data":{"timestamp":1761154843036,"type":"change","change_id":67840129163,"instrument_name":"BTC-PERPETUAL","bids":[["new",107919.5,5.03e4],["delete",1.079e5,0.0]],"asks":[],"prev_change_id":67840129157}}}
1761154844265 {"jsonrpc":"2.0","method":"subscription","params":{"channel":"book.BTC-PERPETUAL.raw","data":{"timestamp":1761154843073,"type":"change","change_id":67840129167,"instrument_name":"BTC-PERPETUAL","bids":[],"asks":[["delete",107923.0,0.0],["new",107951.0,2.5e4]],"prev_change_id":67840129163}}}
1761154844270 {"jsonrpc":"2.0","method":"subscription","params":{"channel":"book.BTC-PERPETUAL.raw","data":{"timestamp":1761154843077,"type":"change","change_id":67840129171,"instrument_name":"BTC-PERPETUAL","bids":[["new",107920.0,15640.0],["delete",107899.0,0.0]],"asks":[],"prev_change_id":67840129167}}}
1761154844303 {"jsonrpc":"2.0","method":"subscription","params":{"channel":"book.BTC-PERPETUAL.raw","data":{"timestamp":1761154843114,"type":"change","change_id":67840129173,"instrument_name":"BTC-PERPETUAL","bids":[],"asks":[["delete",107923.5,0.0],["new",107950.0,20.0]],"prev_change_id":67840129171}}}
1761154844308 {"jsonrpc":"2.0","method":"subscription","params":{"channel":"book.BTC-PERPETUAL.raw","data":{"timestamp":1761154843118,"type":"change","change_id":67840129177,"instrument_name":"BTC-PERPETUAL","bids":[["new",107921.5,8440.0],["delete",107898.0,0.0]],"asks":[],"prev_change_id":67840129173}}}
1761154844345 {"jsonrpc":"2.0","method":"subscription","params":{"channel":"book.BTC-PERPETUAL.raw","data":{"timestamp":1761154843152,"type":"change","change_id":67840129180,"instrument_name":"BTC-PERPETUAL","bids":[],"asks":[["delete",107925.0,0.0],["new",107949.5,8440.0]],"prev_change_id":67840129177}}}
1761154844356 {"jsonrpc":"2.0","method":"subscription","params":{"channel":"book.BTC-PERPETUAL.raw","data":{"timestamp":1761154843159,"type":"change","change_id":67840129186,"instrument_name":"BTC-PERPETUAL","bids":[["new",107922.0,61590.0],["delete",107897.5,0.0]],"asks":[],"prev_change_id":67840129180}}}
1761154844387 {"jsonrpc":"2.0","method":"subscription","params":{"channel":"book.BTC-PERPETUAL.raw","data":{"timestamp":1761154843191,"type":"change","change_id":67840129188,"instrument_name":"BTC-PERPETUAL","bids":[],"asks":[["delete",107926.5,0.0],["new",107949.0,1.88e4]],"prev_change_id":67840129186}}}
1761154844399 {"jsonrpc":"2.0","method":"subscription","params":{"channel":"book.BTC-PERPETUAL.raw","data":{"timestamp":1761154843201,"type":"change","change_id":67840129194,"instrument_name":"BTC-PERPETUAL","bids":[["new",107923.5,8620.0],["delete",107893.0,0.0]],"asks":[],"prev_change_id":67840129188}}}
1761154844433 {"jsonrpc":"2.0","method":"subscription","params":{"channel":"book.BTC-PERPETUAL.raw","data":{"timestamp":1761154843231,"type":"change","change_id":67840129197,"instrument_name":"BTC-PERPETUAL","bids":[],"asks":[["delete",107930.5,0.0],["new",107948.5,510.0]],"prev_change_id":67840129194}}}
1761154844440 {"jsonrpc":"2.0","method":"subscription","params":{"channel":"book.BTC-PERPETUAL.raw","data":{"timestamp":1761154843242,"type":"change","change_id":67840129203,"instrument_name":"BTC-PERPETUAL","bids":[["new",107924.0,30.0],["delete",107892.5,0.0]],"asks":[],"prev_change_id":67840129197}}}
1761154844473 {"jsonrpc":"2.0","method":"subscription","params":{"channel":"book.BTC-PERPETUAL.raw","data":{"timestamp":1761154843270,"type":"change","change_id":67840129206,"instrument_name":"BTC-PERPETUAL","bids":[],"asks":[["delete",107931.5,0.0],["new",107948.0,20.0]],"prev_change_id":67840129203}}}
1761154844485 {"jsonrpc":"2.0","method":"subscription","params":{"channel":"book.BTC-PERPETUAL.raw","data":{"timestamp":1761154843283,"type":"change","change_id":67840129318,"instrument_name":"BTC-PERPETUAL","bids":[["new",107924.5,49340.0],["delete",107890.5,0.0]],"asks":[],"prev_change_id":67840129206}}}
1761154844516 {"jsonrpc":"2.0","method":"subscription","params":{"channel":"book.BTC-PERPETUAL.raw","data":{"timestamp":1761154843310,"type":"change","change_id":67840129352,"instrument_name":"BTC-PERPETUAL","bids":[],"asks":[["delete",107932.0,0.0],["new",107946.5,7.02e4]],"prev_change_id":67840129318}}}
1761154844532 {"jsonrpc":"2.0","method":"subscription","params":{"channel":"book.BTC-PERPETUAL.raw","data":{"timestamp":1761154843323,"type":"change","change_id":67840129360,"instrument_name":"BTC-PERPETUAL","bids":[["new",107925.0,5.48e4],["delete",107889.0,0.0]],"asks":[],"prev_change_id":67840129352}}}
1761154844557 {"jsonrpc":"2.0","method":"subscription","params":{"channel":"book.BTC-PERPETUAL.raw","data":{"timestamp":1761154843350,"type":"change","change_id":67840129362,"instrument_name":"BTC-PERPETUAL","bids":[],"asks":[["delete",107933.0,0.0],["new",107946.0,8620.0]],"prev_change_id":67840129360}}}
1761154844571 {"jsonrpc":"2.0","method":"subscription","params":{"channel":"book.BTC-PERPETUAL.raw","data":{"timestamp":1761154843364,"type":"change","change_id":67840129379,"instrument_name":"BTC-PERPETUAL","bids":[["new",107926.5,54790.0],["delete",107888.0,0.0]],"asks":[],"prev_change_id":67840129362}}}
1761154844599 {"jsonrpc":"2.0","method":"subscription","params":{"channel":"book.BTC-PERPETUAL.raw","data":{"timestamp":1761154843389,"type":"change","change_id":67840129944,"instrument_name":"BTC-PERPETUAL","bids":[],"asks":[["delete",107936.5,0.0],["new",107945.5,23210.0]],"prev_change_id":67840129379}}}
1761154844614 {"jsonrpc":"2.0","method":"subscription","params":{"channel":"book.BTC-PERPETUAL.raw","data":{"timestamp":1761154843403,"type":"change","change_id":67840129954,"instrument_name":"BTC-PERPETUAL","bids":[["new",107927.0,20.0],["delete",107887.0,0.0]],"asks":[],"prev_change_id":67840129944}}}
1761154844649 {"jsonrpc":"2.0","method":"subscription","params":{"channel":"book.BTC-PERPETUAL.raw","data":{"timestamp":1761154843432,"type":"change","change_id":67840129956,"instrument_name":"BTC-PERPETUAL","bids":[],"asks":[["delete",107937.0,0.0],["new",107940.0,20.0]],"prev_change_id":67840129954}}}
1761154844658 {"jsonrpc":"2.0","method":"subscription","params":{"channel":"book.BTC-PERPETUAL.raw","data":{"timestamp":1761154843444,"type":"change","change_id":67840129966,"instrument_name":"BTC-PERPETUAL","bids":[["new",107927.5,20.0],["delete",107886.5,0.0]],"asks":[],"prev_change_id":67840129956}}}
1761154844691 {"jsonrpc":"2.0","method":"subscription","params":{"channel":"book.BTC-PERPETUAL.raw","data":{"timestamp":1761154843475,"type":"change","change_id":67840129968,"instrument_name":"BTC-PERPETUAL","bids":[],"asks":[["delete",107938.5,0.0],["change",107939.5,11020.0]],"prev_change_id":67840129966}}}
1761154844707 {"jsonrpc":"2.0","method":"subscription","params":{"channel":"book.BTC-PERPETUAL.raw","data":{"timestamp":1761154843484,"type":"change","change_id":67840129978,"instrument_name":"BTC-PERPETUAL","bids":[["new",107928.5,50990.0],["delete",107884.0,0.0]],"asks":[],"prev_change_id":67840129968}}}
1761154844733 {"jsonrpc":"2.0","method":"subscription","params":{"channel":"book.BTC-PERPETUAL.raw","data":{"timestamp":1761154843514,"type":"change","change_id":67840130087,"instrument_name":"BTC-PERPETUAL","bids":[],"asks":[["change",107939.0,20.0]],"prev_change_id":67840129978}}}
1761154844747 {"jsonrpc":"2.0","method":"subscription","params":{"channel":"book.BTC-PERPETUAL.raw","data":{"timestamp":1761154843526,"type":"change","change_id":67840130104,"instrument_name":"BTC-PERPETUAL","bids":[["new",107929.0,55490.0],["delete",107883.5,0.0]],"asks":[],"prev_change_id":67840130087}}}
1761154844774 {"jsonrpc":"2.0","method":"subscription","params":{"channel":"book.BTC-PERPETUAL.raw","data":{"timestamp":1761154843552,"type":"change","change_id":67840130106,"instrument_name":"BTC-PERPETUAL","bids":[],"asks":[["new",107935.0,72210.0],["change",107939.5,20.0]],"prev_change_id":67840130104}}}
1761154844792 {"jsonrpc":"2.0","method":"subscription","params":{"channel":"book.BTC-PERPETUAL.raw","data":{"timestamp":1761154843568,"type":"change","change_id":67840130118,"instrument_name":"BTC-PERPETUAL","bids":[["new",107934.5,258770.0],["delete",107882.5,0.0]],"asks":[],"prev_change_id":67840130106}}}
1761154844889 {"jsonrpc":"2.0","method":"subscription","params":{"channel":"book.ETH-PERPETUAL.raw","data":{"timestamp":1761154843659,"type":"change","change_id":46343829993,"instrument_name":"ETH-PERPETUAL","bids":[],"asks":[["change",3827.75,1.0e3],["new",3829.4,6972069.0]],"prev_change_id":46343827652}}}
1761154847737 {"jsonrpc":"2.0","method":"subscription","params":{"channel":"book.ETH-PERPETUAL.raw","data":{"timestamp":1761154846329,"type":"change","change_id":46343832836,"instrument_name":"ETH-PERPETUAL","bids":[],"asks":[["delete",3827.1,0.0],["new",3827.95,6075.0]],"prev_change_id":46343829993}}}
1761154847741 {"jsonrpc":"2.0","method":"subscription","params":{"channel":"book.ETH-PERPETUAL.raw","data":{"timestamp":1761154846331,"type":"change","change_id":46343832837,"instrument_name":"ETH-PERPETUAL","bids":[["delete",3827.05,0.0],["new",3824.65,4429.0]],"asks":[],"prev_change_id":46343832836}}}
1761154847779 {"jsonrpc":"2.0","method":"subscription","params":{"channel":"book.ETH-PERPETUAL.raw","data":{"timestamp":1761154846368,"type":"change","change_id":46343832838,"instrument_name":"ETH-PERPETUAL","bids":[],"asks":[["delete",3827.25,0.0],["new",3827.9,1840.0]],"prev_change_id":46343832837}}}
1761154847785 {"jsonrpc":"2.0","method":"subscription","params":{"channel":"book.ETH-PERPETUAL.raw","data":{"timestamp":1761154846371,"type":"change","change_id":46343832839,"instrument_name":"ETH-PERPETUAL","bids":[["delete",3826.5,0.0],["change",3824.85,9706.0]],"asks":[],"prev_change_id":46343832838}}}
1761154847818 {"jsonrpc":"2.0","method":"subscription","params":{"channel":"book.ETH-PERPETUAL.raw","data":{"timestamp":1761154846407,"type":"change","change_id":46343832843,"instrument_name":"ETH-PERPETUAL","bids":[],"asks":[["delete",3827.3,0.0],["change",3827.75,17717.0]],"prev_change_id":46343832839}}}
1761154847824 {"jsonrpc":"2.0","method":"subscription","params":{"channel":"book.ETH-PERPETUAL.raw","data":{"timestamp":1761154846411,"type":"change","change_id":46343832845,"instrument_name":"ETH-PERPETUAL","bids":[["delete",3826.4,0.0],["change",3824.9,22182.0]],"asks":[],"prev_change_id":46343832843}}}
1761154847865 {"jsonrpc":"2.0","method":"subscription","params":{"channel":"book.ETH-PERPETUAL.raw","data":{"timestamp":1761154846447,"type":"change","change_id":46343833020,"instrument_name":"ETH-PERPETUAL","bids":[],"asks":[["delete",3827.55,0.0],["change",3827.7,21707.0]],"prev_change_id":46343832845}}}
1761154847871 {"jsonrpc":"2.0","method":"subscription","params":{"channel":"book.ETH-PERPETUAL.raw","data":{"timestamp":1761154846451,"type":"change","change_id":46343833021,"instrument_name":"ETH-PERPETUAL","bids":[["delete",3826.15,0.0],["change",3825.0,6486.0]],"asks":[],"prev_change_id":46343833020}}}
1761154847908 {"jsonrpc":"2.0","method":"subscription","params":{"channel":"book.ETH-PERPETUAL.raw","data":{"timestamp":1761154846487,"type":"change","change_id":46343833094,"instrument_name":"ETH-PERPETUAL","bids":[],"asks":[["new",3827.55,4424.0],["delete",3827.6,0.0]],"prev_change_id":46343833021}}}
1761154847914 {"jsonrpc":"2.0","method":"subscription","params":{"channel":"book.ETH-PERPETUAL.raw","data":{"timestamp":1761154846492,"type":"change","change_id":46343833095,"instrument_name":"ETH-PERPETUAL","bids":[["delete",3826.1,0.0],["new",3825.05,19986.0]],"asks":[],"prev_change_id":46343833094}}}
1761154847931 {"jsonrpc":"2.0","method":"subscription","params":{"channel":"book.BTC-PERPETUAL.raw","data":{"timestamp":1761154846512,"type":"change","change_id":67840133848,"instrument_name":"BTC-PERPETUAL","bids":[["new",107881.0,6462890.0],["delete",107855.5,0.0]],"asks":[],"prev_change_id":67840130118}}}
1761154847946 {"jsonrpc":"2.0","method":"subscription","params":{"channel":"book.ETH-PERPETUAL.raw","data":{"timestamp":1761154846528,"type":"change","change_id":46343833102,"instrument_name":"ETH-PERPETUAL","bids":[],"asks":[["new",3827.5,4438.0],["delete",3827.65,0.0]],"prev_change_id":46343833095}}}
1761154847954 {"jsonrpc":"2.0","method":"subscription","params":{"channel":"book.ETH-PERPETUAL.raw","data":{"timestamp":1761154846532,"type":"change","change_id":46343833103,"instrument_name":"ETH-PERPETUAL","bids":[["delete",3826.0,0.0],["change",3825.15,8856.0]],"asks":[],"prev_change_id":46343833102}}}
1761154847991 {"jsonrpc":"2.0","method":"subscription","params":{"channel":"book.ETH-PERPETUAL.raw","data":{"timestamp":1761154846568,"type":"change","change_id":46343833106,"instrument_name":"ETH-PERPETUAL","bids":[],"asks":[["new",3827.4,3645.0],["change",3827.7,4990.0]],"prev_change_id":46343833103}}}
1761154847995 {"jsonrpc":"2.0","method":"subscription","params":{"channel":"book.ETH-PERPETUAL.raw","data":{"timestamp":1761154846576,"type":"change","change_id":46343833108,"instrument_name":"ETH-PERPETUAL","bids":[["delete",3825.95,0.0],["change",3825.25,30404.0]],"asks":[],"prev_change_id":46343833106}}}
1761154848036 {"jsonrpc":"2.0","method":"subscription","params":{"channel":"book.ETH-PERPETUAL.raw","data":{"timestamp":1761154846608,"type":"change","change_id":46343833408,"instrument_name":"ETH-PERPETUAL","bids":[],"asks":[["new",3827.35,1604.0],["change",3827.75,16717.0]],"prev_change_id":46343833108}}}
1761154848041 {"jsonrpc":"2.0","method":"subscription","params":{"channel":"book.ETH-PERPETUAL.raw","data":{"timestamp":1761154846616,"type":"change","change_id":46343833413,"instrument_name":"ETH-PERPETUAL","bids":[["delete",3825.9,0.0],["new",3825.35,15388.0]],"asks":[],"prev_change_id":46343833408}}}
1761154848072 {"jsonrpc":"2.0","method":"subscription","params":{"channel":"book.ETH-PERPETUAL.raw","data":{"timestamp":1761154846647,"type":"change","change_id":46343833438,"instrument_name":"ETH-PERPETUAL","bids":[],"asks":[["new",3827.25,16717.0],["delete",3827.8,0.0]],"prev_change_id":46343833413}}}
1761154848081 {"jsonrpc":"2.0","method":"subscription","params":{"channel":"book.ETH-PERPETUAL.raw","data":{"timestamp":1761154846656,"type":"change","change_id":46343833443,"instrument_name":"ETH-PERPETUAL","bids":[["delete",3825.85,0.0],["change",3825.4,24429.0]],"asks":[],"prev_change_id":46343833438}}}
1761154848114 {"jsonrpc":"2.0","method":"subscription","params":{"channel":"book.ETH-PERPETUAL.raw","data":{"timestamp":1761154846687,"type":"change","change_id":46343833503,"instrument_name":"ETH-PERPETUAL","bids":[],"asks":[["new",3827.2,58930.0],["delete",3827.85,0.0]],"prev_change_id":46343833443}}}
1761154848134 {"jsonrpc":"2.0","method":"subscription","params":{"channel":"book.ETH-PERPETUAL.raw","data":{"timestamp":1761154846697,"type":"change","change_id":46343833507,"instrument_name":"ETH-PERPETUAL","bids":[["delete",3825.8,0.0],["new",3825.5,625.0]],"asks":[],"prev_change_id":46343833503}}}
1761154848157 {"jsonrpc":"2.0","method":"subscription","params":{"channel":"book.ETH-PERPETUAL.raw","data":{"timestamp":1761154846726,"type":"change","change_id":46343833520,"instrument_name":"ETH-PERPETUAL","bids":[],"asks":[["new",3827.1,55080.0],["delete",3828.0,0.0]],"prev_change_id":46343833507}}}
1761154848168 {"jsonrpc":"2.0","method":"subscription","params":{"channel":"book.ETH-PERPETUAL.raw","data":{"timestamp":1761154846738,"type":"change","change_id":46343833523,"instrument_name":"ETH-PERPETUAL","bids":[["delete",3825.65,0.0],["change",3825.6,8866.0]],"asks":[],"prev_change_id":46343833520}}}
1761154848198 {"jsonrpc":"2.0","method":"subscription","params":{"channel":"book.ETH-PERPETUAL.raw","data":{"timestamp":1761154846766,"type":"change","change_id":46343833528,"instrument_name":"ETH-PERPETUAL","bids":[],"asks":[["new",3827.05,55080.0],["delete",3828.05,0.0]],"prev_change_id":46343833523}}}
1761154848212 {"jsonrpc":"2.0","method":"subscription","params":{"channel":"book.ETH-PERPETUAL.raw","data":{"timestamp":1761154846779,"type":"change","change_id":46343833533,"instrument_name":"ETH-PERPETUAL","bids":[["new",3825.65,1323.0],["change",3825.6,4433.0]],"asks":[],"prev_change_id":46343833528}}}
1761154848242 {"jsonrpc":"2.0","method":"subscription","params":{"channel":"book.ETH-PERPETUAL.raw","data":{"timestamp":1761154846807,"type":"change","change_id":46343833612,"instrument_name":"ETH-PERPETUAL","bids":[],"asks":[["new",3827.0,117294.0],["delete",3828.1,0.0]],"prev_change_id":46343833533}}}
1761154848255 {"jsonrpc":"2.0","method":"subscription","params":{"channel":"book.ETH-PERPETUAL.raw","data":{"timestamp":1761154846820,"type":"change","change_id":46343833617,"instrument_name":"ETH-PERPETUAL","bids":[["new",3825.8,16717.0],["change",3825.4,22792.0]],"asks":[],"prev_change_id":46343833612}}}
1761154848281 {"jsonrpc":"2.0","method":"subscription","params":{"channel":"book.BTC-PERPETUAL.raw","data":{"timestamp":1761154846844,"type":"change","change_id":67840134050,"instrument_name":"BTC-PERPETUAL","bids":[],"asks":[["delete",107963.0,0.0],["new",107988.5,5625750.0]],"prev_change_id":67840133848}}}
1761154848289 {"jsonrpc":"2.0","method":"subscription","params":{"channel":"book.ETH-PERPETUAL.raw","data":{"timestamp":1761154846846,"type":"change","change_id":46343833622,"instrument_name":"ETH-PERPETUAL","bids":[],"asks":[["new",3826.95,55080.0],["delete",3828.2,0.0]],"prev_change_id":46343833617}}}
1761154848299 {"jsonrpc":"2.0","method":"subscription","params":{"channel":"book.ETH-PERPETUAL.raw","data":{"timestamp":1761154846861,"type":"change","change_id":46343833627,"instrument_name":"ETH-PERPETUAL","bids":[["new",3825.85,1.5e4],["delete",3825.3,0.0]],"asks":[],"prev_change_id":46343833622}}}
1761154848326 {"jsonrpc":"2.0","method":"subscription","params":{"channel":"book.ETH-PERPETUAL.raw","data":{"timestamp":1761154846887,"type":"change","change_id":46343833632,"instrument_name":"ETH-PERPETUAL","bids":[],"asks":[["new",3826.9,85080.0],["delete",3828.3,0.0]],"prev_change_id":46343833627}}}
1761154848342 {"jsonrpc":"2.0","method":"subscription","params":{"channel":"book.ETH-PERPETUAL.raw","data":{"timestamp":1761154846901,"type":"change","change_id":46343833637,"instrument_name":"ETH-PERPETUAL","bids":[["new",3825.9,19993.0],["change",3825.25,7.0]],"asks":[],"prev_change_id":46343833632}}}
1761154848370 {"jsonrpc":"2.0","method":"subscription","params":{"channel":"book.ETH-PERPETUAL.raw","data":{"timestamp":1761154846928,"type":"change","change_id":46343833642,"instrument_name":"ETH-PERPETUAL","bids":[],"asks":[["new",3826.85,63094.0],["delete",3828.35,0.0]],"prev_change_id":46343833637}}}
1761154848385 {"jsonrpc":"2.0","method":"subscription","params":{"channel":"book.ETH-PERPETUAL.raw","data":{"timestamp":1761154846942,"type":"change","change_id":46343833649,"instrument_name":"ETH-PERPETUAL","bids":[["new",3826.0,15435.0],["change",3825.15,4428.0]],"asks":[],"prev_change_id":46343833642}}}
1761154848415 {"jsonrpc":"2.0","method":"subscription","params":{"channel":"book.ETH-PERPETUAL.raw","data":{"timestamp":1761154846969,"type":"change","change_id":46343833800,"instrument_name":"ETH-PERPETUAL","bids":[],"asks":[["new",3826.8,9.6e3],["delete",3828.4,0.0]],"prev_change_id":46343833649}}}
1761154848433 {"jsonrpc":"2.0","method":"subscription","params":{"channel":"book.ETH-PERPETUAL.raw","data":{"timestamp":1761154846982,"type":"change","change_id":46343833807,"instrument_name":"ETH-PERPETUAL","bids":[["new",3826.15,2852.0],["change",3825.0,2150.0]],"asks":[],"prev_change_id":46343833800}}}
1761154848454 {"jsonrpc":"2.0","method":"subscription","params":{"channel":"book.ETH-PERPETUAL.raw","data":{"timestamp":1761154847007,"type":"change","change_id":46343833812,"instrument_name":"ETH-PERPETUAL","bids":[],"asks":[["new",3826.75,2866.0],["delete",3828.45,0.0]],"prev_change_id":46343833807}}}
1761154848470 {"jsonrpc":"2.0","method":"subscription","params":{"channel":"book.ETH-PERPETUAL.raw","data":{"timestamp":1761154847022,"type":"change","change_id":46343833875,"instrument_name":"ETH-PERPETUAL","bids":[["new",3826.3,1070.0],["change",3824.9,1664.0]],"asks":[],"prev_change_id":46343833812}}}
1761154848498 {"jsonrpc":"2.0","method":"subscription","params":{"channel":"book.ETH-PERPETUAL.raw","data":{"timestamp":1761154847048,"type":"change","change_id":46343833880,"instrument_name":"ETH-PERPETUAL","bids":[],"asks":[["new",3826.6,5.0e3],["delete",3828.55,0.0]],"prev_change_id":46343833875}}}
1761154848512 {"jsonrpc":"2.0","method":"subscription","params":{"channel":"book.ETH-PERPETUAL.raw","data":{"timestamp":1761154847061,"type":"change","change_id":46343833887,"instrument_name":"ETH-PERPETUAL","bids":[["new",3826.4,1.0e3],["change",3824.85,5275.0]],"asks":[],"prev_change_id":46343833880}}}
1761154848540 {"jsonrpc":"2.0","method":"subscription","params":{"channel":"book.ETH-PERPETUAL.raw","data":{"timestamp":1761154847088,"type":"change","change_id":46343833894,"instrument_name":"ETH-PERPETUAL","bids":[],"asks":[["new",3826.55,11848.0],["delete",3828.65,0.0]],"prev_change_id":46343833887}}}
1761154848556 {"jsonrpc":"2.0","method":"subscription","params":{"channel":"book.ETH-PERPETUAL.raw","data":{"timestamp":1761154847103,"type":"change","change_id":46343833901,"instrument_name":"ETH-PERPETUAL","bids":[["new",3826.5,22386.0]],"asks":[],"prev_change_id":46343833894}}}
1761154848816 {"jsonrpc":"2.0","method":"subscription","params":{"channel":"book.BTC-PERPETUAL.raw","data":{"timestamp":1761154847347,"type":"change","change_id":67840134332,"instrument_name":"BTC-PERPETUAL","bids":[["new",107670.5,8.0085e6],["delete",107645.0,0.0]],"asks":[],"prev_change_id":67840134050}}}
1761154848956 {"jsonrpc":"2.0","method":"subscription","params":{"channel":"book.ETH-PERPETUAL.raw","data":{"timestamp":1761154847478,"type":"change","change_id":46343834507,"instrument_name":"ETH-PERPETUAL","bids":[["delete",3826.2,0.0]],"asks":[],"prev_change_id":46343833901}}}
1761154849210 {"jsonrpc":"2.0","method":"subscription","params":{"channel":"book.BTC-PERPETUAL.raw","data":{"timestamp":1761154847716,"type":"change","change_id":67840135176,"instrument_name":"BTC-PERPETUAL","bids":[],"asks":[["delete",108173.5,0.0],["new",108199.0,7.087e6]],"prev_change_id":67840134332}}}
1761154849554 {"jsonrpc":"2.0","method":"subscription","params":{"channel":"book.BTC-PERPETUAL.raw","data":{"timestamp":1761154848039,"type":"change","change_id":67840135370,"instrument_name":"BTC-PERPETUAL","bids":[],"asks":[["delete",107935.0,0.0],["change",107966.5,3.31e4]],"prev_change_id":67840135176}}}
1761154849565 {"jsonrpc":"2.0","method":"subscription","params":{"channel":"book.BTC-PERPETUAL.raw","data":{"timestamp":1761154848040,"type":"change","change_id":67840135371,"instrument_name":"BTC-PERPETUAL","bids":[["delete",107934.5,0.0],["change",107909.5,95290.0]],"asks":[],"prev_change_id":67840135370}}}
1761154849604 {"jsonrpc":"2.0","method":"subscription","params":{"channel":"book.BTC-PERPETUAL.raw","data":{"timestamp":1761154848080,"type":"change","change_id":67840135372,"instrument_name":"BTC-PERPETUAL","bids":[],"asks":[["delete",107939.0,0.0],["new",107965.5,17290.0]],"prev_change_id":67840135371}}}
